Workbook
Name DATA1: Sheet1!#REF!
Name DATA10: Sheet1!#REF!
Name DATA11: Sheet1!$E$2:$E$426
Name DATA12: Sheet1!$F$2:$F$426
Name DATA2: Sheet1!$A$2:$A$426
Name DATA3: Sheet1!$B$2:$B$426
Name DATA4: Sheet1!#REF!
Name DATA5: Sheet1!$G$2:$G$426
Name DATA6: Sheet1!$H$2:$H$426
Name DATA7: Sheet1!$I$2:$I$426
Name DATA8: Sheet1!$J$2:$J$426
Name DATA9: Sheet1!$D$2:$D$426
Name TEST0: Sheet1!$A$2:$J$426
Name TESTHKEY: Sheet1!$D$1:$F$1
Name TESTKEYS: Sheet1!$A$2:$J$426
Name TESTVKEY: Sheet1!$A$1:$J$1

Sheet Sheet2
A3: 合計 / 入庫/所要数量 | B3: 列ラベル
A4: 行ラベル | B4: TEC-1000 | C4: TEC-5600 | D4: 安全在庫 | E4: 購発注 | F4: 送信機 | G4: #N/A | H4: 総計
A5: 46120 | G5: -3204 | H5: -3204
A6: 46122 | C6: -192 | G6: -436 | H6: -628
A7: 46125 | B7: -96 | G7: -120 | H7: -216
A8: 46126 | D8: -8000 | F8: -192 | G8: 0 | H8: -8192
A9: 46127 | C9: -192 | G9: -240 | H9: -432
A10: 46129 | G10: 0 | H10: 0
A11: 46132 | G11: -192 | H11: -192
A12: 46133 | C12: -192 | G12: -96 | H12: -288
A13: 46134 | G13: -288 | H13: -288
A14: 46136 | C14: -192 | F14: -192 | G14: -20 | H14: -404
A15: 46139 | G15: -36 | H15: -36
A16: 46140 | C16: -192 | G16: -144 | H16: -336
A17: 46142 | B17: -480 | G17: -412 | H17: -892
A18: 46149 | G18: -168 | H18: -168
A19: 46150 | B19: -192 | C19: -192 | G19: -60 | H19: -444
A20: 46153 | G20: -1164 | H20: -1164
A21: 46154 | C21: -192 | G21: -576 | H21: -768
A22: 46155 | G22: -360 | H22: -360
A23: 46156 | C23: -192 | G23: -36 | H23: -228
A24: 46157 | B24: -192 | F24: -192 | G24: -144 | H24: -528
A25: 46160 | G25: -312 | H25: -312
A26: 46161 | C26: -192 | G26: -124 | H26: -316
A27: 46162 | F27: -192 | H27: -192
A28: 46163 | B28: -96 | G28: -96 | H28: -192
A29: 46164 | G29: -288 | H29: -288
A30: 46167 | B30: -288 | H30: -288
A31: 46168 | C31: -192 | H31: -192
A32: 46169 | G32: -96 | H32: -96
A33: 46171 | C33: -192 | H33: -192
A34: 46174 | B34: -192 | G34: -168 | H34: -360
A35: 46175 | C35: -192 | G35: -48 | H35: -240
A36: 46176 | G36: -96 | H36: -96
A37: 46177 | C37: -192 | G37: -96 | H37: -288
A38: 46178 | B38: -192 | G38: -1020 | H38: -1212
A39: 46181 | B39: -288 | G39: -192 | H39: -480
A40: 46182 | B40: -192 | C40: -192 | G40: -96 | H40: -480
A41: 46183 | G41: -192 | H41: -192
A42: 46184 | B42: -192 | C42: -192 | G42: -360 | H42: -744
...

Sheet Sheet1
A1: MRP 要素 | B1: MRP 要素データ | C1: グループ名 | D1: 所要日付 | E1: 入庫/所要数量 | F1: 利用可能数量 | G1: 保管場所 | H1: 指図情報 | I1: 外注購買/ファントム | J1: 納期回答済
A2: 在庫 | C2: =IF(A2="SafeSt","安全在庫",IF(A2="購発注","購発注",_xlfn.XLOOKUP(B2,グループ一覧!$B:$B,グループ一覧!$A:$A))) -> #N/A | D2: 46126 | E2: 0 | F2: 27186
A3: SafeSt | B3: 安全在庫 | C3: =IF(A3="SafeSt","安全在庫",IF(A3="購発注","購発注",_xlfn.XLOOKUP(B3,グループ一覧!$B:$B,グループ一覧!$A:$A))) -> 安全在庫 | D3: 46126 | E3: -8000 | F3: 19186
A4: 入出予 | B4: URS-0575 | C4: =IF(A4="SafeSt","安全在庫",IF(A4="購発注","購発注",_xlfn.XLOOKUP(B4,グループ一覧!$B:$B,グループ一覧!$A:$A))) -> #N/A | D4: 46120 | E4: -972 | F4: 18214 | G4: 0001 | H4: 212180188/7116/ REL RMWB PCNF
A5: 入出予 | B5: URS-0576 | C5: =IF(A5="SafeSt","安全在庫",IF(A5="購発注","購発注",_xlfn.XLOOKUP(B5,グループ一覧!$B:$B,グループ一覧!$A:$A))) -> #N/A | D5: 46120 | E5: -1068 | F5: 17146 | G5: 0001 | H5: 212180189/7116/ REL RMWB PCNF
A6: 入出予 | B6: URS-0582 | C6: =IF(A6="SafeSt","安全在庫",IF(A6="購発注","購発注",_xlfn.XLOOKUP(B6,グループ一覧!$B:$B,グループ一覧!$A:$A))) -> #N/A | D6: 46120 | E6: -1164 | F6: 15982 | G6: 0001 | H6: 212180193/7116/ REL BASC BCRQ
A7: 入出予 | B7: URS-0483-01 | C7: =IF(A7="SafeSt","安全在庫",IF(A7="購発注","購発注",_xlfn.XLOOKUP(B7,グループ一覧!$B:$B,グループ一覧!$A:$A))) -> TEC-5600 | D7: 46122 | E7: -192 | F7: 15790 | G7: 0001 | H7: 212181331/7116/ REL RMWB PCNF
A8: 入出予 | B8: URS-4192-01 | C8: =IF(A8="SafeSt","安全在庫",IF(A8="購発注","購発注",_xlfn.XLOOKUP(B8,グループ一覧!$B:$B,グループ一覧!$A:$A))) -> #N/A | D8: 46122 | E8: -100 | F8: 15690 | G8: 0001 | H8: 212181337/7116/ REL RMWB PCNF
A9: 入出予 | B9: UTS-0986-01 | C9: =IF(A9="SafeSt","安全在庫",IF(A9="購発注","購発注",_xlfn.XLOOKUP(B9,グループ一覧!$B:$B,グループ一覧!$A:$A))) -> #N/A | D9: 46122 | E9: -336 | F9: 15354 | G9: 0001 | H9: 212181349/7116/ REL RMWB PCNF
A10: 入出予 | B10: URS-06194 | C10: =IF(A10="SafeSt","安全在庫",IF(A10="購発注","購発注",_xlfn.XLOOKUP(B10,グループ一覧!$B:$B,グループ一覧!$A:$A))) -> TEC-1000 | D10: 46125 | E10: -96 | F10: 15258 | G10: 0001 | H10: 212181978/7116/ REL RMWB BASC
A11: 入出予 | B11: UTS-0981 | C11: =IF(A11="SafeSt","安全在庫",IF(A11="購発注","購発注",_xlfn.XLOOKUP(B11,グループ一覧!$B:$B,グループ一覧!$A:$A))) -> #N/A | D11: 46125 | E11: -96 | F11: 15162 | G11: 0001 | H11: 212181995/7116/ REL BASC BCRQ
A12: 入出予 | B12: UTS-1026-01 | C12: =IF(A12="SafeSt","安全在庫",IF(A12="購発注","購発注",_xlfn.XLOOKUP(B12,グループ一覧!$B:$B,グループ一覧!$A:$A))) -> #N/A | D12: 46125 | E12: -24 | F12: 15138 | G12: 0001 | H12: 212181996/7116/ REL BASC BCRQ
A13: 入出予 | B13: URS-4461 | C13: =IF(A13="SafeSt","安全在庫",IF(A13="購発注","購発注",_xlfn.XLOOKUP(B13,グループ一覧!$B:$B,グループ一覧!$A:$A))) -> 送信機 | D13: 46126 | E13: -192 | F13: 14946 | G13: 0001 | H13: 212178008/7116/ REL BASC BCRQ
A14: 従所要 | B14: URS-0483-01 | C14: =IF(A14="SafeSt","安全在庫",IF(A14="購発注","購発注",_xlfn.XLOOKUP(B14,グループ一覧!$B:$B,グループ一覧!$A:$A))) -> TEC-5600 | D14: 46127 | E14: -192 | F14: 14754 | G14: 0001
A15: 従所要 | B15: URS-4487 | C15: =IF(A15="SafeSt","安全在庫",IF(A15="購発注","購発注",_xlfn.XLOOKUP(B15,グループ一覧!$B:$B,グループ一覧!$A:$A))) -> #N/A | D15: 46127 | E15: -48 | F15: 14706 | G15: 0001
A16: 従所要 | B16: URS-4546 | C16: =IF(A16="SafeSt","安全在庫",IF(A16="購発注","購発注",_xlfn.XLOOKUP(B16,グループ一覧!$B:$B,グループ一覧!$A:$A))) -> #N/A | D16: 46127 | E16: -192 | F16: 14514 | G16: 0001
A17: -----> | B17: 計画タイムフェンス終了 | C17: =IF(A17="SafeSt","安全在庫",IF(A17="購発注","購発注",_xlfn.XLOOKUP(B17,グループ一覧!$B:$B,グループ一覧!$A:$A))) -> #N/A | D17: 46129 | E17: 0 | F17: 0
A18: 入出予 | B18: URS-4424 | C18: =IF(A18="SafeSt","安全在庫",IF(A18="購発注","購発注",_xlfn.XLOOKUP(B18,グループ一覧!$B:$B,グループ一覧!$A:$A))) -> #N/A | D18: 46132 | E18: -192 | F18: 14322 | G18: 0001 | H18: 212179683/7116/ CRTD BASC BCRQ
A19: 従所要 | B19: URS-0483-01 | C19: =IF(A19="SafeSt","安全在庫",IF(A19="購発注","購発注",_xlfn.XLOOKUP(B19,グループ一覧!$B:$B,グループ一覧!$A:$A))) -> TEC-5600 | D19: 46133 | E19: -192 | F19: 14130 | G19: 0001
A20: 従所要 | B20: UTS-0981 | C20: =IF(A20="SafeSt","安全在庫",IF(A20="購発注","購発注",_xlfn.XLOOKUP(B20,グループ一覧!$B:$B,グループ一覧!$A:$A))) -> #N/A | D20: 46133 | E20: -96 | F20: 14034 | G20: 0001
A21: 従所要 | B21: UTS-2536 | C21: =IF(A21="SafeSt","安全在庫",IF(A21="購発注","購発注",_xlfn.XLOOKUP(B21,グループ一覧!$B:$B,グループ一覧!$A:$A))) -> #N/A | D21: 46134 | E21: -288 | F21: 13746 | G21: 0001
A22: 従所要 | B22: UR-45461 | C22: =IF(A22="SafeSt","安全在庫",IF(A22="購発注","購発注",_xlfn.XLOOKUP(B22,グループ一覧!$B:$B,グループ一覧!$A:$A))) -> #N/A | D22: 46136 | E22: -20 | F22: 13726 | G22: 0001
A23: 従所要 | B23: URS-0483-01 | C23: =IF(A23="SafeSt","安全在庫",IF(A23="購発注","購発注",_xlfn.XLOOKUP(B23,グループ一覧!$B:$B,グループ一覧!$A:$A))) -> TEC-5600 | D23: 46136 | E23: -192 | F23: 13534 | G23: 0001
A24: 従所要 | B24: URS-4461 | C24: =IF(A24="SafeSt","安全在庫",IF(A24="購発注","購発注",_xlfn.XLOOKUP(B24,グループ一覧!$B:$B,グループ一覧!$A:$A))) -> 送信機 | D24: 46136 | E24: -192 | F24: 13342 | G24: 0001
A25: 従所要 | B25: UR-43352-02 | C25: =IF(A25="SafeSt","安全在庫",IF(A25="購発注","購発注",_xlfn.XLOOKUP(B25,グループ一覧!$B:$B,グループ一覧!$A:$A))) -> #N/A | D25: 46139 | E25: -12 | F25: 13330 | G25: 0001
A26: 従所要 | B26: URS-43351-02 | C26: =IF(A26="SafeSt","安全在庫",IF(A26="購発注","購発注",_xlfn.XLOOKUP(B26,グループ一覧!$B:$B,グループ一覧!$A:$A))) -> #N/A | D26: 46139 | E26: -24 | F26: 13306 | G26: 0001
A27: 従所要 | B27: URS-0483-01 | C27: =IF(A27="SafeSt","安全在庫",IF(A27="購発注","購発注",_xlfn.XLOOKUP(B27,グループ一覧!$B:$B,グループ一覧!$A:$A))) -> TEC-5600 | D27: 46140 | E27: -192 | F27: 13114 | G27: 0001
A28: 従所要 | B28: UTS-0992-01 | C28: =IF(A28="SafeSt","安全在庫",IF(A28="購発注","購発注",_xlfn.XLOOKUP(B28,グループ一覧!$B:$B,グループ一覧!$A:$A))) -> #N/A | D28: 46140 | E28: -48 | F28: 13066 | G28: 0001
A29: 従所要 | B29: UTS-0987-02 | C29: =IF(A29="SafeSt","安全在庫",IF(A29="購発注","購発注",_xlfn.XLOOKUP(B29,グループ一覧!$B:$B,グループ一覧!$A:$A))) -> #N/A | D29: 46140 | E29: -96 | F29: 12970 | G29: 0001
A30: 従所要 | B30: URS-0596 | C30: =IF(A30="SafeSt","安全在庫",IF(A30="購発注","購発注",_xlfn.XLOOKUP(B30,グループ一覧!$B:$B,グループ一覧!$A:$A))) -> TEC-1000 | D30: 46142 | E30: -192 | F30: 12778 | G30: 0001
... A426: 購発注 | B426: 0406532974/00010 | C426: =IF(A426="SafeSt","安全在庫",IF(A426="購発注","購発注",_xlfn.XLOOKUP(B426,グループ一覧!$B:$B,グループ一覧!$A:$A))) -> 購発注 | D426: 46754 | E426: 10000 | F426: 6955 | G426: 0DA1

Sheet グループ一覧
A1: グループ名 | B1: 品目名 | C1: ライン | D1: 備考 | E1: 追加日
A2: 送信機 | B2: UR-4045 | C2: Line-1
A3: 送信機 | B3: UR-42951 | C3: Line-1
A4: 送信機 | B4: UR-43012 | C4: Line-1
A5: 送信機 | B5: UR-4346 | C5: Line-1
A6: 送信機 | B6: UR-4349-01 | C6: Line-1
A7: 送信機 | B7: UR-4372 | C7: Line-1 | H7: 1000 | I7: =H7-I11 -> 250
A8: 送信機 | B8: URS-4215 | C8: Line-1
A9: 送信機 | B9: URS-42881 | C9: Line-1 | H9: スプライシング切れるライン計算するやつ
A10: 送信機 | B10: URS-42882 | C10: Line-1 | H10: ↓部品 | I10: ↓結果
A11: 送信機 | B11: URS-42883 | C11: Line-1 | H11: 9000055842 | I11: =_xlfn.XLOOKUP(TEXT(H11,"@"),[1]PartList!B:B,[1]PartList!H:H) -> 750
A12: 送信機 | B12: URS-4289 | C12: Line-1
A13: 送信機 | B13: URS-42952 | C13: Line-1 | E13: 45768 | I13: 落ちる数
A14: 送信機 | B14: URS-42981 | C14: Line-1 | I14: =40/_xlfn.XLOOKUP(TEXT(H11,"@"),[1]!PartList[部品名],[1]!PartList[テープピッチ]) -> 10
A15: 送信機 | B15: URS-42982 | C15: Line-1
A16: 送信機 | B16: URS-43011 | C16: Line-1
A17: 送信機 | B17: URS-43013 | C17: Line-1
A18: 送信機 | B18: URS-43014 | C18: Line-1 | E18: 45792
A19: 送信機 | B19: URS-4348 | C19: Line-1 | E19: 45761
A20: 送信機 | B20: URS-43721 | C20: Line-1 | E20: 45819
A21: 送信機 | B21: URS-43721-01 | C21: Line-1 | E21: 46087
A22: 送信機 | B22: URS-4377 | C22: Line-1 | E22: 45761
A23: 送信機 | B23: URS-4377-01 | C23: Line-1 | E23: 46087
A24: 送信機 | B24: URS-4461 | C24: Line-1 | E24: 45824
A25: 送信機 | B25: URS-45451 | C25: Line-1 | E25: 45975
A26: 送信機 | B26: URS-45452 | C26: Line-1 | E26: 45975
A27: TEC-5600 | B27: UR-0475-01 | C27: Line-2 | D27: 試作 S付きで量産中
A28: TEC-5600 | B28: UR-0481-02 | C28: Line-2 | D28: 試作 S付きで量産中
A29: TEC-5600 | B29: UR-0483-01 | C29: Line-2 | D29: 試作 S付きで量産中
A30: TEC-5600 | B30: UR-0486 | C30: Line-2
A31: TEC-5600 | B31: UR-0486-01 | C31: Line-2
A32: TEC-5600 | B32: UR-0488-02 | C32: Line-2 | D32: 試作 S付きで量産中
A33: TEC-5600 | B33: UR-0489-01 | C33: Line-2 | D33: 試作 S付きで量産中
A34: TEC-5600 | B34: UR-0490-01 | C34: Line-2 | D34: 試作 S付きで量産中
A35: TEC-5600 | B35: UR-0493-01 | C35: Line-2 | D35: 試作 S付きで量産中
A36: TEC-5600 | B36: UR-0505-01 | C36: Line-2 | D36: 試作 S付きで量産中
A37: TEC-5600 | B37: URS-0437 | C37: Line-2
A38: TEC-5600 | B38: URS-0437-01 | C38: Line-2
A39: TEC-5600 | B39: URS-0475-01 | C39: Line-2
A40: TEC-5600 | B40: URS-0476-01 | C40: Line-2
...
