Workbook

Sheet 1ライン
A1: ■1ライン現状
B2: 16/12 ノズル | C2: チェンジャー | E2: 140S | F2: 168S | G2: 225S | H2: 226S | I2: 230S | J2: 235S | K2: 240S | L2: - | M2: 256S | N2: - | O2: - | P2: - | Q2: - | R2: - | S2: - | T2: - | U2: - | V2: - | Z2: 空き | AA2: 合計 | AB2: 備考
C3: M1 | D3: 1(16) | E3: 0 | F3: 0 | G3: 0 | H3: 12 | I3: 12 | J3: 6 | K3: 0 | M3: 0 | N3: 0 | O3: 0 | P3: 0 | Q3: 0 | R3: 0 | S3: 0 | T3: 0 | U3: 0 | V3: 0 | Z3: 2 | AA3: =SUM(E3:Z3) -> 32
D4: 2(16) | E4: 0 | F4: 0 | G4: 0 | H4: 12 | I4: 12 | J4: 6 | K4: 0 | M4: 0 | N4: 0 | O4: 0 | P4: 0 | Q4: 0 | R4: 0 | S4: 0 | T4: 0 | U4: 0 | V4: 0 | Z4: 2 | AA4: =SUM(E4:Z4) -> 32
C5: M2 | D5: 3(16) | E5: 0 | F5: 0 | G5: 0 | H5: 8 | I5: 12 | J5: 2 | K5: 2 | M5: 0 | N5: 0 | O5: 0 | P5: 0 | Q5: 0 | R5: 0 | S5: 0 | T5: 0 | U5: 0 | V5: 0 | Z5: 8 | AA5: =SUM(E5:Z5) -> 32
D6: 4(12) | E6: 0 | F6: 0 | G6: 0 | H6: 2 | I6: 2 | J6: 12 | K6: 12 | M6: 0 | N6: 0 | O6: 0 | P6: 0 | Q6: 0 | R6: 0 | S6: 0 | T6: 0 | U6: 0 | V6: 0 | Z6: 4 | AA6: =SUM(E6:Z6) -> 32
C7: M3 | D7: 5(12) | E7: 0 | F7: 4 | G7: 0 | H7: 2 | I7: 2 | J7: 12 | K7: 12 | M7: 0 | N7: 0 | O7: 0 | P7: 0 | Q7: 0 | R7: 0 | S7: 0 | T7: 0 | U7: 0 | V7: 0 | Z7: 0 | AA7: =SUM(E7:Z7) -> 32
D8: 6(12) | E8: 0 | F8: 0 | G8: 0 | H8: 2 | I8: 2 | J8: 12 | K8: 12 | M8: 0 | N8: 0 | O8: 0 | P8: 0 | Q8: 0 | R8: 0 | S8: 0 | T8: 0 | U8: 0 | V8: 0 | Z8: 4 | AA8: =SUM(E8:Z8) -> 32
C9: M4 | D9: 7(12) | E9: 5 | F9: 0 | G9: 0 | H9: 0 | I9: 8 | J9: 10 | K9: 8 | M9: 0 | N9: 0 | O9: 0 | P9: 0 | Q9: 0 | R9: 0 | S9: 0 | T9: 0 | U9: 0 | V9: 0 | Z9: 1 | AA9: =SUM(E9:Z9) -> 32
C10: Total | E10: =SUM(E3:E9) -> 5 | F10: =SUM(F3:F9) -> 4 | G10: =SUM(G3:G9) -> 0 | H10: =SUM(H3:H9) -> 38 | I10: =SUM(I3:I9) -> 50 | J10: =SUM(J3:J9) -> 60 | K10: =SUM(K3:K9) -> 46 | L10: =SUM(L3:L9) -> 0 | ... Z10: =SUM(Z3:Z9) -> 21 | AA10: =SUM(E10:Z10) -> 224
B11: 8ノズル | C11: チェンジャー | E11: 140 | F11: 168 | G11: - | H11: 226 | I11: 230 | J11: 235 | K11: 240 | L11: - | M11: 184 | N11: 185 | O11: 199 | P11: 709 | Q11: 184 | R11: 185 | S11: - | T11: - | U11: - | V11: - | Z11: 空き | AA11: 合計
C12: M4 | D12: 8(8) | E12: 4 | F12: 0 | G12: 0 | H12: 0 | I12: 0 | J12: 0 | K12: 6 | M12: 0 | N12: 0 | O12: 0 | P12: 1 | Q12: 0 | R12: 0 | S12: 0 | T12: 0 | U12: 0 | V12: 0 | Z12: 5 | AA12: =SUM(E12:Z12) -> 16
C13: M5 | D13: 9(8) | E13: 4 | F13: 2 | G13: 0 | H13: 0 | I13: 0 | J13: 2 | K13: 6 | M13: 0 | N13: 0 | O13: 0 | P13: 0 | Q13: 1 | R13: 1 | S13: 0 | T13: 0 | U13: 0 | V13: 0 | Z13: 0 | AA13: =SUM(E13:Z13) -> 16
D14: 10(8) | E14: 4 | F14: 0 | G14: 0 | H14: 0 | I14: 0 | J14: 2 | K14: 6 | M14: 1 | N14: 1 | O14: 0 | P14: 0 | Q14: 0 | R14: 0 | S14: 0 | T14: 0 | U14: 0 | V14: 0 | Z14: 2 | AA14: =SUM(E14:Z14) -> 16
C15: Total | E15: =SUM(E12:E14) -> 12 | F15: =SUM(F12:F14) -> 2 | G15: =SUM(G12:G14) -> 0 | H15: =SUM(H12:H14) -> 0 | I15: =SUM(I12:I14) -> 0 | J15: =SUM(J12:J14) -> 4 | K15: =SUM(K12:K14) -> 18 | M15: =SUM(M12:M14) -> 1 | N15: =SUM(N12:N14) -> 1 | O15: =SUM(O12:O14) -> 0 | P15: =SUM(P12:P14) -> 1 | Q15: =SUM(Q12:Q14) -> 1 | R15: =SUM(R12:R14) -> 1 | S15: =SUM(S12:S14) -> 0 | T15: =SUM(T12:T14) -> 0 | ... V15: =SUM(V12:V14) -> 0 | Z15: =SUM(Z12:Z14) -> 7 | AA15: =SUM(E15:Z15) -> 48
B16: 3ノズル | C16: チェンジャー | E16: 1001 | F16: 1002 | G16: 1003 | H16: 1004 | I16: 1005 | J16: 1006 | K16: 1115 | L16: 1273 | M16: 1404 | N16: 1421 | O16: 1424 | P16: 1479 | Q16: 1551 | R16: 1672 | S16: 2405 | T16: 2418 | U16: 2421 | V16: 2467 | W16: 3192 | X16: 4192 | Y16: 4171 | Z16: 空き | AA16: 合計
C17: M6 | D17: 11(3) | E17: 1 | F17: 1 | G17: 2 | H17: 1 | I17: 2 | J17: 1 | K17: 0 | L17: 0 | M17: 1 | N17: 1 | O17: 1 | P17: 0 | Q17: 1 | R17: 0 | S17: 0 | T17: 0 | U17: 0 | V17: 0 | W17: 1 | X17: 1 | Y17: 0 | Z17: 1 | AA17: =SUM(E17:Z17) -> 15
D18: 12(3) | E18: 1 | F18: 3 | G18: 2 | H18: 1 | I18: 2 | J18: 1 | K18: 0 | L18: 0 | M18: 0 | N18: 0 | O18: 0 | P18: 1 | Q18: 0 | R18: 0 | S18: 0 | T18: 0 | U18: 0 | V18: 1 | W18: 0 | X18: 0 | Y18: 1 | Z18: 2 | AA18: =SUM(E18:Z18) -> 15
C19: M7 | D19: 13(3) | E19: 1 | F19: 1 | G19: 2 | H19: 1 | I19: 2 | J19: 1 | K19: 1 | L19: 1 | M19: 0 | N19: 1 | O19: 0 | P19: 0 | Q19: 0 | R19: 1 | S19: 1 | T19: 1 | U19: 0 | V19: 0 | W19: 0 | X19: 0 | Y19: 0 | Z19: 1 | AA19: =SUM(E19:Z19) -> 15
D20: 14(3) | E20: 1 | F20: 1 | G20: 2 | H20: 1 | I20: 2 | J20: 1 | K20: 1 | L20: 0 | M20: 1 | N20: 1 | O20: 0 | P20: 0 | Q20: 0 | R20: 0 | S20: 1 | T20: 1 | U20: 1 | V20: 0 | W20: 0 | X20: 0 | Y20: 0 | Z20: 1 | AA20: =SUM(E20:Z20) -> 15
C21: Total | E21: =SUM(E17:E20) -> 4 | F21: =SUM(F17:F20) -> 6 | G21: =SUM(G17:G20) -> 8 | H21: =SUM(H17:H20) -> 4 | I21: =SUM(I17:I20) -> 8 | J21: =SUM(J17:J20) -> 4 | K21: =SUM(K17:K20) -> 2 | L21: =SUM(L17:L20) -> 1 | ... Z21: =SUM(Z17:Z20) -> 5 | AA21: =SUM(E21:Z21) -> 60

Sheet 2ライン
A1: ■2ライン現状
B2: 16/12 ノズル | C2: チェンジャー | E2: 140S | F2: 168S | G2: 225S | H2: 226S | I2: 230S | J2: 235S | K2: 240S | L2: - | M2: 256S | N2: - | O2: - | P2: - | Q2: - | R2: - | S2: - | T2: - | U2: - | V2: - | Z2: 空き | AA2: 合計 | AB2: 備考
C3: M1 | D3: 1(16) | E3: 0 | F3: 0 | G3: 0 | H3: 0 | I3: 15 | J3: 15 | K3: 0 | M3: 0 | Z3: 2 | AA3: =SUM(E3:Z3) -> 32
D4: 2(16) | E4: 0 | F4: 0 | G4: 0 | H4: 12 | I4: 12 | J4: 6 | K4: 0 | M4: 0 | Z4: 2 | AA4: =SUM(E4:Z4) -> 32
C5: M2 | D5: 3(16) | E5: 0 | F5: 0 | G5: 0 | H5: 8 | I5: 16 | J5: 6 | K5: 0 | M5: 0 | Z5: 2 | AA5: =SUM(E5:Z5) -> 32
D6: 4(12) | E6: 0 | F6: 0 | G6: 0 | H6: 12 | I6: 12 | J6: 6 | K6: 0 | M6: 0 | Z6: 2 | AA6: =SUM(E6:Z6) -> 32
C7: M3 | D7: 5(12) | E7: 0 | F7: 0 | G7: 0 | H7: 8 | I7: 12 | J7: 2 | K7: 2 | M7: 0 | Z7: 8 | AA7: =SUM(E7:Z7) -> 32
D8: 6(12) | E8: 0 | F8: 0 | G8: 0 | H8: 2 | I8: 2 | J8: 12 | K8: 12 | M8: 0 | Z8: 4 | AA8: =SUM(E8:Z8) -> 32
C9: M4 | D9: 7(12) | E9: 0 | F9: 4 | G9: 0 | H9: 0 | I9: 2 | J9: 12 | K9: 12 | M9: 0 | Z9: 2 | AA9: =SUM(E9:Z9) -> 32
D10: 8(12) | E10: 4 | F10: 0 | G10: 0 | H10: 0 | I10: 8 | J10: 10 | K10: 8 | M10: 0 | Z10: 2 | AA10: =SUM(E10:Z10) -> 32
C11: Total | E11: =SUM(E3:E10) -> 4 | F11: =SUM(F3:F10) -> 4 | G11: =SUM(G3:G10) -> 0 | H11: =SUM(H3:H10) -> 42 | I11: =SUM(I3:I10) -> 79 | J11: =SUM(J3:J10) -> 69 | K11: =SUM(K3:K10) -> 34 | L11: =SUM(L3:L10) -> 0 | ... Y11: =SUM(Y3:Y10) -> 0 | Z11: =SUM(Z3:Z9) -> 22 | AA11: =SUM(E11:Z11) -> 254
B12: 8ノズル | C12: チェンジャー | E12: 140 | F12: 168 | G12: - | H12: 226 | I12: 230 | J12: 235 | K12: 240 | L12: - | M12: 184 | N12: 185 | O12: 199 | P12: 709 | Q12: 184 | R12: 185 | S12: - | T12: - | U12: - | V12: - | Z12: 空き | AA12: 合計
C13: M5 | D13: 9(8) | E13: 4 | F13: 2 | G13: 0 | H13: 0 | I13: 0 | J13: 0 | K13: 8 | M13: 0 | N13: 0 | O13: 1 | P13: 0 | Q13: 0 | R13: 0 | Z13: 1 | AA13: =SUM(E13:Z13) -> 16
D14: 10(8) | E14: 4 | F14: 0 | G14: 0 | H14: 0 | I14: 0 | J14: 2 | K14: 5 | M14: 0 | N14: 0 | O14: 0 | P14: 0 | Q14: 1 | R14: 1 | Z14: 3 | AA14: =SUM(E14:Z14) -> 16
C15: M6 | D15: 11(8) | E15: 4 | F15: 0 | G15: 0 | H15: 0 | I15: 1 | J15: 2 | K15: 5 | M15: 1 | N15: 1 | O15: 0 | P15: 0 | Q15: 0 | R15: 0 | Z15: 2 | AA15: =SUM(E15:Z15) -> 16
C16: Total | E16: =SUM(E13:E15) -> 12 | F16: =SUM(F13:F15) -> 2 | G16: =SUM(G13:G15) -> 0 | H16: =SUM(H13:H15) -> 0 | I16: =SUM(I13:I15) -> 1 | J16: =SUM(J13:J15) -> 4 | K16: =SUM(K13:K15) -> 18 | L16: =SUM(L13:L15) -> 0 | ... AA16: =SUM(AA13:AA15) -> 48
B17: 3ノズル | C17: チェンジャー | E17: 1001 | F17: 1002 | G17: 1003 | H17: 1004 | I17: 1005 | J17: 1006 | K17: 1115 | L17: 1273 | M17: 1404 | N17: 1421 | O17: 1424 | P17: 1479 | Q17: 1551 | R17: 1672 | S17: 2405 | T17: 2418 | U17: 2421 | V17: 2467 | W17: 3192 | X17: 4192 | Y17: 4171 | Z17: 空き | AA17: 合計
D18: 12(3) | E18: 1 | F18: 1 | G18: 2 | H18: 1 | I18: 2 | J18: 1 | K18: 0 | L18: 0 | M18: 1 | N18: 0 | O18: 1 | P18: 0 | Q18: 1 | R18: 1 | S18: 1 | T18: 0 | U18: 0 | V18: 0 | Z18: 2 | AA18: =SUM(E18:Z18) -> 15
C19: M7 | D19: 13(3) | E19: 1 | F19: 1 | G19: 2 | H19: 1 | I19: 3 | J19: 1 | K19: 1 | L19: 0 | M19: 0 | N19: 1 | O19: 0 | P19: 1 | Q19: 0 | R19: 0 | S19: 0 | T19: 1 | U19: 0 | V19: 1 | Z19: 1 | AA19: =SUM(E19:Z19) -> 15
D20: 14(3) | E20: 1 | F20: 1 | G20: 2 | H20: 2 | I20: 2 | J20: 1 | K20: 1 | L20: 0 | M20: 0 | N20: 1 | O20: 1 | P20: 0 | Q20: 0 | R20: 0 | S20: 0 | T20: 1 | U20: 1 | V20: 0 | Z20: 1 | AA20: =SUM(E20:Z20) -> 15
C21: Total | E21: =SUM(E18:E20) -> 3 | F21: =SUM(F18:F20) -> 3 | G21: =SUM(G18:G20) -> 6 | H21: =SUM(H18:H20) -> 4 | I21: =SUM(I18:I20) -> 7 | J21: =SUM(J18:J20) -> 3 | K21: =SUM(K18:K20) -> 2 | L21: =SUM(L18:L20) -> 0 | ... Z21: =SUM(Z18:Z20) -> 4 | AA21: =SUM(E21:Z21) -> 45

Sheet 3ライン
A1: ■3ライン現状
B2: 16/12 ノズル | C2: チェンジャー | E2: 140S | F2: 168S | G2: 225S | H2: 226S | I2: 230S | J2: 235S | K2: 240S | L2: - | M2: 256S | N2: - | O2: - | P2: - | Q2: - | R2: - | S2: - | T2: - | U2: - | V2: - | Z2: 空き | AA2: 合計 | AB2: 備考
C3: M1 | D3: 1(12) | E3: 0 | F3: 2 | G3: 0 | H3: 8 | I3: 8 | J3: 8 | K3: 4 | M3: 0 | N3: 0 | O3: 0 | P3: 0 | Q3: 0 | R3: 0 | S3: 0 | T3: 0 | U3: 0 | V3: 0 | Z3: 2 | AA3: =SUM(E3:Z3) -> 32
D4: 2(12) | E4: 0 | F4: 0 | G4: 0 | H4: 8 | I4: 9 | J4: 8 | K4: 4 | M4: 0 | N4: 0 | O4: 0 | P4: 0 | Q4: 0 | R4: 0 | S4: 0 | T4: 0 | U4: 0 | V4: 0 | Z4: 3 | AA4: =SUM(E4:Z4) -> 32
C5: Total | E5: =SUM(E3:E4) -> 0 | F5: =SUM(F3:F4) -> 2 | G5: =SUM(G3:G4) -> 0 | H5: =SUM(H3:H4) -> 16 | I5: =SUM(I3:I4) -> 17 | J5: =SUM(J3:J4) -> 16 | K5: =SUM(K3:K4) -> 8 | M5: =SUM(M3:M4) -> 0 | N5: =SUM(N3:N4) -> 0 | O5: =SUM(O3:O4) -> 0 | P5: =SUM(P3:P4) -> 0 | Q5: =SUM(Q3:Q4) -> 0 | R5: =SUM(R3:R4) -> 0 | S5: =SUM(S3:S4) -> 0 | T5: =SUM(T3:T4) -> 0 | ... V5: =SUM(V3:V4) -> 0 | Z5: =SUM(Z3:Z4) -> 5 | AA5: =SUM(E5:Z5) -> 64
B6: 8ノズル | C6: チェンジャー | E6: 140 | F6: 168 | G6: - | H6: 226 | I6: 230 | J6: 235 | K6: 240 | L6: - | M6: 184 | N6: 185 | O6: 199 | P6: 709 | Q6: - | R6: - | S6: - | T6: - | U6: - | V6: - | Z6: 空き | AA6: 合計
C7: M2 | D7: 3(8) | E7: 4 | F7: 1 | G7: 0 | H7: 0 | I7: 0 | J7: 4 | K7: 4 | M7: 1 | N7: 1 | O7: 0 | P7: 0 | Q7: 0 | R7: 0 | S7: 0 | T7: 0 | U7: 0 | V7: 0 | Z7: 1 | AA7: =SUM(E7:Z7) -> 16
D8: 4(8) | E8: 4 | F8: 0 | G8: 0 | H8: 0 | I8: 0 | J8: 4 | K8: 4 | M8: 1 | N8: 1 | O8: 0 | P8: 0 | Q8: 0 | R8: 0 | S8: 0 | T8: 0 | U8: 0 | V8: 0 | Z8: 2 | AA8: =SUM(E8:Z8) -> 16
C9: Total | E9: =SUM(E7:E8) -> 8 | F9: =SUM(F7:F8) -> 1 | G9: =SUM(G7:G8) -> 0 | H9: =SUM(H7:H8) -> 0 | I9: =SUM(I7:I8) -> 0 | J9: =SUM(J7:J8) -> 8 | K9: =SUM(K7:K8) -> 8 | M9: =SUM(M7:M8) -> 2 | N9: =SUM(N7:N8) -> 2 | O9: =SUM(O7:O8) -> 0 | P9: =SUM(P7:P8) -> 0 | Q9: =SUM(Q7:Q8) -> 0 | R9: =SUM(R7:R8) -> 0 | S9: =SUM(S7:S8) -> 0 | T9: =SUM(T7:T8) -> 0 | ... V9: =SUM(V7:V8) -> 0 | Z9: =SUM(Z7:Z8) -> 3 | AA9: =SUM(E9:Z9) -> 32
B10: 3ノズル | C10: チェンジャー | E10: 1001 | F10: 1002 | G10: 1003 | H10: 1004 | I10: 1005 | J10: 1006 | K10: 1115 | L10: 1273 | M10: 1404 | N10: 1421 | O10: 1424 | P10: 1479 | Q10: 1551 | R10: 1672 | S10: 2405 | T10: 2418 | U10: 2421 | V10: 2467 | W10: 3192 | X10: 4192 | Y10: 4171 | Z10: 空き | AA10: 合計
C11: M3 | D11: 5(3) | E11: 1 | F11: 1 | G11: 1 | H11: 1 | I11: 1 | J11: 1 | K11: 1 | M11: 1 | N11: 1 | O11: 0 | P11: 1 | Q11: 1 | R11: 1 | S11: 1 | T11: 1 | U11: 0 | V11: 0 | Z11: 1 | AA11: =SUM(E11:Z11) -> 15
D12: 5(3) | E12: 1 | F12: 1 | G12: 2 | H12: 1 | I12: 2 | J12: 1 | K12: 1 | M12: 1 | N12: 1 | O12: 0 | P12: 1 | Q12: 0 | R12: 0 | S12: 1 | T12: 1 | U12: 0 | V12: 0 | Z12: 1 | AA12: =SUM(E12:Z12) -> 15
C13: Total | E13: =SUM(E11:E12) -> 2 | F13: =SUM(F11:F12) -> 2 | G13: =SUM(G11:G12) -> 3 | H13: =SUM(H11:H12) -> 2 | I13: =SUM(I11:I12) -> 3 | J13: =SUM(J11:J12) -> 2 | K13: =SUM(K11:K12) -> 2 | M13: =SUM(M11:M12) -> 2 | N13: =SUM(N11:N12) -> 2 | O13: =SUM(O11:O12) -> 0 | P13: =SUM(P11:P12) -> 2 | Q13: =SUM(Q11:Q12) -> 1 | R13: =SUM(R11:R12) -> 1 | S13: =SUM(S11:S12) -> 2 | T13: =SUM(T11:T12) -> 2 | ... V13: =SUM(V11:V12) -> 0 | Z13: =SUM(Z11:Z12) -> 2 | AA13: =SUM(E13:Z13) -> 30

Sheet ノズル購入検討 (2)
A1: ■現状 | E1: ノズル固定 | P1: 単価 | Q1: 小計
C2: ノズル | D2: 在庫数 | E2: ライン1 | F2: ライン2 | G2: ライン3 | H2: 残り | I2: ブロック1 | J2: ブロック2 | K2: 必要数最大×4 | L2: 不足想定数 | M2: 追加購入予定数 | O2: 備考
B3: 16/12ノズル | C3: 140S | D3: =SUM(E3:H3) -> 14 | E3: 5 | F3: 4 | G3: ='3ライン'!E5 -> 0 | H3: 5 | I3: 8 | J3: 2 | K3: 32 | L3: =D3-K3 -> -18 | M3: 25 | O3: アルミ電解コン、SOP類 | P3: 20000 | Q3: =P3*M3 -> 500000
C4: 168S | D4: =SUM(E4:H4) -> 13 | E4: 4 | F4: 4 | G4: 2 | H4: 3 | I4: 4 | J4: 4 | K4: 16 | L4: =D4-K4 -> -3 | M4: 6 | O4: メルフ部品専用（一部LED含む） | P4: 60000 | Q4: =P4*M4 -> 360000
C5: 225S | D5: =SUM(E5:H5) -> 12 | E5: 0 | F5: 0 | G5: ='3ライン'!G5 -> 0 | H5: 12 | L5: =D5-K5 -> 12 | O5: 用途無し（0603専用） | Q5: =P5*M5 -> 0
C6: 226S | D6: =SUM(E6:H6) -> 123 | E6: 38 | F6: 42 | G6: 16 | H6: 27 | I6: 6 | J6: 6 | K6: 24 | L6: =D6-K6 -> 99 | O6: 0603専用 | Q6: =P6*M6 -> 0
C7: 230S | D7: =SUM(E7:H7) -> 178 | E7: 50 | F7: 79 | G7: ='3ライン'!I5 -> 17 | H7: 32 | I7: 95 | J7: 72 | K7: 380 | L7: =D7-K7 -> -202 | M7: 185 | O7: 1005専用 | P7: 21000 | Q7: =P7*M7 -> 3885000
C8: 235S | D8: =SUM(E8:H8) -> 192 | E8: 60 | F8: 69 | G8: ='3ライン'!J5 -> 16 | H8: 47 | I8: 62 | J8: 77 | K8: 308 | L8: =D8-K8 -> -116 | M8: 125 | O8: 1608,2012,3216専用 | P8: 21000 | Q8: =P8*M8 -> 2625000
C9: 240S | D9: =SUM(E9:H9) -> 104 | E9: 46 | F9: 34 | G9: ='3ライン'!K5 -> 8 | H9: 16 | I9: 38 | J9: 46 | K9: 184 | L9: =D9-K9 -> -80 | M9: 85 | O9: 2.5×2.5mm以上の部品 | P9: 21000 | Q9: =P9*M9 -> 1785000
C10: 256S | D10: =SUM(E10:H10) -> 30 | E10: 0 | F10: 0 | G10: ='3ライン'!M5 -> 0 | H10: 30 | L10: =D10-K10 -> 30 | O10: 0402専用 | Q10: =P10*M10 -> 0
B11: 8ノズル | C11: 140 | D11: =SUM(E11:H11) -> 36 | E11: 12 | F11: 12 | G11: 8 | H11: 4 | I11: 9 | J11: 9 | K11: 36 | L11: =D11-K11 -> 0 | O11: アルミ電解コン（小）、SOP類 | Q11: =P11*M11 -> 0
C12: 168 | D12: =SUM(E12:H12) -> 5 | E12: 2 | F12: 2 | G12: ='3ライン'!F9 -> 1 | H12: 0 | L12: =D12-K12 -> 5 | O12: メルフ部品専用（一部LED含む） | Q12: =P12*M12 -> 0
C13: 184 | D13: =SUM(E13:H13) -> 7 | E13: 2 | F13: 2 | G13: 2 | H13: 1 | I13: 3 | J13: 3 | K13: 12 | L13: =D13-K13 -> -5 | M13: 10 | O13: ？ | P13: 20000 | Q13: =P13*M13 -> 200000
C14: 185 | D14: =SUM(E14:H14) -> 14 | E14: 2 | F14: 2 | G14: 2 | H14: 8 | I14: 1 | K14: 4 | L14: =D14-K14 -> 10 | O14: ？ | Q14: =P14*M14 -> 0
C15: 199 | D15: =SUM(E15:H15) -> 1 | E15: 0 | F15: 1 | G15: 0 | H15: 0 | L15: =D15-K15 -> 1 | O15: ←不明 | Q15: =P15*M15 -> 0
C16: 226 | D16: =SUM(E16:H16) -> 41 | E16: 0 | F16: 0 | G16: 0 | H16: 41 | J16: 2 | K16: 8 | L16: =D16-K16 -> 33 | O16: 0603専用 | Q16: =P16*M16 -> 0
C17: 230 | D17: =SUM(E17:H17) -> 36 | E17: 2 | F17: 1 | G17: 1 | H17: 32 | I17: 8 | J17: 13 | K17: 52 | L17: =D17-K17 -> -16 | M17: 25 | O17: 1005専用 | P17: 21000 | Q17: =P17*M17 -> 525000
C18: 235 | D18: =SUM(E18:H18) -> 39 | E18: 4 | F18: 4 | G18: 8 | H18: 23 | I18: 2 | J18: 14 | K18: 56 | L18: =D18-K18 -> -17 | M18: 25 | O18: 1608,2012,3216専用 | P18: 20000 | Q18: =P18*M18 -> 500000
C19: 240 | D19: =SUM(E19:H19) -> 45 | E19: 18 | F19: 18 | G19: 8 | H19: 1 | I19: 18 | J19: 7 | K19: 72 | L19: =D19-K19 -> -27 | M19: 35 | O19: 2.5×2.5mm以上の部品 | P19: 20000 | Q19: =P19*M19 -> 700000
C20: 709 | D20: =SUM(E20:H20) -> 1 | E20: 1 | F20: 0 | G20: 0 | H20: 0 | L20: =D20-K20 -> 1 | O20: ←不明 | P20: 20000 | Q20: =P20*M20 -> 0
B21: 3ノズル | C21: 1001 | D21: =SUM(E21:H21) -> 12 | E21: 4 | F21: 3 | G21: 2 | H21: 3 | I21: 0 | J21: 1 | K21: 4 | L21: =D21-K21 -> 8 | O21: ミニTr | P21: 67200 | Q21: =P21*M21 -> 0
C22: 1002 | D22: =SUM(E22:H22) -> 15 | E22: 6 | F22: 3 | G22: 2 | H22: 4 | I22: 4 | J22: 6 | K22: 24 | L22: =D22-K22 -> -9 | M22: 15 | O22: アルミ電解コン（中） | P22: 25000 | Q22: =P22*M22 -> 375000
C23: 1003 | D23: =SUM(E23:H23) -> 20 | E23: 8 | F23: 6 | G23: 3 | H23: 3 | I23: 8 | J23: 8 | K23: 32 | L23: =D23-K23 -> -12 | M23: 20 | O23: アルミ電解コン（大）,SOP,BGA,QFN（各小サイズ） | P23: 67200 | Q23: =P23*M23 -> 1344000
C24: 1004 | D24: =SUM(E24:H24) -> 16 | E24: 4 | F24: 4 | G24: 2 | H24: 6 | I24: 1 | J24: 3 | K24: 12 | L24: =D24-K24 -> 4 | O24: SOP,BGA,QFN（各中サイズ） | P24: 67200 | Q24: =P24*M24 -> 0
C25: 1005 | D25: =SUM(E25:H25) -> 25 | E25: 8 | F25: 7 | G25: 3 | H25: 7 | I25: 3 | J25: 2 | K25: 12 | L25: =D25-K25 -> 13 | O25: SOP,BGA,QFN（各大サイズ） | P25: 67200 | Q25: =P25*M25 -> 0
C26: 1006 | D26: =SUM(E26:H26) -> 10 | E26: 4 | F26: 3 | G26: 2 | H26: 1 | I26: 2 | J26: 1 | K26: 8 | L26: =D26-K26 -> 2 | O26: 反射板 | Q26: =P26*M26 -> 0
C27: 1115 | D27: =SUM(E27:H27) -> 6 | E27: 2 | F27: 2 | G27: 2 | H27: 0 | I27: 2 | K27: 8 | L27: =D27-K27 -> -2 | M27: 5 | O27: ？ | P27: 25000 | Q27: =P27*M27 -> 125000
C28: 1273 | D28: =SUM(E28:H28) -> 2 | E28: 1 | F28: 0 | G28: 0 | H28: 1 | L28: =D28-K28 -> 2 | P28: 75000 | Q28: =P28*M28 -> 0
C29: 1404 | D29: =SUM(E29:H29) -> 7 | E29: 2 | F29: 2 | G29: 2 | H29: 1 | I29: 2 | J29: 2 | K29: 8 | L29: =D29-K29 -> -1 | M29: 3 | O29: ？ | P29: 67200 | Q29: =P29*M29 -> 201600
C30: 1421 | D30: =SUM(E30:H30) -> 8 | E30: 3 | F30: 2 | G30: 2 | H30: 1 | J30: 1 | K30: 4 | L30: =D30-K30 -> 4 | O30: ？ | Q30: =P30*M30 -> 0
C31: 1424 | D31: =SUM(E31:H31) -> 9 | E31: 1 | F31: 2 | G31: ='3ライン'!O13 -> 0 | H31: 6 | L31: =D31-K31 -> 9 | O31: ？ | Q31: =P31*M31 -> 0
C32: 1479 | D32: =SUM(E32:H32) -> 6 | E32: 1 | F32: 1 | G32: 2 | H32: 2 | J32: 2 | K32: 8 | L32: =D32-K32 -> -2 | M32: 4 | O32: ？ | P32: 75000 | Q32: =P32*M32 -> 300000
C33: 1551 | D33: =SUM(E33:H33) -> 3 | E33: 1 | F33: 1 | G33: 1 | H33: 0 | I33: 1 | J33: 2 | K33: 8 | L33: =D33-K33 -> -5 | M33: 8 | O33: ？ | P33: 75000 | Q33: =P33*M33 -> 600000
C34: 1672 | D34: =SUM(E34:H34) -> 5 | E34: 1 | F34: 1 | G34: 1 | H34: 2 | J34: 1 | K34: 4 | L34: =D34-K34 -> 1 | O34: ？ | P34: 74300 | Q34: =P34*M34 -> 0
C35: 2405 | D35: =SUM(E35:H35) -> 8 | E35: 2 | F35: 1 | G35: 2 | H35: 3 | I35: 3 | K35: 12 | L35: =D35-K35 -> -4 | M35: 7 | O35: ？ | P35: 62900 | Q35: =P35*M35 -> 440300
C36: 2418 | D36: =SUM(E36:H36) -> 7 | E36: 2 | F36: 2 | G36: 2 | H36: 1 | I36: 1 | J36: 3 | K36: 12 | L36: =D36-K36 -> -5 | M36: 8 | O36: ？ | P36: 75000 | Q36: =P36*M36 -> 600000
C37: 2421 | D37: =SUM(E37:H37) -> 4 | E37: 1 | F37: ='2ライン'!U21 -> 1 | G37: ='3ライン'!U13 -> 0 | H37: 2 | L37: =D37-K37 -> 4 | O37: ？ | P37: 62900 | Q37: =P37*M37 -> 0
C38: 2467 | D38: =SUM(E38:H38) -> 3 | E38: 1 | F38: 1 | G38: 0 | H38: 1 | I38: 1 | K38: 4 | L38: =D38-K38 -> -1 | M38: 3 | P38: 75000 | Q38: =P38*M38 -> 225000
C39: 3192 | D39: =SUM(E39:H39) -> 2 | E39: 1 | F39: 0 | G39: 0 | H39: 1 | L39: =D39-K39 -> 2 | P39: 103000 | Q39: =P39*M39 -> 0
C40: 4171 | D40: =SUM(E40:H40) -> 2 | E40: 1 | F40: 0 | G40: 0 | H40: 1 | L40: =D40-K40 -> 2 | P40: 75000 | Q40: =P40*M40 -> 0
...

Sheet ノズル購入検討
A1: ■現状 | E1: ノズル固定 | O1: 単価 | P1: 小計
C2: ノズル | D2: 在庫数 | E2: ライン1 | F2: ライン2 | G2: ライン3 | H2: 残り | I2: ブロック1 | J2: ブロック2 | K2: 必要数最大×4 | L2: 不足想定数 | M2: 追加購入予定数 | N2: 備考
B3: 16/12ノズル | C3: 140S | D3: =SUM(E3:H3) -> 14 | E3: 5 | F3: 4 | G3: ='3ライン'!E5 -> 0 | H3: 5 | I3: 8 | J3: 2 | K3: 32 | L3: =D3-K3 -> -18 | M3: 25 | N3: アルミ電解コン、SOP類 | O3: 20000 | P3: =O3*M3 -> 500000
C4: 168S | D4: =SUM(E4:H4) -> 13 | E4: 4 | F4: 4 | G4: 2 | H4: 3 | I4: 4 | J4: 4 | K4: 16 | L4: =D4-K4 -> -3 | M4: 6 | N4: メルフ部品専用（一部LED含む） | O4: 60000 | P4: =O4*M4 -> 360000
C5: 225S | D5: =SUM(E5:H5) -> 12 | E5: 0 | F5: 0 | G5: ='3ライン'!G5 -> 0 | H5: 12 | L5: =D5-K5 -> 12 | N5: 用途無し（0603専用） | P5: =O5*M5 -> 0
C6: 226S | D6: =SUM(E6:H6) -> 123 | E6: 38 | F6: 42 | G6: 16 | H6: 27 | I6: 6 | J6: 6 | K6: 24 | L6: =D6-K6 -> 99 | N6: 0603専用 | P6: =O6*M6 -> 0
C7: 230S | D7: =SUM(E7:H7) -> 178 | E7: 50 | F7: 79 | G7: ='3ライン'!I5 -> 17 | H7: 32 | I7: 95 | J7: 72 | K7: 380 | L7: =D7-K7 -> -202 | M7: 185 | N7: 1005専用 | O7: 21000 | P7: =O7*M7 -> 3885000
C8: 235S | D8: =SUM(E8:H8) -> 192 | E8: 60 | F8: 69 | G8: ='3ライン'!J5 -> 16 | H8: 47 | I8: 62 | J8: 77 | K8: 308 | L8: =D8-K8 -> -116 | M8: 125 | N8: 1608,2012,3216専用 | O8: 21000 | P8: =O8*M8 -> 2625000
C9: 240S | D9: =SUM(E9:H9) -> 104 | E9: 46 | F9: 34 | G9: ='3ライン'!K5 -> 8 | H9: 16 | I9: 38 | J9: 46 | K9: 184 | L9: =D9-K9 -> -80 | M9: 85 | N9: 2.5×2.5mm以上の部品 | O9: 21000 | P9: =O9*M9 -> 1785000
C10: 256S | D10: =SUM(E10:H10) -> 30 | E10: 0 | F10: 0 | G10: ='3ライン'!M5 -> 0 | H10: 30 | L10: =D10-K10 -> 30 | N10: 0402専用 | P10: =O10*M10 -> 0
B11: 8ノズル | C11: 140 | D11: =SUM(E11:H11) -> 36 | E11: 12 | F11: 12 | G11: 8 | H11: 4 | I11: 9 | J11: 9 | K11: 36 | L11: =D11-K11 -> 0 | N11: アルミ電解コン（小）、SOP類 | P11: =O11*M11 -> 0
C12: 168 | D12: =SUM(E12:H12) -> 5 | E12: 2 | F12: 2 | G12: ='3ライン'!F9 -> 1 | H12: 0 | L12: =D12-K12 -> 5 | N12: メルフ部品専用（一部LED含む） | P12: =O12*M12 -> 0
C13: 184 | D13: =SUM(E13:H13) -> 7 | E13: 2 | F13: 2 | G13: 2 | H13: 1 | I13: 3 | J13: 3 | K13: 12 | L13: =D13-K13 -> -5 | M13: 10 | N13: ？ | O13: 20000 | P13: =O13*M13 -> 200000
C14: 185 | D14: =SUM(E14:H14) -> 14 | E14: 2 | F14: 2 | G14: 2 | H14: 8 | I14: 1 | K14: 4 | L14: =D14-K14 -> 10 | N14: ？ | P14: =O14*M14 -> 0
C15: 199 | D15: =SUM(E15:H15) -> 1 | E15: 0 | F15: 1 | G15: 0 | H15: 0 | L15: =D15-K15 -> 1 | N15: ←不明 | P15: =O15*M15 -> 0
C16: 226 | D16: =SUM(E16:H16) -> 41 | E16: 0 | F16: 0 | G16: 0 | H16: 41 | J16: 2 | K16: 8 | L16: =D16-K16 -> 33 | N16: 0603専用 | P16: =O16*M16 -> 0
C17: 230 | D17: =SUM(E17:H17) -> 36 | E17: 2 | F17: 1 | G17: 1 | H17: 32 | I17: 8 | J17: 13 | K17: 52 | L17: =D17-K17 -> -16 | M17: 25 | N17: 1005専用 | O17: 21000 | P17: =O17*M17 -> 525000
C18: 235 | D18: =SUM(E18:H18) -> 39 | E18: 4 | F18: 4 | G18: 8 | H18: 23 | I18: 2 | J18: 14 | K18: 56 | L18: =D18-K18 -> -17 | M18: 25 | N18: 1608,2012,3216専用 | O18: 20000 | P18: =O18*M18 -> 500000
C19: 240 | D19: =SUM(E19:H19) -> 45 | E19: 18 | F19: 18 | G19: 8 | H19: 1 | I19: 18 | J19: 7 | K19: 72 | L19: =D19-K19 -> -27 | M19: 35 | N19: 2.5×2.5mm以上の部品 | O19: 20000 | P19: =O19*M19 -> 700000
C20: 709 | D20: =SUM(E20:H20) -> 1 | E20: 1 | F20: 0 | G20: 0 | H20: 0 | L20: =D20-K20 -> 1 | N20: ←不明 | O20: 20000 | P20: =O20*M20 -> 0
B21: 3ノズル | C21: 1001 | D21: =SUM(E21:H21) -> 12 | E21: 4 | F21: 3 | G21: 2 | H21: 3 | I21: 0 | J21: 1 | K21: 4 | L21: =D21-K21 -> 8 | N21: ミニTr | O21: 67200 | P21: =O21*M21 -> 0
C22: 1002 | D22: =SUM(E22:H22) -> 15 | E22: 6 | F22: 3 | G22: 2 | H22: 4 | I22: 4 | J22: 6 | K22: 24 | L22: =D22-K22 -> -9 | M22: 15 | N22: アルミ電解コン（中） | O22: 25000 | P22: =O22*M22 -> 375000
C23: 1003 | D23: =SUM(E23:H23) -> 20 | E23: 8 | F23: 6 | G23: 3 | H23: 3 | I23: 8 | J23: 8 | K23: 32 | L23: =D23-K23 -> -12 | M23: 20 | N23: アルミ電解コン（大）,SOP,BGA,QFN（各小サイズ） | O23: 67200 | P23: =O23*M23 -> 1344000
C24: 1004 | D24: =SUM(E24:H24) -> 16 | E24: 4 | F24: 4 | G24: 2 | H24: 6 | I24: 1 | J24: 3 | K24: 12 | L24: =D24-K24 -> 4 | N24: SOP,BGA,QFN（各中サイズ） | O24: 67200 | P24: =O24*M24 -> 0
C25: 1005 | D25: =SUM(E25:H25) -> 25 | E25: 8 | F25: 7 | G25: 3 | H25: 7 | I25: 3 | J25: 2 | K25: 12 | L25: =D25-K25 -> 13 | N25: SOP,BGA,QFN（各大サイズ） | O25: 67200 | P25: =O25*M25 -> 0
C26: 1006 | D26: =SUM(E26:H26) -> 10 | E26: 4 | F26: 3 | G26: 2 | H26: 1 | I26: 2 | J26: 1 | K26: 8 | L26: =D26-K26 -> 2 | N26: 反射板 | P26: =O26*M26 -> 0
C27: 1115 | D27: =SUM(E27:H27) -> 6 | E27: 2 | F27: 2 | G27: 2 | H27: 0 | I27: 2 | K27: 8 | L27: =D27-K27 -> -2 | M27: 5 | N27: ？ | O27: 25000 | P27: =O27*M27 -> 125000
C28: 1273 | D28: =SUM(E28:H28) -> 2 | E28: 1 | F28: 0 | G28: 0 | H28: 1 | L28: =D28-K28 -> 2 | O28: 75000 | P28: =O28*M28 -> 0
C29: 1404 | D29: =SUM(E29:H29) -> 7 | E29: 2 | F29: 2 | G29: 2 | H29: 1 | I29: 2 | J29: 2 | K29: 8 | L29: =D29-K29 -> -1 | M29: 3 | N29: ？ | O29: 67200 | P29: =O29*M29 -> 201600
C30: 1421 | D30: =SUM(E30:H30) -> 8 | E30: 3 | F30: 2 | G30: 2 | H30: 1 | J30: 1 | K30: 4 | L30: =D30-K30 -> 4 | N30: ？ | P30: =O30*M30 -> 0
C31: 1424 | D31: =SUM(E31:H31) -> 9 | E31: 1 | F31: 2 | G31: ='3ライン'!O13 -> 0 | H31: 6 | L31: =D31-K31 -> 9 | N31: ？ | P31: =O31*M31 -> 0
C32: 1479 | D32: =SUM(E32:H32) -> 6 | E32: 1 | F32: 1 | G32: 2 | H32: 2 | J32: 2 | K32: 8 | L32: =D32-K32 -> -2 | M32: 4 | N32: ？ | O32: 75000 | P32: =O32*M32 -> 300000
C33: 1551 | D33: =SUM(E33:H33) -> 3 | E33: 1 | F33: 1 | G33: 1 | H33: 0 | I33: 1 | J33: 2 | K33: 8 | L33: =D33-K33 -> -5 | M33: 8 | N33: ？ | O33: 75000 | P33: =O33*M33 -> 600000
C34: 1672 | D34: =SUM(E34:H34) -> 5 | E34: 1 | F34: 1 | G34: 1 | H34: 2 | J34: 1 | K34: 4 | L34: =D34-K34 -> 1 | N34: ？ | O34: 74300 | P34: =O34*M34 -> 0
C35: 2405 | D35: =SUM(E35:H35) -> 8 | E35: 2 | F35: 1 | G35: 2 | H35: 3 | I35: 3 | K35: 12 | L35: =D35-K35 -> -4 | M35: 7 | N35: ？ | O35: 62900 | P35: =O35*M35 -> 440300
C36: 2418 | D36: =SUM(E36:H36) -> 7 | E36: 2 | F36: 2 | G36: 2 | H36: 1 | I36: 1 | J36: 3 | K36: 12 | L36: =D36-K36 -> -5 | M36: 8 | N36: ？ | O36: 75000 | P36: =O36*M36 -> 600000
C37: 2421 | D37: =SUM(E37:H37) -> 4 | E37: 1 | F37: ='2ライン'!U21 -> 1 | G37: ='3ライン'!U13 -> 0 | H37: 2 | L37: =D37-K37 -> 4 | N37: ？ | O37: 62900 | P37: =O37*M37 -> 0
C38: 2467 | D38: =SUM(E38:H38) -> 3 | E38: 1 | F38: 1 | G38: 0 | H38: 1 | I38: 1 | K38: 4 | L38: =D38-K38 -> -1 | M38: 3 | O38: 75000 | P38: =O38*M38 -> 225000
C39: 3192 | D39: =SUM(E39:H39) -> 2 | E39: 1 | F39: 0 | G39: 0 | H39: 1 | L39: =D39-K39 -> 2 | O39: 103000 | P39: =O39*M39 -> 0
C40: 4171 | D40: =SUM(E40:H40) -> 2 | E40: 1 | F40: 0 | G40: 0 | H40: 1 | L40: =D40-K40 -> 2 | O40: 75000 | P40: =O40*M40 -> 0
...

Sheet ノズル選定の品目　1ライン
A1: 想定品目 | B1: UR-4244 | D1: 想定品目 | E1: UR-3949
A2: ブロック1 | B2: UR-42461 | D2: ブロック2 | E2: UR-39490
B3: UR-4284 | E3: UR-3962
B4: UR-4364 | E4: UR-4115
B5: UR-4365 | E5: UR-4137
B6: UR-4393 | E6: UR-4238
B7: UR-44171 | E7: UR-4239
B8: UR-44172 | E8: UR-4388
B9: UR-44173 | E9: UR-4394
B10: UR-44174 | E10: UR-4397
B11: UR-44175 | E11: UR-4398
B12: UR-44176 | E12: UR-4402
B13: UR-44177 | E13: UR-4407
B14: UR-44178 | E14: UR-4424
B15: UR-44179 | E15: UR-4459
B16: UR-44201
B17: UR-44202
B18: UR-44203
B19: UR-44204
B20: UR-4425

Sheet ノズル在庫状況
A1: ■現状
C2: ノズル | D2: 在庫数 | E2: ライン1 | F2: ライン2 | G2: ライン3 | H2: 残り | I2: 追加購入数 | J2: 在庫数 | K2: 備考
B3: 16/12ノズル | C3: 140S | D3: =SUM(E3:H3) -> 14 | E3: 5 | F3: 4 | G3: ='3ライン'!E5 -> 0 | H3: 5 | I3: 25 | J3: =I3+D3 -> 39 | K3: アルミ電解コン、SOP類
C4: 168S | D4: =SUM(E4:H4) -> 13 | E4: 4 | F4: 4 | G4: 2 | H4: 3 | I4: 6 | J4: =I4+D4 -> 19 | K4: メルフ部品専用（一部LED含む）
C5: 225S | D5: =SUM(E5:H5) -> 12 | E5: 0 | F5: 0 | G5: ='3ライン'!G5 -> 0 | H5: 12 | I5: 0 | J5: =I5+D5 -> 12 | K5: 用途無し（0603専用）
C6: 226S | D6: =SUM(E6:H6) -> 123 | E6: 38 | F6: 42 | G6: 16 | H6: 27 | I6: 0 | J6: =I6+D6 -> 123 | K6: 0603専用
C7: 230S | D7: =SUM(E7:H7) -> 178 | E7: 50 | F7: 79 | G7: ='3ライン'!I5 -> 17 | H7: 32 | I7: 185 | J7: =I7+D7 -> 363 | K7: 1005専用
C8: 235S | D8: =SUM(E8:H8) -> 192 | E8: 60 | F8: 69 | G8: ='3ライン'!J5 -> 16 | H8: 47 | I8: 125 | J8: =I8+D8 -> 317 | K8: 1608,2012,3216専用
C9: 240S | D9: =SUM(E9:H9) -> 104 | E9: 46 | F9: 34 | G9: ='3ライン'!K5 -> 8 | H9: 16 | I9: 85 | J9: =I9+D9 -> 189 | K9: 2.5×2.5mm以上の部品
C10: 256S | D10: =SUM(E10:H10) -> 30 | E10: 0 | F10: 0 | G10: ='3ライン'!M5 -> 0 | H10: 30 | I10: 0 | J10: =I10+D10 -> 30 | K10: 0402専用
B11: 8ノズル | C11: 140 | D11: =SUM(E11:H11) -> 36 | E11: 12 | F11: 12 | G11: 8 | H11: 4 | I11: 0 | J11: =I11+D11 -> 36 | K11: アルミ電解コン（小）、SOP類
C12: 159 | D12: 0 | I12: 4 | J12: =I12+D12 -> 4
C13: 168 | D13: =SUM(E13:H13) -> 5 | E13: 2 | F13: 2 | G13: ='3ライン'!F9 -> 1 | H13: 0 | I13: 0 | J13: =I13+D13 -> 5 | K13: メルフ部品専用（一部LED含む）
C14: 184 | D14: =SUM(E14:H14) -> 7 | E14: 2 | F14: 2 | G14: 2 | H14: 1 | I14: 10 | J14: =I14+D14 -> 17 | K14: ？
C15: 185 | D15: =SUM(E15:H15) -> 14 | E15: 2 | F15: 2 | G15: 2 | H15: 8 | I15: 0 | J15: =I15+D15 -> 14 | K15: ？
C16: 199 | D16: =SUM(E16:H16) -> 1 | E16: 0 | F16: 1 | G16: 0 | H16: 0 | I16: 0 | J16: =I16+D16 -> 1 | K16: ←不明
C17: 226 | D17: =SUM(E17:H17) -> 41 | E17: 0 | F17: 0 | G17: 0 | H17: 41 | I17: 0 | J17: =I17+D17 -> 41 | K17: 0603専用
C18: 230 | D18: =SUM(E18:H18) -> 36 | E18: 2 | F18: 1 | G18: 1 | H18: 32 | I18: 25 | J18: =I18+D18 -> 61 | K18: 1005専用
C19: 235 | D19: =SUM(E19:H19) -> 39 | E19: 4 | F19: 4 | G19: 8 | H19: 23 | I19: 25 | J19: =I19+D19 -> 64 | K19: 1608,2012,3216専用
C20: 240 | D20: =SUM(E20:H20) -> 45 | E20: 18 | F20: 18 | G20: 8 | H20: 1 | I20: 35 | J20: =I20+D20 -> 80 | K20: 2.5×2.5mm以上の部品
C21: 709 | D21: =SUM(E21:H21) -> 1 | E21: 1 | F21: 0 | G21: 0 | H21: 0 | I21: 0 | J21: =I21+D21 -> 1 | K21: ←不明
B22: 3ノズル | C22: 1001 | D22: =SUM(E22:H22) -> 12 | E22: 4 | F22: 3 | G22: 2 | H22: 3 | I22: 0 | J22: =I22+D22 -> 12 | K22: ミニTr
C23: 1002 | D23: =SUM(E23:H23) -> 15 | E23: 6 | F23: 3 | G23: 2 | H23: 4 | I23: 15 | J23: =I23+D23 -> 30 | K23: アルミ電解コン（中）
C24: 1003 | D24: =SUM(E24:H24) -> 20 | E24: 8 | F24: 6 | G24: 3 | H24: 3 | I24: 20 | J24: =I24+D24 -> 40 | K24: アルミ電解コン（大）,SOP,BGA,QFN（各小サイズ）
C25: 1004 | D25: =SUM(E25:H25) -> 16 | E25: 4 | F25: 4 | G25: 2 | H25: 6 | I25: 0 | J25: =I25+D25 -> 16 | K25: SOP,BGA,QFN（各中サイズ）
C26: 1005 | D26: =SUM(E26:H26) -> 25 | E26: 8 | F26: 7 | G26: 3 | H26: 7 | I26: 0 | J26: =I26+D26 -> 25 | K26: SOP,BGA,QFN（各大サイズ）
C27: 1006 | D27: =SUM(E27:H27) -> 10 | E27: 4 | F27: 3 | G27: 2 | H27: 1 | I27: 0 | J27: =I27+D27 -> 10 | K27: 反射板
C28: 1115 | D28: =SUM(E28:H28) -> 6 | E28: 2 | F28: 2 | G28: 2 | H28: 0 | I28: 5 | J28: =I28+D28 -> 11 | K28: ？
C29: 1273 | D29: =SUM(E29:H29) -> 2 | E29: 1 | F29: 0 | G29: 0 | H29: 1 | I29: 0 | J29: =I29+D29 -> 2
C30: 1404 | D30: =SUM(E30:H30) -> 7 | E30: 2 | F30: 2 | G30: 2 | H30: 1 | I30: 3 | J30: =I30+D30 -> 10 | K30: ？
C31: 1421 | D31: =SUM(E31:H31) -> 8 | E31: 3 | F31: 2 | G31: 2 | H31: 1 | I31: 0 | J31: =I31+D31 -> 8 | K31: ？
C32: 1424 | D32: =SUM(E32:H32) -> 9 | E32: 1 | F32: 2 | G32: ='3ライン'!O13 -> 0 | H32: 6 | I32: 0 | J32: =I32+D32 -> 9 | K32: ？
C33: 1479 | D33: =SUM(E33:H33) -> 6 | E33: 1 | F33: 1 | G33: 2 | H33: 2 | I33: 4 | J33: =I33+D33 -> 10 | K33: ？
C34: 1551 | D34: =SUM(E34:H34) -> 3 | E34: 1 | F34: 1 | G34: 1 | H34: 0 | I34: 8 | J34: =I34+D34 -> 11 | K34: ？
C35: 1672 | D35: =SUM(E35:H35) -> 5 | E35: 1 | F35: 1 | G35: 1 | H35: 2 | I35: 0 | J35: =I35+D35 -> 5 | K35: ？
C36: 2405 | D36: =SUM(E36:H36) -> 8 | E36: 2 | F36: 1 | G36: 2 | H36: 3 | I36: 7 | J36: =I36+D36 -> 15 | K36: ？
C37: 2418 | D37: =SUM(E37:H37) -> 7 | E37: 2 | F37: 2 | G37: 2 | H37: 1 | I37: 8 | J37: =I37+D37 -> 15 | K37: ？
C38: 2421 | D38: =SUM(E38:H38) -> 4 | E38: 1 | F38: ='2ライン'!U21 -> 1 | G38: ='3ライン'!U13 -> 0 | H38: 2 | I38: 0 | J38: =I38+D38 -> 4 | K38: ？
C39: 2467 | D39: =SUM(E39:H39) -> 3 | E39: 1 | F39: 1 | G39: 0 | H39: 1 | I39: 3 | J39: =I39+D39 -> 6
C40: 3192 | D40: =SUM(E40:H40) -> 2 | E40: 1 | F40: 0 | G40: 0 | H40: 1 | I40: 0 | J40: =I40+D40 -> 2
...

Sheet NPMフィーダー在庫状況
B1: NPMフィーダー在庫状況
B2: 4ｍｍ | C2: 0402W | D2: 8ｍｍ | E2: 12/16ｍｍ | N2: 24/32ｍｍ | V2: 44/56ｍｍ
B3: - | C3: - | D3: - | E3: 12*４ | F3: 12*8 | G3: 12*12 | H3: 16*4 | I3: 16*8 | J3: 16*12 | K3: 16*16 | L3: 16*20 | M3: 未設定 | N3: 24*8 | O3: 24*12 | P3: 24*16 | Q3: 24*24 | R3: 32*12 | S3: 32*16 | T3: 32*20 | U3: 32*24 | V3: 44*8 | W3: 44*12 | X3: 44*16 | Y3: 44*20 | Z3: 44*28 | AA3: 44*32 | AB3: 56*12 | AC3: 56*16 | AD3: 56*20 | AE3: 56*24 | AF3: 未設定
A4: 本数 | B4: 8 | C4: 4 | D4: 1432 | E4: =SUM(E5:M5) -> 619 | N4: =SUM(N5:U5) -> 106 | V4: =SUM(V5:AF5) -> 42
A5: 本数(詳細） | B5: 8 | C5: 4 | D5: 1432 | E5: 92 | F5: 312 | G5: 14 | H5: 3 | I5: 86 | J5: 92 | K5: 8 | L5: 2 | M5: 10 | N5: 12 | O5: 54 | P5: 12 | Q5: 1 | R5: 14 | S5: 7 | T5: 1 | U5: 5 | V5: 1 | W5: 13 | X5: 6 | Y5: 2 | Z5: 3 | AA5: 2 | AB5: 4 | AC5: 3 | AD5: 1 | AE5: 2 | AF5: 5
A6: 修理待ち | D6: 14 | F6: 3
A8: 2020/05/14現在

Sheet 設備所有状況
B2: マウンタ | C2: 台数
B3: NPM-W | C3: 8
B4: NPM-W2 | C4: 9
B7: ヘッド
B8: 16ノズル | C8: 7
B9: 12ヘッド | C9: 10
B10: 8ヘッド | C10: 8
B11: 3ヘッド | C11: 9
B13: チェンジャー | D13: 追加後
B14: 12・16ヘッド用チェンジャー | C14: 17 | D14: 34
B15: 8ヘッド用チェンジャー | C15: 8 | D15: 16
B16: 3ヘッド用チェンジャー | C16: 9 | D16: 18

Sheet ライン構成
Q4: 1ライン
Q10: 2ライン
Q16: 3ライン
F22: チェンジャー： | H22: 32 | L22: 予定： | M22: 0603 | N22: 226
F23: ノズル： | H23: 140S,168S,226S,230S,240S,235S | M23: 1005 | N23: 230
M24: 1608 | N24: 235
M25: 2012 | N25: 235
F26: チェンジャー： | H26: 32 | M26: 3216 | N26: 235
F27: ノズル： | H27: 168S,226S,230S,240S,235S | M27: メルフ | N27: 168
F30: チェンジャー： | H30: 16
F31: ノズル： | H31: 140,168,235,240,184,185,199
F34: チェンジャー： | H34: 9
