Workbook

Sheet 2023_07元データ
A1: PCBModel | B1: 検査開始時間 | C1: 検査終了時間
A2: UR-0509-01P4 | B2: 45138.753 | C2: 45138.754
A3: UR-0509-01P4 | B3: 45138.753 | C3: 45138.753
A4: UR-0509-01P4 | B4: 45138.752 | C4: 45138.753
A5: UR-0509-01P4 | B5: 45138.752 | C5: 45138.752
A6: UR-0509-01P4 | B6: 45138.751 | C6: 45138.752
A7: UR-0509-01P4 | B7: 45138.751 | C7: 45138.751
A8: UR-0509-01P4 | B8: 45138.751 | C8: 45138.751
A9: UR-0509-01P4 | B9: 45138.75 | C9: 45138.75
A10: UR-0509-01P4 | B10: 45138.75 | C10: 45138.75
A11: UR-0509-01P4 | B11: 45138.749 | C11: 45138.75
A12: UR-0509-01P4 | B12: 45138.749 | C12: 45138.749
A13: UR-0509-01P4 | B13: 45138.748 | C13: 45138.749
... A28412: URS-42881P6 | B28412: 45110.391 | C28412: 45110.391

Sheet 時間データ
A3: ３日 | F3: ４日 | K3: ５日 | P3: ６日 | U3: ７日 | AA3: １０日 | AF3: １１日 | AK3: １２日 | AP3: １３日 | AU3: １４日 | BA3: １８日 | BF3: １９日 | BK3: ２０日 | BP3: ２１日 | BV3: ２４日 | CA3: ２５日 | CF3: ２６日 | CK3: ２７日 | CP3: ２８日 | CV3: ３１日
A4: PCBModel | B4: 検査開始時間 | C4: 検査終了時間 | F4: PCBModel | G4: 検査開始時間 | H4: 検査終了時間 | K4: PCBModel | L4: 検査開始時間 | M4: 検査終了時間 | P4: PCBModel | Q4: 検査開始時間 | R4: 検査終了時間 | U4: PCBModel | V4: 検査開始時間 | W4: 検査終了時間 | AA4: PCBModel | AB4: 検査開始時間 | AC4: 検査終了時間 | AF4: PCBModel | AG4: 検査開始時間 | AH4: 検査終了時間 | AK4: PCBModel | AL4: 検査開始時間 | AM4: 検査終了時間 | AP4: PCBModel | AQ4: 検査開始時間 | AR4: 検査終了時間 | AU4: PCBModel | AV4: 検査開始時間 | AW4: 検査終了時間 | BA4: PCBModel | BB4: 検査開始時間 | BC4: 検査終了時間 | BF4: PCBModel | BG4: 検査開始時間 | BH4: 検査終了時間 | BK4: PCBModel | BL4: 検査開始時間 | BM4: 検査終了時間 | BP4: PCBModel | BQ4: 検査開始時間 | BR4: 検査終了時間 | BV4: PCBModel | BW4: 検査開始時間 | BX4: 検査終了時間 | CA4: PCBModel | CB4: 検査開始時間 | CC4: 検査終了時間 | CF4: PCBModel | CG4: 検査開始時間 | CH4: 検査終了時間 | CK4: PCBModel | CL4: 検査開始時間 | CM4: 検査終了時間 | CP4: PCBModel | CQ4: 検査開始時間 | CR4: 検査終了時間 | CV4: PCBModel | CW4: 検査開始時間 | CX4: 検査終了時間
A5: J-MVM-4289P1_20220406 | B5: 45110.999 | C5: 45110.999 | D5: =C5-B5 -> 2.3148146e-05 | F5: J-UR-05581P1_20220228 | G5: 45111.854 | H5: 45111.854 | I5: =H5-G5 -> 0.00023148148 | K5: J-UR-05581P4_20220228 | L5: 45112.992 | M5: 45112.992 | N5: =M5-L5 -> 0.00028935185 | P5: J-UR-05581P1_20220228 | Q5: 45113.572 | R5: 45113.572 | S5: =R5-Q5 -> 0.00023148148 | U5: J-UR-05581P1_20220228 | V5: 45114.57 | W5: 45114.57 | X5: =W5-V5 -> 0.00023148148 | AA5: J-UR-05581P1_20220228 | AB5: 45117.58 | AC5: 45117.58 | AD5: =AC5-AB5 -> 0.00023148148 | AF5: J-UR-05581P1_20220228 | AG5: 45118.909 | AH5: 45118.91 | AI5: =AH5-AG5 -> 0.00023148148 | AK5: J-UR-05581P4_20220228 | AL5: 45119.968 | AM5: 45119.968 | AN5: =AM5-AL5 -> 0.00030092592 | AP5: J-MVM-4289P1_20220406 | AQ5: 45120.934 | AR5: 45120.934 | AS5: =AR5-AQ5 -> 2.3148146e-05 | AU5: J-UR-05581P1_20220228 | AV5: 45121.494 | AW5: 45121.494 | AX5: =AW5-AV5 -> 0.00023148148 | BA5: J-UR-0550-01P1_20210830 | BB5: 45125.763 | BC5: 45125.763 | BD5: =BC5-BB5 -> 0.00011574074 | BF5: J-UR-05581P4_20220228 | BG5: 45127.018 | BH5: 45127.018 | BI5: =BH5-BG5 -> 0.00028935185 | BK5: J-UR-05581P1_20220228 | BL5: 45127.494 | BM5: 45127.495 | BN5: =BM5-BL5 -> 0.00023148148 | BP5: J-MVM-4289P1_20220406 | BQ5: 45128.814 | BR5: 45128.814 | BS5: =BR5-BQ5 -> 2.3148146e-05 | BV5: J-UR-05581P1_20220228 | BW5: 45131.56 | BX5: 45131.56 | BY5: =BX5-BW5 -> 0.00023148148 | CA5: J-UR-05581P1_20220228 | CB5: 45132.506 | CC5: 45132.506 | CD5: =CC5-CB5 -> 0.00023148148 | CF5: J-UR-05581P1_20220228 | CG5: 45133.889 | CH5: 45133.89 | CI5: =CH5-CG5 -> 0.00023148148 | CK5: J-UR-05581P4_20220228 | CL5: 45135.013 | CM5: 45135.014 | CN5: =CM5-CL5 -> 0.00028935185 | CP5: J-MVH-7249-01P4_20220419 | CQ5: 45135.44 | CR5: 45135.44 | CS5: =CR5-CQ5 -> 6.9444446e-05 | CV5: J-UR-05581P1_20220228 | CW5: 45138.546 | CX5: 45138.546 | CY5: =CX5-CW5 -> 0.00023148148
A6: J-MVM-4289P1_20220406 | B6: 45110.994 | C6: 45110.994 | D6: =C6-B6 -> 2.3148146e-05 | F6: J-UR-05581P1_20220228 | G6: 45111.854 | H6: 45111.854 | I6: =H6-G6 -> 0.00023148148 | K6: J-UR-05581P4_20220228 | L6: 45112.992 | M6: 45112.992 | N6: =M6-L6 -> 0.00028935185 | P6: J-UR-05581P1_20220228 | Q6: 45113.571 | R6: 45113.571 | S6: =R6-Q6 -> 0.00023148148 | U6: J-UR-05581P1_20220228 | V6: 45114.57 | W6: 45114.57 | X6: =W6-V6 -> 0.00023148148 | AA6: J-UR-05581P1_20220228 | AB6: 45117.58 | AC6: 45117.58 | AD6: =AC6-AB6 -> 0.00023148148 | AF6: J-UR-05581P1_20220228 | AG6: 45118.909 | AH6: 45118.909 | AI6: =AH6-AG6 -> 0.00021990741 | AK6: J-UR-05581P4_20220228 | AL6: 45119.967 | AM6: 45119.968 | AN6: =AM6-AL6 -> 0.00030092592 | AP6: J-MVM-4289P1_20220406 | AQ6: 45120.934 | AR6: 45120.934 | AS6: =AR6-AQ6 -> 2.3148154e-05 | AU6: J-UR-05581P1_20220228 | AV6: 45121.494 | AW6: 45121.494 | AX6: =AW6-AV6 -> 0.00023148148 | BA6: J-UR-0550-01P1_20210830 | BB6: 45125.762 | BC6: 45125.762 | BD6: =BC6-BB6 -> 0.00012731482 | BF6: J-UR-05581P4_20220228 | BG6: 45127.017 | BH6: 45127.018 | BI6: =BH6-BG6 -> 0.00028935185 | BK6: J-UR-05581P1_20220228 | BL6: 45127.494 | BM6: 45127.494 | BN6: =BM6-BL6 -> 0.00023148148 | BP6: J-MVM-4289P1_20220406 | BQ6: 45128.814 | BR6: 45128.814 | BS6: =BR6-BQ6 -> 2.3148146e-05 | BV6: J-UR-05581P1_20220228 | BW6: 45131.56 | BX6: 45131.56 | BY6: =BX6-BW6 -> 0.00021990741 | CA6: J-UR-05581P1_20220228 | CB6: 45132.506 | CC6: 45132.506 | CD6: =CC6-CB6 -> 0.00023148148 | CF6: J-UR-05581P1_20220228 | CG6: 45133.889 | CH6: 45133.889 | CI6: =CH6-CG6 -> 0.00023148148 | CK6: J-UR-05581P4_20220228 | CL6: 45135.013 | CM6: 45135.013 | CN6: =CM6-CL6 -> 0.00030092592 | CP6: J-MVH-7249-01P4_20220419 | CQ6: 45135.44 | CR6: 45135.44 | CS6: =CR6-CQ6 -> 6.9444446e-05 | CV6: J-UR-05581P1_20220228 | CW6: 45138.546 | CX6: 45138.546 | CY6: =CX6-CW6 -> 0.00023148148
A7: J-MVM-4289P2_20220406 | B7: 45110.984 | C7: 45110.984 | D7: =C7-B7 -> 2.3148154e-05 | F7: J-UR-05581P1_20220228 | G7: 45111.853 | H7: 45111.854 | I7: =H7-G7 -> 0.00023148148 | K7: J-UR-05581P4_20220228 | L7: 45112.991 | M7: 45112.992 | N7: =M7-L7 -> 0.00030092593 | P7: J-UR-05581P1_20220228 | Q7: 45113.571 | R7: 45113.571 | S7: =R7-Q7 -> 0.00023148148 | U7: J-UR-05581P1_20220228 | V7: 45114.569 | W7: 45114.57 | X7: =W7-V7 -> 0.0002199074 | AA7: J-UR-05581P1_20220228 | AB7: 45117.579 | AC7: 45117.58 | AD7: =AC7-AB7 -> 0.00023148148 | AF7: J-UR-05581P1_20220228 | AG7: 45118.909 | AH7: 45118.909 | AI7: =AH7-AG7 -> 0.00023148148 | AK7: J-UR-05581P4_20220228 | AL7: 45119.967 | AM7: 45119.967 | AN7: =AM7-AL7 -> 0.00030092592 | AP7: J-MVM-4289P1_20220406 | AQ7: 45120.934 | AR7: 45120.934 | AS7: =AR7-AQ7 -> 2.3148154e-05 | AU7: J-UR-05581P1_20220228 | AV7: 45121.493 | AW7: 45121.493 | AX7: =AW7-AV7 -> 0.00023148148 | BA7: J-UR-0550-01P1_20210830 | BB7: 45125.762 | BC7: 45125.762 | BD7: =BC7-BB7 -> 0.00012731482 | BF7: J-UR-05581P4_20220228 | BG7: 45127.017 | BH7: 45127.017 | BI7: =BH7-BG7 -> 0.00028935185 | BK7: J-UR-05581P1_20220228 | BL7: 45127.494 | BM7: 45127.494 | BN7: =BM7-BL7 -> 0.00023148148 | BP7: J-MVM-4289P1_20220406 | BQ7: 45128.814 | BR7: 45128.814 | BS7: =BR7-BQ7 -> 2.3148146e-05 | BV7: J-UR-05581P1_20220228 | BW7: 45131.56 | BX7: 45131.56 | BY7: =BX7-BW7 -> 0.00023148148 | CA7: J-UR-05581P1_20220228 | CB7: 45132.505 | CC7: 45132.506 | CD7: =CC7-CB7 -> 0.00023148148 | CF7: J-UR-05581P1_20220228 | CG7: 45133.889 | CH7: 45133.889 | CI7: =CH7-CG7 -> 0.00023148148 | CK7: J-UR-05581P4_20220228 | CL7: 45135.013 | CM7: 45135.013 | CN7: =CM7-CL7 -> 0.00028935185 | CP7: J-MVH-7249-01P4_20220419 | CQ7: 45135.439 | CR7: 45135.439 | CS7: =CR7-CQ7 -> 6.9444446e-05 | CV7: J-UR-05581P1_20220228 | CW7: 45138.546 | CX7: 45138.546 | CY7: =CX7-CW7 -> 0.00023148148
A8: J-MVM-4289P2_20220406 | B8: 45110.979 | C8: 45110.979 | D8: =C8-B8 -> 3.4722223e-05 | F8: J-UR-05581P1_20220228 | G8: 45111.853 | H8: 45111.853 | I8: =H8-G8 -> 0.00023148148 | K8: J-UR-05581P4_20220228 | L8: 45112.991 | M8: 45112.991 | N8: =M8-L8 -> 0.00028935185 | P8: J-UR-05581P1_20220228 | Q8: 45113.571 | R8: 45113.571 | S8: =R8-Q8 -> 0.00023148148 | U8: J-UR-05581P1_20220228 | V8: 45114.569 | W8: 45114.569 | X8: =W8-V8 -> 0.00023148148 | AA8: J-UR-05581P1_20220228 | AB8: 45117.579 | AC8: 45117.579 | AD8: =AC8-AB8 -> 0.00023148148 | AF8: J-UR-05581P1_20220228 | AG8: 45118.909 | AH8: 45118.909 | AI8: =AH8-AG8 -> 0.00023148148 | AK8: J-UR-05581P4_20220228 | AL8: 45119.967 | AM8: 45119.967 | AN8: =AM8-AL8 -> 0.00028935185 | AP8: J-MVM-4289P1_20220406 | AQ8: 45120.934 | AR8: 45120.934 | AS8: =AR8-AQ8 -> 2.3148154e-05 | AU8: J-UR-05581P1_20220228 | AV8: 45121.493 | AW8: 45121.493 | AX8: =AW8-AV8 -> 0.00023148148 | BA8: J-UR-0550-01P1_20210830 | BB8: 45125.762 | BC8: 45125.762 | BD8: =BC8-BB8 -> 0.00012731482 | BF8: J-UR-05581P4_20220228 | BG8: 45127.016 | BH8: 45127.017 | BI8: =BH8-BG8 -> 0.00030092593 | BK8: J-UR-05581P1_20220228 | BL8: 45127.493 | BM8: 45127.494 | BN8: =BM8-BL8 -> 0.00021990741 | BP8: J-MVM-4289P1_20220406 | BQ8: 45128.814 | BR8: 45128.814 | BS8: =BR8-BQ8 -> 2.3148146e-05 | BV8: J-UR-05581P1_20220228 | BW8: 45131.559 | BX8: 45131.559 | BY8: =BX8-BW8 -> 0.00023148148 | CA8: J-UR-05581P1_20220228 | CB8: 45132.505 | CC8: 45132.505 | CD8: =CC8-CB8 -> 0.00023148148 | CF8: J-UR-05581P1_20220228 | CG8: 45133.888 | CH8: 45133.888 | CI8: =CH8-CG8 -> 0.00024305555 | CK8: J-UR-05581P4_20220228 | CL8: 45135.012 | CM8: 45135.013 | CN8: =CM8-CL8 -> 0.00030092593 | CP8: J-MVH-7249-01P4_20220419 | CQ8: 45135.439 | CR8: 45135.439 | CS8: =CR8-CQ8 -> 6.9444446e-05 | CV8: J-UR-05581P1_20220228 | CW8: 45138.545 | CX8: 45138.545 | CY8: =CX8-CW8 -> 0.00023148148
A9: J-UR-05581P1_20220228 | B9: 45110.904 | C9: 45110.904 | D9: =C9-B9 -> 0.00023148148 | F9: J-UR-05581P1_20220228 | G9: 45111.853 | H9: 45111.853 | I9: =H9-G9 -> 0.00023148148 | K9: J-UR-05581P4_20220228 | L9: 45112.991 | M9: 45112.991 | N9: =M9-L9 -> 0.00030092593 | P9: J-UR-05581P1_20220228 | Q9: 45113.57 | R9: 45113.571 | S9: =R9-Q9 -> 0.00023148148 | U9: J-UR-05581P1_20220228 | V9: 45114.569 | W9: 45114.569 | X9: =W9-V9 -> 0.00023148148 | AA9: J-UR-05581P1_20220228 | AB9: 45117.579 | AC9: 45117.579 | AD9: =AC9-AB9 -> 0.00023148148 | AF9: J-UR-05581P1_20220228 | AG9: 45118.908 | AH9: 45118.908 | AI9: =AH9-AG9 -> 0.00023148148 | AK9: J-UR-05581P4_20220228 | AL9: 45119.966 | AM9: 45119.967 | AN9: =AM9-AL9 -> 0.00028935185 | AP9: J-MVM-4289P1_20220406 | AQ9: 45120.934 | AR9: 45120.934 | AS9: =AR9-AQ9 -> 2.3148154e-05 | AU9: J-UR-05581P1_20220228 | AV9: 45121.493 | AW9: 45121.493 | AX9: =AW9-AV9 -> 0.00021990741 | BA9: J-UR-0550-01P1_20210830 | BB9: 45125.762 | BC9: 45125.762 | BD9: =BC9-BB9 -> 0.00012731482 | BF9: J-UR-05581P4_20220228 | BG9: 45127.016 | BH9: 45127.016 | BI9: =BH9-BG9 -> 0.00030092592 | BK9: J-UR-05581P1_20220228 | BL9: 45127.493 | BM9: 45127.493 | BN9: =BM9-BL9 -> 0.00023148148 | BP9: J-MVM-4289P1_20220406 | BQ9: 45128.813 | BR9: 45128.813 | BS9: =BR9-BQ9 -> 2.3148146e-05 | BV9: J-UR-05581P1_20220228 | BW9: 45131.559 | BX9: 45131.559 | BY9: =BX9-BW9 -> 0.00023148148 | CA9: J-UR-05581P1_20220228 | CB9: 45132.505 | CC9: 45132.505 | CD9: =CC9-CB9 -> 0.00023148148 | CF9: J-UR-05581P1_20220228 | CG9: 45133.888 | CH9: 45133.888 | CI9: =CH9-CG9 -> 0.00023148148 | CK9: J-UR-05581P4_20220228 | CL9: 45135.012 | CM9: 45135.012 | CN9: =CM9-CL9 -> 0.00030092592 | CP9: J-MVH-7249-01P4_20220419 | CQ9: 45135.439 | CR9: 45135.439 | CS9: =CR9-CQ9 -> 8.1018516e-05 | CV9: J-UR-05581P1_20220228 | CW9: 45138.545 | CX9: 45138.545 | CY9: =CX9-CW9 -> 0.00023148148
A10: J-UR-05581P1_20220228 | B10: 45110.883 | C10: 45110.883 | D10: =C10-B10 -> 0.00023148148 | F10: J-UR-05581P1_20220228 | G10: 45111.853 | H10: 45111.853 | I10: =H10-G10 -> 0.00023148148 | K10: J-UR-05581P4_20220228 | L10: 45112.99 | M10: 45112.991 | N10: =M10-L10 -> 0.00030092593 | P10: J-UR-05581P1_20220228 | Q10: 45113.57 | R10: 45113.57 | S10: =R10-Q10 -> 0.00023148148 | U10: J-UR-05581P1_20220228 | V10: 45114.569 | W10: 45114.569 | X10: =W10-V10 -> 0.00023148148 | AA10: J-UR-05581P1_20220228 | AB10: 45117.578 | AC10: 45117.579 | AD10: =AC10-AB10 -> 0.00024305555 | AF10: J-UR-05581P1_20220228 | AG10: 45118.908 | AH10: 45118.908 | AI10: =AH10-AG10 -> 0.00023148148 | AK10: J-UR-05581P4_20220228 | AL10: 45119.966 | AM10: 45119.966 | AN10: =AM10-AL10 -> 0.00030092592 | AP10: J-MVM-4289P1_20220406 | AQ10: 45120.934 | AR10: 45120.934 | AS10: =AR10-AQ10 -> 2.3148146e-05 | AU10: J-UR-05581P1_20220228 | AV10: 45121.492 | AW10: 45121.493 | AX10: =AW10-AV10 -> 0.00021990741 | BA10: J-UR-0550-01P1_20210830 | BB10: 45125.762 | BC10: 45125.762 | BD10: =BC10-BB10 -> 0.00012731482 | BF10: J-UR-05581P4_20220228 | BG10: 45127.016 | BH10: 45127.016 | BI10: =BH10-BG10 -> 0.00028935185 | BK10: J-UR-05581P1_20220228 | BL10: 45127.493 | BM10: 45127.493 | BN10: =BM10-BL10 -> 0.00023148148 | BP10: J-MVM-4289P1_20220406 | BQ10: 45128.813 | BR10: 45128.813 | BS10: =BR10-BQ10 -> 2.3148146e-05 | BV10: J-UR-05581P1_20220228 | BW10: 45131.559 | BX10: 45131.559 | BY10: =BX10-BW10 -> 0.00023148148 | CA10: J-UR-05581P1_20220228 | CB10: 45132.504 | CC10: 45132.505 | CD10: =CC10-CB10 -> 0.00023148148 | CF10: J-UR-05581P1_20220228 | CG10: 45133.888 | CH10: 45133.888 | CI10: =CH10-CG10 -> 0.00023148148 | CK10: J-UR-05581P4_20220228 | CL10: 45135.012 | CM10: 45135.012 | CN10: =CM10-CL10 -> 0.00028935185 | CP10: J-MVH-7249-01P4_20220419 | CQ10: 45135.439 | CR10: 45135.439 | CS10: =CR10-CQ10 -> 6.9444446e-05 | CV10: J-UR-05581P1_20220228 | CW10: 45138.545 | CX10: 45138.545 | CY10: =CX10-CW10 -> 0.00023148148
A11: J-UR-05581P4_20220228 | B11: 45110.767 | C11: 45110.768 | D11: =C11-B11 -> 0.00028935185 | F11: J-UR-05581P1_20220228 | G11: 45111.852 | H11: 45111.852 | I11: =H11-G11 -> 0.00021990741 | K11: J-UR-05581P4_20220228 | L11: 45112.99 | M11: 45112.99 | N11: =M11-L11 -> 0.00028935185 | P11: J-UR-05581P1_20220228 | Q11: 45113.57 | R11: 45113.57 | S11: =R11-Q11 -> 0.00023148148 | U11: J-UR-05581P1_20220228 | V11: 45114.568 | W11: 45114.568 | X11: =W11-V11 -> 0.00023148148 | AA11: J-UR-05581P1_20220228 | AB11: 45117.578 | AC11: 45117.578 | AD11: =AC11-AB11 -> 0.00023148148 | AF11: J-UR-05581P1_20220228 | AG11: 45118.908 | AH11: 45118.908 | AI11: =AH11-AG11 -> 0.00023148148 | AK11: J-UR-05581P4_20220228 | AL11: 45119.965 | AM11: 45119.966 | AN11: =AM11-AL11 -> 0.00030092592 | AP11: J-MVM-4289P1_20220406 | AQ11: 45120.934 | AR11: 45120.934 | AS11: =AR11-AQ11 -> 2.3148146e-05 | AU11: J-UR-05581P1_20220228 | AV11: 45121.492 | AW11: 45121.492 | AX11: =AW11-AV11 -> 0.00023148148 | BA11: J-UR-0550-01P1_20210830 | BB11: 45125.761 | BC11: 45125.762 | BD11: =BC11-BB11 -> 0.00012731482 | BF11: J-UR-05581P4_20220228 | BG11: 45127.015 | BH11: 45127.016 | BI11: =BH11-BG11 -> 0.00028935185 | BK11: J-UR-05581P1_20220228 | BL11: 45127.492 | BM11: 45127.493 | BN11: =BM11-BL11 -> 0.00023148148 | BP11: J-MVM-4289P1_20220406 | BQ11: 45128.813 | BR11: 45128.813 | BS11: =BR11-BQ11 -> 2.3148146e-05 | BV11: J-UR-05581P1_20220228 | BW11: 45131.558 | BX11: 45131.559 | BY11: =BX11-BW11 -> 0.00023148148 | CA11: J-UR-05581P1_20220228 | CB11: 45132.504 | CC11: 45132.504 | CD11: =CC11-CB11 -> 0.00023148148 | CF11: J-UR-05581P1_20220228 | CG11: 45133.887 | CH11: 45133.887 | CI11: =CH11-CG11 -> 0.00023148148 | CK11: J-UR-05581P4_20220228 | CL11: 45135.011 | CM11: 45135.011 | CN11: =CM11-CL11 -> 0.00028935185 | CP11: J-MVH-7249-01P4_20220419 | CQ11: 45135.439 | CR11: 45135.439 | CS11: =CR11-CQ11 -> 6.9444446e-05 | CV11: J-UR-05581P1_20220228 | CW11: 45138.544 | CX11: 45138.545 | CY11: =CX11-CW11 -> 0.00023148148
A12: J-UR-05581P4_20220228 | B12: 45110.742 | C12: 45110.742 | D12: =C12-B12 -> 0.00028935185 | F12: J-UR-05581P1_20220228 | G12: 45111.852 | H12: 45111.852 | I12: =H12-G12 -> 0.00023148148 | K12: J-UR-05581P4_20220228 | L12: 45112.99 | M12: 45112.99 | N12: =M12-L12 -> 0.00030092592 | P12: J-UR-05581P1_20220228 | Q12: 45113.569 | R12: 45113.57 | S12: =R12-Q12 -> 0.00023148148 | U12: J-UR-05581P1_20220228 | V12: 45114.568 | W12: 45114.568 | X12: =W12-V12 -> 0.00023148148 | AA12: J-UR-05581P1_20220228 | AB12: 45117.578 | AC12: 45117.578 | AD12: =AC12-AB12 -> 0.00023148148 | AF12: J-UR-05581P1_20220228 | AG12: 45118.907 | AH12: 45118.907 | AI12: =AH12-AG12 -> 0.00023148148 | AK12: J-UR-05581P4_20220228 | AL12: 45119.965 | AM12: 45119.965 | AN12: =AM12-AL12 -> 0.00028935185 | AP12: J-MVM-4289P1_20220406 | AQ12: 45120.934 | AR12: 45120.934 | AS12: =AR12-AQ12 -> 2.3148146e-05 | AU12: J-UR-05581P1_20220228 | AV12: 45121.492 | AW12: 45121.492 | AX12: =AW12-AV12 -> 0.00021990741 | BA12: J-UR-0550-01P1_20210830 | BB12: 45125.761 | BC12: 45125.761 | BD12: =BC12-BB12 -> 0.00012731482 | BF12: J-UR-05581P4_20220228 | BG12: 45127.015 | BH12: 45127.015 | BI12: =BH12-BG12 -> 0.00030092593 | BK12: J-UR-05581P1_20220228 | BL12: 45127.492 | BM12: 45127.492 | BN12: =BM12-BL12 -> 0.00023148148 | BP12: J-MVM-4289P1_20220406 | BQ12: 45128.813 | BR12: 45128.813 | BS12: =BR12-BQ12 -> 2.3148146e-05 | BV12: J-UR-05581P1_20220228 | BW12: 45131.558 | BX12: 45131.558 | BY12: =BX12-BW12 -> 0.00023148148 | CA12: J-UR-05581P1_20220228 | CB12: 45132.504 | CC12: 45132.504 | CD12: =CC12-CB12 -> 0.00023148148 | CF12: J-UR-05581P1_20220228 | CG12: 45133.887 | CH12: 45133.887 | CI12: =CH12-CG12 -> 0.00023148148 | CK12: J-UR-05581P4_20220228 | CL12: 45135.011 | CM12: 45135.011 | CN12: =CM12-CL12 -> 0.00028935185 | CP12: J-MVH-7249-01P4_20220419 | CQ12: 45135.438 | CR12: 45135.439 | CS12: =CR12-CQ12 -> 8.1018516e-05 | CV12: J-UR-05581P1_20220228 | CW12: 45138.544 | CX12: 45138.544 | CY12: =CX12-CW12 -> 0.00023148148
A13: J-UR-0578P4_20220525 | B13: 45110.471 | C13: 45110.472 | D13: =C13-B13 -> 6.9444439e-05 | F13: J-UR-05581P1_20220228 | G13: 45111.852 | H13: 45111.852 | I13: =H13-G13 -> 0.00023148148 | K13: J-UR-05581P4_20220228 | L13: 45112.989 | M13: 45112.989 | N13: =M13-L13 -> 0.00030092593 | P13: J-UR-05581P1_20220228 | Q13: 45113.569 | R13: 45113.569 | S13: =R13-Q13 -> 0.00023148148 | U13: J-UR-05581P1_20220228 | V13: 45114.568 | W13: 45114.568 | X13: =W13-V13 -> 0.00023148148 | AA13: J-UR-05581P1_20220228 | AB13: 45117.578 | AC13: 45117.578 | AD13: =AC13-AB13 -> 0.00023148148 | AF13: J-UR-05581P1_20220228 | AG13: 45118.907 | AH13: 45118.907 | AI13: =AH13-AG13 -> 0.00023148148 | AK13: J-UR-05581P4_20220228 | AL13: 45119.965 | AM13: 45119.965 | AN13: =AM13-AL13 -> 0.00028935185 | AP13: J-MVM-4289P1_20220406 | AQ13: 45120.933 | AR13: 45120.934 | AS13: =AR13-AQ13 -> 2.3148146e-05 | AU13: J-UR-05581P1_20220228 | AV13: 45121.491 | AW13: 45121.492 | AX13: =AW13-AV13 -> 0.00023148148 | BA13: J-UR-0550-01P1_20210830 | BB13: 45125.761 | BC13: 45125.761 | BD13: =BC13-BB13 -> 0.00012731482 | BF13: J-UR-05581P4_20220228 | BG13: 45127.015 | BH13: 45127.015 | BI13: =BH13-BG13 -> 0.00028935185 | BK13: J-UR-05581P1_20220228 | BL13: 45127.492 | BM13: 45127.492 | BN13: =BM13-BL13 -> 0.00023148148 | BP13: J-MVM-4289P1_20220406 | BQ13: 45128.813 | BR13: 45128.813 | BS13: =BR13-BQ13 -> 2.3148146e-05 | BV13: J-UR-05581P1_20220228 | BW13: 45131.558 | BX13: 45131.558 | BY13: =BX13-BW13 -> 0.00023148148 | CA13: J-UR-05581P1_20220228 | CB13: 45132.503 | CC13: 45132.504 | CD13: =CC13-CB13 -> 0.00021990741 | CF13: J-UR-05581P1_20220228 | CG13: 45133.886 | CH13: 45133.887 | CI13: =CH13-CG13 -> 0.00024305555 | CK13: J-UR-05581P4_20220228 | CL13: 45135.01 | CM13: 45135.011 | CN13: =CM13-CL13 -> 0.00030092592 | CP13: J-UR-05581P1_20220228 | CQ13: 45135.544 | CR13: 45135.544 | CS13: =CR13-CQ13 -> 0.00023148148 | CV13: J-UR-05581P1_20220228 | CW13: 45138.544 | CX13: 45138.544 | CY13: =CX13-CW13 -> 0.00021990741
A14: J-UR-0578P4_20220525 | B14: 45110.47 | C14: 45110.47 | D14: =C14-B14 -> 5.7870369e-05 | F14: J-UR-05581P1_20220228 | G14: 45111.851 | H14: 45111.852 | I14: =H14-G14 -> 0.00023148148 | K14: J-UR-05581P4_20220228 | L14: 45112.989 | M14: 45112.989 | N14: =M14-L14 -> 0.00030092592 | P14: J-UR-05581P1_20220228 | Q14: 45113.569 | R14: 45113.569 | S14: =R14-Q14 -> 0.00021990741 | U14: J-UR-05581P1_20220228 | V14: 45114.567 | W14: 45114.567 | X14: =W14-V14 -> 0.00023148148 | AA14: J-UR-05581P1_20220228 | AB14: 45117.577 | AC14: 45117.577 | AD14: =AC14-AB14 -> 0.00023148148 | AF14: J-UR-05581P1_20220228 | AG14: 45118.907 | AH14: 45118.907 | AI14: =AH14-AG14 -> 0.00023148148 | AK14: J-UR-05581P4_20220228 | AL14: 45119.964 | AM14: 45119.965 | AN14: =AM14-AL14 -> 0.00030092592 | AP14: J-MVM-4289P1_20220406 | AQ14: 45120.933 | AR14: 45120.933 | AS14: =AR14-AQ14 -> 3.4722223e-05 | AU14: J-UR-05581P1_20220228 | AV14: 45121.491 | AW14: 45121.491 | AX14: =AW14-AV14 -> 0.00023148148 | BA14: J-UR-0550-01P1_20210830 | BB14: 45125.761 | BC14: 45125.761 | BD14: =BC14-BB14 -> 0.00012731482 | BF14: J-UR-05581P4_20220228 | BG14: 45127.014 | BH14: 45127.014 | BI14: =BH14-BG14 -> 0.00028935185 | BK14: J-UR-05581P1_20220228 | BL14: 45127.491 | BM14: 45127.492 | BN14: =BM14-BL14 -> 0.00023148148 | BP14: J-MVM-4289P1_20220406 | BQ14: 45128.813 | BR14: 45128.813 | BS14: =BR14-BQ14 -> 2.3148154e-05 | BV14: J-UR-05581P1_20220228 | BW14: 45131.557 | BX14: 45131.558 | BY14: =BX14-BW14 -> 0.00023148148 | CA14: J-UR-05581P1_20220228 | CB14: 45132.503 | CC14: 45132.503 | CD14: =CC14-CB14 -> 0.00021990741 | CF14: J-UR-05581P1_20220228 | CG14: 45133.886 | CH14: 45133.886 | CI14: =CH14-CG14 -> 0.00023148148 | CK14: J-UR-05581P4_20220228 | CL14: 45135.01 | CM14: 45135.01 | CN14: =CM14-CL14 -> 0.00030092592 | CP14: J-UR-05581P1_20220228 | CQ14: 45135.543 | CR14: 45135.544 | CS14: =CR14-CQ14 -> 0.00023148148 | CV14: J-UR-05581P1_20220228 | CW14: 45138.543 | CX14: 45138.544 | CY14: =CX14-CW14 -> 0.00023148148
A15: J-UR-0585P1_20220601 | B15: 45110.539 | C15: 45110.539 | D15: =C15-B15 -> 3.4722223e-05 | F15: J-UR-05581P1_20220228 | G15: 45111.851 | H15: 45111.851 | I15: =H15-G15 -> 0.00023148148 | K15: J-UR-05581P4_20220228 | L15: 45112.988 | M15: 45112.989 | N15: =M15-L15 -> 0.00030092592 | P15: J-UR-05581P1_20220228 | Q15: 45113.568 | R15: 45113.569 | S15: =R15-Q15 -> 0.00023148148 | U15: J-UR-05581P1_20220228 | V15: 45114.567 | W15: 45114.567 | X15: =W15-V15 -> 0.00023148148 | AA15: J-UR-05581P1_20220228 | AB15: 45117.577 | AC15: 45117.577 | AD15: =AC15-AB15 -> 0.00023148148 | AF15: J-UR-05581P1_20220228 | AG15: 45118.906 | AH15: 45118.907 | AI15: =AH15-AG15 -> 0.00023148148 | AK15: J-UR-05581P4_20220228 | AL15: 45119.964 | AM15: 45119.964 | AN15: =AM15-AL15 -> 0.00030092592 | AP15: J-MVM-4289P1_20220406 | AQ15: 45120.933 | AR15: 45120.933 | AS15: =AR15-AQ15 -> 2.3148146e-05 | AU15: J-UR-05581P1_20220228 | AV15: 45121.491 | AW15: 45121.491 | AX15: =AW15-AV15 -> 0.00023148148 | BA15: J-UR-0550-01P1_20210830 | BB15: 45125.761 | BC15: 45125.761 | BD15: =BC15-BB15 -> 0.00012731482 | BF15: J-UR-05581P4_20220228 | BG15: 45127.014 | BH15: 45127.014 | BI15: =BH15-BG15 -> 0.00030092593 | BK15: J-UR-05581P1_20220228 | BL15: 45127.491 | BM15: 45127.491 | BN15: =BM15-BL15 -> 0.00023148148 | BP15: J-MVM-4289P1_20220406 | BQ15: 45128.813 | BR15: 45128.813 | BS15: =BR15-BQ15 -> 2.3148154e-05 | BV15: J-UR-05581P1_20220228 | BW15: 45131.557 | BX15: 45131.557 | BY15: =BX15-BW15 -> 0.00021990741 | CA15: J-UR-05581P1_20220228 | CB15: 45132.503 | CC15: 45132.503 | CD15: =CC15-CB15 -> 0.00023148148 | CF15: J-UR-05581P1_20220228 | CG15: 45133.886 | CH15: 45133.886 | CI15: =CH15-CG15 -> 0.00023148148 | CK15: J-UR-05581P4_20220228 | CL15: 45135.01 | CM15: 45135.01 | CN15: =CM15-CL15 -> 0.00028935185 | CP15: J-UR-05581P1_20220228 | CQ15: 45135.543 | CR15: 45135.543 | CS15: =CR15-CQ15 -> 0.00023148148 | CV15: J-UR-05581P1_20220228 | CW15: 45138.543 | CX15: 45138.543 | CY15: =CX15-CW15 -> 0.00023148148
A16: J-UR-0585P1_20220601 | B16: 45110.505 | C16: 45110.505 | D16: =C16-B16 -> 2.3148146e-05 | F16: J-UR-05581P1_20220228 | G16: 45111.851 | H16: 45111.851 | I16: =H16-G16 -> 0.00023148148 | K16: J-UR-05581P4_20220228 | L16: 45112.988 | M16: 45112.988 | N16: =M16-L16 -> 0.00030092592 | P16: J-UR-05581P1_20220228 | Q16: 45113.568 | R16: 45113.568 | S16: =R16-Q16 -> 0.00023148148 | U16: J-UR-05581P1_20220228 | V16: 45114.567 | W16: 45114.567 | X16: =W16-V16 -> 0.00023148148 | AA16: J-UR-05581P1_20220228 | AB16: 45117.577 | AC16: 45117.577 | AD16: =AC16-AB16 -> 0.00023148148 | AF16: J-UR-05581P1_20220228 | AG16: 45118.906 | AH16: 45118.906 | AI16: =AH16-AG16 -> 0.00023148148 | AK16: J-UR-05581P4_20220228 | AL16: 45119.964 | AM16: 45119.964 | AN16: =AM16-AL16 -> 0.00028935185 | AP16: J-MVM-4289P1_20220406 | AQ16: 45120.933 | AR16: 45120.933 | AS16: =AR16-AQ16 -> 2.3148154e-05 | AU16: J-UR-05581P1_20220228 | AV16: 45121.49 | AW16: 45121.491 | AX16: =AW16-AV16 -> 0.00023148148 | BA16: J-UR-0550-01P1_20210830 | BB16: 45125.76 | BC16: 45125.76 | BD16: =BC16-BB16 -> 0.00012731482 | BF16: J-UR-05581P4_20220228 | BG16: 45127.013 | BH16: 45127.014 | BI16: =BH16-BG16 -> 0.00028935185 | BK16: J-UR-05581P1_20220228 | BL16: 45127.491 | BM16: 45127.491 | BN16: =BM16-BL16 -> 0.00023148148 | BP16: J-MVM-4289P1_20220406 | BQ16: 45128.813 | BR16: 45128.813 | BS16: =BR16-BQ16 -> 3.4722223e-05 | BV16: J-UR-05581P1_20220228 | BW16: 45131.557 | BX16: 45131.557 | BY16: =BX16-BW16 -> 0.00023148148 | CA16: J-UR-05581P1_20220228 | CB16: 45132.503 | CC16: 45132.503 | CD16: =CC16-CB16 -> 0.00023148148 | CF16: J-UR-05581P1_20220228 | CG16: 45133.885 | CH16: 45133.886 | CI16: =CH16-CG16 -> 0.00023148148 | CK16: J-UR-05581P4_20220228 | CL16: 45135.009 | CM16: 45135.01 | CN16: =CM16-CL16 -> 0.00030092592 | CP16: J-UR-05581P1_20220228 | CQ16: 45135.543 | CR16: 45135.543 | CS16: =CR16-CQ16 -> 0.00023148148 | CV16: J-UR-05581P1_20220228 | CW16: 45138.543 | CX16: 45138.543 | CY16: =CX16-CW16 -> 0.00023148148
... A66: UTS-0717P6 | B66: 45110.86 | C66: 45110.86 | D66: =C66-B66 -> 0.00010416666 | F66: J-UR-05581P4_20220228 | G66: 45111.744 | H66: 45111.744 | I66: =H66-G66 -> 0.00028935185 | K66: J-UR-4192-01P1_20211105 | L66: 45112.434 | M66: 45112.434 | N66: =M66-L66 -> 6.9444446e-05 | P66: J-URS-43013P1_20221028 | Q66: 45113.599 | R66: 45113.599 | S66: =R66-Q66 -> 6.9444446e-05 | U66: J-UR-05581P4_20220228 | V66: 45114.989 | W66: 45114.989 | X66: =W66-V66 -> 0.00027777778 | AA66: J-UR-05581P4_20220228 | AB66: 45117.937 | AC66: 45117.937 | AD66: =AC66-AB66 -> 0.00030092593 | AF66: J-UR-05581P1_20220228 | AG66: 45118.49 | AH66: 45118.49 | AI66: =AH66-AG66 -> 0.00021990741 | AK66: UR-0480P1 | AL66: 45119.393 | AM66: 45119.394 | AN66: =AM66-AL66 -> 0.00010416667 | AP66: J-MVM-4289P2_20220406 | AQ66: 45120.925 | AR66: 45120.925 | AS66: =AR66-AQ66 -> 2.3148154e-05 | AU66: J-UR-05581P4_20220228 | AV66: 45121.389 | AW66: 45121.39 | AX66: =AW66-AV66 -> 0.00030092593 | BA66: J-UR-0550-01P8_20210830 | BB66: 45125.728 | BC66: 45125.728 | BD66: =BC66-BB66 -> 0.00019675926 | BF66: J-UR-0582P10_20230706 | BG66: 45126.446 | BH66: 45126.446 | BI66: =BH66-BG66 -> 0.00041666666 | BK66: UR-04511P1 | BL66: 45127.735 | BM66: 45127.735 | BN66: =BM66-BL66 -> 6.9444446e-05 | BP66: J-MVM-4289P2_20220406 | BQ66: 45128.804 | BR66: 45128.804 | BS66: =BR66-BQ66 -> 2.3148146e-05 | BV66: J-UR-05581P4_20220228 | BW66: 45132.015 | BX66: 45132.016 | BY66: =BX66-BW66 -> 0.00030092592 | CA66: J-UR-05581P4_20220228 | CB66: 45132.86 | CC66: 45132.86 | CD66: =CC66-CB66 -> 0.00028935185 | CF66: J-UR-05581P1_20220228 | CG66: 45133.557 | CH66: 45133.557 | CI66: =CH66-CG66 -> 0.00023148148 | CK66: MVD-0415P1 | CL66: 45134.626 | CM66: 45134.626 | CN66: =CM66-CL66 -> 0.00019675926 | CP66: J-UR-05581P4_20220228 | CQ66: 45135.963 | CR66: 45135.963 | CS66: =CR66-CQ66 -> 0.00028935185 | CV66: UR-0483P1 | CW66: 45138.605 | CX66: 45138.605 | CY66: =CX66-CW66 -> 5.7870377e-05
F67: J-UR-05581P4_20220228 | G67: 45111.743 | H67: 45111.743 | I67: =H67-G67 -> 0.00030092592 | K67: J-UR-4192-01P1_20211105 | L67: 45112.434 | M67: 45112.434 | N67: =M67-L67 -> 6.9444446e-05 | P67: J-URS-43013P1_20221028 | Q67: 45113.598 | R67: 45113.598 | S67: =R67-Q67 -> 6.9444446e-05 | U67: J-UR-05581P4_20220228 | V67: 45114.989 | W67: 45114.989 | X67: =W67-V67 -> 0.00030092593 | AA67: J-UR-05581P4_20220228 | AB67: 45117.936 | AC67: 45117.937 | AD67: =AC67-AB67 -> 0.00030092593 | AF67: J-UR-05581P1_20220228 | AG67: 45118.489 | AH67: 45118.49 | AI67: =AH67-AG67 -> 0.00023148148 | AK67: UR-0480P1 | AL67: 45119.393 | AM67: 45119.393 | AN67: =AM67-AL67 -> 0.00010416666 | AP67: J-MVM-4289P2_20220406 | AQ67: 45120.925 | AR67: 45120.925 | AS67: =AR67-AQ67 -> 3.4722216e-05 | AU67: J-UR-05581P4_20220228 | AV67: 45121.389 | AW67: 45121.389 | AX67: =AW67-AV67 -> 0.00028935185 | BA67: J-UR-0550-01P8_20210830 | BB67: 45125.727 | BC67: 45125.728 | BD67: =BC67-BB67 -> 0.00019675925 | BF67: J-UR-0582P10_20230706 | BG67: 45126.445 | BH67: 45126.446 | BI67: =BH67-BG67 -> 0.00040509259 | BK67: UR-04511P1 | BL67: 45127.735 | BM67: 45127.735 | BN67: =BM67-BL67 -> 8.1018516e-05 | BP67: J-MVM-4289P2_20220406 | BQ67: 45128.804 | BR67: 45128.804 | BS67: =BR67-BQ67 -> 2.3148146e-05 | BV67: J-UR-05581P4_20220228 | BW67: 45132.015 | BX67: 45132.015 | BY67: =BX67-BW67 -> 0.00028935185 | CA67: J-UR-05581P4_20220228 | CB67: 45132.86 | CC67: 45132.86 | CD67: =CC67-CB67 -> 0.00028935185 | CF67: J-UR-05581P1_20220228 | CG67: 45133.556 | CH67: 45133.557 | CI67: =CH67-CG67 -> 0.00023148148 | CK67: MVD-0415P1 | CL67: 45134.626 | CM67: 45134.626 | CN67: =CM67-CL67 -> 0.00018518518 | CP67: J-UR-05581P4_20220228 | CQ67: 45135.963 | CR67: 45135.963 | CS67: =CR67-CQ67 -> 0.00030092593 | CV67: UR-0483P1 | CW67: 45138.605 | CX67: 45138.605 | CY67: =CX67-CW67 -> 5.7870369e-05
F68: J-UR-05581P4_20220228 | G68: 45111.743 | H68: 45111.743 | I68: =H68-G68 -> 0.00028935185 | K68: J-UR-4192-01P1_20211105 | L68: 45112.433 | M68: 45112.433 | N68: =M68-L68 -> 6.9444446e-05 | P68: J-URS-43013P1_20221028 | Q68: 45113.598 | R68: 45113.598 | S68: =R68-Q68 -> 8.1018516e-05 | U68: J-UR-05581P4_20220228 | V68: 45114.988 | W68: 45114.989 | X68: =W68-V68 -> 0.00030092593 | AA68: J-UR-05581P4_20220228 | AB68: 45117.936 | AC68: 45117.936 | AD68: =AC68-AB68 -> 0.00028935185 | AF68: J-UR-05581P1_20220228 | AG68: 45118.489 | AH68: 45118.489 | AI68: =AH68-AG68 -> 0.00023148148 | AK68: UR-0480P1 | AL68: 45119.393 | AM68: 45119.393 | AN68: =AM68-AL68 -> 0.00011574074 | AP68: J-MVM-4289P2_20220406 | AQ68: 45120.925 | AR68: 45120.925 | AS68: =AR68-AQ68 -> 2.3148146e-05 | AU68: J-UR-05581P4_20220228 | AV68: 45121.389 | AW68: 45121.389 | AX68: =AW68-AV68 -> 0.00030092593 | BA68: J-UR-0550-01P8_20210830 | BB68: 45125.727 | BC68: 45125.727 | BD68: =BC68-BB68 -> 0.00019675926 | BF68: J-UR-0582P10_20230706 | BG68: 45126.445 | BH68: 45126.445 | BI68: =BH68-BG68 -> 0.00041666667 | BK68: UR-04511P1 | BL68: 45127.735 | BM68: 45127.735 | BN68: =BM68-BL68 -> 6.9444439e-05 | BP68: J-MVM-4289P2_20220406 | BQ68: 45128.804 | BR68: 45128.804 | BS68: =BR68-BQ68 -> 2.3148154e-05 | BV68: J-UR-05581P4_20220228 | BW68: 45132.015 | BX68: 45132.015 | BY68: =BX68-BW68 -> 0.00028935185 | CA68: J-UR-05581P4_20220228 | CB68: 45132.859 | CC68: 45132.86 | CD68: =CC68-CB68 -> 0.00028935185 | CF68: J-UR-05581P1_20220228 | CG68: 45133.556 | CH68: 45133.556 | CI68: =CH68-CG68 -> 0.00023148148 | CK68: MVD-0415P1 | CL68: 45134.625 | CM68: 45134.625 | CN68: =CM68-CL68 -> 0.00018518518 | CP68: J-UR-05581P4_20220228 | CQ68: 45135.962 | CR68: 45135.962 | CS68: =CR68-CQ68 -> 0.00028935185 | CV68: UR-0483P1 | CW68: 45138.605 | CX68: 45138.605 | CY68: =CX68-CW68 -> 5.7870369e-05
F69: J-UR-05581P4_20220228 | G69: 45111.742 | H69: 45111.743 | I69: =H69-G69 -> 0.00028935185 | K69: J-UR-4192-01P1_20211105 | L69: 45112.433 | M69: 45112.433 | N69: =M69-L69 -> 6.9444446e-05 | P69: J-URS-43013P1_20221028 | Q69: 45113.598 | R69: 45113.598 | S69: =R69-Q69 -> 6.9444446e-05 | U69: J-UR-05581P4_20220228 | V69: 45114.988 | W69: 45114.988 | X69: =W69-V69 -> 0.00030092593 | AA69: J-UR-05581P4_20220228 | AB69: 45117.936 | AC69: 45117.936 | AD69: =AC69-AB69 -> 0.00028935185 | AF69: J-UR-05581P1_20220228 | AG69: 45118.489 | AH69: 45118.489 | AI69: =AH69-AG69 -> 0.00023148148 | AK69: UR-0480P1 | AL69: 45119.393 | AM69: 45119.393 | AN69: =AM69-AL69 -> 0.00011574074 | AP69: J-MVM-4289P2_20220406 | AQ69: 45120.925 | AR69: 45120.925 | AS69: =AR69-AQ69 -> 3.4722223e-05 | AU69: J-UR-05581P4_20220228 | AV69: 45121.388 | AW69: 45121.389 | AX69: =AW69-AV69 -> 0.00028935185 | BA69: J-UR-0550-01P8_20210830 | BB69: 45125.727 | BC69: 45125.727 | BD69: =BC69-BB69 -> 0.00019675926 | BF69: J-UR-0582P10_20230706 | BG69: 45126.444 | BH69: 45126.445 | BI69: =BH69-BG69 -> 0.00041666666 | BK69: UR-04511P1 | BL69: 45127.734 | BM69: 45127.734 | BN69: =BM69-BL69 -> 6.9444446e-05 | BP69: J-MVM-4289P2_20220406 | BQ69: 45128.804 | BR69: 45128.804 | BS69: =BR69-BQ69 -> 3.4722223e-05 | BV69: J-UR-05581P4_20220228 | BW69: 45132.014 | BX69: 45132.015 | BY69: =BX69-BW69 -> 0.00030092592 | CA69: J-UR-05581P4_20220228 | CB69: 45132.859 | CC69: 45132.859 | CD69: =CC69-CB69 -> 0.00030092592 | CF69: J-UR-05581P1_20220228 | CG69: 45133.556 | CH69: 45133.556 | CI69: =CH69-CG69 -> 0.00023148148 | CK69: MVD-0415P1 | CL69: 45134.625 | CM69: 45134.625 | CN69: =CM69-CL69 -> 0.00018518519 | CP69: J-UR-05581P4_20220228 | CQ69: 45135.962 | CR69: 45135.962 | CS69: =CR69-CQ69 -> 0.00028935185 | CV69: UR-0483P1 | CW69: 45138.605 | CX69: 45138.605 | CY69: =CX69-CW69 -> 4.6296293e-05
F70: J-UR-05581P4_20220228 | G70: 45111.742 | H70: 45111.742 | I70: =H70-G70 -> 0.00028935185 | K70: J-UR-4192-01P1_20211105 | L70: 45112.433 | M70: 45112.433 | N70: =M70-L70 -> 6.9444446e-05 | P70: J-URS-43013P1_20221028 | Q70: 45113.598 | R70: 45113.598 | S70: =R70-Q70 -> 8.1018516e-05 | U70: J-UR-05581P4_20220228 | V70: 45114.988 | W70: 45114.988 | X70: =W70-V70 -> 0.00028935185 | AA70: J-UR-05581P4_20220228 | AB70: 45117.935 | AC70: 45117.936 | AD70: =AC70-AB70 -> 0.00028935185 | AF70: J-UR-05581P1_20220228 | AG70: 45118.488 | AH70: 45118.489 | AI70: =AH70-AG70 -> 0.00023148148 | AK70: UR-0480P1 | AL70: 45119.393 | AM70: 45119.393 | AN70: =AM70-AL70 -> 0.00010416667 | AP70: J-MVM-4289P2_20220406 | AQ70: 45120.925 | AR70: 45120.925 | AS70: =AR70-AQ70 -> 2.3148146e-05 | AU70: J-UR-05581P4_20220228 | AV70: 45121.388 | AW70: 45121.388 | AX70: =AW70-AV70 -> 0.00030092592 | BA70: J-UR-0550-01P8_20210830 | BB70: 45125.727 | BC70: 45125.727 | BD70: =BC70-BB70 -> 0.00018518518 | BF70: J-UR-0582P10_20230706 | BG70: 45126.444 | BH70: 45126.444 | BI70: =BH70-BG70 -> 0.00040509259 | BK70: UR-04511P1 | BL70: 45127.734 | BM70: 45127.734 | BN70: =BM70-BL70 -> 6.9444446e-05 | BP70: J-MVM-4289P2_20220406 | BQ70: 45128.804 | BR70: 45128.804 | BS70: =BR70-BQ70 -> 3.4722223e-05 | BV70: J-UR-05581P4_20220228 | BW70: 45132.014 | BX70: 45132.014 | BY70: =BX70-BW70 -> 0.00028935185 | CA70: J-UR-05581P4_20220228 | CB70: 45132.859 | CC70: 45132.859 | CD70: =CC70-CB70 -> 0.00030092592 | CF70: J-UR-05581P1_20220228 | CG70: 45133.555 | CH70: 45133.556 | CI70: =CH70-CG70 -> 0.00023148148 | CK70: MVD-0415P1 | CL70: 45134.625 | CM70: 45134.625 | CN70: =CM70-CL70 -> 0.00018518518 | CP70: J-UR-05581P4_20220228 | CQ70: 45135.961 | CR70: 45135.962 | CS70: =CR70-CQ70 -> 0.00030092593 | CV70: UR-0483P1 | CW70: 45138.605 | CX70: 45138.605 | CY70: =CX70-CW70 -> 5.7870369e-05
F71: J-UR-05581P4_20220228 | G71: 45111.742 | H71: 45111.742 | I71: =H71-G71 -> 0.00030092592 | K71: J-UR-4192-01P1_20211105 | L71: 45112.433 | M71: 45112.433 | N71: =M71-L71 -> 6.9444446e-05 | P71: J-URS-43013P1_20221028 | Q71: 45113.598 | R71: 45113.598 | S71: =R71-Q71 -> 6.9444446e-05 | U71: J-UR-05581P4_20220228 | V71: 45114.987 | W71: 45114.988 | X71: =W71-V71 -> 0.00030092592 | AA71: J-UR-05581P4_20220228 | AB71: 45117.935 | AC71: 45117.935 | AD71: =AC71-AB71 -> 0.00028935185 | AF71: J-UR-05581P1_20220228 | AG71: 45118.488 | AH71: 45118.488 | AI71: =AH71-AG71 -> 0.00023148148 | AK71: UR-0480P1 | AL71: 45119.392 | AM71: 45119.392 | AN71: =AM71-AL71 -> 0.00010416667 | AP71: J-MVM-4289P2_20220406 | AQ71: 45120.925 | AR71: 45120.925 | AS71: =AR71-AQ71 -> 2.3148146e-05 | AU71: J-UR-05581P4_20220228 | AV71: 45121.388 | AW71: 45121.388 | AX71: =AW71-AV71 -> 0.00028935185 | BA71: J-UR-0550-01P8_20210830 | BB71: 45125.726 | BC71: 45125.727 | BD71: =BC71-BB71 -> 0.00019675926 | BF71: J-UR-0582P10_20230706 | BG71: 45126.443 | BH71: 45126.444 | BI71: =BH71-BG71 -> 0.00040509259 | BK71: UR-04511P1 | BL71: 45127.734 | BM71: 45127.734 | BN71: =BM71-BL71 -> 6.9444446e-05 | BP71: J-MVM-4289P2_20220406 | BQ71: 45128.804 | BR71: 45128.804 | BS71: =BR71-BQ71 -> 2.3148146e-05 | BV71: J-UR-05581P4_20220228 | BW71: 45132.013 | BX71: 45132.014 | BY71: =BX71-BW71 -> 0.00028935185 | CA71: J-UR-05581P4_20220228 | CB71: 45132.858 | CC71: 45132.858 | CD71: =CC71-CB71 -> 0.00028935185 | CF71: J-UR-05581P1_20220228 | CG71: 45133.555 | CH71: 45133.555 | CI71: =CH71-CG71 -> 0.00023148148 | CK71: MVD-0415P1 | CL71: 45134.624 | CM71: 45134.625 | CN71: =CM71-CL71 -> 0.00019675925 | CP71: J-UR-05581P4_20220228 | CQ71: 45135.961 | CR71: 45135.961 | CS71: =CR71-CQ71 -> 0.00030092593 | CV71: UR-0483P1 | CW71: 45138.604 | CX71: 45138.605 | CY71: =CX71-CW71 -> 5.7870369e-05
F72: J-UR-05581P4_20220228 | G72: 45111.741 | H72: 45111.742 | I72: =H72-G72 -> 0.00028935185 | K72: J-UR-4192-01P1_20211105 | L72: 45112.433 | M72: 45112.433 | N72: =M72-L72 -> 6.9444439e-05 | P72: J-URS-43013P1_20221028 | Q72: 45113.598 | R72: 45113.598 | S72: =R72-Q72 -> 8.1018516e-05 | U72: J-UR-05581P4_20220228 | V72: 45114.987 | W72: 45114.987 | X72: =W72-V72 -> 0.00028935185 | AA72: J-UR-05581P4_20220228 | AB72: 45117.935 | AC72: 45117.935 | AD72: =AC72-AB72 -> 0.00030092593 | AF72: J-UR-05581P1_20220228 | AG72: 45118.488 | AH72: 45118.488 | AI72: =AH72-AG72 -> 0.00023148148 | AK72: UR-0480P1 | AL72: 45119.392 | AM72: 45119.392 | AN72: =AM72-AL72 -> 0.00011574074 | AP72: J-MVM-4289P2_20220406 | AQ72: 45120.925 | AR72: 45120.925 | AS72: =AR72-AQ72 -> 2.3148146e-05 | AU72: J-UR-05581P4_20220228 | AV72: 45121.387 | AW72: 45121.387 | AX72: =AW72-AV72 -> 0.00030092592 | BA72: J-UR-0550-01P8_20210830 | BB72: 45125.726 | BC72: 45125.726 | BD72: =BC72-BB72 -> 0.00019675926 | BF72: J-UR-0582P10_20230706 | BG72: 45126.443 | BH72: 45126.443 | BI72: =BH72-BG72 -> 0.00040509259 | BK72: UR-04511P1 | BL72: 45127.734 | BM72: 45127.734 | BN72: =BM72-BL72 -> 6.9444446e-05 | BP72: J-MVM-4289P2_20220406 | BQ72: 45128.804 | BR72: 45128.804 | BS72: =BR72-BQ72 -> 3.4722223e-05 | BV72: J-UR-05581P4_20220228 | BW72: 45132.013 | BX72: 45132.013 | BY72: =BX72-BW72 -> 0.00028935185 | CA72: J-UR-05581P4_20220228 | CB72: 45132.858 | CC72: 45132.858 | CD72: =CC72-CB72 -> 0.00030092592 | CF72: J-UR-05581P1_20220228 | CG72: 45133.555 | CH72: 45133.555 | CI72: =CH72-CG72 -> 0.00023148148 | CK72: MVD-0415P1 | CL72: 45134.624 | CM72: 45134.624 | CN72: =CM72-CL72 -> 0.00019675925 | CP72: J-UR-05581P4_20220228 | CQ72: 45135.961 | CR72: 45135.961 | CS72: =CR72-CQ72 -> 0.00030092592 | CV72: UR-0483P1 | CW72: 45138.604 | CX72: 45138.604 | CY72: =CX72-CW72 -> 5.7870369e-05
F73: J-UR-05581P4_20220228 | G73: 45111.741 | H73: 45111.741 | I73: =H73-G73 -> 0.00030092592 | K73: J-UR-4192-01P1_20211105 | L73: 45112.433 | M73: 45112.433 | N73: =M73-L73 -> 5.7870369e-05 | P73: J-URS-43013P1_20221028 | Q73: 45113.598 | R73: 45113.598 | S73: =R73-Q73 -> 8.1018523e-05 | U73: J-UR-05581P4_20220228 | V73: 45114.986 | W73: 45114.987 | X73: =W73-V73 -> 0.00028935185 | AA73: J-UR-05581P4_20220228 | AB73: 45117.934 | AC73: 45117.935 | AD73: =AC73-AB73 -> 0.00030092593 | AF73: J-UR-05581P1_20220228 | AG73: 45118.487 | AH73: 45118.488 | AI73: =AH73-AG73 -> 0.00023148148 | AK73: UR-0480P1 | AL73: 45119.392 | AM73: 45119.392 | AN73: =AM73-AL73 -> 0.00011574074 | AP73: J-MVM-4289P2_20220406 | AQ73: 45120.924 | AR73: 45120.924 | AS73: =AR73-AQ73 -> 3.4722216e-05 | AU73: J-UR-05581P4_20220228 | AV73: 45121.387 | AW73: 45121.387 | AX73: =AW73-AV73 -> 0.00028935185 | BA73: J-UR-0550-01P8_20210830 | BB73: 45125.726 | BC73: 45125.726 | BD73: =BC73-BB73 -> 0.00019675926 | BF73: J-UR-0582P10_20230706 | BG73: 45126.442 | BH73: 45126.443 | BI73: =BH73-BG73 -> 0.00041666666 | BK73: UR-04511P1 | BL73: 45127.734 | BM73: 45127.734 | BN73: =BM73-BL73 -> 6.9444446e-05 | BP73: J-MVM-4289P2_20220406 | BQ73: 45128.804 | BR73: 45128.804 | BS73: =BR73-BQ73 -> 2.3148146e-05 | BV73: J-UR-05581P4_20220228 | BW73: 45132.013 | BX73: 45132.013 | BY73: =BX73-BW73 -> 0.00030092592 | CA73: J-UR-05581P4_20220228 | CB73: 45132.857 | CC73: 45132.858 | CD73: =CC73-CB73 -> 0.00030092592 | CF73: J-UR-05581P1_20220228 | CG73: 45133.554 | CH73: 45133.555 | CI73: =CH73-CG73 -> 0.00023148148 | CK73: MVD-0415P1 | CL73: 45134.624 | CM73: 45134.624 | CN73: =CM73-CL73 -> 0.00018518518 | CP73: J-UR-05581P4_20220228 | CQ73: 45135.96 | CR73: 45135.961 | CS73: =CR73-CQ73 -> 0.00030092592 | CV73: UR-0483P1 | CW73: 45138.604 | CX73: 45138.604 | CY73: =CX73-CW73 -> 5.7870369e-05
F74: J-UR-05581P4_20220228 | G74: 45111.74 | H74: 45111.741 | I74: =H74-G74 -> 0.00028935185 | K74: J-UR-4192-01P1_20211105 | L74: 45112.432 | M74: 45112.433 | N74: =M74-L74 -> 6.9444446e-05 | P74: J-URS-43013P1_20221028 | Q74: 45113.597 | R74: 45113.597 | S74: =R74-Q74 -> 6.9444446e-05 | U74: J-UR-05581P4_20220228 | V74: 45114.986 | W74: 45114.986 | X74: =W74-V74 -> 0.00028935185 | AA74: J-UR-05581P4_20220228 | AB74: 45117.934 | AC74: 45117.934 | AD74: =AC74-AB74 -> 0.00028935185 | AF74: J-UR-05581P1_20220228 | AG74: 45118.487 | AH74: 45118.487 | AI74: =AH74-AG74 -> 0.00023148148 | AK74: UR-0480P1 | AL74: 45119.392 | AM74: 45119.392 | AN74: =AM74-AL74 -> 0.00011574074 | AP74: J-MVM-4289P2_20220406 | AQ74: 45120.924 | AR74: 45120.924 | AS74: =AR74-AQ74 -> 2.3148146e-05 | AU74: J-UR-05581P4_20220228 | AV74: 45121.386 | AW74: 45121.387 | AX74: =AW74-AV74 -> 0.00028935185 | BA74: J-UR-0550-01P8_20210830 | BB74: 45125.726 | BC74: 45125.726 | BD74: =BC74-BB74 -> 0.00019675925 | BF74: J-UR-0582P10_20230706 | BG74: 45126.442 | BH74: 45126.442 | BI74: =BH74-BG74 -> 0.00040509259 | BK74: UR-04511P1 | BL74: 45127.733 | BM74: 45127.734 | BN74: =BM74-BL74 -> 8.1018523e-05 | BP74: J-MVM-4289P2_20220406 | BQ74: 45128.804 | BR74: 45128.804 | BS74: =BR74-BQ74 -> 2.3148146e-05 | BV74: J-UR-05581P4_20220228 | BW74: 45132.012 | BX74: 45132.013 | BY74: =BX74-BW74 -> 0.00028935185 | CA74: J-UR-05581P4_20220228 | CB74: 45132.857 | CC74: 45132.857 | CD74: =CC74-CB74 -> 0.00028935185 | CF74: J-UR-05581P1_20220228 | CG74: 45133.554 | CH74: 45133.554 | CI74: =CH74-CG74 -> 0.00023148148 | CK74: MVD-0415P1 | CL74: 45134.624 | CM74: 45134.624 | CN74: =CM74-CL74 -> 0.00019675926 | CP74: J-UR-05581P4_20220228 | CQ74: 45135.96 | CR74: 45135.96 | CS74: =CR74-CQ74 -> 0.00030092593 | CV74: UR-0483P1 | CW74: 45138.604 | CX74: 45138.604 | CY74: =CX74-CW74 -> 5.7870369e-05
F75: J-UR-05581P4_20220228 | G75: 45111.74 | H75: 45111.74 | I75: =H75-G75 -> 0.00030092593 | K75: J-UR-4192-01P1_20211105 | L75: 45112.432 | M75: 45112.432 | N75: =M75-L75 -> 6.9444446e-05 | P75: J-URS-43013P1_20221028 | Q75: 45113.597 | R75: 45113.597 | S75: =R75-Q75 -> 6.9444439e-05 | U75: J-UR-05581P4_20220228 | V75: 45114.986 | W75: 45114.986 | X75: =W75-V75 -> 0.00030092592 | AA75: J-UR-05581P4_20220228 | AB75: 45117.933 | AC75: 45117.934 | AD75: =AC75-AB75 -> 0.00030092593 | AF75: J-UR-05581P1_20220228 | AG75: 45118.487 | AH75: 45118.487 | AI75: =AH75-AG75 -> 0.00023148148 | AK75: UR-0480P1 | AL75: 45119.391 | AM75: 45119.392 | AN75: =AM75-AL75 -> 0.00010416666 | AP75: J-MVM-4289P2_20220406 | AQ75: 45120.924 | AR75: 45120.924 | AS75: =AR75-AQ75 -> 2.3148154e-05 | AU75: J-UR-05581P4_20220228 | AV75: 45121.386 | AW75: 45121.386 | AX75: =AW75-AV75 -> 0.00028935185 | BA75: J-UR-0550-01P8_20210830 | BB75: 45125.725 | BC75: 45125.725 | BD75: =BC75-BB75 -> 0.00019675925 | BF75: J-UR-0582P10_20230706 | BG75: 45126.441 | BH75: 45126.442 | BI75: =BH75-BG75 -> 0.00040509259 | BK75: UR-04511P1 | BL75: 45127.733 | BM75: 45127.733 | BN75: =BM75-BL75 -> 8.1018516e-05 | BP75: J-MVM-4289P2_20220406 | BQ75: 45128.803 | BR75: 45128.803 | BS75: =BR75-BQ75 -> 2.3148146e-05 | BV75: J-UR-05581P4_20220228 | BW75: 45132.012 | BX75: 45132.012 | BY75: =BX75-BW75 -> 0.00028935185 | CA75: J-UR-05581P4_20220228 | CB75: 45132.857 | CC75: 45132.857 | CD75: =CC75-CB75 -> 0.00028935185 | CF75: J-UR-05581P1_20220228 | CG75: 45133.554 | CH75: 45133.554 | CI75: =CH75-CG75 -> 0.00024305555 | CK75: MVD-0415P1 | CL75: 45134.623 | CM75: 45134.623 | CN75: =CM75-CL75 -> 0.00018518518 | CP75: J-UR-05581P4_20220228 | CQ75: 45135.96 | CR75: 45135.96 | CS75: =CR75-CQ75 -> 0.00028935185 | CV75: UR-0483P1 | CW75: 45138.604 | CX75: 45138.604 | CY75: =CX75-CW75 -> 5.7870369e-05
F76: J-UR-05581P4_20220228 | G76: 45111.74 | H76: 45111.74 | I76: =H76-G76 -> 0.00030092593 | K76: J-UR-4192-01P1_20211105 | L76: 45112.432 | M76: 45112.432 | N76: =M76-L76 -> 5.7870369e-05 | P76: J-URS-43013P1_20221028 | Q76: 45113.597 | R76: 45113.597 | S76: =R76-Q76 -> 8.1018516e-05 | U76: J-UR-05581P4_20220228 | V76: 45114.985 | W76: 45114.986 | X76: =W76-V76 -> 0.00028935185 | AA76: J-UR-05581P4_20220228 | AB76: 45117.933 | AC76: 45117.933 | AD76: =AC76-AB76 -> 0.00028935185 | AF76: J-UR-05581P1_20220228 | AG76: 45118.487 | AH76: 45118.487 | AI76: =AH76-AG76 -> 0.00023148148 | AK76: UR-0480P1 | AL76: 45119.391 | AM76: 45119.391 | AN76: =AM76-AL76 -> 0.00010416667 | AP76: J-MVM-4289P2_20220406 | AQ76: 45120.924 | AR76: 45120.924 | AS76: =AR76-AQ76 -> 2.3148146e-05 | AU76: J-UR-05581P4_20220228 | AV76: 45121.386 | AW76: 45121.386 | AX76: =AW76-AV76 -> 0.00030092592 | BA76: J-UR-0550-01P8_20210830 | BB76: 45125.725 | BC76: 45125.725 | BD76: =BC76-BB76 -> 0.00020833333 | BF76: J-UR-0582P10_20230706 | BG76: 45126.441 | BH76: 45126.441 | BI76: =BH76-BG76 -> 0.00040509259 | BK76: UR-04511P1 | BL76: 45127.733 | BM76: 45127.733 | BN76: =BM76-BL76 -> 6.9444439e-05 | BP76: J-MVM-4289P2_20220406 | BQ76: 45128.803 | BR76: 45128.803 | BS76: =BR76-BQ76 -> 3.4722223e-05 | BV76: J-UR-05581P4_20220228 | BW76: 45132.012 | BX76: 45132.012 | BY76: =BX76-BW76 -> 0.00028935185 | CA76: J-UR-05581P4_20220228 | CB76: 45132.856 | CC76: 45132.857 | CD76: =CC76-CB76 -> 0.00028935185 | CF76: J-UR-05581P1_20220228 | CG76: 45133.554 | CH76: 45133.554 | CI76: =CH76-CG76 -> 0.00023148148 | CK76: MVD-0415P1 | CL76: 45134.623 | CM76: 45134.623 | CN76: =CM76-CL76 -> 0.00018518518 | CP76: J-UR-05581P4_20220228 | CQ76: 45135.959 | CR76: 45135.959 | CS76: =CR76-CQ76 -> 0.00030092592 | CV76: UR-0483P1 | CW76: 45138.604 | CX76: 45138.604 | CY76: =CX76-CW76 -> 6.9444446e-05
F77: J-UR-05581P4_20220228 | G77: 45111.739 | H77: 45111.74 | I77: =H77-G77 -> 0.00028935185 | K77: J-UR-4192-01P1_20211105 | L77: 45112.432 | M77: 45112.432 | N77: =M77-L77 -> 6.9444446e-05 | P77: J-URS-43013P1_20221028 | Q77: 45113.597 | R77: 45113.597 | S77: =R77-Q77 -> 6.9444446e-05 | U77: J-UR-05581P4_20220228 | V77: 45114.985 | W77: 45114.985 | X77: =W77-V77 -> 0.00028935185 | AA77: J-UR-05581P4_20220228 | AB77: 45117.933 | AC77: 45117.933 | AD77: =AC77-AB77 -> 0.00030092592 | AF77: J-UR-05581P1_20220228 | AG77: 45118.486 | AH77: 45118.486 | AI77: =AH77-AG77 -> 0.00023148148 | AK77: UR-0480P1 | AL77: 45119.391 | AM77: 45119.391 | AN77: =AM77-AL77 -> 0.00010416666 | AP77: J-MVM-4289P2_20220406 | AQ77: 45120.924 | AR77: 45120.924 | AS77: =AR77-AQ77 -> 3.4722223e-05 | AU77: MVD-0467-01P1_20230710 | AV77: 45121.732 | AW77: 45121.732 | AX77: =AW77-AV77 -> 0.00018518518 | BA77: J-UR-0550-01P8_20210830 | BB77: 45125.725 | BC77: 45125.725 | BD77: =BC77-BB77 -> 0.00019675926 | BF77: J-UR-0582P10_20230706 | BG77: 45126.44 | BH77: 45126.441 | BI77: =BH77-BG77 -> 0.00040509259 | BK77: UR-04511P1 | BL77: 45127.733 | BM77: 45127.733 | BN77: =BM77-BL77 -> 8.1018523e-05 | BP77: J-MVM-4289P2_20220406 | BQ77: 45128.803 | BR77: 45128.803 | BS77: =BR77-BQ77 -> 2.3148146e-05 | BV77: J-UR-05581P4_20220228 | BW77: 45132.011 | BX77: 45132.012 | BY77: =BX77-BW77 -> 0.00030092592 | CA77: J-UR-05581P4_20220228 | CB77: 45132.856 | CC77: 45132.856 | CD77: =CC77-CB77 -> 0.00030092593 | CF77: J-UR-05581P1_20220228 | CG77: 45133.553 | CH77: 45133.553 | CI77: =CH77-CG77 -> 0.00024305555 | CK77: MVD-0415P1 | CL77: 45134.623 | CM77: 45134.623 | CN77: =CM77-CL77 -> 0.00019675925 | CP77: J-UR-05581P4_20220228 | CQ77: 45135.959 | CR77: 45135.959 | CS77: =CR77-CQ77 -> 0.00030092592 | CV77: UR-0483P1 | CW77: 45138.603 | CX77: 45138.603 | CY77: =CX77-CW77 -> 5.7870369e-05
F78: J-UR-05581P4_20220228 | G78: 45111.739 | H78: 45111.739 | I78: =H78-G78 -> 0.00030092592 | K78: J-UR-4192-01P1_20211105 | L78: 45112.432 | M78: 45112.432 | N78: =M78-L78 -> 6.9444446e-05 | P78: J-URS-43013P1_20221028 | Q78: 45113.597 | R78: 45113.597 | S78: =R78-Q78 -> 8.1018516e-05 | U78: J-UR-05581P4_20220228 | V78: 45114.985 | W78: 45114.985 | X78: =W78-V78 -> 0.00030092592 | AA78: J-UR-05581P4_20220228 | AB78: 45117.932 | AC78: 45117.933 | AD78: =AC78-AB78 -> 0.00030092593 | AF78: J-UR-05581P1_20220228 | AG78: 45118.486 | AH78: 45118.486 | AI78: =AH78-AG78 -> 0.00023148148 | AK78: UR-0480P1 | AL78: 45119.391 | AM78: 45119.391 | AN78: =AM78-AL78 -> 0.00010416667 | AP78: J-MVM-4289P2_20220406 | AQ78: 45120.924 | AR78: 45120.924 | AS78: =AR78-AQ78 -> 2.3148146e-05 | AU78: MVD-0467-01P1_20230710 | AV78: 45121.732 | AW78: 45121.732 | AX78: =AW78-AV78 -> 0.00018518518 | BA78: J-UR-0550-01P8_20210830 | BB78: 45125.724 | BC78: 45125.725 | BD78: =BC78-BB78 -> 0.00019675926 | BF78: J-UR-0582P10_20230706 | BG78: 45126.44 | BH78: 45126.44 | BI78: =BH78-BG78 -> 0.00041666667 | BK78: UR-04511P1 | BL78: 45127.733 | BM78: 45127.733 | BN78: =BM78-BL78 -> 6.9444446e-05 | BP78: J-MVM-4289P2_20220406 | BQ78: 45128.803 | BR78: 45128.803 | BS78: =BR78-BQ78 -> 2.3148146e-05 | BV78: J-UR-05581P4_20220228 | BW78: 45132.011 | BX78: 45132.011 | BY78: =BX78-BW78 -> 0.00028935185 | CA78: J-UR-05581P4_20220228 | CB78: 45132.856 | CC78: 45132.856 | CD78: =CC78-CB78 -> 0.00030092593 | CF78: J-UR-05581P1_20220228 | CG78: 45133.553 | CH78: 45133.553 | CI78: =CH78-CG78 -> 0.00024305555 | CK78: MVD-0415P1 | CL78: 45134.622 | CM78: 45134.623 | CN78: =CM78-CL78 -> 0.00019675926 | CP78: J-UR-05581P4_20220228 | CQ78: 45135.958 | CR78: 45135.959 | CS78: =CR78-CQ78 -> 0.00028935185 | CV78: UR-0483P1 | CW78: 45138.603 | CX78: 45138.603 | CY78: =CX78-CW78 -> 5.7870369e-05
... F731: UR-4425P1 | G731: 45111.704 | H731: 45111.704 | I731: =H731-G731 -> 6.9444439e-05 | K731: UR-0511P1 | L731: 45112.448 | M731: 45112.449 | N731: =M731-L731 -> 0.00020833333 | P731: UR-0509-01P4 | Q731: 45113.617 | R731: 45113.617 | S731: =R731-Q731 -> 0.00035879629 | U731: UR-0538P1 | V731: 45114.959 | W731: 45114.959 | X731: =W731-V731 -> 6.9444446e-05 | AA731: UR-0486P4 | AB731: 45117.458 | AC731: 45117.458 | AD731: =AC731-AB731 -> 0.00018518518 | AF731: UR-0509-01P4 | AG731: 45118.914 | AH731: 45118.914 | AI731: =AH731-AG731 -> 0.00035879629 | AK731: UR-4341-02P4 | AL731: 45119.752 | AM731: 45119.752 | AN731: =AM731-AL731 -> 0.00010416667 | AP731: UR-0559-01P1 | AQ731: 45120.556 | AR731: 45120.556 | AS731: =AR731-AQ731 -> 0.0002662037 | AU731: UR-43351-01P1 | AV731: 45121.421 | AW731: 45121.422 | AX731: =AW731-AV731 -> 8.1018523e-05 | BA731: UR-0524P1 | BB731: 45125.639 | BC731: 45125.639 | BD731: =BC731-BB731 -> 5.7870369e-05 | BF731: UR-0509-01P4 | BG731: 45126.958 | BH731: 45126.958 | BI731: =BH731-BG731 -> 0.00037037037 | BK731: UR-06101P1 | BL731: 45127.77 | BM731: 45127.771 | BN731: =BM731-BL731 -> 0.00023148148 | BP731: UR-0489P4 | BQ731: 45129.015 | BR731: 45129.015 | BS731: =BR731-BQ731 -> 5.7870369e-05 | BV731: UR-0509-01P4 | BW731: 45131.97 | BX731: 45131.97 | BY731: =BX731-BW731 -> 0.00037037037 | CA731: UR-0509-01P1 | CB731: 45132.479 | CC731: 45132.479 | CD731: =CC731-CB731 -> 0.00024305556 | CF731: UR-0509-01P1 | CG731: 45133.585 | CH731: 45133.585 | CI731: =CH731-CG731 -> 0.00024305555 | CK731: UR-0519P8 | CL731: 45134.723 | CM731: 45134.724 | CN731: =CM731-CL731 -> 0.00030092592 | CP731: UR-0481-01P6 | CQ731: 45135.913 | CR731: 45135.913 | CS731: =CR731-CQ731 -> 0.00023148148 | CV731: URS-4343P4 | CW731: 45138.462 | CX731: 45138.462 | CY731: =CX731-CW731 -> 5.7870369e-05
F732: UR-4425P1 | G732: 45111.704 | H732: 45111.704 | I732: =H732-G732 -> 6.9444439e-05 | K732: UR-0511P1 | L732: 45112.448 | M732: 45112.448 | N732: =M732-L732 -> 0.00020833333 | P732: UR-0509-01P4 | Q732: 45113.616 | R732: 45113.616 | S732: =R732-Q732 -> 0.00035879629 | U732: UR-0538P1 | V732: 45114.959 | W732: 45114.959 | X732: =W732-V732 -> 5.7870369e-05 | AA732: UR-0486P4 | AB732: 45117.458 | AC732: 45117.458 | AD732: =AC732-AB732 -> 0.00018518518 | AF732: UR-0509-01P4 | AG732: 45118.913 | AH732: 45118.913 | AI732: =AH732-AG732 -> 0.00037037038 | AK732: UR-4341-02P4 | AL732: 45119.752 | AM732: 45119.752 | AN732: =AM732-AL732 -> 0.00011574074 | AP732: UR-0559-01P1 | AQ732: 45120.556 | AR732: 45120.556 | AS732: =AR732-AQ732 -> 0.0002662037 | AU732: UR-43351-01P1 | AV732: 45121.421 | AW732: 45121.421 | AX732: =AW732-AV732 -> 9.2592592e-05 | BA732: UR-0524P1 | BB732: 45125.639 | BC732: 45125.639 | BD732: =BC732-BB732 -> 5.7870369e-05 | BF732: UR-0509-01P4 | BG732: 45126.958 | BH732: 45126.958 | BI732: =BH732-BG732 -> 0.00037037037 | BK732: UR-06101P1 | BL732: 45127.77 | BM732: 45127.77 | BN732: =BM732-BL732 -> 0.00023148148 | BP732: UR-0489P4 | BQ732: 45129.014 | BR732: 45129.014 | BS732: =BR732-BQ732 -> 6.9444446e-05 | BV732: UR-0509-01P4 | BW732: 45131.969 | BX732: 45131.97 | BY732: =BX732-BW732 -> 0.0003587963 | CA732: UR-0509-01P1 | CB732: 45132.479 | CC732: 45132.479 | CD732: =CC732-CB732 -> 0.00024305555 | CF732: UR-0509-01P1 | CG732: 45133.585 | CH732: 45133.585 | CI732: =CH732-CG732 -> 0.00025462963 | CK732: UR-0519P8 | CL732: 45134.723 | CM732: 45134.723 | CN732: =CM732-CL732 -> 0.00030092592 | CP732: UR-0481-01P6 | CQ732: 45135.912 | CR732: 45135.913 | CS732: =CR732-CQ732 -> 0.00024305556
F733: UR-4425P1 | G733: 45111.704 | H733: 45111.704 | I733: =H733-G733 -> 5.7870369e-05 | K733: UR-0511P1 | L733: 45112.448 | M733: 45112.448 | N733: =M733-L733 -> 0.00020833334 | P733: UR-0509-01P4 | Q733: 45113.616 | R733: 45113.616 | S733: =R733-Q733 -> 0.00035879629 | U733: UR-0538P1 | V733: 45114.959 | W733: 45114.959 | X733: =W733-V733 -> 6.9444439e-05 | AA733: UR-0486P4 | AB733: 45117.457 | AC733: 45117.458 | AD733: =AC733-AB733 -> 0.00018518518 | AF733: UR-0509-01P4 | AG733: 45118.913 | AH733: 45118.913 | AI733: =AH733-AG733 -> 0.00035879629 | AK733: UR-4341-02P4 | AL733: 45119.752 | AM733: 45119.752 | AN733: =AM733-AL733 -> 0.00011574074 | AP733: UR-0559-01P1 | AQ733: 45120.555 | AR733: 45120.555 | AS733: =AR733-AQ733 -> 0.00026620371 | AU733: UR-43351-01P1 | AV733: 45121.421 | AW733: 45121.421 | AX733: =AW733-AV733 -> 9.2592592e-05 | BA733: UR-0524P1 | BB733: 45125.639 | BC733: 45125.639 | BD733: =BC733-BB733 -> 5.7870369e-05 | BF733: UR-0511P1 | BG733: 45126.607 | BH733: 45126.607 | BI733: =BH733-BG733 -> 0.00019675925 | BK733: UR-06101P1 | BL733: 45127.77 | BM733: 45127.77 | BN733: =BM733-BL733 -> 0.00023148148 | BP733: UR-0489P4 | BQ733: 45129.014 | BR733: 45129.014 | BS733: =BR733-BQ733 -> 6.9444439e-05 | BV733: UR-0509-01P4 | BW733: 45131.969 | BX733: 45131.969 | BY733: =BX733-BW733 -> 0.00037037037 | CA733: UR-0509-01P1 | CB733: 45132.478 | CC733: 45132.478 | CD733: =CC733-CB733 -> 0.00024305555 | CF733: UR-0509-01P1 | CG733: 45133.584 | CH733: 45133.584 | CI733: =CH733-CG733 -> 0.00024305555 | CK733: UR-0519P8 | CL733: 45134.723 | CM733: 45134.723 | CN733: =CM733-CL733 -> 0.00030092592 | CP733: UR-0481-01P6 | CQ733: 45135.912 | CR733: 45135.912 | CS733: =CR733-CQ733 -> 0.00023148148
F734: UR-4425P1 | G734: 45111.704 | H734: 45111.704 | I734: =H734-G734 -> 6.9444439e-05 | K734: UR-0511P1 | L734: 45112.448 | M734: 45112.448 | N734: =M734-L734 -> 0.00020833333 | P734: UR-0509-01P4 | Q734: 45113.615 | R734: 45113.616 | S734: =R734-Q734 -> 0.0003587963 | U734: UR-0538P1 | V734: 45114.959 | W734: 45114.959 | X734: =W734-V734 -> 5.7870369e-05 | AA734: UR-0486P4 | AB734: 45117.457 | AC734: 45117.457 | AD734: =AC734-AB734 -> 0.00018518518 | AF734: UR-0509-01P4 | AG734: 45118.912 | AH734: 45118.913 | AI734: =AH734-AG734 -> 0.00035879629 | AK734: UR-4341-02P4 | AL734: 45119.751 | AM734: 45119.752 | AN734: =AM734-AL734 -> 0.00011574074 | AP734: UR-0559-01P1 | AQ734: 45120.555 | AR734: 45120.555 | AS734: =AR734-AQ734 -> 0.0002662037 | AU734: UR-43351-01P1 | AV734: 45121.421 | AW734: 45121.421 | AX734: =AW734-AV734 -> 8.1018516e-05 | BA734: UR-0524P4 | BB734: 45125.621 | BC734: 45125.621 | BD734: =BC734-BB734 -> 6.9444446e-05 | BF734: UR-0511P1 | BG734: 45126.606 | BH734: 45126.606 | BI734: =BH734-BG734 -> 0.00020833334 | BK734: UR-06101P1 | BL734: 45127.769 | BM734: 45127.77 | BN734: =BM734-BL734 -> 0.00023148148 | BP734: UR-0489P4 | BQ734: 45129.014 | BR734: 45129.014 | BS734: =BR734-BQ734 -> 6.9444446e-05 | BV734: UR-0509-01P4 | BW734: 45131.969 | BX734: 45131.969 | BY734: =BX734-BW734 -> 0.00035879629 | CA734: UR-0509-01P1 | CB734: 45132.478 | CC734: 45132.478 | CD734: =CC734-CB734 -> 0.00024305555 | CF734: UR-0509-01P1 | CG734: 45133.584 | CH734: 45133.584 | CI734: =CH734-CG734 -> 0.00024305555 | CK734: UR-0519P8 | CL734: 45134.722 | CM734: 45134.722 | CN734: =CM734-CL734 -> 0.00030092593 | CP734: UR-0481-01P6 | CQ734: 45135.912 | CR734: 45135.912 | CS734: =CR734-CQ734 -> 0.00024305556
F735: UR-4425P1 | G735: 45111.703 | H735: 45111.704 | I735: =H735-G735 -> 5.7870369e-05 | K735: UR-0511P1 | L735: 45112.447 | M735: 45112.448 | N735: =M735-L735 -> 0.00020833334 | P735: UR-0509-01P4 | Q735: 45113.615 | R735: 45113.615 | S735: =R735-Q735 -> 0.00037037037 | U735: UR-0538P1 | V735: 45114.958 | W735: 45114.958 | X735: =W735-V735 -> 6.9444446e-05 | AA735: UR-0486P4 | AB735: 45117.457 | AC735: 45117.457 | AD735: =AC735-AB735 -> 0.00018518518 | AF735: UR-0509-01P4 | AG735: 45118.912 | AH735: 45118.912 | AI735: =AH735-AG735 -> 0.00037037037 | AK735: UR-4341-02P4 | AL735: 45119.751 | AM735: 45119.751 | AN735: =AM735-AL735 -> 0.00010416666 | AP735: UR-0559-01P1 | AQ735: 45120.554 | AR735: 45120.555 | AS735: =AR735-AQ735 -> 0.0002662037 | AU735: UR-43351-01P1 | AV735: 45121.421 | AW735: 45121.421 | AX735: =AW735-AV735 -> 9.2592592e-05 | BA735: UR-0524P4 | BB735: 45125.621 | BC735: 45125.621 | BD735: =BC735-BB735 -> 6.9444439e-05 | BF735: UR-0511P1 | BG735: 45126.606 | BH735: 45126.606 | BI735: =BH735-BG735 -> 0.00020833333 | BK735: UR-06101P1 | BL735: 45127.769 | BM735: 45127.769 | BN735: =BM735-BL735 -> 0.00023148148 | BP735: UR-0489P4 | BQ735: 45129.014 | BR735: 45129.014 | BS735: =BR735-BQ735 -> 6.9444446e-05 | BV735: UR-0509-01P4 | BW735: 45131.968 | BX735: 45131.969 | BY735: =BX735-BW735 -> 0.0003587963 | CA735: UR-0509-01P1 | CB735: 45132.478 | CC735: 45132.478 | CD735: =CC735-CB735 -> 0.00024305555 | CF735: UR-0509-01P1 | CG735: 45133.584 | CH735: 45133.584 | CI735: =CH735-CG735 -> 0.00025462963 | CK735: UR-0519P8 | CL735: 45134.722 | CM735: 45134.722 | CN735: =CM735-CL735 -> 0.00030092593 | CP735: UR-0481-01P6 | CQ735: 45135.911 | CR735: 45135.912 | CS735: =CR735-CQ735 -> 0.00023148148
