Workbook

Sheet 151
C2: TOTAL | D2: =SUM(D4:D20) -> 0.059502315 | H2: TOTAL | I2: =SUM(I4:I20) -> 0.15425926 | M2: TOTAL | N2: =SUM(N4:N20) -> 0.077719907 | R2: TOTAL | S2: =SUM(S4:S20) -> 0.13954861 | W2: TOTAL | X2: =SUM(X4:X20) -> 0.046087963 | AC2: TOTAL | AD2: =SUM(AD4:AD20) -> 0.1191088 | AH2: TOTAL | AI2: =SUM(AI4:AI20) -> 0.14050926 | AM2: TOTAL | AN2: =SUM(AN4:AN20) -> 0.085520833 | AR2: TOTAL | AS2: =SUM(AS4:AS20) -> 0.060381944 | AW2: TOTAL | AX2: =SUM(AX4:AX20) -> 0.11644676 | BC2: TOTAL | BD2: =SUM(BD4:BD20) -> 0.075694444 | BH2: TOTAL | BI2: =SUM(BI4:BI20) -> 0.083564815 | BM2: TOTAL | BN2: =SUM(BN20:BN20) -> 0 | BR2: TOTAL | BS2: =SUM(BS4:BS20) -> 0.1008912 | BX2: TOTAL | BY2: =SUM(BY4:BY20) -> 0.11256944 | CC2: TOTAL | CD2: =SUM(CD4:CD20) -> 0.095069444 | CH2: TOTAL | CI2: =SUM(CI4:CI20) -> 0.068252315 | CM2: TOTAL | CN2: =SUM(CN4:CN20) -> 0.10450231 | CR2: TOTAL | CS2: =SUM(CS4:CS20) -> 0.080150463 | CX2: TOTAL | CY2: =SUM(CY4:CY20) -> 0.12003472
A3: ３日 | B3: 検査開始時間 | C3: 検査終了時間 | D3: 検査時間 | F3: ４日 | G3: 検査開始時間 | H3: 検査終了時間 | I3: 検査時間 | K3: ５日 | L3: 検査開始時間 | M3: 検査終了時間 | N3: 検査時間 | P3: ６日 | Q3: 検査開始時間 | R3: 検査終了時間 | S3: 検査時間 | U3: ７日 | V3: 検査開始時間 | W3: 検査終了時間 | X3: 検査時間 | AA3: １０日 | AB3: 検査開始時間 | AC3: 検査終了時間 | AD3: 検査時間 | AF3: １１日 | AG3: 検査開始時間 | AH3: 検査終了時間 | AI3: 検査時間 | AK3: １２日 | AL3: 検査開始時間 | AM3: 検査終了時間 | AN3: 検査時間 | AP3: １３日 | AQ3: 検査開始時間 | AR3: 検査終了時間 | AS3: 検査時間 | AU3: １４日 | AV3: 検査開始時間 | AW3: 検査終了時間 | AX3: 検査時間 | BA3: １８日 | BB3: 検査開始時間 | BC3: 検査終了時間 | BD3: 検査時間 | BF3: １９日 | BG3: 検査開始時間 | BH3: 検査終了時間 | BI3: 検査時間 | BK3: ２０日 | BL3: 検査開始時間 | BM3: 検査終了時間 | BN3: 検査時間 | BP3: ２１日 | BQ3: 検査開始時間 | BR3: 検査終了時間 | BS3: 検査時間 | BV3: ２４日 | BW3: 検査開始時間 | BX3: 検査終了時間 | BY3: 検査時間 | CA3: ２５日 | CB3: 検査開始時間 | CC3: 検査終了時間 | CD3: 検査時間 | CF3: ２６日 | CG3: 検査開始時間 | CH3: 検査終了時間 | CI3: 検査時間 | CK3: ２７日 | CL3: 検査開始時間 | CM3: 検査終了時間 | CN3: 検査時間 | CP3: ２８日 | CQ3: 検査開始時間 | CR3: 検査終了時間 | CS3: 検査時間 | CV3: ３１日 | CW3: 検査開始時間 | CX3: 検査終了時間 | CY3: 検査時間
A4: UR-0509-01P1 | B4: 45110.594 | C4: 45110.621 | D4: =C4-B4 -> 0.026481481 | F4: URS-0475P2 | G4: 45111.378 | H4: 45111.381 | I4: =H4-G4 -> 0.0025810185 | K4: UR-0489P1 | L4: 45112.463 | M4: 45112.472 | N4: =M4-L4 -> 0.0082986111 | P4: URS-0483P4 | Q4: 45113.383 | R4: 45113.397 | S4: =R4-Q4 -> 0.014074074 | U4: UR-0481-01P6 | V4: 45114.55 | W4: 45114.575 | X4: =W4-V4 -> 0.025844907 | AA4: URS-0483P4 | AB4: 45117.38 | AC4: 45117.394 | AD4: =AC4-AB4 -> 0.013449074 | AF4: UR-0486P4 | AG4: 45118.378 | AH4: 45118.389 | AI4: =AH4-AG4 -> 0.0109375 | AK4: UR-0480P1 | AL4: 45119.386 | AM4: 45119.394 | AN4: =AM4-AL4 -> 0.0081597222 | AP4: UR-0489P4 | AQ4: 45120.443 | AR4: 45120.454 | AS4: =AR4-AQ4 -> 0.010659722 | AU4: UR-0489P4 | AV4: 45121.379 | AW4: 45121.388 | AX4: =AW4-AV4 -> 0.0090046296 | BA4: UR-0480P4 | BB4: 45125.379 | BC4: 45125.387 | BD4: =BC4-BB4 -> 0.0075462963 | BF4: URS-0437P1 | BG4: 45126.419 | BH4: 45126.433 | BI4: =BH4-BG4 -> 0.014768519 | BP4: URS-0437P1 | BQ4: 45128.384 | BR4: 45128.398 | BS4: =BR4-BQ4 -> 0.014074074 | BV4: UR-0480P4 | BW4: 45131.376 | BX4: 45131.384 | BY4: =BX4-BW4 -> 0.0075810185 | CA4: URS-0437P1 | CB4: 45132.378 | CC4: 45132.396 | CD4: =CC4-CB4 -> 0.018449074 | CF4: URS-0437P1 | CG4: 45133.378 | CH4: 45133.393 | CI4: =CH4-CG4 -> 0.014560185 | CK4: UR-4461P6 | CL4: 45134.372 | CM4: 45134.384 | CN4: =CM4-CL4 -> 0.011678241 | CP4: URS-0475P2 | CQ4: 45135.381 | CR4: 45135.384 | CS4: =CR4-CQ4 -> 0.0028356481 | CV4: UR-0486P4 | CW4: 45138.443 | CX4: 45138.454 | CY4: =CX4-CW4 -> 0.011030093
A5: UR-0559-01P1 | B5: 45110.624 | C5: 45110.636 | D5: =C5-B5 -> 0.012395833 | F5: UR-0476P2 | G5: 45111.386 | H5: 45111.387 | I5: =H5-G5 -> 0.0012037037 | K5: UR-0481-01P6 | L5: 45112.585 | M5: 45112.611 | N5: =M5-L5 -> 0.025914352 | P5: URS-0437P1 | Q5: 45113.406 | R5: 45113.422 | S5: =R5-Q5 -> 0.015416667 | U5: UR-0481-01P1 | V5: 45114.631 | W5: 45114.651 | X5: =W5-V5 -> 0.020243056 | AA5: URS-0437P2 | AB5: 45117.414 | AC5: 45117.434 | AD5: =AC5-AB5 -> 0.019456019 | AF5: URS-0475P1 | AG5: 45118.392 | AH5: 45118.394 | AI5: =AH5-AG5 -> 0.0021875 | AK5: UR-0488-01P4 | AL5: 45119.566 | AM5: 45119.576 | AN5: =AM5-AL5 -> 0.010046296 | AP5: UR-0489P1 | AQ5: 45120.542 | AR5: 45120.551 | AS5: =AR5-AQ5 -> 0.0096759259 | AU5: UR-0489P1 | AV5: 45121.397 | AW5: 45121.406 | AX5: =AW5-AV5 -> 0.0085185185 | BA5: URS-0486P1 | BB5: 45125.391 | BC5: 45125.398 | BD5: =BC5-BB5 -> 0.0072106482 | BF5: URS-0437P2 | BG5: 45126.436 | BH5: 45126.451 | BI5: =BH5-BG5 -> 0.015393519 | BP5: URS-0437P2 | BQ5: 45128.4 | BR5: 45128.415 | BS5: =BR5-BQ5 -> 0.015208333 | BV5: UR-0476P2 | BW5: 45131.389 | BX5: 45131.39 | BY5: =BX5-BW5 -> 0.0011689815 | CA5: URS-0437P2 | CB5: 45132.398 | CC5: 45132.413 | CD5: =CC5-CB5 -> 0.015381944 | CF5: URS-0437P2 | CG5: 45133.396 | CH5: 45133.412 | CI5: =CH5-CG5 -> 0.015381944 | CK5: UR-4461P1 | CL5: 45134.408 | CM5: 45134.418 | CN5: =CM5-CL5 -> 0.0097337963 | CP5: UR-0493P2 | CQ5: 45135.389 | CR5: 45135.392 | CS5: =CR5-CQ5 -> 0.0027199074 | CV5: UR-0488-01P4 | CW5: 45138.459 | CX5: 45138.469 | CY5: =CX5-CW5 -> 0.0095833333
A6: UT-0969P1 | B6: 45110.647 | C6: 45110.649 | D6: =C6-B6 -> 0.0016550926 | F6: URS-0437P1 | G6: 45111.393 | H6: 45111.41 | I6: =H6-G6 -> 0.016643519 | K6: UR-0481-01P1 | L6: 45112.615 | M6: 45112.636 | N6: =M6-L6 -> 0.020266204 | P6: UR-0483P1 | Q6: 45113.43 | R6: 45113.443 | S6: =R6-Q6 -> 0.0128125 | AA6: UR-0483P1 | AB6: 45117.437 | AC6: 45117.451 | AD6: =AC6-AB6 -> 0.013842593 | AF6: URS-0486P1 | AG6: 45118.4 | AH6: 45118.407 | AI6: =AH6-AG6 -> 0.0065625 | AK6: UR-0488-01P1 | AL6: 45119.594 | AM6: 45119.601 | AN6: =AM6-AL6 -> 0.0071296296 | AP6: UR-0511P1 | AQ6: 45120.576 | AR6: 45120.591 | AS6: =AR6-AQ6 -> 0.015358796 | AU6: UR-43351-01P6 | AV6: 45121.41 | AW6: 45121.415 | AX6: =AW6-AV6 -> 0.0050925926 | BA6: UR-0493P1 | BB6: 45125.406 | BC6: 45125.408 | BD6: =BC6-BB6 -> 0.0026157407 | BF6: UR-0489P4 | BG6: 45126.544 | BH6: 45126.553 | BI6: =BH6-BG6 -> 0.0091898148 | BP6: UR-0493P2 | BQ6: 45128.421 | BR6: 45128.424 | BS6: =BR6-BQ6 -> 0.0027546296 | BV6: UR-0489P1 | BW6: 45131.402 | BX6: 45131.411 | BY6: =BX6-BW6 -> 0.0086805556 | CA6: UR-0480P4 | CB6: 45132.423 | CC6: 45132.431 | CD6: =CC6-CB6 -> 0.0083101852 | CF6: UR-0489P4 | CG6: 45133.417 | CH6: 45133.426 | CI6: =CH6-CG6 -> 0.0093171296 | CK6: UR-0511P1 | CL6: 45134.456 | CM6: 45134.507 | CN6: =CM6-CL6 -> 0.050625 | CP6: URS-0486P1 | CQ6: 45135.398 | CR6: 45135.405 | CS6: =CR6-CQ6 -> 0.0070138889 | CV6: URS-0486P1 | CW6: 45138.476 | CX6: 45138.483 | CY6: =CX6-CW6 -> 0.0067939815
A7: UR-0488-01P4 | B7: 45110.654 | C7: 45110.665 | D7: =C7-B7 -> 0.010694444 | F7: URS-0437P2 | G7: 45111.419 | H7: 45111.438 | I7: =H7-G7 -> 0.019351852 | K7: UR-0489P4 | L7: 45112.655 | M7: 45112.664 | N7: =M7-L7 -> 0.0089814815 | P7: UR-0511P1 | Q7: 45113.455 | R7: 45113.47 | S7: =R7-Q7 -> 0.014988426 | AA7: UR-0489P4 | AB7: 45117.457 | AC7: 45117.467 | AD7: =AC7-AB7 -> 0.010069444 | AF7: UR-0493P2 | AG7: 45118.41 | AH7: 45118.413 | AI7: =AH7-AG7 -> 0.0026967593 | AK7: UR-0486P4 | AL7: 45119.605 | AM7: 45119.616 | AN7: =AM7-AL7 -> 0.010833333 | AP7: UR-0476P2 | AQ7: 45120.598 | AR7: 45120.6 | AS7: =AR7-AQ7 -> 0.0012615741 | AU7: UR-43351-01P1 | AV7: 45121.419 | AW7: 45121.424 | AX7: =AW7-AV7 -> 0.0049189815 | BA7: UR-0480P1 | BB7: 45125.425 | BC7: 45125.434 | BD7: =BC7-BB7 -> 0.0081481481 | BF7: UR-0489P1 | BG7: 45126.563 | BH7: 45126.572 | BI7: =BH7-BG7 -> 0.0084143519 | BP7: UR-0476P2 | BQ7: 45128.428 | BR7: 45128.43 | BS7: =BR7-BQ7 -> 0.0011921296 | BV7: UR-0480P1 | BW7: 45131.419 | BX7: 45131.428 | BY7: =BX7-BW7 -> 0.0085763889 | CA7: UR-0511P1 | CB7: 45132.445 | CC7: 45132.461 | CD7: =CC7-CB7 -> 0.015532407 | CF7: UR-0489P1 | CG7: 45133.439 | CH7: 45133.448 | CI7: =CH7-CG7 -> 0.0088425926 | CK7: UR-0511P1 | CL7: 45134.538 | CM7: 45134.545 | CN7: =CM7-CL7 -> 0.0077314815 | CP7: UR-0511P1 | CQ7: 45135.411 | CR7: 45135.427 | CS7: =CR7-CQ7 -> 0.015462963 | CV7: URS-0483P4 | CW7: 45138.503 | CX7: 45138.541 | CY7: =CX7-CW7 -> 0.038668981
A8: UR-0488-01P1 | B8: 45110.667 | C8: 45110.676 | D8: =C8-B8 -> 0.008275463 | F8: UR-0559-01P1 | G8: 45111.453 | H8: 45111.473 | I8: =H8-G8 -> 0.019953704 | K8: UR-0489P1 | L8: 45112.683 | M8: 45112.691 | N8: =M8-L8 -> 0.0079050926 | P8: UR-0480P4 | Q8: 45113.484 | R8: 45113.497 | S8: =R8-Q8 -> 0.012546296 | AA8: UR-0489P1 | AB8: 45117.489 | AC8: 45117.498 | AD8: =AC8-AB8 -> 0.0091319444 | AF8: UR-0493P1 | AG8: 45118.422 | AH8: 45118.424 | AI8: =AH8-AG8 -> 0.0026273148 | AK8: UR-0509-01P4 | AL8: 45119.619 | AM8: 45119.654 | AN8: =AM8-AL8 -> 0.035150463 | AP8: URS-0505P2 | AQ8: 45120.608 | AR8: 45120.61 | AS8: =AR8-AQ8 -> 0.0016319444 | AU8: UR-0511P1 | AV8: 45121.448 | AW8: 45121.463 | AX8: =AW8-AV8 -> 0.014826389 | BA8: UR-0511P1 | BB8: 45125.561 | BC8: 45125.576 | BD8: =BC8-BB8 -> 0.014548611 | BF8: UR-0511P1 | BG8: 45126.592 | BH8: 45126.607 | BI8: =BH8-BG8 -> 0.014490741 | BP8: UR-0493P1 | BQ8: 45128.454 | BR8: 45128.457 | BS8: =BR8-BQ8 -> 0.0026157407 | BV8: UR-0511P1 | BW8: 45131.453 | BX8: 45131.468 | BY8: =BX8-BW8 -> 0.015486111 | CA8: UR-0480P1 | CB8: 45132.464 | CC8: 45132.472 | CD8: =CC8-CB8 -> 0.0082638889 | CF8: J-UR-05581P4_20220228 | CG8: 45133.799 | CH8: 45133.819 | CI8: =CH8-CG8 -> 0.020150463 | CK8: URS-0429P4 | CL8: 45134.548 | CM8: 45134.55 | CN8: =CM8-CL8 -> 0.0021527778 | CP8: UR-0480P4 | CQ8: 45135.435 | CR8: 45135.445 | CS8: =CR8-CQ8 -> 0.0096643518 | CV8: UR-0488-01P1 | CW8: 45138.545 | CX8: 45138.552 | CY8: =CX8-CW8 -> 0.0073263889
F9: UR-0493P1 | G9: 45111.487 | H9: 45111.49 | I9: =H9-G9 -> 0.0026157407 | K9: URS-0475P2 | L9: 45112.694 | M9: 45112.697 | N9: =M9-L9 -> 0.0025115741 | P9: UR-0480P1 | Q9: 45113.541 | R9: 45113.55 | S9: =R9-Q9 -> 0.0082638889 | AA9: UR-0396P4 | AB9: 45117.544 | AC9: 45117.547 | AD9: =AC9-AB9 -> 0.0029282407 | AF9: UR-0511P1 | AG9: 45118.444 | AH9: 45118.458 | AI9: =AH9-AG9 -> 0.014548611 | AK9: URS-0486P1 | AL9: 45119.658 | AM9: 45119.672 | AN9: =AM9-AL9 -> 0.014201389 | AP9: URS-0475P2 | AQ9: 45120.647 | AR9: 45120.65 | AS9: =AR9-AQ9 -> 0.0025 | AU9: UR-0481-01P6 | AV9: 45121.545 | AW9: 45121.571 | AX9: =AW9-AV9 -> 0.02599537 | BA9: URS-0418P4 | BB9: 45125.582 | BC9: 45125.592 | BD9: =BC9-BB9 -> 0.010439815 | BF9: UR-06101P8 | BG9: 45126.619 | BH9: 45126.631 | BI9: =BH9-BG9 -> 0.012025463 | BP9: UR-0481-01P6 | BQ9: 45128.479 | BR9: 45128.506 | BS9: =BR9-BQ9 -> 0.026157407 | BV9: UR-0388P2 | BW9: 45131.473 | BX9: 45131.475 | BY9: =BX9-BW9 -> 0.0020949074 | CA9: UR-0488-01P4 | CB9: 45132.476 | CC9: 45132.486 | CD9: =CC9-CB9 -> 0.0094791667 | CK9: UR-0476P2 | CL9: 45134.555 | CM9: 45134.556 | CN9: =CM9-CL9 -> 0.0011689815 | CP9: UR-0481-01P1 | CQ9: 45135.555 | CR9: 45135.575 | CS9: =CR9-CQ9 -> 0.020219907 | CV9: UR-0559-03P8 | CW9: 45138.558 | CX9: 45138.573 | CY9: =CX9-CW9 -> 0.014768519
F10: URS-0475P1 | G10: 45111.573 | H10: 45111.605 | I10: =H10-G10 -> 0.03150463 | K10: URS-0505P2 | L10: 45112.7 | M10: 45112.701 | N10: =M10-L10 -> 0.0016550926 | P10: UR-0481-01P6 | Q10: 45113.557 | R10: 45113.584 | S10: =R10-Q10 -> 0.026388889 | AA10: UR-0480P4 | AB10: 45117.551 | AC10: 45117.559 | AD10: =AC10-AB10 -> 0.0076851852 | AF10: UR-0481-01P6 | AG10: 45118.475 | AH10: 45118.501 | AI10: =AH10-AG10 -> 0.026134259 | AP10: URS-0475P1 | AQ10: 45120.655 | AR10: 45120.657 | AS10: =AR10-AQ10 -> 0.0021759259 | AU10: UR-0481-01P1 | AV10: 45121.62 | AW10: 45121.64 | AX10: =AW10-AV10 -> 0.020381944 | BA10: URS-0418P1 | BB10: 45125.602 | BC10: 45125.609 | BD10: =BC10-BB10 -> 0.0075231481 | BF10: UR-06101P1 | BG10: 45126.662 | BH10: 45126.671 | BI10: =BH10-BG10 -> 0.0092824074 | BP10: UR-0481-01P1 | BQ10: 45128.61 | BR10: 45128.63 | BS10: =BR10-BQ10 -> 0.02025463 | BV10: UR-0388P1 | BW10: 45131.481 | BX10: 45131.483 | BY10: =BX10-BW10 -> 0.0016550926 | CA10: UR-0488-01P1 | CB10: 45132.5 | CC10: 45132.507 | CD10: =CC10-CB10 -> 0.0068055556 | CK10: URS-0429P1 | CL10: 45134.6 | CM10: 45134.602 | CN10: =CM10-CL10 -> 0.0019560185 | CP10: URS-0475P1 | CQ10: 45135.615 | CR10: 45135.617 | CS10: =CR10-CQ10 -> 0.0021875 | CV10: UR-0476P2 | CW10: 45138.578 | CX10: 45138.58 | CY10: =CX10-CW10 -> 0.0011689815
F11: URS-0475P2 | G11: 45111.579 | H11: 45111.581 | I11: =H11-G11 -> 0.0026157407 | K11: URS-0475P1 | L11: 45112.704 | M11: 45112.706 | N11: =M11-L11 -> 0.0021875 | P11: UR-0481-01P1 | Q11: 45113.602 | R11: 45113.623 | S11: =R11-Q11 -> 0.020196759 | AA11: UR-0396P1 | AB11: 45117.563 | AC11: 45117.565 | AD11: =AC11-AB11 -> 0.0019791667 | AF11: UR-0481-01P1 | AG11: 45118.553 | AH11: 45118.573 | AI11: =AH11-AG11 -> 0.020277778 | AP11: UR-0488-01P4 | AQ11: 45120.661 | AR11: 45120.672 | AS11: =AR11-AQ11 -> 0.010277778 | AU11: UR-0488-01P4 | AV11: 45121.644 | AW11: 45121.654 | AX11: =AW11-AV11 -> 0.0099884259 | BA11: UR-0524P4 | BB11: 45125.612 | BC11: 45125.621 | BD11: =BC11-BB11 -> 0.008912037 | BP11: J-UR-05581P1_20220228 | BQ11: 45128.643 | BR11: 45128.661 | BS11: =BR11-BQ11 -> 0.018634259 | BV11: UR-0481-01P6 | BW11: 45131.496 | BX11: 45131.519 | BY11: =BX11-BW11 -> 0.02375 | CA11: URS-0475P2 | CB11: 45132.545 | CC11: 45132.548 | CD11: =CC11-CB11 -> 0.0028472222 | CK11: UR-0388P2 | CL11: 45134.609 | CM11: 45134.611 | CN11: =CM11-CL11 -> 0.0020833333 | CP11: UR-0493P1 | CQ11: 45135.621 | CR11: 45135.624 | CS11: =CR11-CQ11 -> 0.0026157407 | CV11: UR-0483P1 | CW11: 45138.59 | CX11: 45138.606 | CY11: =CX11-CW11 -> 0.016215278
F12: URS-0505P2 | G12: 45111.585 | H12: 45111.587 | I12: =H12-G12 -> 0.0016435185 | P12: UR-0493P2 | Q12: 45113.651 | R12: 45113.653 | S12: =R12-Q12 -> 0.0027430556 | AA12: UR-0480P1 | AB12: 45117.57 | AC12: 45117.578 | AD12: =AC12-AB12 -> 0.0081134259 | AF12: UR-0488-01P4 | AG12: 45118.577 | AH12: 45118.587 | AI12: =AH12-AG12 -> 0.0095138889 | AP12: UR-0488-01P1 | AQ12: 45120.688 | AR12: 45120.695 | AS12: =AR12-AQ12 -> 0.0068402778 | AU12: UR-0488-01P1 | AV12: 45121.68 | AW12: 45121.686 | AX12: =AW12-AV12 -> 0.0068171296 | BA12: UR-0524P1 | BB12: 45125.639 | BC12: 45125.648 | BD12: =BC12-BB12 -> 0.00875 | BV12: UR-0481-01P6 | BW12: 45131.541 | BX12: 45131.543 | BY12: =BX12-BW12 -> 0.0020601852 | CA12: URS-0505P2 | CB12: 45132.554 | CC12: 45132.556 | CD12: =CC12-CB12 -> 0.0017013889 | CK12: UR-0388P1 | CL12: 45134.618 | CM12: 45134.619 | CN12: =CM12-CL12 -> 0.0015972222 | CP12: UR-0480P1 | CQ12: 45135.64 | CR12: 45135.648 | CS12: =CR12-CQ12 -> 0.008125 | CV12: UR-0559-01P1 | CW12: 45138.629 | CX12: 45138.644 | CY12: =CX12-CW12 -> 0.014479167
F13: UR-0486P4 | G13: 45111.609 | H13: 45111.62 | I13: =H13-G13 -> 0.011296296 | P13: UR-0488-01P4 | Q13: 45113.657 | R13: 45113.666 | S13: =R13-Q13 -> 0.0095023148 | AA13: URS-0483P4 | AB13: 45117.582 | AC13: 45117.595 | AD13: =AC13-AB13 -> 0.013483796 | AF13: UR-0388P2 | AG13: 45118.591 | AH13: 45118.593 | AI13: =AH13-AG13 -> 0.0020833333 | AU13: UR-0486P4 | AV13: 45121.691 | AW13: 45121.702 | AX13: =AW13-AV13 -> 0.010902778 | BV13: UR-0481-01P1 | BW13: 45131.571 | BX13: 45131.592 | BY13: =BX13-BW13 -> 0.020706019 | CA13: URS-0475P1 | CB13: 45132.559 | CC13: 45132.561 | CD13: =CC13-CB13 -> 0.0021875 | CK13: URS-0505P2 | CL13: 45134.653 | CM13: 45134.655 | CN13: =CM13-CL13 -> 0.0016435185 | CP13: UR-0396P4 | CQ13: 45135.653 | CR13: 45135.657 | CS13: =CR13-CQ13 -> 0.0045717593 | CY13: =CX13-CW13 -> 0
F14: URS-0486P1 | G14: 45111.624 | H14: 45111.631 | I14: =H14-G14 -> 0.0066550926 | P14: UR-0493P1 | Q14: 45113.685 | R14: 45113.688 | S14: =R14-Q14 -> 0.0026157407 | AA14: UR-0587P4_20230629 | AB14: 45117.601 | AC14: 45117.604 | AD14: =AC14-AB14 -> 0.0027546296 | AF14: UR-0476P2 | AG14: 45118.598 | AH14: 45118.599 | AI14: =AH14-AG14 -> 0.0011689815 | BV14: UR-0488-01P4 | BW14: 45131.596 | BX14: 45131.606 | BY14: =BX14-BW14 -> 0.0094791667 | CA14: UR-0396P4 | CB14: 45132.567 | CC14: 45132.57 | CD14: =CC14-CB14 -> 0.0029282407 | CK14: UR-0486P4 | CL14: 45134.666 | CM14: 45134.68 | CN14: =CM14-CL14 -> 0.014131944 | CP14: UR-0396P1 | CQ14: 45135.662 | CR14: 45135.664 | CS14: =CR14-CQ14 -> 0.0019444444 | CY14: =CX14-CW14 -> 0
F15: UR-0480P4 | G15: 45111.654 | H15: 45111.663 | I15: =H15-G15 -> 0.0095833333 | AA15: UR-0587P1_20230629 | AB15: 45117.628 | AC15: 45117.63 | AD15: =AC15-AB15 -> 0.0016203704 | AF15: UR-0559-03P8 | AG15: 45118.607 | AH15: 45118.622 | AI15: =AH15-AG15 -> 0.015717593 | BV15: URS-0505P2 | BW15: 45131.611 | BX15: 45131.613 | BY15: =BX15-BW15 -> 0.0016666667 | CA15: UR-0476P2 | CB15: 45132.574 | CC15: 45132.575 | CD15: =CC15-CB15 -> 0.0012268519 | CP15: UR-0493P2 | CQ15: 45135.675 | CR15: 45135.678 | CS15: =CR15-CQ15 -> 0.0027893518 | CY15: =CX15-CW15 -> 0
F16: UR-0480P1 | G16: 45111.666 | H16: 45111.675 | I16: =H16-G16 -> 0.0089699074 | AA16: UR-0483P2 | AB16: 45117.651 | AC16: 45117.664 | AD16: =AC16-AB16 -> 0.012488426 | AF16: UR-0488-01P1 | AG16: 45118.628 | AH16: 45118.641 | AI16: =AH16-AG16 -> 0.012974537 | BV16: URS-0475P2 | BW16: 45131.626 | BX16: 45131.628 | BY16: =BX16-BW16 -> 0.0025810185 | CA16: UR-0396P1 | CB16: 45132.585 | CC16: 45132.587 | CD16: =CC16-CB16 -> 0.0019560185 | CY16: =CX16-CW16 -> 0
F17: UR-4425P4 | G17: 45111.681 | H17: 45111.692 | I17: =H17-G17 -> 0.010925926 | AA17: UR-0476P2 | AB17: 45117.676 | AC17: 45117.678 | AD17: =AC17-AB17 -> 0.0021064815 | AF17: UR-0388P1 | AG17: 45118.645 | AH17: 45118.646 | AI17: =AH17-AG17 -> 0.0015277778 | BV17: UR-0488-01P1 | BW17: 45131.646 | BX17: 45131.653 | BY17: =BX17-BW17 -> 0.0070833333 | CY17: =CX17-CW17 -> 0
F18: UR-4425P1 | G18: 45111.701 | H18: 45111.71 | I18: =H18-G18 -> 0.0087152778 | AF18: UR-0486P4 | AG18: 45118.65 | AH18: 45118.662 | AI18: =AH18-AG18 -> 0.011550926 | CY18: =CX18-CW18 -> 0
AI19: =AH19-AG19 -> 0 | CY19: =CX19-CW19 -> 0
AI20: =AH20-AG20 -> 0 | CY20: =CX20-CW20 -> 0
C25: TOTAL | D25: =SUM(D27:D43) -> 0.09787037 | H25: TOTAL | I25: =SUM(I27:I43) -> 0.014907407 | M25: TOTAL | N25: =SUM(N27:N43) -> 0.035092593 | R25: TOTAL | S25: =SUM(S27:S43) -> 0.016944444 | W25: TOTAL | X25: =SUM(X27:X43) -> 0.14811343 | AC25: TOTAL | AD25: =SUM(AD27:AD43) -> 0.052858796 | AH25: TOTAL | AI25: =SUM(AI27:AI43) -> 0.019664352 | AM25: TOTAL | AN25: =SUM(AN27:AN43) -> 0.061574074 | AR25: TOTAL | AS25: =SUM(AS27:AS43) -> 0.022141204 | AW25: TOTAL | AX25: =SUM(AX27:AX43) -> 0.039641204 | BC25: TOTAL | BD25: =SUM(BD27:BD43) -> 0.034305556 | BH25: TOTAL | BI25: =SUM(BI27:BI43) -> 0.075347222 | BM25: TOTAL | BN25: =SUM(BN27:BN43) -> 0.026215278 | BR25: TOTAL | BS25: =SUM(BS27:BS43) -> 0.046886574 | BX25: TOTAL | BY25: =SUM(BY27:BY43) -> 0.027777778 | CC25: TOTAL | CD25: =SUM(CD27:CD43) -> 0.043969907 | CH25: TOTAL | CI25: =SUM(CI27:CI43) -> 0.059236111 | CM25: TOTAL | CN25: =SUM(CN27:CN43) -> 0.025821759 | CR25: TOTAL | CS25: =SUM(CS27:CS43) -> 0.138125 | CX25: TOTAL | CY25: =SUM(CY27:CY43) -> 0
A26: ３日 | B26: 検査開始時間 | C26: 検査終了時間 | D26: 検査時間 | F26: ４日 | G26: 検査開始時間 | H26: 検査終了時間 | I26: 検査時間 | K26: ５日 | L26: 検査開始時間 | M26: 検査終了時間 | N26: 検査時間 | P26: ６日 | Q26: 検査開始時間 | R26: 検査終了時間 | S26: 検査時間 | U26: ７日 | V26: 検査開始時間 | W26: 検査終了時間 | X26: 検査時間 | AA26: １０日 | AB26: 検査開始時間 | AC26: 検査終了時間 | AD26: 検査時間 | AF26: １１日 | AG26: 検査開始時間 | AH26: 検査終了時間 | AI26: 検査時間 | AK26: １２日 | AL26: 検査開始時間 | AM26: 検査終了時間 | AN26: 検査時間 | AP26: １３日 | AQ26: 検査開始時間 | AR26: 検査終了時間 | AS26: 検査時間 | AU26: １４日 | AV26: 検査開始時間 | AW26: 検査終了時間 | AX26: 検査時間 | BA26: １８日 | BB26: 検査開始時間 | BC26: 検査終了時間 | BD26: 検査時間 | BF26: １９日 | BG26: 検査開始時間 | BH26: 検査終了時間 | BI26: 検査時間 | BK26: ２０日 | BL26: 検査開始時間 | BM26: 検査終了時間 | BN26: 検査時間 | BP26: ２１日 | BQ26: 検査開始時間 | BR26: 検査終了時間 | BS26: 検査時間 | BV26: ２４日 | BW26: 検査開始時間 | BX26: 検査終了時間 | BY26: 検査時間 | CA26: ２５日 | CB26: 検査開始時間 | CC26: 検査終了時間 | CD26: 検査時間 | CF26: ２６日 | CG26: 検査開始時間 | CH26: 検査終了時間 | CI26: 検査時間 | CK26: ２７日 | CL26: 検査開始時間 | CM26: 検査終了時間 | CN26: 検査時間 | CP26: ２８日 | CQ26: 検査開始時間 | CR26: 検査終了時間 | CS26: 検査時間 | CV26: ３１日 | CW26: 検査開始時間 | CX26: 検査終了時間 | CY26: 検査時間
A27: J-UR-05581P4_20220228 | B27: 45110.742 | C27: 45110.768 | D27: =C27-B27 -> 0.025625 | F27: URS-0428P6 | G27: 45111.792 | H27: 45111.795 | I27: =H27-G27 -> 0.0023611111 | K27: UR-0493P2 | L27: 45112.733 | M27: 45112.735 | N27: =M27-L27 -> 0.0028009259 | P27: UR-0480P4 | Q27: 45113.916 | R27: 45113.924 | S27: =R27-Q27 -> 0.0075347222 | U27: UT-0988P4 | V27: 45114.801 | W27: 45114.807 | X27: =W27-V27 -> 0.0057175926 | AA27: UR-0481-01P6 | AB27: 45117.746 | AC27: 45117.772 | AD27: =AC27-AB27 -> 0.026111111 | AF27: URS-0486P1 | AG27: 45118.901 | AH27: 45118.908 | AI27: =AH27-AG27 -> 0.006724537 | AK27: URS-0437P1 | AL27: 45119.861 | AM27: 45119.875 | AN27: =AM27-AL27 -> 0.014097222 | AP27: UR-0480P4 | AQ27: 45120.744 | AR27: 45120.753 | AS27: =AR27-AQ27 -> 0.0086111111 | AU27: URS-0475P2 | AV27: 45121.902 | AW27: 45121.905 | AX27: =AW27-AV27 -> 0.0027314815 | BA27: UR-0493P2 | BB27: 45125.849 | BC27: 45125.852 | BD27: =BC27-BB27 -> 0.0030902778 | BF27: UR-0486P4 | BG27: 45126.855 | BH27: 45126.867 | BI27: =BH27-BG27 -> 0.012256944 | BK27: URS-0483P4 | BL27: 45127.791 | BM27: 45127.804 | BN27: =BM27-BL27 -> 0.013518519 | BP27: UR-0486P4 | BQ27: 45128.948 | BR27: 45128.959 | BS27: =BR27-BQ27 -> 0.011261574 | BV27: URS-0475P1 | BW27: 45131.735 | BX27: 45131.738 | BY27: =BX27-BW27 -> 0.0021759259 | CA27: URS-0483P4 | CB27: 45132.722 | CC27: 45132.736 | CD27: =CC27-CB27 -> 0.013842593 | CF27: J-UR-05581P1_20220228 | CG27: 45133.872 | CH27: 45133.89 | CI27: =CH27-CG27 -> 0.017083333 | CK27: UR-0481-01P6 | CL27: 45134.866 | CM27: 45134.892 | CN27: =CM27-CL27 -> 0.025821759 | CP27: UR-0481-01P1 | CQ27: 45135.885 | CR27: 45135.977 | CS27: =CR27-CQ27 -> 0.091840278 | CY27: =CX27-CW27 -> 0
A28: UR-0509-01P1 | B28: 45110.785 | C28: 45110.811 | D28: =C28-B28 -> 0.026388889 | F28: URS-0428P1 | G28: 45111.966 | H28: 45111.969 | I28: =H28-G28 -> 0.0034490741 | K28: UR-0493P1 | L28: 45112.957 | M28: 45112.96 | N28: =M28-L28 -> 0.0027893519 | P28: UR-0480P1 | Q28: 45113.971 | R28: 45113.979 | S28: =R28-Q28 -> 0.0082291667 | U28: UT-0988P1 | V28: 45114.807 | W28: 45114.816 | X28: =W28-V28 -> 0.0090625 | AA28: UR-0481-01P1 | AB28: 45117.868 | AC28: 45117.889 | AD28: =AC28-AB28 -> 0.021805556 | AF28: URS-0475P2 | AG28: 45118.92 | AH28: 45118.923 | AI28: =AH28-AG28 -> 0.0025462963 | AK28: URS-0437P2 | AL28: 45119.879 | AM28: 45119.894 | AN28: =AM28-AL28 -> 0.015266204 | AP28: UR-0493P2 | AQ28: 45120.8 | AR28: 45120.803 | AS28: =AR28-AQ28 -> 0.0027546296 | AU28: URS-0475P1 | AV28: 45121.907 | AW28: 45121.909 | AX28: =AW28-AV28 -> 0.0022106481 | BA28: UR-0480P4 | BB28: 45125.908 | BC28: 45125.923 | BD28: =BC28-BB28 -> 0.015428241 | BF28: URS-0475P2 | BG28: 45126.878 | BH28: 45126.881 | BI28: =BH28-BG28 -> 0.0027662037 | BK28: UR-0483P1 | BL28: 45128.017 | BM28: 45128.03 | BN28: =BM28-BL28 -> 0.012696759 | BP28: URS-0486P1 | BQ28: 45128.964 | BR28: 45128.97 | BS28: =BR28-BQ28 -> 0.0065625 | BV28: UR-0486P4 | BW28: 45131.747 | BX28: 45131.761 | BY28: =BX28-BW28 -> 0.013541667 | CA28: UR-0480P4 | CB28: 45132.768 | CC28: 45132.776 | CD28: =CC28-CB28 -> 0.0079513889 | CF28: UR-0480P4 | CG28: 45133.899 | CH28: 45133.907 | CI28: =CH28-CG28 -> 0.0081481481 | CN28: =CM28-CL28 -> 0 | CP28: UR-0481-01P6 | CQ28: 45135.908 | CR28: 45135.934 | CS28: =CR28-CQ28 -> 0.026030093 | CY28: =CX28-CW28 -> 0
A29: J-UR-05581P1_20220228 | B29: 45110.883 | C29: 45110.904 | D29: =C29-B29 -> 0.021331019 | F29: UR-0489P4 | G29: 45111.984 | H29: 45111.993 | I29: =H29-G29 -> 0.0090972222 | K29: URS-0437P1 | L29: 45112.974 | M29: 45112.988 | N29: =M29-L29 -> 0.014155093 | P29: UR-0476P2 | Q29: 45113.986 | R29: 45113.987 | S29: =R29-Q29 -> 0.0011805556 | U29: UR-0476P2 | V29: 45114.816 | W29: 45114.843 | X29: =W29-V29 -> 0.026909722 | AA29: URS-0475P2 | AB29: 45117.913 | AC29: 45117.916 | AD29: =AC29-AB29 -> 0.0027199074 | AF29: URS-0475P1 | AG29: 45118.931 | AH29: 45118.934 | AI29: =AH29-AG29 -> 0.0021759259 | AK29: URS-0483P4 | AL29: 45119.905 | AM29: 45119.919 | AN29: =AM29-AL29 -> 0.014050926 | AP29: UR-0480P1 | AQ29: 45120.903 | AR29: 45120.911 | AS29: =AR29-AQ29 -> 0.0081597222 | AU29: URS-0505P2 | AV29: 45121.911 | AW29: 45121.914 | AX29: =AW29-AV29 -> 0.0021643518 | BA29: UR-0493P1 | BB29: 45125.978 | BC29: 45125.98 | BD29: =BC29-BB29 -> 0.0026157407 | BF29: URS-0486P1 | BG29: 45126.933 | BH29: 45126.94 | BI29: =BH29-BG29 -> 0.0067013889 | BN29: =BM29-BL29 -> 0 | BP29: UR-0493P2 | BQ29: 45128.977 | BR29: 45128.98 | BS29: =BR29-BQ29 -> 0.0027662037 | BV29: UR-0493P2 | BW29: 45131.764 | BX29: 45131.767 | BY29: =BX29-BW29 -> 0.0028935185 | CA29: UR-0483P1 | CB29: 45132.845 | CC29: 45132.858 | CD29: =CC29-CB29 -> 0.012708333 | CF29: UR-0493P2 | CG29: 45133.921 | CH29: 45133.924 | CI29: =CH29-CG29 -> 0.0026967593 | CN29: =CM29-CL29 -> 0 | CP29: UR-0489P4 | CQ29: 45135.983 | CR29: 45135.992 | CS29: =CR29-CQ29 -> 0.009375 | CY29: =CX29-CW29 -> 0
A30: UR-0559-03P8 | B30: 45110.959 | C30: 45110.979 | D30: =C30-B30 -> 0.019699074 | I30: =H30-G30 -> 0 | K30: URS-0437P2 | L30: 45112.994 | M30: 45113.01 | N30: =M30-L30 -> 0.015347222 | S30: =R30-Q30 -> 0 | U30: UR-0493P2 | V30: 45114.842 | W30: 45114.857 | X30: =W30-V30 -> 0.014270833 | AA30: URS-0505P2 | AB30: 45117.919 | AC30: 45117.921 | AD30: =AC30-AB30 -> 0.0022222222 | AF30: UR-0480P4 | AG30: 45118.949 | AH30: 45118.957 | AI30: =AH30-AG30 -> 0.0082175926 | AK30: UR-0493P2 | AL30: 45119.948 | AM30: 45119.951 | AN30: =AM30-AL30 -> 0.002662037 | AP30: UR-0493P1 | AQ30: 45120.914 | AR30: 45120.917 | AS30: =AR30-AQ30 -> 0.0026157407 | AU30: UR-0493P2 | AV30: 45121.957 | AW30: 45121.96 | AX30: =AW30-AV30 -> 0.0027777778 | BA30: UR-0480P1 | BB30: 45125.984 | BC30: 45125.992 | BD30: =BC30-BB30 -> 0.0081365741 | BF30: URS-0475P1 | BG30: 45126.949 | BH30: 45126.951 | BI30: =BH30-BG30 -> 0.0021875 | BN30: =BM30-BL30 -> 0 | BP30: UR-0511P1 | BQ30: 45128.988 | BR30: 45129.003 | BS30: =BR30-BQ30 -> 0.014490741 | BV30: UR-0493P1 | BW30: 45131.849 | BX30: 45131.851 | BY30: =BX30-BW30 -> 0.0026041667 | CA30: UR-0480P1 | CB30: 45132.861 | CC30: 45132.87 | CD30: =CC30-CB30 -> 0.0094675926 | CF30: UR-0480P1 | CG30: 45133.945 | CH30: 45133.953 | CI30: =CH30-CG30 -> 0.0081597222 | CN30: =CM30-CL30 -> 0 | CP30: UR-0493P1 | CQ30: 45135.996 | CR30: 45135.999 | CS30: =CR30-CQ30 -> 0.0026157407 | CY30: =CX30-CW30 -> 0
A31: UR-0493P2 | B31: 45110.99 | C31: 45110.993 | D31: =C31-B31 -> 0.0026273148 | I31: =H31-G31 -> 0 | N31: =M31-L31 -> 0 | S31: =R31-Q31 -> 0 | U31: UTS-0831 | V31: 45114.857 | W31: 45114.86 | X31: =W31-V31 -> 0.0035763889 | AD31: =AC31-AB31 -> 0 | AI31: =AH31-AG31 -> 0 | AK31: UR-0483P1 | AL31: 45119.96 | AM31: 45119.973 | AN31: =AM31-AL31 -> 0.01287037 | AS31: =AR31-AQ31 -> 0 | AU31: URS-0437P1 | AV31: 45121.973 | AW31: 45121.987 | AX31: =AW31-AV31 -> 0.013969907 | BA31: UR-4035P4 | BB31: 45125.996 | BC31: 45126.001 | BD31: =BC31-BB31 -> 0.0050347222 | BF31: URS-0437P1 | BG31: 45126.964 | BH31: 45126.981 | BI31: =BH31-BG31 -> 0.016539352 | BN31: =BM31-BL31 -> 0 | BP31: UR-0489P4 | BQ31: 45129.012 | BR31: 45129.021 | BS31: =BR31-BQ31 -> 0.0091898148 | BV31: URS-0486P1 | BW31: 45131.855 | BX31: 45131.862 | BY31: =BX31-BW31 -> 0.0065625 | CD31: =CC31-CB31 -> 0 | CF31: UR-0493P1 | CG31: 45133.955 | CH31: 45133.958 | CI31: =CH31-CG31 -> 0.0026157407 | CN31: =CM31-CL31 -> 0 | CP31: UR-0489P1 | CQ31: 45136.023 | CR31: 45136.031 | CS31: =CR31-CQ31 -> 0.0082638889 | CY31: =CX31-CW31 -> 0
A32: URS-0505P2 | B32: 45111.003 | C32: 45111.005 | D32: =C32-B32 -> 0.0021990741 | I32: =H32-G32 -> 0 | N32: =M32-L32 -> 0 | S32: =R32-Q32 -> 0 | U32: UT-2507-01P6 | V32: 45114.86 | W32: 45114.875 | X32: =W32-V32 -> 0.015023148 | AD32: =AC32-AB32 -> 0 | AI32: =AH32-AG32 -> 0 | AK32: UR-0493P1 | AL32: 45119.976 | AM32: 45119.978 | AN32: =AM32-AL32 -> 0.0026273148 | AS32: =AR32-AQ32 -> 0 | AU32: URS-0437P2 | AV32: 45121.995 | AW32: 45122.011 | AX32: =AW32-AV32 -> 0.015787037 | BD32: =BC32-BB32 -> 0 | BF32: URS-0437P2 | BG32: 45126.984 | BH32: 45127.001 | BI32: =BH32-BG32 -> 0.016678241 | BN32: =BM32-BL32 -> 0 | BP32: UR-0493P1 | BQ32: 45129.025 | BR32: 45129.027 | BS32: =BR32-BQ32 -> 0.0026157407 | BY32: =BX32-BW32 -> 0 | CD32: =CC32-CB32 -> 0 | CF32: UR-0554P6 | CG32: 45133.972 | CH32: 45133.983 | CI32: =CH32-CG32 -> 0.01099537 | CN32: =CM32-CL32 -> 0 | CS32: =CR32-CQ32 -> 0 | CY32: =CX32-CW32 -> 0
D33: =C33-B33 -> 0 | I33: =H33-G33 -> 0 | N33: =M33-L33 -> 0 | S33: =R33-Q33 -> 0 | U33: UR-0493P1 | V33: 45114.875 | W33: 45114.882 | X33: =W33-V33 -> 0.0063425926 | AD33: =AC33-AB33 -> 0 | AI33: =AH33-AG33 -> 0 | AN33: =AM33-AL33 -> 0 | AS33: =AR33-AQ33 -> 0 | AX33: =AW33-AV33 -> 0 | BD33: =BC33-BB33 -> 0 | BF33: UR-0476P2 | BG33: 45127.005 | BH33: 45127.007 | BI33: =BH33-BG33 -> 0.0018981482 | BN33: =BM33-BL33 -> 0 | BS33: =BR33-BQ33 -> 0 | BY33: =BX33-BW33 -> 0 | CD33: =CC33-CB33 -> 0 | CF33: UR-0554P1 | CG33: 45134.012 | CH33: 45134.022 | CI33: =CH33-CG33 -> 0.009537037 | CN33: =CM33-CL33 -> 0 | CS33: =CR33-CQ33 -> 0 | CY33: =CX33-CW33 -> 0
D34: =C34-B34 -> 0 | I34: =H34-G34 -> 0 | N34: =M34-L34 -> 0 | S34: =R34-Q34 -> 0 | U34: UT-2507-01P1 | V34: 45114.882 | W34: 45114.898 | X34: =W34-V34 -> 0.016886574 | AD34: =AC34-AB34 -> 0 | AI34: =AH34-AG34 -> 0 | AN34: =AM34-AL34 -> 0 | AS34: =AR34-AQ34 -> 0 | AX34: =AW34-AV34 -> 0 | BD34: =BC34-BB34 -> 0 | BF34: UR-0480P4 | BG34: 45127.014 | BH34: 45127.022 | BI34: =BH34-BG34 -> 0.0081134259 | BN34: =BM34-BL34 -> 0 | BS34: =BR34-BQ34 -> 0 | BY34: =BX34-BW34 -> 0 | CD34: =CC34-CB34 -> 0 | CI34: =CH34-CG34 -> 0 | CN34: =CM34-CL34 -> 0 | CS34: =CR34-CQ34 -> 0 | CY34: =CX34-CW34 -> 0
D35: =C35-B35 -> 0 | I35: =H35-G35 -> 0 | N35: =M35-L35 -> 0 | S35: =R35-Q35 -> 0 | U35: URS-0437P1 | V35: 45114.898 | W35: 45114.949 | X35: =W35-V35 -> 0.050324074 | AD35: =AC35-AB35 -> 0 | AI35: =AH35-AG35 -> 0 | AN35: =AM35-AL35 -> 0 | AS35: =AR35-AQ35 -> 0 | AX35: =AW35-AV35 -> 0 | BD35: =BC35-BB35 -> 0 | BF35: UR-0480P1 | BG35: 45127.025 | BH35: 45127.033 | BI35: =BH35-BG35 -> 0.0082060185 | BN35: =BM35-BL35 -> 0 | BS35: =BR35-BQ35 -> 0 | BY35: =BX35-BW35 -> 0 | CD35: =CC35-CB35 -> 0 | CI35: =CH35-CG35 -> 0 | CN35: =CM35-CL35 -> 0 | CS35: =CR35-CQ35 -> 0 | CY35: =CX35-CW35 -> 0
D36: =C36-B36 -> 0 | I36: =H36-G36 -> 0 | N36: =M36-L36 -> 0 | S36: =R36-Q36 -> 0 | X36: 0 | AD36: =AC36-AB36 -> 0 | AI36: =AH36-AG36 -> 0 | AN36: =AM36-AL36 -> 0 | AS36: =AR36-AQ36 -> 0 | AX36: =AW36-AV36 -> 0 | BD36: =BC36-BB36 -> 0 | BI36: =BH36-BG36 -> 0 | BN36: =BM36-BL36 -> 0 | BS36: =BR36-BQ36 -> 0 | BY36: =BX36-BW36 -> 0 | CD36: =CC36-CB36 -> 0 | CI36: =CH36-CG36 -> 0 | CN36: =CM36-CL36 -> 0 | CY36: =CX36-CW36 -> 0
D37: =C37-B37 -> 0 | I37: =H37-G37 -> 0 | N37: =M37-L37 -> 0 | S37: =R37-Q37 -> 0 | X37: 0 | AD37: =AC37-AB37 -> 0 | AI37: =AH37-AG37 -> 0 | AN37: =AM37-AL37 -> 0 | AS37: =AR37-AQ37 -> 0 | AX37: =AW37-AV37 -> 0 | BD37: =BC37-BB37 -> 0 | BI37: =BH37-BG37 -> 0 | BN37: =BM37-BL37 -> 0 | BS37: =BR37-BQ37 -> 0 | BY37: =BX37-BW37 -> 0 | CD37: =CC37-CB37 -> 0 | CI37: =CH37-CG37 -> 0 | CN37: =CM37-CL37 -> 0 | CY37: =CX37-CW37 -> 0
D38: =C38-B38 -> 0 | I38: =H38-G38 -> 0 | N38: =M38-L38 -> 0 | S38: =R38-Q38 -> 0 | X38: 0 | AD38: =AC38-AB38 -> 0 | AI38: =AH38-AG38 -> 0 | AN38: =AM38-AL38 -> 0 | AS38: =AR38-AQ38 -> 0 | AX38: =AW38-AV38 -> 0 | BD38: =BC38-BB38 -> 0 | BI38: =BH38-BG38 -> 0 | BN38: =BM38-BL38 -> 0 | BS38: =BR38-BQ38 -> 0 | BY38: =BX38-BW38 -> 0 | CD38: =CC38-CB38 -> 0 | CI38: =CH38-CG38 -> 0 | CN38: =CM38-CL38 -> 0 | CY38: =CX38-CW38 -> 0
D39: =C39-B39 -> 0 | I39: =H39-G39 -> 0 | N39: =M39-L39 -> 0 | S39: =R39-Q39 -> 0 | X39: 0 | AD39: =AC39-AB39 -> 0 | AI39: =AH39-AG39 -> 0 | AN39: =AM39-AL39 -> 0 | AS39: =AR39-AQ39 -> 0 | AX39: =AW39-AV39 -> 0 | BD39: =BC39-BB39 -> 0 | BI39: =BH39-BG39 -> 0 | BN39: =BM39-BL39 -> 0 | BS39: =BR39-BQ39 -> 0 | BY39: =BX39-BW39 -> 0 | CD39: =CC39-CB39 -> 0 | CI39: =CH39-CG39 -> 0 | CN39: =CM39-CL39 -> 0 | CY39: =CX39-CW39 -> 0
D40: =C40-B40 -> 0 | I40: =H40-G40 -> 0 | N40: =M40-L40 -> 0 | S40: =R40-Q40 -> 0 | X40: 0 | AD40: =AC40-AB40 -> 0 | AI40: =AH40-AG40 -> 0 | AN40: =AM40-AL40 -> 0 | AS40: =AR40-AQ40 -> 0 | AX40: =AW40-AV40 -> 0 | BD40: =BC40-BB40 -> 0 | BI40: =BH40-BG40 -> 0 | BN40: =BM40-BL40 -> 0 | BS40: =BR40-BQ40 -> 0 | BY40: =BX40-BW40 -> 0 | CD40: =CC40-CB40 -> 0 | CI40: =CH40-CG40 -> 0 | CN40: =CM40-CL40 -> 0 | CY40: =CX40-CW40 -> 0
D41: =C41-B41 -> 0 | I41: =H41-G41 -> 0 | N41: =M41-L41 -> 0 | S41: =R41-Q41 -> 0 | X41: 0 | AD41: =AC41-AB41 -> 0 | AI41: =AH41-AG41 -> 0 | AN41: =AM41-AL41 -> 0 | AS41: =AR41-AQ41 -> 0 | AX41: =AW41-AV41 -> 0 | BD41: =BC41-BB41 -> 0 | BI41: =BH41-BG41 -> 0 | BN41: =BM41-BL41 -> 0 | BS41: =BR41-BQ41 -> 0 | BY41: =BX41-BW41 -> 0 | CD41: =CC41-CB41 -> 0 | CI41: =CH41-CG41 -> 0 | CN41: =CM41-CL41 -> 0 | CY41: =CX41-CW41 -> 0
D42: =C42-B42 -> 0 | I42: =H42-G42 -> 0 | N42: =M42-L42 -> 0 | S42: =R42-Q42 -> 0 | X42: 0 | AD42: =AC42-AB42 -> 0 | AI42: =AH42-AG42 -> 0 | AN42: =AM42-AL42 -> 0 | AS42: =AR42-AQ42 -> 0 | AX42: =AW42-AV42 -> 0 | BD42: =BC42-BB42 -> 0 | BI42: =BH42-BG42 -> 0 | BN42: =BM42-BL42 -> 0 | BS42: =BR42-BQ42 -> 0 | BY42: =BX42-BW42 -> 0 | CD42: =CC42-CB42 -> 0 | CI42: =CH42-CG42 -> 0 | CN42: =CM42-CL42 -> 0 | CY42: =CX42-CW42 -> 0
D43: =C43-B43 -> 0 | I43: =H43-G43 -> 0 | N43: =M43-L43 -> 0 | S43: =R43-Q43 -> 0 | X43: 0 | AD43: =AC43-AB43 -> 0 | AI43: =AH43-AG43 -> 0 | AN43: =AM43-AL43 -> 0 | AS43: =AR43-AQ43 -> 0 | AX43: =AW43-AV43 -> 0 | BD43: =BC43-BB43 -> 0 | BI43: =BH43-BG43 -> 0 | BN43: =BM43-BL43 -> 0 | BS43: =BR43-BQ43 -> 0 | BY43: =BX43-BW43 -> 0 | CD43: =CC43-CB43 -> 0 | CI43: =CH43-CG43 -> 0 | CN43: =CM43-CL43 -> 0 | CY43: =CX43-CW43 -> 0
CP1009: UR-0489P4 | CQ1009: 45111.42 | CR1009: 45111.42
CP1010: UR-0489P4 | CQ1010: 45111.42 | CR1010: 45111.42
...

Sheet 205
C2: TOTAL | D2: =SUM(D4:D20) -> 0.16349537 | H2: TOTAL | I2: =SUM(I4:I20) -> 0.092002315 | M2: TOTAL | N2: =SUM(N4:N20) -> 0.14037037 | R2: TOTAL | S2: =SUM(S4:S20) -> 0.14037037 | W2: TOTAL | X2: =SUM(X4:X21) -> 0.18686343 | AC2: TOTAL | AD2: =SUM(AD4:AD20) -> 0.10143519 | AH2: TOTAL | AI2: =SUM(AI4:AI20) -> 0.044143519 | AM2: TOTAL | AN2: =SUM(AN4:AN20) -> 0.07880787 | AR2: TOTAL | AS2: =SUM(AS4:AS20) -> 0.059872685 | AW2: TOTAL | AX2: =SUM(AX4:AX20) -> 0.06462963 | BC2: TOTAL | BD2: =SUM(BD4:BD20) -> 0.10065972 | BH2: TOTAL | BI2: =SUM(BI4:BI20) -> 0.12107639 | BM2: TOTAL | BN2: =SUM(BN4:BN22) -> 0.11875 | BR2: TOTAL | BS2: =SUM(BS4:BS20) -> 0.080740741 | BX2: TOTAL | BY2: =SUM(BY4:BY20) -> 0.13335648 | CC2: TOTAL | CD2: =SUM(CD4:CD20) -> 0.12944444 | CH2: TOTAL | CI2: =SUM(CI4:CI20) -> 0.14322917 | CM2: TOTAL | CN2: =SUM(CN4:CN20) -> 0.13185185 | CR2: TOTAL | CS2: =SUM(CS4:CS23) -> 0.11368056 | CX2: TOTAL | CY2: =SUM(CY4:CY20) -> 0.079837963
A3: ３日 | B3: 検査開始時間 | C3: 検査終了時間 | D3: 検査時間 | F3: ４日 | G3: 検査開始時間 | H3: 検査終了時間 | I3: 検査時間 | K3: ５日 | L3: 検査開始時間 | M3: 検査終了時間 | N3: 検査時間 | P3: ６日 | Q3: 検査開始時間 | R3: 検査終了時間 | S3: 検査時間 | U3: ７日 | V3: 検査開始時間 | W3: 検査終了時間 | X3: 検査時間 | AA3: １０日 | AB3: 検査開始時間 | AC3: 検査終了時間 | AD3: 検査時間 | AF3: １１日 | AG3: 検査開始時間 | AH3: 検査終了時間 | AI3: 検査時間 | AK3: １２日 | AL3: 検査開始時間 | AM3: 検査終了時間 | AN3: 検査時間 | AP3: １３日 | AQ3: 検査開始時間 | AR3: 検査終了時間 | AS3: 検査時間 | AU3: １４日 | AV3: 検査開始時間 | AW3: 検査終了時間 | AX3: 検査時間 | BA3: １８日 | BB3: 検査開始時間 | BC3: 検査終了時間 | BD3: 検査時間 | BF3: １９日 | BG3: 検査開始時間 | BH3: 検査終了時間 | BI3: 検査時間 | BK3: ２０日 | BL3: 検査開始時間 | BM3: 検査終了時間 | BN3: 検査時間 | BP3: ２１日 | BQ3: 検査開始時間 | BR3: 検査終了時間 | BS3: 検査時間 | BV3: ２４日 | BW3: 検査開始時間 | BX3: 検査終了時間 | BY3: 検査時間 | CA3: ２５日 | CB3: 検査開始時間 | CC3: 検査終了時間 | CD3: 検査時間 | CF3: ２６日 | CG3: 検査開始時間 | CH3: 検査終了時間 | CI3: 検査時間 | CK3: ２７日 | CL3: 検査開始時間 | CM3: 検査終了時間 | CN3: 検査時間 | CP3: ２８日 | CQ3: 検査開始時間 | CR3: 検査終了時間 | CS3: 検査時間 | CV3: ３１日 | CW3: 検査開始時間 | CX3: 検査終了時間 | CY3: 検査時間
A4: URS-42881P6 | B4: 45110.391 | C4: 45110.399 | D4: =C4-B4 -> 0.0088657407 | F4: UR-4489P8 | G4: 45111.372 | H4: 45111.379 | I4: =H4-G4 -> 0.0069212963 | K4: UR-0559-03P8 | L4: 45113 | M4: 45113.015 | N4: =M4-L4 -> 0.014421296 | P4: UR-0559-03P8 | Q4: 45113 | R4: 45113.015 | S4: =R4-Q4 -> 0.014421296 | U4: UR-0483P1 | V4: 45114.388 | W4: 45114.398 | X4: =W4-V4 -> 0.010185185 | AA4: UR-0511P1 | AB4: 45117.435 | AC4: 45117.448 | AD4: =AC4-AB4 -> 0.013194444 | AF4: UT-1006P1 | AG4: 45118.44 | AH4: 45118.442 | AI4: =AH4-AG4 -> 0.0021180556 | AK4: UT-2508P1_20230620 | AL4: 45119.404 | AM4: 45119.408 | AN4: =AM4-AL4 -> 0.0042708333 | AP4: UR-0559-01P1 | AQ4: 45120.547 | AR4: 45120.56 | AS4: =AR4-AQ4 -> 0.012534722 | AU4: J-UR-05581P4_20220228 | AV4: 45121.386 | AW4: 45121.395 | AX4: =AW4-AV4 -> 0.0090046296 | BA4: J-UR-05581P1_20220228 | BB4: 45125.453 | BC4: 45125.46 | BD4: =BC4-BB4 -> 0.0074074074 | BF4: J-UR-0576P10_20230707 | BG4: 45126.41 | BH4: 45126.418 | BI4: =BH4-BG4 -> 0.0075115741 | BK4: URS-0419P2 | BL4: 45127.416 | BM4: 45127.419 | BN4: =BM4-BL4 -> 0.0022337963 | BP4: UR-0486P4 | BQ4: 45128.39 | BR4: 45128.399 | BS4: =BR4-BQ4 -> 0.0093287037 | BV4: UR-4377P6 | BW4: 45131.405 | BX4: 45131.411 | BY4: =BX4-BW4 -> 0.0059837963 | CA4: UR-0456P6 | CB4: 45132.381 | CC4: 45132.392 | CD4: =CC4-CB4 -> 0.011851852 | CF4: URS-42144-02P6_20230523 | CG4: 45133.442 | CH4: 45133.464 | CI4: =CH4-CG4 -> 0.021516204 | CK4: URS-4215P1 | CL4: 45134.44 | CM4: 45134.447 | CN4: =CM4-CL4 -> 0.0064814815 | CP4: URS-43011P6 | CQ4: 45135.421 | CR4: 45135.423 | CS4: =CR4-CQ4 -> 0.0019097222 | CV4: URS-4343P4 | CW4: 45138.462 | CX4: 45138.464 | CY4: =CX4-CW4 -> 0.0015046296
A5: URS-42144-02P1_20230523 | B5: 45110.408 | C5: 45110.431 | D5: =C5-B5 -> 0.023402778 | F5: UR-0388P2 | G5: 45111.383 | H5: 45111.385 | I5: =H5-G5 -> 0.0017013889 | K5: J-URS-43013P6_20221028 | L5: 45113.406 | M5: 45113.41 | N5: =M5-L5 -> 0.003900463 | P5: J-URS-43013P6_20221028 | Q5: 45113.406 | R5: 45113.41 | S5: =R5-Q5 -> 0.003900463 | U5: UR-0580P6_20230628 | V5: 45114.404 | W5: 45114.411 | X5: =W5-V5 -> 0.0072916667 | AA5: UR-0486P4 | AB5: 45117.456 | AC5: 45117.466 | AD5: =AC5-AB5 -> 0.010266204 | AF5: J-UR-05581P1_20220228 | AG5: 45118.471 | AH5: 45118.49 | AI5: =AH5-AG5 -> 0.018726852 | AK5: UR-0511P1 | AL5: 45119.437 | AM5: 45119.45 | AN5: =AM5-AL5 -> 0.01337963 | AP5: J-UR-05581P1_20220228 | AQ5: 45120.568 | AR5: 45120.587 | AS5: =AR5-AQ5 -> 0.018564815 | AU5: UR-0509-01P1 | AV5: 45121.435 | AW5: 45121.459 | AX5: =AW5-AV5 -> 0.023611111 | BA5: UR-0584P12_20230706 | BB5: 45125.471 | BC5: 45125.477 | BD5: =BC5-BB5 -> 0.0060185185 | BF5: UR-0576P1_20230707 | BG5: 45126.424 | BH5: 45126.429 | BI5: =BH5-BG5 -> 0.0055555556 | BK5: UR-0511P1 | BL5: 45127.439 | BM5: 45127.452 | BN5: =BM5-BL5 -> 0.013206019 | BP5: URS-0505P2 | BQ5: 45128.403 | BR5: 45128.405 | BS5: =BR5-BQ5 -> 0.00125 | BV5: URS-42144-02P6_20230523 | BW5: 45131.428 | BX5: 45131.449 | BY5: =BX5-BW5 -> 0.021527778 | CA5: J-URS-43833P6_20221109 | CB5: 45132.437 | CC5: 45132.446 | CD5: =CC5-CB5 -> 0.0090856481 | CF5: UR-0541P4 | CG5: 45133.488 | CH5: 45133.489 | CI5: =CH5-CG5 -> 0.0013888889 | CK5: URS-4215P4 | CL5: 45134.448 | CM5: 45134.456 | CN5: =CM5-CL5 -> 0.0078472222 | CP5: J-MVH-7249-01P4_20220419 | CQ5: 45135.438 | CR5: 45135.44 | CS5: =CR5-CQ5 -> 0.0013657407 | CV5: J-UR-05581P1_20220228 | CW5: 45138.494 | CX5: 45138.503 | CY5: =CX5-CW5 -> 0.008900463
A6: UR-0511P1 | B6: 45110.435 | C6: 45110.448 | D6: =C6-B6 -> 0.013032407 | F6: UR-0388P1 | G6: 45111.387 | H6: 45111.389 | I6: =H6-G6 -> 0.0011574074 | K6: UR-0388P2 | L6: 45113.435 | M6: 45113.436 | N6: =M6-L6 -> 0.0017592593 | P6: UR-0388P2 | Q6: 45113.435 | R6: 45113.436 | S6: =R6-Q6 -> 0.0017592593 | U6: UR-0580P1_20230628 | V6: 45114.416 | W6: 45114.421 | X6: =W6-V6 -> 0.0045023148 | AA6: URS-0486P1 | AB6: 45117.544 | AC6: 45117.549 | AD6: =AC6-AB6 -> 0.0051736111 | AF6: UR-0588P4_20230630 | AG6: 45118.561 | AH6: 45118.562 | AI6: =AH6-AG6 -> 0.0016319444 | AK6: UR-0483P1 | AL6: 45119.487 | AM6: 45119.498 | AN6: =AM6-AL6 -> 0.010150463 | AP6: MVJ-0501-02P8_20230704 | AQ6: 45120.61 | AR6: 45120.614 | AS6: =AR6-AQ6 -> 0.00375 | AU6: UR-0559-01P1 | AV6: 45121.463 | AW6: 45121.476 | AX6: =AW6-AV6 -> 0.012615741 | BA6: UR-0584P1_20230706 | BB6: 45125.541 | BC6: 45125.545 | BD6: =BC6-BB6 -> 0.0041203704 | BF6: J-UR-0582P10_20230706 | BG6: 45126.439 | BH6: 45126.448 | BI6: =BH6-BG6 -> 0.0083217593 | BK6: UR-4421-01P4 | BL6: 45127.46 | BM6: 45127.465 | BN6: =BM6-BL6 -> 0.005 | BP6: URS-0431P4 | BQ6: 45128.431 | BR6: 45128.433 | BS6: =BR6-BQ6 -> 0.0019097222 | BV6: UR-42143-02P6 | BW6: 45131.452 | BX6: 45131.456 | BY6: =BX6-BW6 -> 0.0041087963 | CA6: UT-2508P6_20230620 | CB6: 45132.45 | CC6: 45132.452 | CD6: =CC6-CB6 -> 0.0024884259 | CF6: UR-0541P1 | CG6: 45133.491 | CH6: 45133.492 | CI6: =CH6-CG6 -> 0.0012847222 | CK6: UR-0509-01P1 | CL6: 45134.462 | CM6: 45134.486 | CN6: =CM6-CL6 -> 0.023194444 | CP6: MVH-7249-01P01_20230720 | CQ6: 45135.459 | CR6: 45135.46 | CS6: =CR6-CQ6 -> 0.0011111111 | CV6: J-UR-05581P1_20220228 | CW6: 45138.541 | CX6: 45138.546 | CY6: =CX6-CW6 -> 0.0058333333
A7: URS-42881P1 | B7: 45110.451 | C7: 45110.461 | D7: =C7-B7 -> 0.0094212963 | F7: J-UT-1010P1_20220817 | G7: 45111.414 | H7: 45111.415 | I7: =H7-G7 -> 0.00096064815 | K7: UR-0388P1 | L7: 45113.438 | M7: 45113.439 | N7: =M7-L7 -> 0.0011574074 | P7: UR-0388P1 | Q7: 45113.438 | R7: 45113.439 | S7: =R7-Q7 -> 0.0011574074 | U7: UR-0595P6_20230628 | V7: 45114.425 | W7: 45114.428 | X7: =W7-V7 -> 0.002974537 | AA7: J-UR-05581P1_20220228 | AB7: 45117.562 | AC7: 45117.58 | AD7: =AC7-AB7 -> 0.018518519 | AF7: UR-0588P1_20230630 | AG7: 45118.567 | AH7: 45118.568 | AI7: =AH7-AG7 -> 0.0011921296 | AK7: URS-0505P2 | AL7: 45119.545 | AM7: 45119.547 | AN7: =AM7-AL7 -> 0.0015277778 | AP7: MVJ-0501-02P1_20230704 | AQ7: 45120.628 | AR7: 45120.63 | AS7: =AR7-AQ7 -> 0.0026273148 | AU7: J-UR-05581P1_20220228 | AV7: 45121.487 | AW7: 45121.494 | AX7: =AW7-AV7 -> 0.007337963 | BA7: UR-0575P10_20230705 | BB7: 45125.549 | BC7: 45125.556 | BD7: =BC7-BB7 -> 0.0075347222 | BF7: J-UR-0583P10_20230707 | BG7: 45126.462 | BH7: 45126.47 | BI7: =BH7-BG7 -> 0.0075115741 | BK7: URS-0543P6 | BL7: 45127.467 | BM7: 45127.471 | BN7: =BM7-BL7 -> 0.0042013889 | BP7: UR-0509-01P1 | BQ7: 45128.438 | BR7: 45128.461 | BS7: =BR7-BQ7 -> 0.023240741 | BV7: UR-0509-01P1 | BW7: 45131.478 | BX7: 45131.501 | BY7: =BX7-BW7 -> 0.023333333 | CA7: UT-2508P1_20230620 | CB7: 45132.455 | CC7: 45132.459 | CD7: =CC7-CB7 -> 0.0040277778 | CF7: UR-0511P1 | CG7: 45133.501 | CH7: 45133.509 | CI7: =CH7-CG7 -> 0.0077662037 | CK7: UR-0559-01P1 | CL7: 45134.489 | CM7: 45134.502 | CN7: =CM7-CL7 -> 0.01244213 | CP7: URS-43011P1 | CQ7: 45135.464 | CR7: 45135.465 | CS7: =CR7-CQ7 -> 0.0015393519 | CV7: UR-0559-01P1 | CW7: 45138.557 | CX7: 45138.57 | CY7: =CX7-CW7 -> 0.012488426
A8: J-UR-0578P4_20220525 | B8: 45110.47 | C8: 45110.472 | D8: =C8-B8 -> 0.0013888889 | F8: UR-0511P1 | G8: 45111.423 | H8: 45111.436 | I8: =H8-G8 -> 0.013240741 | K8: UR-4435P6 | L8: 45113.455 | M8: 45113.464 | N8: =M8-L8 -> 0.0083101852 | P8: UR-4435P6 | Q8: 45113.455 | R8: 45113.464 | S8: =R8-Q8 -> 0.0083101852 | U8: UR-0595P1_20230628 | V8: 45114.434 | W8: 45114.437 | X8: =W8-V8 -> 0.0029282407 | AA8: UR-0559-01P1 | AB8: 45117.586 | AC8: 45117.603 | AD8: =AC8-AB8 -> 0.016631944 | AF8: UR-0590P4_20230703 | AG8: 45118.581 | AH8: 45118.583 | AI8: =AH8-AG8 -> 0.0018171296 | AK8: UR-0509-01P1 | AL8: 45119.562 | AM8: 45119.586 | AN8: =AM8-AL8 -> 0.023993056 | AP8: MVJ-0518P4_20230704 | AQ8: 45120.681 | AR8: 45120.682 | AS8: =AR8-AQ8 -> 0.00060185185 | AU8: URS-0540P4 | AV8: 45121.561 | AW8: 45121.565 | AX8: =AW8-AV8 -> 0.0040625 | BA8: UR-0575P1_20230705 | BB8: 45125.564 | BC8: 45125.57 | BD8: =BC8-BB8 -> 0.0056712963 | BF8: J-UR-0583P01_20230707 | BG8: 45126.489 | BH8: 45126.496 | BI8: =BH8-BG8 -> 0.0073148148 | BK8: UR-0559-01P1 | BL8: 45127.476 | BM8: 45127.484 | BN8: =BM8-BL8 -> 0.0083101852 | BP8: J-UR-05581P4_20220228 | BQ8: 45128.466 | BR8: 45128.485 | BS8: =BR8-BQ8 -> 0.018113426 | BV8: J-UR-05581P1_20220228 | BW8: 45131.546 | BX8: 45131.56 | BY8: =BX8-BW8 -> 0.014733796 | CA8: UR-0509-01P1 | CB8: 45132.463 | CC8: 45132.487 | CD8: =CC8-CB8 -> 0.023252315 | CF8: UR-0511P1 | CG8: 45133.537 | CH8: 45133.543 | CI8: =CH8-CG8 -> 0.0059953704 | CK8: MVD-0415P4 | CL8: 45134.556 | CM8: 45134.574 | CN8: =CM8-CL8 -> 0.018263889 | CP8: UR-0509-01P1 | CQ8: 45135.469 | CR8: 45135.496 | CS8: =CR8-CQ8 -> 0.026956019 | CV8: URS-4272P6 | CW8: 45138.575 | CX8: 45138.579 | CY8: =CX8-CW8 -> 0.004224537
A9: J-UR-0585P6_20220601 | B9: 45110.495 | C9: 45110.498 | D9: =C9-B9 -> 0.0030208333 | F9: UR-0396P4 | G9: 45111.45 | H9: 45111.453 | I9: =H9-G9 -> 0.0024768519 | K9: J-UR-05581P1_20220228 | L9: 45113.553 | M9: 45113.572 | N9: =M9-L9 -> 0.019270833 | P9: J-UR-05581P1_20220228 | Q9: 45113.553 | R9: 45113.572 | S9: =R9-Q9 -> 0.019270833 | U9: UR-0511P1 | V9: 45114.441 | W9: 45114.454 | X9: =W9-V9 -> 0.01318287 | AA9: UR-0589P4_20230629 | AB9: 45117.611 | AC9: 45117.613 | AD9: =AC9-AB9 -> 0.0017824074 | AF9: UR-0590P1_20230703 | AG9: 45118.585 | AH9: 45118.587 | AI9: =AH9-AG9 -> 0.0015162037 | AK9: UT-0931-01P10 | AL9: 45119.603 | AM9: 45119.613 | AN9: =AM9-AL9 -> 0.0094675926 | AP9: MVJ-0518P1_20230704 | AQ9: 45120.684 | AR9: 45120.684 | AS9: =AR9-AQ9 -> 0.00042824074 | AU9: UR-4421-01P4 | AV9: 45121.567 | AW9: 45121.572 | AX9: =AW9-AV9 -> 0.0049768519 | BA9: UR-0559-01P1 | BB9: 45125.577 | BC9: 45125.59 | BD9: =BC9-BB9 -> 0.012511574 | BF9: J-UR-0582P01_20230706 | BG9: 45126.5 | BH9: 45126.506 | BI9: =BH9-BG9 -> 0.0059722222 | BK9: J-UR-05581P1_20220228 | BL9: 45127.487 | BM9: 45127.495 | BN9: =BM9-BL9 -> 0.0074074074 | BP9: URS-0431P1 | BQ9: 45128.492 | BR9: 45128.494 | BS9: =BR9-BQ9 -> 0.0021296296 | BV9: UR-06101P8 | BW9: 45131.566 | BX9: 45131.577 | BY9: =BX9-BW9 -> 0.010925926 | CA9: J-UR-05581P1_20220228 | CB9: 45132.491 | CC9: 45132.506 | CD9: =CC9-CB9 -> 0.015034722 | CF9: J-UR-05581P1_20220228 | CG9: 45133.546 | CH9: 45133.561 | CI9: =CH9-CG9 -> 0.014861111 | CK9: UR-0488-01P4 | CL9: 45134.597 | CM9: 45134.605 | CN9: =CM9-CL9 -> 0.0080555556 | CP9: J-UR-05581P1_20220228 | CQ9: 45135.499 | CR9: 45135.506 | CS9: =CR9-CQ9 -> 0.0073148148 | CV9: UR-4515P4 | CW9: 45138.581 | CX9: 45138.586 | CY9: =CX9-CW9 -> 0.005462963
A10: J-UR-0585P1_20220601 | B10: 45110.505 | C10: 45110.539 | D10: =C10-B10 -> 0.034826389 | F10: UR-0396P1 | G10: 45111.454 | H10: 45111.456 | I10: =H10-G10 -> 0.0015393518 | K10: UR-0559-01P1 | L10: 45113.576 | M10: 45113.593 | N10: =M10-L10 -> 0.016678241 | P10: UR-0559-01P1 | Q10: 45113.576 | R10: 45113.593 | S10: =R10-Q10 -> 0.016678241 | U10: UR-4377P1 | V10: 45114.456 | W10: 45114.464 | X10: =W10-V10 -> 0.0074537037 | AA10: UR-0589P1_20230629 | AB10: 45117.614 | AC10: 45117.616 | AD10: =AC10-AB10 -> 0.0013310185 | AF10: UR-0615P4_20230703 | AG10: 45118.597 | AH10: 45118.598 | AI10: =AH10-AG10 -> 0.00086805555 | AK10: UT-0931-01P1 | AL10: 45119.619 | AM10: 45119.627 | AN10: =AM10-AL10 -> 0.0078587963 | AP10: URS-42144-02P6_20230523 | AQ10: 45120.695 | AR10: 45120.716 | AS10: =AR10-AQ10 -> 0.021365741 | AU10: URS-0540P1 | AV10: 45121.576 | AW10: 45121.579 | AX10: =AW10-AV10 -> 0.0030208333 | BA10: UR-0509-01P1 | BB10: 45125.604 | BC10: 45125.628 | BD10: =BC10-BB10 -> 0.023287037 | BF10: J-UR-0582P01_20230706 | BG10: 45126.541 | BH10: 45126.543 | BI10: =BH10-BG10 -> 0.0022800926 | BK10: UR-0509-01P1 | BL10: 45127.497 | BM10: 45127.505 | BN10: =BM10-BL10 -> 0.007650463 | BP10: URS-0486P1 | BQ10: 45128.496 | BR10: 45128.501 | BS10: =BR10-BQ10 -> 0.005150463 | BV10: UR-4377P1 | BW10: 45131.587 | BX10: 45131.593 | BY10: =BX10-BW10 -> 0.0066087963 | CA10: J-URS-43833P1_20221109 | CB10: 45132.544 | CC10: 45132.554 | CD10: =CC10-CB10 -> 0.010104167 | CF10: UR-0509-01P1 | CG10: 45133.564 | CH10: 45133.587 | CI10: =CH10-CG10 -> 0.023240741 | CK10: MVD-0415P1 | CL10: 45134.616 | CM10: 45134.63 | CN10: =CM10-CL10 -> 0.013391204 | CP10: J-UR-05581P1_20220228 | CQ10: 45135.537 | CR10: 45135.544 | CS10: =CR10-CQ10 -> 0.0073148148 | CV10: UR-4341-02P4 | CW10: 45138.595 | CX10: 45138.597 | CY10: =CX10-CW10 -> 0.0021296296
A11: J-UR-0586P6_20220601 | B11: 45110.56 | C11: 45110.564 | D11: =C11-B11 -> 0.0045601852 | F11: UR-4489P1 | G11: 45111.459 | H11: 45111.465 | I11: =H11-G11 -> 0.0062268519 | K11: J-URS-43013P1_20221028 | L11: 45113.595 | M11: 45113.599 | N11: =M11-L11 -> 0.0039467593 | P11: J-URS-43013P1_20221028 | Q11: 45113.595 | R11: 45113.599 | S11: =R11-Q11 -> 0.0039467593 | U11: URS-4215P1 | V11: 45114.467 | W11: 45114.473 | X11: =W11-V11 -> 0.0064351852 | AA11: UR-0614P4_20230630 | AB11: 45117.629 | AC11: 45117.63 | AD11: =AC11-AB11 -> 0.00085648148 | AF11: UR-0615P1_20230703 | AG11: 45118.604 | AH11: 45118.604 | AI11: =AH11-AG11 -> 0.00065972222 | AK11: UR-4207-01P2 | AL11: 45119.643 | AM11: 45119.649 | AN11: =AM11-AL11 -> 0.006087963 | BA11: UR-06101P8 | BB11: 45125.63 | BC11: 45125.641 | BD11: =BC11-BB11 -> 0.010949074 | BF11: UR-4035P1 | BG11: 45126.555 | BH11: 45126.559 | BI11: =BH11-BG11 -> 0.003587963 | BK11: UR-0509-01P1 | BL11: 45127.541 | BM11: 45127.556 | BN11: =BM11-BL11 -> 0.015381944 | BP11: UT-0988P4 | BQ11: 45128.57 | BR11: 45128.575 | BS11: =BR11-BQ11 -> 0.0047569444 | BV11: URS-42144-02P1_20230523 | BW11: 45131.605 | BX11: 45131.629 | BY11: =BX11-BW11 -> 0.023518519 | CA11: UT-0992-01P6_20220909 | CB11: 45132.559 | CC11: 45132.564 | CD11: =CC11-CB11 -> 0.0047222222 | CF11: URS-42144-02P1_20230523 | CG11: 45133.591 | CH11: 45133.614 | CI11: =CH11-CG11 -> 0.023229167 | CK11: UR-0488-01P1 | CL11: 45134.645 | CM11: 45134.651 | CN11: =CM11-CL11 -> 0.0053009259 | CP11: UR-0559-01P1 | CQ11: 45135.546 | CR11: 45135.559 | CS11: =CR11-CQ11 -> 0.012546296 | CV11: UR-0509-01P1 | CW11: 45138.609 | CX11: 45138.642 | CY11: =CX11-CW11 -> 0.032696759
A12: J-UR-0586P1_20220601 | B12: 45110.573 | C12: 45110.576 | D12: =C12-B12 -> 0.0026273148 | F12: URS-0400P2 | G12: 45111.472 | H12: 45111.473 | I12: =H12-G12 -> 0.0016782407 | K12: UR-4435P1 | L12: 45113.601 | M12: 45113.607 | N12: =M12-L12 -> 0.0065277778 | P12: UR-4435P1 | Q12: 45113.601 | R12: 45113.607 | S12: =R12-Q12 -> 0.0065277778 | U12: URS-4215P4 | V12: 45114.475 | W12: 45114.483 | X12: =W12-V12 -> 0.0079050926 | AA12: UR-0614P1_20230630 | AB12: 45117.639 | AC12: 45117.64 | AD12: =AC12-AB12 -> 0.00071759259 | AF12: UR-0520P1 | AG12: 45118.615 | AH12: 45118.631 | AI12: =AH12-AG12 -> 0.015243056 | AK12: URS-42511P6 | AL12: 45119.684 | AM12: 45119.686 | AN12: =AM12-AL12 -> 0.0020717593 | BA12: UR-06101P1 | BB12: 45125.657 | BC12: 45125.664 | BD12: =BC12-BB12 -> 0.0074421296 | BF12: J-UR-43511P2_20220916 | BG12: 45126.569 | BH12: 45126.572 | BI12: =BH12-BG12 -> 0.0036226852 | BK12: URS-0543P1 | BL12: 45127.562 | BM12: 45127.565 | BN12: =BM12-BL12 -> 0.0030092593 | BP12: UT-0988P1 | BQ12: 45128.576 | BR12: 45128.581 | BS12: =BR12-BQ12 -> 0.0046412037 | BV12: UR-42143-02P1 | BW12: 45131.648 | BX12: 45131.654 | BY12: =BX12-BW12 -> 0.0054976852 | CA12: UR-4551P06_20230714 | CB12: 45132.593 | CC12: 45132.595 | CD12: =CC12-CB12 -> 0.0024189815 | CF12: UR-0388P2 | CG12: 45133.619 | CH12: 45133.62 | CI12: =CH12-CG12 -> 0.0017013889 | CK12: UR-0519P8 | CL12: 45134.691 | CM12: 45134.727 | CN12: =CM12-CL12 -> 0.036875 | CP12: URS-0304-01P4 | CQ12: 45135.566 | CR12: 45135.571 | CS12: =CR12-CQ12 -> 0.0043055556 | CV12: URS-4272P1 | CW12: 45138.673 | CX12: 45138.678 | CY12: =CX12-CW12 -> 0.0045138889
A13: J-UR-0594P4_20220602 | B13: 45110.612 | C13: 45110.613 | D13: =C13-B13 -> 0.0012847222 | F13: UR-0476P2 | G13: 45111.477 | H13: 45111.478 | I13: =H13-G13 -> 0.00094907408 | K13: UR-0509-01P4 | L13: 45113.61 | M13: 45113.641 | N13: =M13-L13 -> 0.031770833 | P13: UR-0509-01P4 | Q13: 45113.61 | R13: 45113.641 | S13: =R13-Q13 -> 0.031770833 | U13: J-UR-05581P4_20220228 | V13: 45114.486 | W13: 45114.504 | X13: =W13-V13 -> 0.018020833 | AA13: UR-04511P2 | AB13: 45117.653 | AC13: 45117.661 | AD13: =AC13-AB13 -> 0.0074537037 | AF13: UT-2537P8_20221102 | AG13: 45118.679 | AH13: 45118.679 | AI13: =AH13-AG13 -> 0.00018518518 | BA13: UR-0488-01P4 | BB13: 45125.669 | BC13: 45125.677 | BD13: =BC13-BB13 -> 0.0080439815 | BF13: J-UR-43511P1_20220916 | BG13: 45126.581 | BH13: 45126.584 | BI13: =BH13-BG13 -> 0.0031828704 | BK13: UR-43721P8 | BL13: 45127.577 | BM13: 45127.584 | BN13: =BM13-BL13 -> 0.0070601852 | BP13: URS-4273P4 | BQ13: 45128.66 | BR13: 45128.664 | BS13: =BR13-BQ13 -> 0.0036458333 | BV13: UR-06101P1 | BW13: 45131.659 | BX13: 45131.667 | BY13: =BX13-BW13 -> 0.0078009259 | CA13: UR-4551P01_20230714 | CB13: 45132.608 | CC13: 45132.611 | CD13: =CC13-CB13 -> 0.0033333333 | CF13: UR-0388P1 | CG13: 45133.622 | CH13: 45133.623 | CI13: =CH13-CG13 -> 0.0011689815 | CP13: UR-4349-01P4 | CQ13: 45135.583 | CR13: 45135.585 | CS13: =CR13-CQ13 -> 0.0020486111 | CV13: UR-4341-02P1 | CW13: 45138.687 | CX13: 45138.689 | CY13: =CX13-CW13 -> 0.0020833333
A14: J-UR-0594P1_20220602 | B14: 45110.614 | C14: 45110.615 | D14: =C14-B14 -> 0.000625 | F14: UR-0488-01P4 | G14: 45111.55 | H14: 45111.559 | I14: =H14-G14 -> 0.008912037 | K14: UR-0509-01P1 | L14: 45113.651 | M14: 45113.674 | N14: =M14-L14 -> 0.023159722 | P14: UR-0509-01P1 | Q14: 45113.651 | R14: 45113.674 | S14: =R14-Q14 -> 0.023159722 | U14: J-UR-05581P4_20220228 | V14: 45114.539 | W14: 45114.544 | X14: =W14-V14 -> 0.0044444444 | AA14: UR-04511P1 | AB14: 45117.664 | AC14: 45117.671 | AD14: =AC14-AB14 -> 0.0072916667 | AF14: UT-2537P1_20221102 | AG14: 45118.681 | AH14: 45118.681 | AI14: =AH14-AG14 -> 0.00018518518 | BA14: UR-0488-01P1 | BB14: 45125.689 | BC14: 45125.697 | BD14: =BC14-BB14 -> 0.0076736111 | BF14: URS-42883P6 | BG14: 45126.594 | BH14: 45126.599 | BI14: =BH14-BG14 -> 0.0041666667 | BK14: UR-43721P1 | BL14: 45127.598 | BM14: 45127.605 | BN14: =BM14-BL14 -> 0.0074537037 | BP14: URS-4273P1 | BQ14: 45128.665 | BR14: 45128.669 | BS14: =BR14-BQ14 -> 0.0033680556 | BV14: UR-4487P8 | BW14: 45131.696 | BX14: 45131.705 | BY14: =BX14-BW14 -> 0.0093171296 | CA14: UR-0456P1 | CB14: 45132.614 | CC14: 45132.626 | CD14: =CC14-CB14 -> 0.012071759 | CF14: UR-0486P4 | CG14: 45133.649 | CH14: 45133.658 | CI14: =CH14-CG14 -> 0.0093518519 | CP14: URS-42982P1 | CQ14: 45135.591 | CR14: 45135.6 | CS14: =CR14-CQ14 -> 0.0087847222
A15: MVM-4424P1 | B15: 45110.639 | C15: 45110.657 | D15: =C15-B15 -> 0.018449074 | F15: UR-0488-01P1 | G15: 45111.561 | H15: 45111.568 | I15: =H15-G15 -> 0.007025463 | K15: UR-0577P6_20230627 | L15: 45113.689 | M15: 45113.694 | N15: =M15-L15 -> 0.0052777778 | P15: UR-0577P6_20230627 | Q15: 45113.689 | R15: 45113.694 | S15: =R15-Q15 -> 0.0052777778 | U15: J-UR-05581P1_20220228 | V15: 45114.552 | W15: 45114.57 | X15: =W15-V15 -> 0.018634259 | AA15: J-UT-0986P10_20220902 | AB15: 45117.678 | AC15: 45117.696 | AD15: =AC15-AB15 -> 0.018217593 | BF15: URS-42883P1 | BG15: 45126.604 | BH15: 45126.609 | BI15: =BH15-BG15 -> 0.0050115741 | BK15: UT-0987-01P6_20220909 | BL15: 45127.608 | BM15: 45127.614 | BN15: =BM15-BL15 -> 0.005625 | BP15: MVH-7242P02_20230719 | BQ15: 45128.692 | BR15: 45128.694 | BS15: =BR15-BQ15 -> 0.0020023148 | CA15: UR-04511P2 | CB15: 45132.629 | CC15: 45132.642 | CD15: =CC15-CB15 -> 0.013553241 | CF15: URS-0486P1 | CG15: 45133.66 | CH15: 45133.666 | CI15: =CH15-CG15 -> 0.0054282407 | CP15: UR-0489P4 | CQ15: 45135.605 | CR15: 45135.613 | CS15: =CR15-CQ15 -> 0.0079398148
A16: UR-0509-01P4 | B16: 45110.668 | C16: 45110.7 | D16: =C16-B16 -> 0.031921296 | F16: UR-0574P12_20230623 | G16: 45111.628 | H16: 45111.633 | I16: =H16-G16 -> 0.0045949074 | K16: UR-0577P1_20230627 | L16: 45113.698 | M16: 45113.702 | N16: =M16-L16 -> 0.0041898148 | P16: UR-0577P1_20230627 | Q16: 45113.698 | R16: 45113.702 | S16: =R16-Q16 -> 0.0041898148 | U16: UR-0559-03P8 | V16: 45114.573 | W16: 45114.591 | X16: =W16-V16 -> 0.017743056 | BF16: UT-0983P4 | BG16: 45126.612 | BH16: 45126.615 | BI16: =BH16-BG16 -> 0.0024305556 | BK16: UT-0987-01P1_20220909 | BL16: 45127.623 | BM16: 45127.627 | BN16: =BM16-BL16 -> 0.0043634259 | BP16: MVH-7242P01_20230719 | BQ16: 45128.698 | BR16: 45128.7 | BS16: =BR16-BQ16 -> 0.0012037037 | CA16: UR-04511P1 | CB16: 45132.649 | CC16: 45132.657 | CD16: =CC16-CB16 -> 0.0074074074 | CF16: URS-0505P2 | CG16: 45133.671 | CH16: 45133.673 | CI16: =CH16-CG16 -> 0.0012731481 | CP16: URS-0505P2 | CQ16: 45135.621 | CR16: 45135.623 | CS16: =CR16-CQ16 -> 0.0012615741
A17: UT-0931-01P10 | B17: 45110.705 | C17: 45110.715 | D17: =C17-B17 -> 0.010069444 | F17: J-UR-0574P01_20230623_mp | G17: 45111.65 | H17: 45111.652 | I17: =H17-G17 -> 0.0027314815 | U17: UR-0559-01P1 | V17: 45114.6 | W17: 45114.617 | X17: =W17-V17 -> 0.016724537 | BF17: UR-0559-01P1 | BG17: 45126.639 | BH17: 45126.648 | BI17: =BH17-BG17 -> 0.0082407407 | BK17: UR-4368P2 | BL17: 45127.638 | BM17: 45127.639 | BN17: =BM17-BL17 -> 0.001412037 | CA17: UT-0992-01P1_20220909 | CB17: 45132.661 | CC17: 45132.666 | CD17: =CC17-CB17 -> 0.0049074074 | CF17: UR-0456P6 | CG17: 45133.676 | CH17: 45133.689 | CI17: =CH17-CG17 -> 0.012835648 | CP17: UR-4349-01P4 | CQ17: 45135.627 | CR17: 45135.629 | CS17: =CR17-CQ17 -> 0.002037037
F18: UR-0509-01P4 | G18: 45111.676 | H18: 45111.708 | I18: =H18-G18 -> 0.031886574 | U18: UT-0996P6 | V18: 45114.642 | W18: 45114.644 | X18: =W18-V18 -> 0.0023958333 | BF18: UR-0509-01P1 | BG18: 45126.65 | BH18: 45126.673 | BI18: =BH18-BG18 -> 0.023287037 | BK18: UR-4368P1 | BL18: 45127.641 | BM18: 45127.643 | BN18: =BM18-BL18 -> 0.0014351852 | CA18: UTS-0918P2 | CB18: 45132.669 | CC18: 45132.67 | CD18: =CC18-CB18 -> 0.0010763889 | CF18: UR-0456P1 | CG18: 45133.698 | CH18: 45133.71 | CI18: =CH18-CG18 -> 0.0121875 | CP18: URS-4002P4 | CQ18: 45135.642 | CR18: 45135.642 | CS18: =CR18-CQ18 -> 0.00015046296
U19: UT-0996P1 | V19: 45114.654 | W19: 45114.656 | X19: =W19-V19 -> 0.0011574074 | BF19: UR-0481-01P6 | BG19: 45126.699 | BH19: 45126.722 | BI19: =BH19-BG19 -> 0.023078704 | BK19: UR-0396P4 | BL19: 45127.648 | BM19: 45127.65 | BN19: =BM19-BL19 -> 0.0025115741 | CA19: UR-4341-02P4 | CB19: 45132.676 | CC19: 45132.679 | CD19: =CC19-CB19 -> 0.0021180556 | CP19: URS-4002P1 | CQ19: 45135.643 | CR19: 45135.643 | CS19: =CR19-CQ19 -> 0.00017361111
U20: URS-42144-02P6_20230523 | V20: 45114.667 | W20: 45114.689 | X20: =W20-V20 -> 0.021678241 | BK20: URS-0483P4 | BL20: 45127.653 | BM20: 45127.663 | BN20: =BM20-BL20 -> 0.010555556 | CA20: UR-4341-02P1 | CB20: 45132.681 | CC20: 45132.683 | CD20: =CC20-CB20 -> 0.0019907407 | CP20: URS-0304-01P1 | CQ20: 45135.669 | CR20: 45135.674 | CS20: =CR20-CQ20 -> 0.005462963
U21: URS-42144-02P1_20230523 | V21: 45114.698 | W21: 45114.721 | X21: =W21-V21 -> 0.023206019 | BK21: UR-0396P1 | BL21: 45127.674 | BM21: 45127.676 | BN21: =BM21-BL21 -> 0.0015625 | CP21: UR-4489P8 | CQ21: 45135.68 | CR21: 45135.687 | CS21: =CR21-CQ21 -> 0.0068865741
BK22: UR-0483P1 | BL22: 45127.684 | BM22: 45127.695 | BN22: =BM22-BL22 -> 0.01037037 | CP22: UR-04511P2 | CQ22: 45135.69 | CR22: 45135.698 | CS22: =CR22-CQ22 -> 0.0073842593
CP23: UR-04511P1 | CQ23: 45135.7 | CR23: 45135.707 | CS23: =CR23-CQ23 -> 0.0071875
C25: TOTAL | D25: =SUM(D27:D44) -> 0.034965278 | H25: TOTAL | I25: =SUM(I27:I50) -> 0.078101852 | M25: TOTAL | N25: =SUM(N27:N45) -> 0.064826389 | R25: TOTAL | S25: =SUM(S27:S50) -> 0.064826389 | W25: TOTAL | X25: =SUM(X27:X51) -> 0.17181713 | AC25: TOTAL | AD25: =SUM(AD27:AD52) -> 0.1446412 | AH25: TOTAL | AI25: =SUM(AI27:AI56) -> 0.10953704 | AM25: TOTAL | AN25: =SUM(AN27:AN50) -> 0.091770833 | AR25: TOTAL | AS25: =SUM(AS27:AS43) -> 0.15799769 | AW25: TOTAL | AX25: =SUM(AX27:AX43) -> 0.071666667 | BC25: TOTAL | BD25: =SUM(BD27:BD43) -> 0.15314815 | BH25: TOTAL | BI25: =SUM(BI27:BI43) -> 0.13952546 | BM25: TOTAL | BN25: =SUM(BN27:BN43) -> 0.11196759 | BR25: TOTAL | BS25: =SUM(BS27:BS52) -> 0.16320602 | BX25: TOTAL | BY25: =SUM(BY27:BY55) -> 0.10400463 | CC25: TOTAL | CD25: =SUM(CD27:CD51) -> 0.063333333 | CH25: TOTAL | CI25: =SUM(CI27:CI45) -> 0.11392361 | CM25: TOTAL | CN25: =SUM(CN27:CN55) -> 0.11482639 | CR25: TOTAL | CS25: =SUM(CS27:CS59) -> 0.097719907 | CX25: TOTAL | CY25: =SUM(CY27:CY43) -> 0.037673611
