Workbook

Sheet 倉庫
A1: シリアル | B1: 品番 | C1: 入庫数 | D1: 在庫数 | E1: ステータス | F1: 保管場所 | G1: 倉庫ロケーション
A2: 154468A100006 | B2: 154468A | C2: 5000 | D2: 1246 | E2: 生産終了 | F2: ハズシ(L2) | G2: 01-01-01-01
A3: 154468A100007 | B3: 154468A | C3: 5000 | D3: 3793 | E3: 貯蔵 | F3: 棚 | G3: 01-01-01-01
A4: 154468A100008 | B4: 154468A | C4: 5000 | D4: 5000 | E4: 出庫 | F4: 2ライン倉庫 | G4: 01-01-01-01
A5: 154468A100009 | B5: 154468A | C5: 5000 | D5: 4940 | E5: 貯蔵 | F5: 棚 | G5: 01-01-01-01
A6: 154468A100010 | B6: 154468A | C6: 5000 | D6: 5000 | E6: 貯蔵 | F6: 棚 | G6: 01-01-01-01
A7: 154468A100011 | B7: 154468A | C7: 5000 | D7: 5000 | E7: 貯蔵 | F7: 棚 | G7: 01-01-01-01
A8: 158704B100174 | B8: 158704B | C8: 2000 | D8: 3 | E8: 生産終了 | F8: 0確認(L1) | G8: 01-01-01-02
A9: 158704B100183 | B9: 158704B | C9: 2000 | D9: 1413 | E9: 貯蔵 | F9: 棚 | G9: 01-01-01-02
A10: 158704B100188 | B10: 158704B | C10: 2000 | D10: 2000 | E10: 貯蔵 | F10: 棚 | G10: 01-01-01-02
A11: 158704B100192 | B11: 158704B | C11: 2000 | D11: 2000 | E11: 貯蔵 | F11: 棚 | G11: 01-01-01-02
A12: 158704B100199 | B12: 158704B | C12: 2000 | D12: 2000 | E12: 貯蔵 | F12: 棚 | G12: 01-01-01-02
A13: 158731B100202 | B13: 158731B | C13: 2000 | D13: 102 | E13: 貯蔵 | F13: 棚 | G13: 01-01-01-03
... A55: 159552C100019 | B55: 159552C | C55: 5000 | D55: 3169 | E55: 貯蔵 | F55: 棚 | G55: 01-01-02-09
A56: 159695 100152 | B56: 159695 | C56: 500 | D56: 414 | E56: 貯蔵 | F56: 棚 | G56: 01-01-03-02
A57: 159695 100158 | B57: 159695 | C57: 500 | D57: 500 | E57: 貯蔵 | F57: 棚 | G57: 01-01-03-02
A58: 159695 100160 | B58: 159695 | C58: 500 | D58: 500 | E58: 貯蔵 | F58: 棚 | G58: 01-01-03-02
A59: 159695 100162 | B59: 159695 | C59: 500 | D59: 500 | E59: 貯蔵 | F59: 棚 | G59: 01-01-03-02
A60: 159695 100164 | B60: 159695 | C60: 500 | D60: 500 | E60: 貯蔵 | F60: 棚 | G60: 01-01-03-02
A61: 159695 100165 | B61: 159695 | C61: 500 | D61: 500 | E61: 貯蔵 | F61: 棚 | G61: 01-01-03-02
A62: 159695 100167 | B62: 159695 | C62: 500 | D62: 500 | E62: 貯蔵 | F62: 棚 | G62: 01-01-03-02
A63: 159695 100172 | B63: 159695 | C63: 500 | D63: 500 | E63: 貯蔵 | F63: 棚 | G63: 01-01-03-02
A64: 159695 100174 | B64: 159695 | C64: 500 | D64: 500 | E64: 貯蔵 | F64: 棚 | G64: 01-01-03-02
A65: 159695 100175 | B65: 159695 | C65: 500 | D65: 500 | E65: 貯蔵 | F65: 棚 | G65: 01-01-03-02
A66: 159695 100176 | B66: 159695 | C66: 500 | D66: 500 | E66: 貯蔵 | F66: 棚 | G66: 01-01-03-02
A67: 159695 100179 | B67: 159695 | C67: 500 | D67: 500 | E67: 貯蔵 | F67: 棚 | G67: 01-01-03-02
A68: 160078A100047 | B68: 160078A | C68: 2500 | D68: 106 | E68: 貯蔵 | F68: 棚 | G68: 08-32-01-01
A69: 160078A100055 | B69: 160078A | C69: 2500 | D69: 17 | E69: 貯蔵 | F69: 棚 | G69: 08-32-01-01
A70: 160096C100626 | B70: 160096C | C70: 3000 | D70: 4 | E70: 生産終了 | F70: 0確認(L1) | G70: 03-42-01-01
A71: 160096C100627 | B71: 160096C | C71: 3000 | D71: 803 | E71: 生産終了 | F71: ハズシ(L3) | G71: 03-42-01-01
A72: 160096C100628 | B72: 160096C | C72: 3000 | D72: 1542 | E72: 貯蔵 | F72: 棚 | G72: 03-42-01-01
A73: 160096C100631 | B73: 160096C | C73: 3000 | D73: 2506 | E73: 生産中 | F73: 設備(L1) | G73: 03-42-01-01
A74: 160096C100632 | B74: 160096C | C74: 3000 | D74: 3000 | E74: 出庫 | F74: 3ライン倉庫 | G74: 03-42-01-01
A75: 160096C100633 | B75: 160096C | C75: 3000 | D75: 3000 | E75: 出庫 | F75: 3ライン倉庫 | G75: 03-42-01-01
A76: 160096C100638 | B76: 160096C | C76: 3000 | D76: 3000 | E76: 貯蔵 | F76: 棚 | G76: 03-42-01-01
A77: 160096C100639 | B77: 160096C | C77: 3000 | D77: 3000 | E77: 貯蔵 | F77: 棚 | G77: 03-42-01-01
A78: 160096C100640 | B78: 160096C | C78: 3000 | D78: 3000 | E78: 貯蔵 | F78: 棚 | G78: 03-42-01-01
A79: 160096C100642 | B79: 160096C | C79: 3000 | D79: 3000 | E79: 貯蔵 | F79: 棚 | G79: 03-42-01-01
... A125: 190954A100175 | B125: 190954A | C125: 3000 | D125: 3000 | E125: 貯蔵 | F125: 棚 | G125: 03-01-01-02
A126: 191017 000014 | B126: 191017 | C126: 181 | D126: 64 | E126: 貯蔵 | F126: 棚 | G126: 20-01-01-01
...

Sheet 倉庫piv
A1: 保管場所 | B1: 棚 | D1: 保管場所 | E1: 1ライン倉庫 | F1: ←現場倉庫 | G1: 保管場所 | H1: 設備(L1) | I1: ←設備 | J1: 保管場所 | K1: ハズシ(L1) | L1: ←はずし
A3: 行ラベル | B3: 個数 / シリアル | D3: 行ラベル | E3: 個数 / シリアル | G3: 行ラベル | H3: 個数 / シリアル | J3: 行ラベル | K3: 個数 / シリアル | M3: 行ラベル | N3: 個数 / シリアル
A4: 159695 | B4: 12 | D4: 582228 | E4: 1 | G4: 608843 | H4: 1 | J4: 703482 | K4: 1 | M4: 159695 | N4: 12
A5: 191017 | B5: 3 | D5: 606489 | E5: 1 | G5: 621552 | H5: 1 | J5: 738293 | K5: 1 | M5: 棚 | N5: 12
A6: 309328 | B6: 2 | D6: 620598 | E6: 1 | G6: 632594 | H6: 1 | J6: 9000033474 | K6: 1 | M6: 191017 | N6: 3
A7: 309417 | B7: 2 | D7: 620606 | E7: 1 | G7: 649255 | H7: 1 | J7: 9000040011 | K7: 1 | M7: 棚 | N7: 3
A8: 357605 | B8: 1 | D8: 620624 | E8: 1 | G8: 650422 | H8: 1 | J8: 9000059415 | K8: 1 | M8: 309328 | N8: 2
A9: 384834 | B9: 1 | D9: 621552 | E9: 1 | G9: 654597 | H9: 1 | J9: 9000066849 | K9: 1 | M9: 棚 | N9: 2
A10: 485663 | B10: 2 | D10: 632023 | E10: 1 | G10: 654659 | H10: 1 | J10: 9000068520 | K10: 1 | M10: 309417 | N10: 2
A11: 512991 | B11: 14 | D11: 632718 | E11: 1 | G11: 659298 | H11: 1 | J11: 558986A | K11: 1 | M11: 棚 | N11: 2
A12: 513517 | B12: 19 | D12: 639132 | E12: 1 | G12: 661339 | H12: 1 | J12: 654819A | K12: 1 | M12: 357605 | N12: 1
A13: 514311 | B13: 2 | D13: 641263 | E13: 1 | G13: 661366 | H13: 1 | J13: 665255B | K13: 1 | M13: 棚 | N13: 1
A14: 517415 | B14: 1 | D14: 644955 | E14: 1 | G14: 661375 | H14: 1 | J14: 902285B | K14: 1 | M14: 384834 | N14: 1
A15: 530035 | B15: 4 | D15: 654605 | E15: 1 | G15: 663275 | H15: 1 | J15: 総計 | K15: 11 | M15: 棚 | N15: 1
A16: 534806 | B16: 6 | D16: 654614 | E16: 1 | G16: 666192 | H16: 1 | M16: 485663 | N16: 2
A17: 536172 | B17: 3 | D17: 654632 | E17: 1 | G17: 666789 | H17: 1 | M17: 棚 | N17: 2
A18: 542735 | B18: 4 | D18: 654641 | E18: 1 | G18: 667636 | H18: 1 | M18: 512991 | N18: 14
A19: 546143 | B19: 2 | D19: 654659 | E19: 2 | G19: 667645 | H19: 1 | M19: 棚 | N19: 14
A20: 548132 | B20: 2 | D20: 659298 | E20: 1 | G20: 667654 | H20: 1 | M20: 513517 | N20: 22
A21: 553982 | B21: 1 | D21: 659476 | E21: 1 | G21: 667707 | H21: 1 | M21: 0確認(L2) | N21: 1
A22: 554081 | B22: 1 | D22: 659681 | E22: 1 | G22: 667761 | H22: 1 | M22: ハズシ(L2) | N22: 2
A23: 554116 | B23: 4 | D23: 661339 | E23: 1 | G23: 668885 | H23: 1 | M23: 棚 | N23: 19
A24: 554179 | B24: 2 | D24: 662507 | E24: 1 | G24: 678615 | H24: 1 | M24: 514311 | N24: 2
A25: 554286 | B25: 1 | D25: 662525 | E25: 1 | G25: 683912 | H25: 1 | M25: 棚 | N25: 2
A26: 554295 | B26: 3 | D26: 662543 | E26: 1 | G26: 683921 | H26: 1 | M26: 517415 | N26: 1
A27: 554446 | B27: 1 | D27: 666192 | E27: 1 | G27: 683948 | H27: 1 | M27: 棚 | N27: 1
A28: 569056 | B28: 3 | D28: 666798 | E28: 1 | G28: 684368 | H28: 1 | M28: 530035 | N28: 4
A29: 578046 | B29: 4 | D29: 666824 | E29: 1 | G29: 690896 | H29: 1 | M29: 棚 | N29: 4
A30: 581354 | B30: 2 | D30: 667627 | E30: 1 | G30: 735812 | H30: 1 | M30: 534806 | N30: 10
A31: 581399 | B31: 9 | D31: 667636 | E31: 2 | G31: 738293 | H31: 1 | M31: 3ライン倉庫 | N31: 1
A32: 581568 | B32: 2 | D32: 667645 | E32: 1 | G32: 901179 | H32: 1 | M32: ハズシ(L2) | N32: 1
A33: 581693 | B33: 4 | D33: 667654 | E33: 1 | G33: 906058 | H33: 1 | M33: 設備(L2) | N33: 1
A34: 581719 | B34: 1 | D34: 667672 | E34: 1 | G34: 906459 | H34: 1 | M34: 棚 | N34: 6
A35: 581728 | B35: 5 | D35: 667681 | E35: 1 | G35: 906468 | H35: 1 | M35: 設備(L3) | N35: 1
A36: 581755 | B36: 1 | D36: 667699 | E36: 1 | G36: 906619 | H36: 1 | M36: 536172 | N36: 3
A37: 582112 | B37: 1 | D37: 667707 | E37: 1 | G37: 906664 | H37: 1 | M37: 棚 | N37: 3
A38: 582139 | B38: 18 | D38: 667725 | E38: 1 | G38: 906708 | H38: 1 | M38: 542735 | N38: 4
A39: 582148 | B39: 9 | D39: 667734 | E39: 2 | G39: 906717 | H39: 1 | M39: 棚 | N39: 4
A40: 582157 | B40: 3 | D40: 667743 | E40: 1 | G40: 906726 | H40: 1 | M40: 546143 | N40: 2
A41: 582166 | B41: 12 | D41: 667752 | E41: 2 | G41: 906789 | H41: 1 | M41: 棚 | N41: 2
...

Sheet Egproと比較
A3: 行ラベル | B3: 合計 / L1必要リール数(切り上げ) | E3: 必要 | F3: 在庫 | G3: 現場倉庫 | H3: 設備 | I3: 外し | J3: 不足
A4: 513517 | B4: 0 | E4: =SUM(B4:D4) -> 0 | F4: =_xlfn.XLOOKUP(A4,倉庫piv!$A:$A,倉庫piv!$B:$B) -> 19 | G4: =_xlfn.XLOOKUP(A4,倉庫piv!$D:$D,倉庫piv!$E:$E,0) -> 0 | H4: =_xlfn.XLOOKUP(A4,倉庫piv!$G:$G,倉庫piv!$H:$H,0) -> 0 | I4: =_xlfn.XLOOKUP(A4,倉庫piv!$J:$J,倉庫piv!$K:$K,0) -> 0 | J4: =F4-E4 -> 19
A5: 534806 | B5: 0 | E5: =SUM(B5:D5) -> 0 | F5: =_xlfn.XLOOKUP(A5,倉庫piv!$A:$A,倉庫piv!$B:$B) -> 6 | G5: =_xlfn.XLOOKUP(A5,倉庫piv!$D:$D,倉庫piv!$E:$E,0) -> 0 | H5: =_xlfn.XLOOKUP(A5,倉庫piv!$G:$G,倉庫piv!$H:$H,0) -> 0 | I5: =_xlfn.XLOOKUP(A5,倉庫piv!$J:$J,倉庫piv!$K:$K,0) -> 0 | J5: =F5-E5 -> 6
A6: 536172 | B6: 1 | E6: =SUM(B6:D6) -> 1 | F6: =_xlfn.XLOOKUP(A6,倉庫piv!$A:$A,倉庫piv!$B:$B) -> 3 | G6: =_xlfn.XLOOKUP(A6,倉庫piv!$D:$D,倉庫piv!$E:$E,0) -> 0 | H6: =_xlfn.XLOOKUP(A6,倉庫piv!$G:$G,倉庫piv!$H:$H,0) -> 0 | I6: =_xlfn.XLOOKUP(A6,倉庫piv!$J:$J,倉庫piv!$K:$K,0) -> 0 | J6: =F6-E6 -> 2
A7: 554116 | B7: 0 | E7: =SUM(B7:D7) -> 0 | F7: =_xlfn.XLOOKUP(A7,倉庫piv!$A:$A,倉庫piv!$B:$B) -> 4 | G7: =_xlfn.XLOOKUP(A7,倉庫piv!$D:$D,倉庫piv!$E:$E,0) -> 0 | H7: =_xlfn.XLOOKUP(A7,倉庫piv!$G:$G,倉庫piv!$H:$H,0) -> 0 | I7: =_xlfn.XLOOKUP(A7,倉庫piv!$J:$J,倉庫piv!$K:$K,0) -> 0 | J7: =F7-E7 -> 4
A8: 554179 | B8: 0 | E8: =SUM(B8:D8) -> 0 | F8: =_xlfn.XLOOKUP(A8,倉庫piv!$A:$A,倉庫piv!$B:$B) -> 2 | G8: =_xlfn.XLOOKUP(A8,倉庫piv!$D:$D,倉庫piv!$E:$E,0) -> 0 | H8: =_xlfn.XLOOKUP(A8,倉庫piv!$G:$G,倉庫piv!$H:$H,0) -> 0 | I8: =_xlfn.XLOOKUP(A8,倉庫piv!$J:$J,倉庫piv!$K:$K,0) -> 0 | J8: =F8-E8 -> 2
A9: 554295 | B9: 1 | E9: =SUM(B9:D9) -> 1 | F9: =_xlfn.XLOOKUP(A9,倉庫piv!$A:$A,倉庫piv!$B:$B) -> 3 | G9: =_xlfn.XLOOKUP(A9,倉庫piv!$D:$D,倉庫piv!$E:$E,0) -> 0 | H9: =_xlfn.XLOOKUP(A9,倉庫piv!$G:$G,倉庫piv!$H:$H,0) -> 0 | I9: =_xlfn.XLOOKUP(A9,倉庫piv!$J:$J,倉庫piv!$K:$K,0) -> 0 | J9: =F9-E9 -> 2
A10: 581399 | B10: 1 | E10: =SUM(B10:D10) -> 1 | F10: =_xlfn.XLOOKUP(A10,倉庫piv!$A:$A,倉庫piv!$B:$B) -> 9 | G10: =_xlfn.XLOOKUP(A10,倉庫piv!$D:$D,倉庫piv!$E:$E,0) -> 0 | H10: =_xlfn.XLOOKUP(A10,倉庫piv!$G:$G,倉庫piv!$H:$H,0) -> 0 | I10: =_xlfn.XLOOKUP(A10,倉庫piv!$J:$J,倉庫piv!$K:$K,0) -> 0 | J10: =F10-E10 -> 8
A11: 581568 | B11: 1 | E11: =SUM(B11:D11) -> 1 | F11: =_xlfn.XLOOKUP(A11,倉庫piv!$A:$A,倉庫piv!$B:$B) -> 2 | G11: =_xlfn.XLOOKUP(A11,倉庫piv!$D:$D,倉庫piv!$E:$E,0) -> 0 | H11: =_xlfn.XLOOKUP(A11,倉庫piv!$G:$G,倉庫piv!$H:$H,0) -> 0 | I11: =_xlfn.XLOOKUP(A11,倉庫piv!$J:$J,倉庫piv!$K:$K,0) -> 0 | J11: =F11-E11 -> 1
A12: 582139 | B12: 0 | E12: =SUM(B12:D12) -> 0 | F12: =_xlfn.XLOOKUP(A12,倉庫piv!$A:$A,倉庫piv!$B:$B) -> 18 | G12: =_xlfn.XLOOKUP(A12,倉庫piv!$D:$D,倉庫piv!$E:$E,0) -> 0 | H12: =_xlfn.XLOOKUP(A12,倉庫piv!$G:$G,倉庫piv!$H:$H,0) -> 0 | I12: =_xlfn.XLOOKUP(A12,倉庫piv!$J:$J,倉庫piv!$K:$K,0) -> 0 | J12: =F12-E12 -> 18
A13: 582228 | B13: 0 | E13: =SUM(B13:D13) -> 0 | F13: =_xlfn.XLOOKUP(A13,倉庫piv!$A:$A,倉庫piv!$B:$B) -> 10 | G13: =_xlfn.XLOOKUP(A13,倉庫piv!$D:$D,倉庫piv!$E:$E,0) -> 1 | H13: =_xlfn.XLOOKUP(A13,倉庫piv!$G:$G,倉庫piv!$H:$H,0) -> 0 | I13: =_xlfn.XLOOKUP(A13,倉庫piv!$J:$J,倉庫piv!$K:$K,0) -> 0 | J13: =F13-E13 -> 10
A14: 582709 | B14: 1 | E14: =SUM(B14:D14) -> 1 | F14: =_xlfn.XLOOKUP(A14,倉庫piv!$A:$A,倉庫piv!$B:$B) -> 3 | G14: =_xlfn.XLOOKUP(A14,倉庫piv!$D:$D,倉庫piv!$E:$E,0) -> 0 | H14: =_xlfn.XLOOKUP(A14,倉庫piv!$G:$G,倉庫piv!$H:$H,0) -> 0 | I14: =_xlfn.XLOOKUP(A14,倉庫piv!$J:$J,倉庫piv!$K:$K,0) -> 0 | J14: =F14-E14 -> 2
A15: 587535 | B15: 0 | E15: =SUM(B15:D15) -> 0 | F15: =_xlfn.XLOOKUP(A15,倉庫piv!$A:$A,倉庫piv!$B:$B) -> 15 | G15: =_xlfn.XLOOKUP(A15,倉庫piv!$D:$D,倉庫piv!$E:$E,0) -> 0 | H15: =_xlfn.XLOOKUP(A15,倉庫piv!$G:$G,倉庫piv!$H:$H,0) -> 0 | I15: =_xlfn.XLOOKUP(A15,倉庫piv!$J:$J,倉庫piv!$K:$K,0) -> 0 | J15: =F15-E15 -> 15
... A1050: 9000070327 | B1050: 1 | E1050: =SUM(B1050:D1050) -> 1 | F1050: =_xlfn.XLOOKUP(A1050,倉庫piv!$A:$A,倉庫piv!$B:$B) -> 1 | G1050: =_xlfn.XLOOKUP(A1050,倉庫piv!$D:$D,倉庫piv!$E:$E,0) -> 0 | H1050: =_xlfn.XLOOKUP(A1050,倉庫piv!$G:$G,倉庫piv!$H:$H,0) -> 0 | I1050: =_xlfn.XLOOKUP(A1050,倉庫piv!$J:$J,倉庫piv!$K:$K,0) -> 0 | J1050: =F1050-E1050 -> 0
A1051: 154468A | B1051: 0 | E1051: =SUM(B1051:D1051) -> 0 | F1051: =_xlfn.XLOOKUP(A1051,倉庫piv!$A:$A,倉庫piv!$B:$B) -> 4 | G1051: =_xlfn.XLOOKUP(A1051,倉庫piv!$D:$D,倉庫piv!$E:$E,0) -> 0 | H1051: =_xlfn.XLOOKUP(A1051,倉庫piv!$G:$G,倉庫piv!$H:$H,0) -> 0 | I1051: =_xlfn.XLOOKUP(A1051,倉庫piv!$J:$J,倉庫piv!$K:$K,0) -> 0 | J1051: =F1051-E1051 -> 4
A1052: 160096C | B1052: 0 | E1052: =SUM(B1052:D1052) -> 0 | F1052: =_xlfn.XLOOKUP(A1052,倉庫piv!$A:$A,倉庫piv!$B:$B) -> 17 | G1052: =_xlfn.XLOOKUP(A1052,倉庫piv!$D:$D,倉庫piv!$E:$E,0) -> 0 | H1052: =_xlfn.XLOOKUP(A1052,倉庫piv!$G:$G,倉庫piv!$H:$H,0) -> 1 | I1052: =_xlfn.XLOOKUP(A1052,倉庫piv!$J:$J,倉庫piv!$K:$K,0) -> 0 | J1052: =F1052-E1052 -> 17
A1053: 190954A | B1053: 0 | E1053: =SUM(B1053:D1053) -> 0 | F1053: =_xlfn.XLOOKUP(A1053,倉庫piv!$A:$A,倉庫piv!$B:$B) -> 18 | G1053: =_xlfn.XLOOKUP(A1053,倉庫piv!$D:$D,倉庫piv!$E:$E,0) -> 0 | H1053: =_xlfn.XLOOKUP(A1053,倉庫piv!$G:$G,倉庫piv!$H:$H,0) -> 0 | I1053: =_xlfn.XLOOKUP(A1053,倉庫piv!$J:$J,倉庫piv!$K:$K,0) -> 0 | J1053: =F1053-E1053 -> 18
A1054: 193202B | B1054: 0 | E1054: =SUM(B1054:D1054) -> 0 | F1054: =_xlfn.XLOOKUP(A1054,倉庫piv!$A:$A,倉庫piv!$B:$B) -> 9 | G1054: =_xlfn.XLOOKUP(A1054,倉庫piv!$D:$D,倉庫piv!$E:$E,0) -> 1 | H1054: =_xlfn.XLOOKUP(A1054,倉庫piv!$G:$G,倉庫piv!$H:$H,0) -> 0 | I1054: =_xlfn.XLOOKUP(A1054,倉庫piv!$J:$J,倉庫piv!$K:$K,0) -> 0 | J1054: =F1054-E1054 -> 9
A1055: 193211A | B1055: 0 | E1055: =SUM(B1055:D1055) -> 0 | F1055: =_xlfn.XLOOKUP(A1055,倉庫piv!$A:$A,倉庫piv!$B:$B) -> 6 | G1055: =_xlfn.XLOOKUP(A1055,倉庫piv!$D:$D,倉庫piv!$E:$E,0) -> 0 | H1055: =_xlfn.XLOOKUP(A1055,倉庫piv!$G:$G,倉庫piv!$H:$H,0) -> 0 | I1055: =_xlfn.XLOOKUP(A1055,倉庫piv!$J:$J,倉庫piv!$K:$K,0) -> 0 | J1055: =F1055-E1055 -> 6
A1056: 193238A | B1056: 0 | E1056: =SUM(B1056:D1056) -> 0 | F1056: =_xlfn.XLOOKUP(A1056,倉庫piv!$A:$A,倉庫piv!$B:$B) -> 10 | G1056: =_xlfn.XLOOKUP(A1056,倉庫piv!$D:$D,倉庫piv!$E:$E,0) -> 0 | H1056: =_xlfn.XLOOKUP(A1056,倉庫piv!$G:$G,倉庫piv!$H:$H,0) -> 0 | I1056: =_xlfn.XLOOKUP(A1056,倉庫piv!$J:$J,倉庫piv!$K:$K,0) -> 0 | J1056: =F1056-E1056 -> 10
A1057: 193247A | B1057: 0 | E1057: =SUM(B1057:D1057) -> 0 | F1057: =_xlfn.XLOOKUP(A1057,倉庫piv!$A:$A,倉庫piv!$B:$B) -> 3 | G1057: =_xlfn.XLOOKUP(A1057,倉庫piv!$D:$D,倉庫piv!$E:$E,0) -> 0 | H1057: =_xlfn.XLOOKUP(A1057,倉庫piv!$G:$G,倉庫piv!$H:$H,0) -> 0 | I1057: =_xlfn.XLOOKUP(A1057,倉庫piv!$J:$J,倉庫piv!$K:$K,0) -> 0 | J1057: =F1057-E1057 -> 3
A1058: 193274A | B1058: 0 | E1058: =SUM(B1058:D1058) -> 0 | F1058: =_xlfn.XLOOKUP(A1058,倉庫piv!$A:$A,倉庫piv!$B:$B) -> 15 | G1058: =_xlfn.XLOOKUP(A1058,倉庫piv!$D:$D,倉庫piv!$E:$E,0) -> 0 | H1058: =_xlfn.XLOOKUP(A1058,倉庫piv!$G:$G,倉庫piv!$H:$H,0) -> 0 | I1058: =_xlfn.XLOOKUP(A1058,倉庫piv!$J:$J,倉庫piv!$K:$K,0) -> 0 | J1058: =F1058-E1058 -> 15
A1059: 201346B | B1059: 0 | E1059: =SUM(B1059:D1059) -> 0 | F1059: =_xlfn.XLOOKUP(A1059,倉庫piv!$A:$A,倉庫piv!$B:$B) -> 5 | G1059: =_xlfn.XLOOKUP(A1059,倉庫piv!$D:$D,倉庫piv!$E:$E,0) -> 0 | H1059: =_xlfn.XLOOKUP(A1059,倉庫piv!$G:$G,倉庫piv!$H:$H,0) -> 0 | I1059: =_xlfn.XLOOKUP(A1059,倉庫piv!$J:$J,倉庫piv!$K:$K,0) -> 0 | J1059: =F1059-E1059 -> 5
A1060: 206858A | B1060: 0 | E1060: =SUM(B1060:D1060) -> 0 | F1060: =_xlfn.XLOOKUP(A1060,倉庫piv!$A:$A,倉庫piv!$B:$B) -> 2 | G1060: =_xlfn.XLOOKUP(A1060,倉庫piv!$D:$D,倉庫piv!$E:$E,0) -> 0 | H1060: =_xlfn.XLOOKUP(A1060,倉庫piv!$G:$G,倉庫piv!$H:$H,0) -> 0 | I1060: =_xlfn.XLOOKUP(A1060,倉庫piv!$J:$J,倉庫piv!$K:$K,0) -> 0 | J1060: =F1060-E1060 -> 2
A1061: 309756E | B1061: 0 | E1061: =SUM(B1061:D1061) -> 0 | F1061: =_xlfn.XLOOKUP(A1061,倉庫piv!$A:$A,倉庫piv!$B:$B) -> 9 | G1061: =_xlfn.XLOOKUP(A1061,倉庫piv!$D:$D,倉庫piv!$E:$E,0) -> 0 | H1061: =_xlfn.XLOOKUP(A1061,倉庫piv!$G:$G,倉庫piv!$H:$H,0) -> 0 | I1061: =_xlfn.XLOOKUP(A1061,倉庫piv!$J:$J,倉庫piv!$K:$K,0) -> 0 | J1061: =F1061-E1061 -> 9
A1062: 328726B | B1062: 0 | E1062: =SUM(B1062:D1062) -> 0 | F1062: =_xlfn.XLOOKUP(A1062,倉庫piv!$A:$A,倉庫piv!$B:$B) -> 5 | G1062: =_xlfn.XLOOKUP(A1062,倉庫piv!$D:$D,倉庫piv!$E:$E,0) -> 0 | H1062: =_xlfn.XLOOKUP(A1062,倉庫piv!$G:$G,倉庫piv!$H:$H,0) -> 0 | I1062: =_xlfn.XLOOKUP(A1062,倉庫piv!$J:$J,倉庫piv!$K:$K,0) -> 0 | J1062: =F1062-E1062 -> 5
... A1313: 総計 | B1313: 474 | E1313: =SUM(B1313:D1313) -> 474 | F1313: =_xlfn.XLOOKUP(A1313,倉庫piv!$A:$A,倉庫piv!$B:$B) -> 28105 | G1313: =_xlfn.XLOOKUP(A1313,倉庫piv!$D:$D,倉庫piv!$E:$E,0) -> 432 | H1313: =_xlfn.XLOOKUP(A1313,倉庫piv!$G:$G,倉庫piv!$H:$H,0) -> 166 | I1313: =_xlfn.XLOOKUP(A1313,倉庫piv!$J:$J,倉庫piv!$K:$K,0) -> 11 | J1313: =F1313-E1313 -> 27631

Sheet BASE
A1: 1リールあたりの数量 | B1: 部品 | C1: 形式 | D1: テープ幅 | E1: リールサイズ | F1: ノズル分類 | G1: マックドライ | H1: L1必要リール数 | I1: L2必要リール数 | J1: L3必要リール数 | K1: L1必要リール数(切り上げ) | L1: L2必要リール数(切り上げ) | M1: L3必要リール数(切り上げ)
A2: 500 | B2: 937202 | C2: テープ | D2: 56 | E2: 大 | F2: 4桁 | H2: 0 | I2: 0.048 | J2: 0 | K2: =ROUNDUP(テーブル1[[#This Row],[L1必要リール数]],0) -> 0 | L2: =ROUNDUP(テーブル1[[#This Row],[L2必要リール数]],0) -> 1 | M2: =ROUNDUP(テーブル1[[#This Row],[L3必要リール数]],0) -> 0
A3: 1000 | B3: 9000065097 | C3: テープ | D3: 56 | E3: 大 | F3: 4桁 | H3: 0 | I3: 0.048 | J3: 0 | K3: =ROUNDUP(テーブル1[[#This Row],[L1必要リール数]],0) -> 0 | L3: =ROUNDUP(テーブル1[[#This Row],[L2必要リール数]],0) -> 1 | M3: =ROUNDUP(テーブル1[[#This Row],[L3必要リール数]],0) -> 0
A4: 1000 | B4: 608014 | C4: テープ | D4: 44 | E4: 大 | F4: 4桁 | H4: 0 | I4: 0.024 | J4: 0 | K4: =ROUNDUP(テーブル1[[#This Row],[L1必要リール数]],0) -> 0 | L4: =ROUNDUP(テーブル1[[#This Row],[L2必要リール数]],0) -> 1 | M4: =ROUNDUP(テーブル1[[#This Row],[L3必要リール数]],0) -> 0
A5: 1000 | B5: 719073 | C5: テープ | D5: 44 | E5: 大 | F5: 4桁 | H5: 0 | I5: 0.048 | J5: 0 | K5: =ROUNDUP(テーブル1[[#This Row],[L1必要リール数]],0) -> 0 | L5: =ROUNDUP(テーブル1[[#This Row],[L2必要リール数]],0) -> 1 | M5: =ROUNDUP(テーブル1[[#This Row],[L3必要リール数]],0) -> 0
A6: 1500 | B6: 912924 | C6: テープ | D6: 44 | E6: 大 | F6: 4桁 | H6: 0 | I6: 0.064 | J6: 0 | K6: =ROUNDUP(テーブル1[[#This Row],[L1必要リール数]],0) -> 0 | L6: =ROUNDUP(テーブル1[[#This Row],[L2必要リール数]],0) -> 1 | M6: =ROUNDUP(テーブル1[[#This Row],[L3必要リール数]],0) -> 0
A7: 2000 | B7: 920336 | C7: テープ | D7: 44 | E7: 大 | F7: 4桁 | H7: 0 | I7: 0.055 | J7: 0.048 | K7: =ROUNDUP(テーブル1[[#This Row],[L1必要リール数]],0) -> 0 | L7: =ROUNDUP(テーブル1[[#This Row],[L2必要リール数]],0) -> 1 | M7: =ROUNDUP(テーブル1[[#This Row],[L3必要リール数]],0) -> 1
A8: 2000 | B8: 921665 | C8: テープ | D8: 44 | E8: 大 | F8: 4桁 | H8: 0.012 | I8: 0 | J8: 0 | K8: =ROUNDUP(テーブル1[[#This Row],[L1必要リール数]],0) -> 1 | L8: =ROUNDUP(テーブル1[[#This Row],[L2必要リール数]],0) -> 0 | M8: =ROUNDUP(テーブル1[[#This Row],[L3必要リール数]],0) -> 0
A9: 5000 | B9: 922414 | C9: テープ | D9: 44 | E9: 大 | F9: 4桁 | H9: 0.0048 | I9: 0 | J9: 0 | K9: =ROUNDUP(テーブル1[[#This Row],[L1必要リール数]],0) -> 1 | L9: =ROUNDUP(テーブル1[[#This Row],[L2必要リール数]],0) -> 0 | M9: =ROUNDUP(テーブル1[[#This Row],[L3必要リール数]],0) -> 0
A10: 1000 | B10: 9000002588 | C10: テープ | D10: 44 | E10: 大 | F10: 4桁 | H10: 0 | I10: 0.024 | J10: 0 | K10: =ROUNDUP(テーブル1[[#This Row],[L1必要リール数]],0) -> 0 | L10: =ROUNDUP(テーブル1[[#This Row],[L2必要リール数]],0) -> 1 | M10: =ROUNDUP(テーブル1[[#This Row],[L3必要リール数]],0) -> 0
A11: 1000 | B11: 9000046816 | C11: テープ | D11: 44 | E11: 大 | F11: 4桁 | H11: 0 | I11: 0.096 | J11: 0 | K11: =ROUNDUP(テーブル1[[#This Row],[L1必要リール数]],0) -> 0 | L11: =ROUNDUP(テーブル1[[#This Row],[L2必要リール数]],0) -> 1 | M11: =ROUNDUP(テーブル1[[#This Row],[L3必要リール数]],0) -> 0
A12: 800 | B12: 9000046834 | C12: テープ | D12: 44 | E12: 大 | F12: 4桁 | H12: 0 | I12: 0.12 | J12: 0 | K12: =ROUNDUP(テーブル1[[#This Row],[L1必要リール数]],0) -> 0 | L12: =ROUNDUP(テーブル1[[#This Row],[L2必要リール数]],0) -> 1 | M12: =ROUNDUP(テーブル1[[#This Row],[L3必要リール数]],0) -> 0
A13: 5000 | B13: 9000047067 | C13: テープ | D13: 44 | E13: 大 | F13: 4桁 | H13: 0.0192 | I13: 0 | J13: 0 | K13: =ROUNDUP(テーブル1[[#This Row],[L1必要リール数]],0) -> 1 | L13: =ROUNDUP(テーブル1[[#This Row],[L2必要リール数]],0) -> 0 | M13: =ROUNDUP(テーブル1[[#This Row],[L3必要リール数]],0) -> 0
... A27: 200 | B27: 9000069182 | C27: テープ | D27: 44 | E27: 大 | F27: 4桁 | H27: 0 | I27: 0.96 | J27: 0 | K27: =ROUNDUP(テーブル1[[#This Row],[L1必要リール数]],0) -> 0 | L27: =ROUNDUP(テーブル1[[#This Row],[L2必要リール数]],0) -> 1 | M27: =ROUNDUP(テーブル1[[#This Row],[L3必要リール数]],0) -> 0
A28: 1000 | B28: 547472A | C28: テープ | D28: 44 | E28: 大 | F28: 4桁 | H28: 0 | I28: 0.15 | J28: 0 | K28: =ROUNDUP(テーブル1[[#This Row],[L1必要リール数]],0) -> 0 | L28: =ROUNDUP(テーブル1[[#This Row],[L2必要リール数]],0) -> 1 | M28: =ROUNDUP(テーブル1[[#This Row],[L3必要リール数]],0) -> 0
A29: 450 | B29: 911578B | C29: テープ | D29: 44 | E29: 大 | F29: 4桁 | H29: 0 | I29: 0.32 | J29: 0 | K29: =ROUNDUP(テーブル1[[#This Row],[L1必要リール数]],0) -> 0 | L29: =ROUNDUP(テーブル1[[#This Row],[L2必要リール数]],0) -> 1 | M29: =ROUNDUP(テーブル1[[#This Row],[L3必要リール数]],0) -> 0
A30: 1000 | B30: 937194 | C30: テープ | D30: 32 | E30: 大 | F30: 4桁 | H30: 0 | I30: 0.024 | J30: 0 | K30: =ROUNDUP(テーブル1[[#This Row],[L1必要リール数]],0) -> 0 | L30: =ROUNDUP(テーブル1[[#This Row],[L2必要リール数]],0) -> 1 | M30: =ROUNDUP(テーブル1[[#This Row],[L3必要リール数]],0) -> 0
A31: 500 | B31: 937666 | C31: テープ | D31: 32 | E31: 大 | F31: 4桁 | H31: 0 | I31: 0.336 | J31: 0 | K31: =ROUNDUP(テーブル1[[#This Row],[L1必要リール数]],0) -> 0 | L31: =ROUNDUP(テーブル1[[#This Row],[L2必要リール数]],0) -> 1 | M31: =ROUNDUP(テーブル1[[#This Row],[L3必要リール数]],0) -> 0
A32: 500 | B32: 937675 | C32: テープ | D32: 32 | E32: 大 | F32: 4桁 | H32: 0 | I32: 0.144 | J32: 0 | K32: =ROUNDUP(テーブル1[[#This Row],[L1必要リール数]],0) -> 0 | L32: =ROUNDUP(テーブル1[[#This Row],[L2必要リール数]],0) -> 1 | M32: =ROUNDUP(テーブル1[[#This Row],[L3必要リール数]],0) -> 0
A33: 2000 | B33: 9000001152 | C33: テープ | D33: 32 | E33: 大 | F33: 4桁 | H33: 0 | I33: 0.086 | J33: 0.096 | K33: =ROUNDUP(テーブル1[[#This Row],[L1必要リール数]],0) -> 0 | L33: =ROUNDUP(テーブル1[[#This Row],[L2必要リール数]],0) -> 1 | M33: =ROUNDUP(テーブル1[[#This Row],[L3必要リール数]],0) -> 1
A34: 1100 | B34: 9000003114 | C34: テープ | D34: 32 | E34: 大 | F34: 4桁 | H34: 0 | I34: 0.043636364 | J34: 0 | K34: =ROUNDUP(テーブル1[[#This Row],[L1必要リール数]],0) -> 0 | L34: =ROUNDUP(テーブル1[[#This Row],[L2必要リール数]],0) -> 1 | M34: =ROUNDUP(テーブル1[[#This Row],[L3必要リール数]],0) -> 0
A35: 800 | B35: 9000003132 | C35: テープ | D35: 32 | E35: 大 | F35: 4桁 | H35: 0 | I35: 0.3675 | J35: 0 | K35: =ROUNDUP(テーブル1[[#This Row],[L1必要リール数]],0) -> 0 | L35: =ROUNDUP(テーブル1[[#This Row],[L2必要リール数]],0) -> 1 | M35: =ROUNDUP(テーブル1[[#This Row],[L3必要リール数]],0) -> 0
A36: 1300 | B36: 9000003141 | C36: テープ | D36: 32 | E36: 大 | F36: 4桁 | H36: 0 | I36: 0.073846154 | J36: 0 | K36: =ROUNDUP(テーブル1[[#This Row],[L1必要リール数]],0) -> 0 | L36: =ROUNDUP(テーブル1[[#This Row],[L2必要リール数]],0) -> 1 | M36: =ROUNDUP(テーブル1[[#This Row],[L3必要リール数]],0) -> 0
A37: 500 | B37: 9000005585 | C37: テープ | D37: 32 | E37: 大 | F37: 4桁 | H37: 0 | I37: 0.048 | J37: 0 | K37: =ROUNDUP(テーブル1[[#This Row],[L1必要リール数]],0) -> 0 | L37: =ROUNDUP(テーブル1[[#This Row],[L2必要リール数]],0) -> 1 | M37: =ROUNDUP(テーブル1[[#This Row],[L3必要リール数]],0) -> 0
A38: 1100 | B38: 9000006031 | C38: テープ | D38: 32 | E38: 大 | F38: 4桁 | H38: 0 | I38: 0.021818182 | J38: 0 | K38: =ROUNDUP(テーブル1[[#This Row],[L1必要リール数]],0) -> 0 | L38: =ROUNDUP(テーブル1[[#This Row],[L2必要リール数]],0) -> 1 | M38: =ROUNDUP(テーブル1[[#This Row],[L3必要リール数]],0) -> 0
A39: 1000 | B39: 9000056859 | C39: テープ | D39: 32 | E39: 大 | F39: 4桁 | H39: 0.192 | I39: 0 | J39: 0 | K39: =ROUNDUP(テーブル1[[#This Row],[L1必要リール数]],0) -> 1 | L39: =ROUNDUP(テーブル1[[#This Row],[L2必要リール数]],0) -> 0 | M39: =ROUNDUP(テーブル1[[#This Row],[L3必要リール数]],0) -> 0
A40: 200 | B40: 9000057279 | C40: テープ | D40: 32 | E40: 大 | F40: 4桁 | H40: 0 | I40: 0.24 | J40: 11.41 | K40: =ROUNDUP(テーブル1[[#This Row],[L1必要リール数]],0) -> 0 | L40: =ROUNDUP(テーブル1[[#This Row],[L2必要リール数]],0) -> 1 | M40: =ROUNDUP(テーブル1[[#This Row],[L3必要リール数]],0) -> 12
A41: 1400 | B41: 9000059207 | C41: テープ | D41: 32 | E41: 大 | F41: 4桁 | H41: 0 | I41: 0 | J41: 1.1157143 | K41: =ROUNDUP(テーブル1[[#This Row],[L1必要リール数]],0) -> 0 | L41: =ROUNDUP(テーブル1[[#This Row],[L2必要リール数]],0) -> 0 | M41: =ROUNDUP(テーブル1[[#This Row],[L3必要リール数]],0) -> 2
... A45: 250 | B45: 9000069183 | C45: テープ | D45: 32 | E45: 大 | F45: 4桁 | H45: 0 | I45: 0.192 | J45: 0 | K45: =ROUNDUP(テーブル1[[#This Row],[L1必要リール数]],0) -> 0 | L45: =ROUNDUP(テーブル1[[#This Row],[L2必要リール数]],0) -> 1 | M45: =ROUNDUP(テーブル1[[#This Row],[L3必要リール数]],0) -> 0
A46: 200 | B46: 568752A | C46: テープ | D46: 32 | E46: 大 | F46: 4桁 | H46: 0 | I46: 0.36 | J46: 0 | K46: =ROUNDUP(テーブル1[[#This Row],[L1必要リール数]],0) -> 0 | L46: =ROUNDUP(テーブル1[[#This Row],[L2必要リール数]],0) -> 1 | M46: =ROUNDUP(テーブル1[[#This Row],[L3必要リール数]],0) -> 0
A47: 1250 | B47: 661099A | C47: テープ | D47: 32 | E47: 大 | F47: 4桁 | H47: 0 | I47: 0.048 | J47: 0 | K47: =ROUNDUP(テーブル1[[#This Row],[L1必要リール数]],0) -> 0 | L47: =ROUNDUP(テーブル1[[#This Row],[L2必要リール数]],0) -> 1 | M47: =ROUNDUP(テーブル1[[#This Row],[L3必要リール数]],0) -> 0
A48: 1000 | B48: 659369 | C48: テープ | D48: 24 | E48: 大 | F48: 4桁 | H48: 0.048 | I48: 0 | J48: 0 | K48: =ROUNDUP(テーブル1[[#This Row],[L1必要リール数]],0) -> 1 | L48: =ROUNDUP(テーブル1[[#This Row],[L2必要リール数]],0) -> 0 | M48: =ROUNDUP(テーブル1[[#This Row],[L3必要リール数]],0) -> 0
A49: 400 | B49: 664425 | C49: テープ | D49: 24 | E49: 大 | F49: 4桁 | H49: 0 | I49: 0.15 | J49: 0 | K49: =ROUNDUP(テーブル1[[#This Row],[L1必要リール数]],0) -> 0 | L49: =ROUNDUP(テーブル1[[#This Row],[L2必要リール数]],0) -> 1 | M49: =ROUNDUP(テーブル1[[#This Row],[L3必要リール数]],0) -> 0
A50: 400 | B50: 716486 | C50: テープ | D50: 24 | E50: 大 | F50: 4桁 | G50: マックドライ | H50: 0 | I50: 0.3 | J50: 0 | K50: =ROUNDUP(テーブル1[[#This Row],[L1必要リール数]],0) -> 0 | L50: =ROUNDUP(テーブル1[[#This Row],[L2必要リール数]],0) -> 1 | M50: =ROUNDUP(テーブル1[[#This Row],[L3必要リール数]],0) -> 0
A51: 500 | B51: 910213 | C51: テープ | D51: 24 | E51: 大 | F51: 4桁 | H51: 0 | I51: 0 | J51: 3.808 | K51: =ROUNDUP(テーブル1[[#This Row],[L1必要リール数]],0) -> 0 | L51: =ROUNDUP(テーブル1[[#This Row],[L2必要リール数]],0) -> 0 | M51: =ROUNDUP(テーブル1[[#This Row],[L3必要リール数]],0) -> 4
A52: 400 | B52: 911426 | C52: テープ | D52: 24 | E52: 大 | F52: 4桁 | H52: 0 | I52: 0.06 | J52: 0 | K52: =ROUNDUP(テーブル1[[#This Row],[L1必要リール数]],0) -> 0 | L52: =ROUNDUP(テーブル1[[#This Row],[L2必要リール数]],0) -> 1 | M52: =ROUNDUP(テーブル1[[#This Row],[L3必要リール数]],0) -> 0
A53: 500 | B53: 915663 | C53: テープ | D53: 24 | E53: 大 | F53: 4桁 | H53: 0 | I53: 3.012 | J53: 0 | K53: =ROUNDUP(テーブル1[[#This Row],[L1必要リール数]],0) -> 0 | L53: =ROUNDUP(テーブル1[[#This Row],[L2必要リール数]],0) -> 4 | M53: =ROUNDUP(テーブル1[[#This Row],[L3必要リール数]],0) -> 0
A54: 500 | B54: 917607 | C54: テープ | D54: 24 | E54: 大 | F54: 4桁 | H54: 0 | I54: 0.192 | J54: 6.248 | K54: =ROUNDUP(テーブル1[[#This Row],[L1必要リール数]],0) -> 0 | L54: =ROUNDUP(テーブル1[[#This Row],[L2必要リール数]],0) -> 1 | M54: =ROUNDUP(テーブル1[[#This Row],[L3必要リール数]],0) -> 7
A55: 500 | B55: 917616 | C55: テープ | D55: 24 | E55: 大 | F55: 4桁 | H55: 0 | I55: 0.768 | J55: 0 | K55: =ROUNDUP(テーブル1[[#This Row],[L1必要リール数]],0) -> 0 | L55: =ROUNDUP(テーブル1[[#This Row],[L2必要リール数]],0) -> 1 | M55: =ROUNDUP(テーブル1[[#This Row],[L3必要リール数]],0) -> 0
A56: 500 | B56: 917625 | C56: テープ | D56: 24 | E56: 大 | F56: 4桁 | H56: 0 | I56: 0.096 | J56: 0 | K56: =ROUNDUP(テーブル1[[#This Row],[L1必要リール数]],0) -> 0 | L56: =ROUNDUP(テーブル1[[#This Row],[L2必要リール数]],0) -> 1 | M56: =ROUNDUP(テーブル1[[#This Row],[L3必要リール数]],0) -> 0
...

Sheet →修正必要

Sheet L1
A1: 1リールあたりの数量 | B1: 部品 | C1: 形式 | D1: テープ幅 | E1: リールサイズ | F1: ノズル分類 | G1: マックドライ | H1: L1必要リール数 | I1: L1必要リール数(切り上げ)
A2: 2000 | B2: 921665 | C2: テープ | D2: 44 | E2: 大 | F2: 4桁 | H2: 0.012 | I2: =_xlfn.CEILING.MATH(テーブル15[[#This Row],[L1必要リール数]]) -> 1
A3: 5000 | B3: 922414 | C3: テープ | D3: 44 | E3: 大 | F3: 4桁 | H3: 0.0048 | I3: =_xlfn.CEILING.MATH(テーブル15[[#This Row],[L1必要リール数]]) -> 1
A4: 5000 | B4: 9000047067 | C4: テープ | D4: 44 | E4: 大 | F4: 4桁 | H4: 0.0192 | I4: =_xlfn.CEILING.MATH(テーブル15[[#This Row],[L1必要リール数]]) -> 1
A5: 1000 | B5: 9000056859 | C5: テープ | D5: 32 | E5: 大 | F5: 4桁 | H5: 0.192 | I5: =_xlfn.CEILING.MATH(テーブル15[[#This Row],[L1必要リール数]]) -> 1
A6: 1000 | B6: 659369 | C6: テープ | D6: 24 | E6: 大 | F6: 4桁 | G6: マックドライ | H6: 0.048 | I6: =_xlfn.CEILING.MATH(テーブル15[[#This Row],[L1必要リール数]]) -> 1
A7: 1000 | B7: 9000031565 | C7: テープ | D7: 24 | E7: 大 | F7: 4桁 | H7: 0.24 | I7: =_xlfn.CEILING.MATH(テーブル15[[#This Row],[L1必要リール数]]) -> 1
A8: 950 | B8: 9000031574 | C8: テープ | D8: 24 | E8: 大 | F8: 4桁 | H8: 0.25263158 | I8: =_xlfn.CEILING.MATH(テーブル15[[#This Row],[L1必要リール数]]) -> 1
A9: 5000 | B9: 9000047076 | C9: テープ | D9: 24 | E9: 大 | F9: 4桁 | H9: 0.1212 | I9: =_xlfn.CEILING.MATH(テーブル15[[#This Row],[L1必要リール数]]) -> 1
A10: 5000 | B10: 9000056324 | C10: テープ | D10: 24 | E10: 大 | F10: 4桁 | H10: 0.0496 | I10: =_xlfn.CEILING.MATH(テーブル15[[#This Row],[L1必要リール数]]) -> 1
A11: 3500 | B11: 9000056333 | C11: テープ | D11: 24 | E11: 大 | F11: 4桁 | H11: 0.084571429 | I11: =_xlfn.CEILING.MATH(テーブル15[[#This Row],[L1必要リール数]]) -> 1
A12: 5000 | B12: 9000056841 | C12: テープ | D12: 24 | E12: 大 | F12: 4桁 | H12: 0.0192 | I12: =_xlfn.CEILING.MATH(テーブル15[[#This Row],[L1必要リール数]]) -> 1
A13: 5000 | B13: 9000058133 | C13: テープ | D13: 24 | E13: 大 | F13: 4桁 | H13: 0.0192 | I13: =_xlfn.CEILING.MATH(テーブル15[[#This Row],[L1必要リール数]]) -> 1
A14: 500 | B14: 9000063376 | C14: テープ | D14: 24 | E14: 大 | F14: 4桁 | H14: 0.24 | I14: =_xlfn.CEILING.MATH(テーブル15[[#This Row],[L1必要リール数]]) -> 1
A15: 2000 | B15: 9000070060 | C15: テープ | D15: 24 | E15: 大 | F15: 4桁 | H15: 0.246 | I15: =_xlfn.CEILING.MATH(テーブル15[[#This Row],[L1必要リール数]]) -> 1
A16: 1500 | B16: 682584B | C16: テープ | D16: 24 | E16: 大 | F16: 4桁 | H16: 0.256 | I16: =_xlfn.CEILING.MATH(テーブル15[[#This Row],[L1必要リール数]]) -> 1
A17: 1000 | B17: 9000026232A | C17: テープ | D17: 24 | E17: 大 | F17: 4桁 | H17: 0.336 | I17: =_xlfn.CEILING.MATH(テーブル15[[#This Row],[L1必要リール数]]) -> 1
A18: 2500 | B18: 906735 | C18: テープ | D18: 16 | E18: 大 | F18: 3桁 | H18: 0.0096 | I18: =_xlfn.CEILING.MATH(テーブル15[[#This Row],[L1必要リール数]]) -> 1
A19: 400 | B19: 939637 | C19: テープ | D19: 16 | E19: 大 | F19: 3桁 | H19: 1.845 | I19: =_xlfn.CEILING.MATH(テーブル15[[#This Row],[L1必要リール数]]) -> 2
A20: 2000 | B20: 9000011007 | C20: テープ | D20: 16 | E20: 大 | F20: 3桁 | H20: 0.12 | I20: =_xlfn.CEILING.MATH(テーブル15[[#This Row],[L1必要リール数]]) -> 1
A21: 2500 | B21: 9000023984 | C21: テープ | D21: 16 | E21: 小/大 | F21: 3桁 | H21: 0.096 | I21: =_xlfn.CEILING.MATH(テーブル15[[#This Row],[L1必要リール数]]) -> 1
A22: 2500 | B22: 9000024555 | C22: テープ | D22: 16 | E22: 大 | F22: 3桁 | H22: 0.1728 | I22: =_xlfn.CEILING.MATH(テーブル15[[#This Row],[L1必要リール数]]) -> 1
A23: 2000 | B23: 9000036952 | C23: テープ | D23: 16 | E23: 大 | F23: 4桁 | H23: 0.012 | I23: =_xlfn.CEILING.MATH(テーブル15[[#This Row],[L1必要リール数]]) -> 1
A24: 5000 | B24: 9000047548 | C24: テープ | D24: 16 | E24: 大 | F24: 4桁 | H24: 0.0588 | I24: =_xlfn.CEILING.MATH(テーブル15[[#This Row],[L1必要リール数]]) -> 1
A25: 4500 | B25: 9000056173 | C25: テープ | D25: 16 | E25: 大 | F25: 4桁 | H25: 0.023111111 | I25: =_xlfn.CEILING.MATH(テーブル15[[#This Row],[L1必要リール数]]) -> 1
A26: 1800 | B26: 9000057977 | C26: テープ | D26: 16 | E26: 大 | F26: 4桁 | H26: 0.10666667 | I26: =_xlfn.CEILING.MATH(テーブル15[[#This Row],[L1必要リール数]]) -> 1
A27: 2499 | B27: 9000058875 | C27: テープ | D27: 16 | E27: 大 | F27: 4桁 | H27: 0.038415366 | I27: =_xlfn.CEILING.MATH(テーブル15[[#This Row],[L1必要リール数]]) -> 1
A28: 4701 | B28: 9000060354 | C28: テープ | D28: 16 | E28: 大 | F28: 4桁 | H28: 0.0051052967 | I28: =_xlfn.CEILING.MATH(テーブル15[[#This Row],[L1必要リール数]]) -> 1
A29: 2702 | B29: 9000060397 | C29: テープ | D29: 16 | E29: 大 | F29: 3桁 | H29: 0.0088823094 | I29: =_xlfn.CEILING.MATH(テーブル15[[#This Row],[L1必要リール数]]) -> 1
... A33: 1000 | B33: 9000067967 | C33: テープ | D33: 16 | E33: 小/大 | F33: 3桁 | H33: 0.252 | I33: =_xlfn.CEILING.MATH(テーブル15[[#This Row],[L1必要リール数]]) -> 1
A34: 500 | B34: 655408A | C34: テープ | D34: 16 | E34: 大 | F34: 3桁 | H34: 0.24 | I34: =_xlfn.CEILING.MATH(テーブル15[[#This Row],[L1必要リール数]]) -> 1
A35: 2000 | B35: 680826A | C35: テープ | D35: 16 | E35: 大 | F35: 4桁 | H35: 0.315 | I35: =_xlfn.CEILING.MATH(テーブル15[[#This Row],[L1必要リール数]]) -> 1
A36: 1000 | B36: 938023A | C36: テープ | D36: 16 | E36: 小 | F36: 3桁 | H36: 0.24 | I36: =_xlfn.CEILING.MATH(テーブル15[[#This Row],[L1必要リール数]]) -> 1
A37: 2500 | B37: 581399 | C37: テープ | D37: 12 | E37: 大 | F37: 3桁 | H37: 0.2304 | I37: =_xlfn.CEILING.MATH(テーブル15[[#This Row],[L1必要リール数]]) -> 1
A38: 2500 | B38: 581568 | C38: テープ | D38: 12 | E38: 大 | F38: 3桁 | H38: 0.0192 | I38: =_xlfn.CEILING.MATH(テーブル15[[#This Row],[L1必要リール数]]) -> 1
A39: 2000 | B39: 675039 | C39: テープ | D39: 12 | E39: 大 | F39: 3桁 | H39: 0.06 | I39: =_xlfn.CEILING.MATH(テーブル15[[#This Row],[L1必要リール数]]) -> 1
A40: 4000 | B40: 677269 | C40: テープ | D40: 12 | E40: 小 | F40: 3桁 | H40: 0.636 | I40: =_xlfn.CEILING.MATH(テーブル15[[#This Row],[L1必要リール数]]) -> 1
A41: 3000 | B41: 684359 | C41: テープ | D41: 12 | E41: 大 | F41: 3桁 | H41: 0.184 | I41: =_xlfn.CEILING.MATH(テーブル15[[#This Row],[L1必要リール数]]) -> 1
A42: 4500 | B42: 690673 | C42: テープ | D42: 12 | E42: 大 | F42: 3桁 | H42: 0.056 | I42: =_xlfn.CEILING.MATH(テーブル15[[#This Row],[L1必要リール数]]) -> 1
A43: 2000 | B43: 692742 | C43: テープ | D43: 12 | E43: 大 | F43: 3桁 | H43: 0.36 | I43: =_xlfn.CEILING.MATH(テーブル15[[#This Row],[L1必要リール数]]) -> 1
...

Sheet L1 piv
A3: 行ラベル | B3: 合計 / L1必要リール数(切り上げ)
B4: 436
A5: テープ | B5: 427
A6: 3桁 | B6: 395
A7: 8 | B7: 322
A8: 小 | B8: 313
A9: 小/大 | B9: 6
A10: 大 | B10: 3
A11: 12 | B11: 61
A12: 小 | B12: 22
A13: 小/大 | B13: 3
A14: 大 | B14: 36
A15: 16 | B15: 12
A16: 小 | B16: 2
A17: 小/大 | B17: 3
A18: 大 | B18: 7
A19: 4桁 | B19: 32
A20: 8 | B20: 6
A21: 小 | B21: 6
A22: 12 | B22: 3
A23: 小 | B23: 1
A24: 大 | B24: 2
A25: 16 | B25: 8
A26: 大 | B26: 8
A27: 24 | B27: 11
A28: 大 | B28: 11
A29: 32 | B29: 1
A30: 大 | B30: 1
A31: 44 | B31: 3
A32: 大 | B32: 3
A33: トレイ | B33: 9
A34: マックドライ | B34: 38
A35: 総計 | B35: 474

Sheet L2
A1: 1リールあたりの数量 | B1: 部品 | C1: 形式 | D1: テープ幅 | E1: リールサイズ | F1: ノズル分類 | G1: マックドライ | H1: L2必要リール数 | I1: L2必要リール数(切り上げ)
A2: 500 | B2: 937202 | C2: テープ | D2: 56 | E2: 大 | F2: 4桁 | G2: マックドライ | H2: 0.048 | I2: =_xlfn.CEILING.MATH(テーブル14[[#This Row],[L2必要リール数]]) -> 1
A3: 1000 | B3: 9000065097 | C3: テープ | D3: 56 | E3: 大 | F3: 4桁 | H3: 0.048 | I3: =_xlfn.CEILING.MATH(テーブル14[[#This Row],[L2必要リール数]]) -> 1
A4: 1000 | B4: 608014 | C4: テープ | D4: 44 | E4: 大 | F4: 4桁 | H4: 0.024 | I4: =_xlfn.CEILING.MATH(テーブル14[[#This Row],[L2必要リール数]]) -> 1
A5: 1000 | B5: 719073 | C5: テープ | D5: 44 | E5: 大 | F5: 4桁 | H5: 0.048 | I5: =_xlfn.CEILING.MATH(テーブル14[[#This Row],[L2必要リール数]]) -> 1
A6: 1500 | B6: 912924 | C6: テープ | D6: 44 | E6: 大 | F6: 4桁 | H6: 0.064 | I6: =_xlfn.CEILING.MATH(テーブル14[[#This Row],[L2必要リール数]]) -> 1
A7: 2000 | B7: 920336 | C7: テープ | D7: 44 | E7: 大 | F7: 4桁 | H7: 0.055 | I7: =_xlfn.CEILING.MATH(テーブル14[[#This Row],[L2必要リール数]]) -> 1
A8: 1000 | B8: 9000002588 | C8: テープ | D8: 44 | E8: 大 | F8: 4桁 | H8: 0.024 | I8: =_xlfn.CEILING.MATH(テーブル14[[#This Row],[L2必要リール数]]) -> 1
A9: 1000 | B9: 9000046816 | C9: テープ | D9: 44 | E9: 大 | F9: 4桁 | H9: 0.096 | I9: =_xlfn.CEILING.MATH(テーブル14[[#This Row],[L2必要リール数]]) -> 1
A10: 800 | B10: 9000046834 | C10: テープ | D10: 44 | E10: 大 | F10: 4桁 | H10: 0.12 | I10: =_xlfn.CEILING.MATH(テーブル14[[#This Row],[L2必要リール数]]) -> 1
A11: 900 | B11: 9000047441 | C11: テープ | D11: 44 | E11: 大 | F11: 4桁 | H11: 0.26666667 | I11: =_xlfn.CEILING.MATH(テーブル14[[#This Row],[L2必要リール数]]) -> 1
A12: 800 | B12: 9000052943 | C12: テープ | D12: 44 | E12: 大 | F12: 4桁 | H12: 0.24 | I12: =_xlfn.CEILING.MATH(テーブル14[[#This Row],[L2必要リール数]]) -> 1
A13: 650 | B13: 9000052961 | C13: テープ | D13: 44 | E13: 大 | F13: 4桁 | H13: 0.88615385 | I13: =_xlfn.CEILING.MATH(テーブル14[[#This Row],[L2必要リール数]]) -> 1
A14: 350 | B14: 9000054442 | C14: テープ | D14: 44 | E14: 大 | F14: 4桁 | H14: 0.13714286 | I14: =_xlfn.CEILING.MATH(テーブル14[[#This Row],[L2必要リール数]]) -> 1
... A23: 200 | B23: 9000069182 | C23: テープ | D23: 44 | E23: 大 | F23: 4桁 | H23: 0.96 | I23: =_xlfn.CEILING.MATH(テーブル14[[#This Row],[L2必要リール数]]) -> 1
A24: 1000 | B24: 547472A | C24: テープ | D24: 44 | E24: 大 | F24: 4桁 | H24: 0.15 | I24: =_xlfn.CEILING.MATH(テーブル14[[#This Row],[L2必要リール数]]) -> 1
A25: 450 | B25: 911578B | C25: テープ | D25: 44 | E25: 大 | F25: 4桁 | H25: 0.32 | I25: =_xlfn.CEILING.MATH(テーブル14[[#This Row],[L2必要リール数]]) -> 1
A26: 1000 | B26: 937194 | C26: テープ | D26: 32 | E26: 大 | F26: 4桁 | H26: 0.024 | I26: =_xlfn.CEILING.MATH(テーブル14[[#This Row],[L2必要リール数]]) -> 1
A27: 500 | B27: 937666 | C27: テープ | D27: 32 | E27: 大 | F27: 4桁 | H27: 0.336 | I27: =_xlfn.CEILING.MATH(テーブル14[[#This Row],[L2必要リール数]]) -> 1
A28: 500 | B28: 937675 | C28: テープ | D28: 32 | E28: 大 | F28: 4桁 | H28: 0.144 | I28: =_xlfn.CEILING.MATH(テーブル14[[#This Row],[L2必要リール数]]) -> 1
A29: 2000 | B29: 9000001152 | C29: テープ | D29: 32 | E29: 大 | F29: 4桁 | H29: 0.086 | I29: =_xlfn.CEILING.MATH(テーブル14[[#This Row],[L2必要リール数]]) -> 1
A30: 1100 | B30: 9000003114 | C30: テープ | D30: 32 | E30: 大 | F30: 4桁 | H30: 0.043636364 | I30: =_xlfn.CEILING.MATH(テーブル14[[#This Row],[L2必要リール数]]) -> 1
A31: 800 | B31: 9000003132 | C31: テープ | D31: 32 | E31: 大 | F31: 4桁 | H31: 0.3675 | I31: =_xlfn.CEILING.MATH(テーブル14[[#This Row],[L2必要リール数]]) -> 1
A32: 1300 | B32: 9000003141 | C32: テープ | D32: 32 | E32: 大 | F32: 4桁 | H32: 0.073846154 | I32: =_xlfn.CEILING.MATH(テーブル14[[#This Row],[L2必要リール数]]) -> 1
A33: 500 | B33: 9000005585 | C33: テープ | D33: 32 | E33: 大 | F33: 4桁 | H33: 0.048 | I33: =_xlfn.CEILING.MATH(テーブル14[[#This Row],[L2必要リール数]]) -> 1
A34: 1100 | B34: 9000006031 | C34: テープ | D34: 32 | E34: 大 | F34: 4桁 | H34: 0.021818182 | I34: =_xlfn.CEILING.MATH(テーブル14[[#This Row],[L2必要リール数]]) -> 1
A35: 200 | B35: 9000057279 | C35: テープ | D35: 32 | E35: 大 | F35: 4桁 | H35: 0.24 | I35: =_xlfn.CEILING.MATH(テーブル14[[#This Row],[L2必要リール数]]) -> 1
A36: 1000 | B36: 9000065016 | C36: テープ | D36: 32 | E36: 大 | F36: 4桁 | H36: 0.096 | I36: =_xlfn.CEILING.MATH(テーブル14[[#This Row],[L2必要リール数]]) -> 1
A37: 1000 | B37: 9000065017 | C37: テープ | D37: 32 | E37: 大 | F37: 4桁 | H37: 0.12 | I37: =_xlfn.CEILING.MATH(テーブル14[[#This Row],[L2必要リール数]]) -> 1
... A39: 250 | B39: 9000069183 | C39: テープ | D39: 32 | E39: 大 | F39: 4桁 | H39: 0.192 | I39: =_xlfn.CEILING.MATH(テーブル14[[#This Row],[L2必要リール数]]) -> 1
A40: 200 | B40: 568752A | C40: テープ | D40: 32 | E40: 大 | F40: 4桁 | H40: 0.36 | I40: =_xlfn.CEILING.MATH(テーブル14[[#This Row],[L2必要リール数]]) -> 1
A41: 1250 | B41: 661099A | C41: テープ | D41: 32 | E41: 大 | F41: 4桁 | H41: 0.048 | I41: =_xlfn.CEILING.MATH(テーブル14[[#This Row],[L2必要リール数]]) -> 1
A42: 400 | B42: 664425 | C42: テープ | D42: 24 | E42: 大 | F42: 4桁 | H42: 0.15 | I42: =_xlfn.CEILING.MATH(テーブル14[[#This Row],[L2必要リール数]]) -> 1
A43: 400 | B43: 716486 | C43: テープ | D43: 24 | E43: 大 | F43: 4桁 | H43: 0.3 | I43: =_xlfn.CEILING.MATH(テーブル14[[#This Row],[L2必要リール数]]) -> 1
A44: 400 | B44: 911426 | C44: テープ | D44: 24 | E44: 大 | F44: 4桁 | H44: 0.06 | I44: =_xlfn.CEILING.MATH(テーブル14[[#This Row],[L2必要リール数]]) -> 1
A45: 500 | B45: 915663 | C45: テープ | D45: 24 | E45: 大 | F45: 4桁 | H45: 3.012 | I45: =_xlfn.CEILING.MATH(テーブル14[[#This Row],[L2必要リール数]]) -> 4
A46: 500 | B46: 917607 | C46: テープ | D46: 24 | E46: 大 | F46: 4桁 | H46: 0.192 | I46: =_xlfn.CEILING.MATH(テーブル14[[#This Row],[L2必要リール数]]) -> 1
A47: 500 | B47: 917616 | C47: テープ | D47: 24 | E47: 大 | F47: 4桁 | H47: 0.768 | I47: =_xlfn.CEILING.MATH(テーブル14[[#This Row],[L2必要リール数]]) -> 1
A48: 500 | B48: 917625 | C48: テープ | D48: 24 | E48: 大 | F48: 4桁 | H48: 0.096 | I48: =_xlfn.CEILING.MATH(テーブル14[[#This Row],[L2必要リール数]]) -> 1
A49: 2000 | B49: 920167 | C49: テープ | D49: 24 | E49: 大 | F49: 4桁 | H49: 0.024 | I49: =_xlfn.CEILING.MATH(テーブル14[[#This Row],[L2必要リール数]]) -> 1
...

Sheet L2 piv
A3: 行ラベル | B3: 合計 / L2必要リール数(切り上げ) | R3: 行ラベル | S3: 合計 / L2必要リール数(切り上げ)
B4: 855 | F4: ラック幅 | H4: テープ幅 | I4: リール幅 | J4: 仕切り | K4: 1ラック入る量 | L4: 必要数量 | S4: 855
A5: テープ | B5: 820 | F5: 665 | H5: 8 | I5: =H5+4 -> 12 | J5: 6 | K5: =ROUNDDOWN($F$5/SUM(I5:J5),0)*4 -> 144 | L5: 480 | O5: =L5/K5 -> 3.3333333 | R5: テープ | S5: 820
A6: 3桁 | B6: 706 | H6: 12 | I6: =H6+4 -> 16 | J6: 6 | K6: =ROUNDDOWN($F$5/SUM(I6:J6),0)*4 -> 120 | L6: 65 | O6: =L6/K6 -> 0.54166667 | R6: 8 | S6: 490
A7: 8 | B7: 486 | H7: 16 | I7: =H7+4 -> 20 | J7: 6 | K7: =ROUNDDOWN($F$5/SUM(I7:J7),0)*4 -> 100 | L7: 4 | O7: =L7/K7 -> 0.04 | R7: 小 | S7: 480
A8: 小 | B8: 476 | R8: 小/大 | S8: 8
A9: 小/大 | B9: 8 | R9: 大 | S9: 2
A10: 大 | B10: 2 | R10: 12 | S10: 163
A11: 12 | B11: 157 | H11: 12 | I11: =H11+4 -> 16 | J11: 6 | K11: =ROUNDDOWN($F$5/SUM(I11:J11),0)*2 -> 60 | L11: 90 | O11: =L11/K11 -> 1.5 | R11: 小 | S11: 65
A12: 小 | B12: 62 | H12: 16 | I12: =H12+4 -> 20 | J12: 6 | K12: =ROUNDDOWN($F$5/SUM(I12:J12),0)*2 -> 50 | L12: 71 | O12: =L12/K12 -> 1.42 | R12: 小/大 | S12: 8
A13: 小/大 | B13: 8 | H13: 24 | I13: =H13+4 -> 28 | J13: 7 | K13: =ROUNDDOWN($F$5/SUM(I13:J13),0)*2 -> 38 | L13: 53 | O13: =L13/K13 -> 1.3947368 | R13: 大 | S13: 90
A14: 大 | B14: 87 | H14: 32 | I14: =H14+4 -> 36 | J14: 8 | K14: =ROUNDDOWN($F$5/SUM(I14:J14),0)*2 -> 30 | L14: 16 | O14: =L14/K14 -> 0.53333333 | R14: 16 | S14: 75
A15: 16 | B15: 60 | H15: 44 | I15: =H15+4 -> 48 | J15: 9 | K15: =ROUNDDOWN($F$5/SUM(I15:J15),0)*2 -> 22 | L15: 22 | O15: =L15/K15 -> 1 | R15: 小 | S15: 4
A16: 小 | B16: 3 | H16: 56 | I16: =H16+4 -> 60 | J16: 10 | K16: =ROUNDDOWN($F$5/SUM(I16:J16),0)*2 -> 18 | L16: 1 | O16: =L16/K16 -> 0.055555556 | R16: 大 | S16: 71
A17: 大 | B17: 57 | R17: 24 | S17: 53
A18: 24 | B18: 3 | R18: 大 | S18: 53
A19: 大 | B19: 3 | R19: 32 | S19: 16
A20: 4桁 | B20: 114 | R20: 大 | S20: 16
A21: 8 | B21: 4 | R21: 44 | S21: 22
A22: 小 | B22: 4 | R22: 大 | S22: 22
A23: 12 | B23: 6 | R23: 56 | S23: 1
A24: 小 | B24: 3 | R24: 大 | S24: 1
A25: 大 | B25: 3 | R25: トレイ | S25: 35
A26: 16 | B26: 15 | R26: マックドライ | S26: 64
A27: 小 | B27: 1 | R27: 総計 | S27: 919
A28: 大 | B28: 14
A29: 24 | B29: 50
A30: 大 | B30: 50
A31: 32 | B31: 16
A32: 大 | B32: 16
A33: 44 | B33: 22
A34: 大 | B34: 22
A35: 56 | B35: 1
A36: 大 | B36: 1
A37: トレイ | B37: 35
A38: マックドライ | B38: 64
A39: 総計 | B39: 919

Sheet L3
A1: 1リールあたりの数量 | B1: 部品 | C1: 形式 | D1: テープ幅 | E1: リールサイズ | F1: ノズル分類 | G1: マックドライ | H1: L3必要リール数 | I1: L3必要リール数(切り上げ)
A2: 5000 | B2: 667191A | C2: テープ | D2: 8 | E2: 小 | F2: 3桁 | H2: 0.0056 | I2: =_xlfn.CEILING.MATH(テーブル2[[#This Row],[L3必要リール数]]) -> 1
A3: 5000 | B3: 667378A | C3: テープ | D3: 8 | E3: 小 | F3: 3桁 | H3: 0.0056 | I3: =_xlfn.CEILING.MATH(テーブル2[[#This Row],[L3必要リール数]]) -> 1
A4: 5000 | B4: 667449A | C4: テープ | D4: 8 | E4: 小 | F4: 3桁 | H4: 0.01 | I4: =_xlfn.CEILING.MATH(テーブル2[[#This Row],[L3必要リール数]]) -> 1
A5: 4000 | B5: 363447B | C5: テープ | D5: 8 | E5: 小 | F5: 3桁 | H5: 0.0125 | I5: =_xlfn.CEILING.MATH(テーブル2[[#This Row],[L3必要リール数]]) -> 1
A6: 10000 | B6: 9000069231 | C6: テープ | D6: 8 | E6: 小 | F6: 3桁 | H6: 0.0156 | I6: =_xlfn.CEILING.MATH(テーブル2[[#This Row],[L3必要リール数]]) -> 1
A7: 3000 | B7: 9000057802 | C7: テープ | D7: 12 | E7: 小 | F7: 3桁 | G7: マックドライ | H7: 0.016666667 | I7: =_xlfn.CEILING.MATH(テーブル2[[#This Row],[L3必要リール数]]) -> 1
A8: 2500 | B8: 9000061125 | C8: テープ | D8: 16 | E8: 大 | F8: 4桁 | H8: 0.02 | I8: =_xlfn.CEILING.MATH(テーブル2[[#This Row],[L3必要リール数]]) -> 1
A9: 5000 | B9: 716423 | C9: テープ | D9: 8 | E9: 小 | F9: 3桁 | H9: 0.02 | I9: =_xlfn.CEILING.MATH(テーブル2[[#This Row],[L3必要リール数]]) -> 1
A10: 2000 | B10: 9000002543 | C10: テープ | D10: 16 | E10: 大 | F10: 3桁 | H10: 0.025 | I10: =_xlfn.CEILING.MATH(テーブル2[[#This Row],[L3必要リール数]]) -> 1
A11: 2000 | B11: 537251A | C11: テープ | D11: 8 | E11: 小 | F11: 3桁 | H11: 0.025 | I11: =_xlfn.CEILING.MATH(テーブル2[[#This Row],[L3必要リール数]]) -> 1
A12: 960 | B12: 9000058027 | C12: トレイ | D12: 0 | E12: #N/A | F12: 3桁 | H12: 0.029166667 | I12: =_xlfn.CEILING.MATH(テーブル2[[#This Row],[L3必要リール数]]) -> 1
A13: 3000 | B13: 662543 | C13: テープ | D13: 8 | E13: 小 | F13: 3桁 | H13: 0.032 | I13: =_xlfn.CEILING.MATH(テーブル2[[#This Row],[L3必要リール数]]) -> 1
A14: 3000 | B14: 9000006771 | C14: テープ | D14: 8 | E14: 小 | F14: 3桁 | H14: 0.032 | I14: =_xlfn.CEILING.MATH(テーブル2[[#This Row],[L3必要リール数]]) -> 1
A15: 3000 | B15: 9000059478 | C15: テープ | D15: 8 | E15: 小 | F15: 3桁 | H15: 0.032 | I15: =_xlfn.CEILING.MATH(テーブル2[[#This Row],[L3必要リール数]]) -> 1
A16: 3000 | B16: 569608B | C16: テープ | D16: 8 | E16: 小 | F16: 3桁 | H16: 0.032 | I16: =_xlfn.CEILING.MATH(テーブル2[[#This Row],[L3必要リール数]]) -> 1
A17: 1500 | B17: 920069 | C17: テープ | D17: 24 | E17: 大 | F17: 3桁 | H17: 0.033333333 | I17: =_xlfn.CEILING.MATH(テーブル2[[#This Row],[L3必要リール数]]) -> 1
A18: 5000 | B18: 667396A | C18: テープ | D18: 8 | E18: 小 | F18: 3桁 | H18: 0.0384 | I18: =_xlfn.CEILING.MATH(テーブル2[[#This Row],[L3必要リール数]]) -> 1
A19: 1250 | B19: 656461A | C19: テープ | D19: 24 | E19: 大 | F19: 4桁 | G19: マックドライ | H19: 0.04 | I19: =_xlfn.CEILING.MATH(テーブル2[[#This Row],[L3必要リール数]]) -> 1
A20: 2500 | B20: 907592 | C20: テープ | D20: 12 | E20: 大 | F20: 3桁 | H20: 0.04 | I20: =_xlfn.CEILING.MATH(テーブル2[[#This Row],[L3必要リール数]]) -> 1
A21: 15000 | B21: 9000067549 | C21: テープ | D21: 8 | E21: 小 | F21: 3桁 | H21: 0.040666667 | I21: =_xlfn.CEILING.MATH(テーブル2[[#This Row],[L3必要リール数]]) -> 1
A22: 2000 | B22: 920336 | C22: テープ | D22: 44 | E22: 大 | F22: 4桁 | H22: 0.048 | I22: =_xlfn.CEILING.MATH(テーブル2[[#This Row],[L3必要リール数]]) -> 1
A23: 2000 | B23: 607497B | C23: テープ | D23: 12 | E23: 大 | F23: 3桁 | H23: 0.048 | I23: =_xlfn.CEILING.MATH(テーブル2[[#This Row],[L3必要リール数]]) -> 1
A24: 2000 | B24: 666789 | C24: テープ | D24: 16 | E24: 大 | F24: 3桁 | H24: 0.05 | I24: =_xlfn.CEILING.MATH(テーブル2[[#This Row],[L3必要リール数]]) -> 1
A25: 2000 | B25: 692671A | C25: テープ | D25: 12 | E25: 大 | F25: 3桁 | H25: 0.05 | I25: =_xlfn.CEILING.MATH(テーブル2[[#This Row],[L3必要リール数]]) -> 1
A26: 3000 | B26: 608932 | C26: テープ | D26: 8 | E26: 小 | F26: 3桁 | H26: 0.052 | I26: =_xlfn.CEILING.MATH(テーブル2[[#This Row],[L3必要リール数]]) -> 1
A27: 3000 | B27: 9000066685 | C27: テープ | D27: 8 | E27: 小 | F27: 3桁 | H27: 0.052 | I27: =_xlfn.CEILING.MATH(テーブル2[[#This Row],[L3必要リール数]]) -> 1
A28: 3000 | B28: 9000069334 | C28: テープ | D28: 8 | E28: 小 | F28: 3桁 | H28: 0.052 | I28: =_xlfn.CEILING.MATH(テーブル2[[#This Row],[L3必要リール数]]) -> 1
A29: 960 | B29: 922432 | C29: トレイ | D29: 0 | E29: #N/A | F29: 3桁 | H29: 0.052083333 | I29: =_xlfn.CEILING.MATH(テーブル2[[#This Row],[L3必要リール数]]) -> 1
A30: 10000 | B30: 677349 | C30: テープ | D30: 8 | E30: 小 | F30: 3桁 | H30: 0.061 | I30: =_xlfn.CEILING.MATH(テーブル2[[#This Row],[L3必要リール数]]) -> 1
A31: 10000 | B31: 927062 | C31: テープ | D31: 8 | E31: 小 | F31: 3桁 | H31: 0.061 | I31: =_xlfn.CEILING.MATH(テーブル2[[#This Row],[L3必要リール数]]) -> 1
A32: 10000 | B32: 9000061992 | C32: テープ | D32: 8 | E32: 小 | F32: 3桁 | H32: 0.061 | I32: =_xlfn.CEILING.MATH(テーブル2[[#This Row],[L3必要リール数]]) -> 1
A33: 10000 | B33: 9000063510 | C33: テープ | D33: 8 | E33: 小 | F33: 3桁 | H33: 0.061 | I33: =_xlfn.CEILING.MATH(テーブル2[[#This Row],[L3必要リール数]]) -> 1
A34: 10000 | B34: 9000066681 | C34: テープ | D34: 8 | E34: 小 | F34: 3桁 | H34: 0.061 | I34: =_xlfn.CEILING.MATH(テーブル2[[#This Row],[L3必要リール数]]) -> 1
A35: 10000 | B35: 9000066816 | C35: テープ | D35: 8 | E35: 小 | F35: 3桁 | H35: 0.061 | I35: =_xlfn.CEILING.MATH(テーブル2[[#This Row],[L3必要リール数]]) -> 1
A36: 10000 | B36: 9000067541 | C36: テープ | D36: 8 | E36: 小 | F36: 3桁 | H36: 0.061 | I36: =_xlfn.CEILING.MATH(テーブル2[[#This Row],[L3必要リール数]]) -> 1
A37: 10000 | B37: 9000067542 | C37: テープ | D37: 8 | E37: 小 | F37: 3桁 | H37: 0.061 | I37: =_xlfn.CEILING.MATH(テーブル2[[#This Row],[L3必要リール数]]) -> 1
A38: 400 | B38: 9000067025 | C38: トレイ | D38: 0 | E38: #N/A | F38: 3桁 | H38: 0.07 | I38: =_xlfn.CEILING.MATH(テーブル2[[#This Row],[L3必要リール数]]) -> 1
A39: 10000 | B39: 9000058701 | C39: テープ | D39: 8 | E39: 小 | F39: 3桁 | H39: 0.072 | I39: =_xlfn.CEILING.MATH(テーブル2[[#This Row],[L3必要リール数]]) -> 1
A40: 2500 | B40: 654588 | C40: テープ | D40: 12 | E40: 大 | F40: 3桁 | H40: 0.0768 | I40: =_xlfn.CEILING.MATH(テーブル2[[#This Row],[L3必要リール数]]) -> 1
...

Sheet L3 piv
A3: 行ラベル | B3: 合計 / L3必要リール数(切り上げ)
B4: 622
A5: テープ | B5: 603
A6: 3桁 | B6: 547
A7: 8 | B7: 441
A8: 小 | B8: 423
A9: 小/大 | B9: 18 | F9: 665
A10: 12 | B10: 76 | F10: 12 | G10: 6 | H10: 6
A11: 小 | B11: 36 | F11: =ROUNDDOWN(F9/F10,0) -> 55 | G11: =ROUNDDOWN(F9/SUM(F10:G10),0) -> 36 | H11: =ROUNDDOWN(F9/SUM(F10:H10),0) -> 27
A12: 大 | B12: 40 | F12: =F11*4 -> 220 | G12: =G11*4 -> 144 | H12: =H11*4 -> 108
A13: 16 | B13: 28
A14: 大 | B14: 28
A15: 24 | B15: 2
A16: 大 | B16: 2
A17: 4桁 | B17: 56
A18: 8 | B18: 1 | G18: =423/G12 -> 2.9375
A19: 小 | B19: 1
A20: 16 | B20: 11
A21: 大 | B21: 11
A22: 24 | B22: 27
A23: 大 | B23: 27
A24: 32 | B24: 15
A25: 大 | B25: 15
A26: 44 | B26: 2
A27: 大 | B27: 2
A28: トレイ | B28: 19
A29: マックドライ | B29: 36
A30: 総計 | B30: 658
