Workbook

Sheet 問題まとめ
A1: EGProの問題
A2: ・スプライシングテープがセンサーを通過したのに認識せず、15%のズレを生じさせることがある。
A3: ・存在しない実績を上げることがある。1000個のリールに対して、1000個実装したうえで、1003個の実績をMESに送信する。
A4: ・存在しない実績を上げることがある。1000個のリールに対して、1000個実装したうえで、997個の実績をMESに送信する。
A5: ・スプライシングのつなぎ方の誤差や、作業上の問題で、数個のズレが発生する。
A6: ・テープが摩耗で実装中に物理的に切れる・ジャミングを起こして部品を飛散させる等で、データ上に存在しないロスを生じさせることがある。
A7: ・部品カットの工程で、部品カウントではなく、メジャーで数量を測ることがあり、数個の在庫ズレを起こすことがある。
A8: ・現場担当者が吸着確認の為、データ上に存在しないロスを生じさせることがある。
A9: ・誤入力で棚卸しされてることがある。
A10: ・トレイ部品が、バーコードを読むのを失念した状態で実装されることがある。(設備側が、部品のバーコードを読み漏れても実装できる仕様になっている。実装履歴はNullで出力される。)
A13: ・10000個のリールに対して、9998個の実績をMESに送信する。０確認を行わないとEgpとMES/BOSSで差異が出る①
A14: 期間を決めて処理を行わないと棚卸差異としての処理が増える。

Sheet 手順
A1: ■実装履歴
A2: http://nksv1359.ad.nkc.co.jp/cgi/qcd_DB/qcd_DB_Release/html/scrap_search.cgi
A3: ■シリアルごと吸着サマリ
A4: http://nksv1359.ad.nkc.co.jp/cgi/qcd_DB/qcd_DB_Release/html/scrap_search2.cgi
A5: ■在庫一覧
A6: http://nksv1359.ad.nkc.co.jp/cgi/qcd_DB/qcd_DB_Release/html/Get_EG_Wherehouse.cgi
A9: ①Web[シリアルごとの吸着サマリ]で部品を叩く
A10: ②エラーが発生した注番[ロット]で、異常が発生していないか確認、シリアルを特定する
A11: └分からない場合、対象部品の全在庫を棚卸しして、本来消費されたはずのロットを特定する。
A12: └EGProがどう見ても正常にしか見えない場合、異常無しで報告
A13: ③Web[実装履歴]で、部品番号を叩く
A14: ④対象のシリアルの履歴で、フィーダーアドレスやラインを良く見て、固定品目なのかどうか特定する。(L2L3であれば固定、L1であればフィーダーアドレスが同じであれば固定
... A29: https://nk365.sharepoint.com/sites/itpt000509/Shared Documents/100_SMT関連/02_手順書関連/スプライシング解除・在庫修正手順.pptx

Sheet 依頼
A1: やってないカウント | B1: ◯ | D1: 番号 | F1: 品目 | G1: ロット | H1: 差異入力数 | I1: 棚分類 | J1: EGPro巻き数 | K1: 0.15 | L1: 指図差異数 | M1: 使用数 | N1: 実際に使用した数 | P1: 単価 | Q1: 金額 | R1: シリアル番号 | S1: 移動元プラント | T1: 移動元保管場所 | U1: 移動元ロケーション | V1: メッセージテキスト
A2: =IF(B2="◯",COUNTIF(#REF!,#REF!),"") | C2: 4/6 | D2: 212176524 | F2: 667743 | G2: 406097891 | H2: 70 | I2: R3101 | J2: 10000 | K2: 1500 | N2: 27 | O2: 0.41 | P2: 28.7 | S2: B020 | T2: 0001 | U2: 0001-3 | V2: BA 利用可能在庫 69 PC : 667743 B020 0001 406097891 が不足です | W2: 4940995531対応済み | X2: 確認
A3: =IF(B3="◯",COUNTIF(#REF!,#REF!),"") | C3: 4/6 | D3: 212176524 | F3: 667743 | G3: 406147189 | I3: R3101 | J3: 10000 | K3: 1500 | N3: 70
A4: =IF(B4="◯",COUNTIF(#REF!,#REF!),"") | C4: 4/6 | D4: 212176505 | F4: 9000053399 | G4: 406117964 | H4: 372 | I4: R0103 | J4: 3000 | K4: 450 | L4: 156 | N4: 36 | O4: 81.16 | P4: 30191.52 | Q4: 4941010906 | S4: B020 | T4: 0001 | U4: 0001-3 | V4: BA 利用可能在庫 156 PC : 9000053399 B020 0001 406117964 が不足です | W4: 4941010617対応済
A5: =IF(B5="◯",COUNTIF(#REF!,#REF!),"") | C5: 4/6 | D5: 212176505 | F5: 9000053399 | G5: 406092812 | I5: R0103 | J5: 3000 | K5: 450 | N5: 156
A6: =IF(B6="◯",COUNTIF(#REF!,#REF!),"") | C6: 4/6 | D6: 202176507 | F6: 9000053399 | G6: 406092812 | I6: R0103 | J6: 3000 | K6: 450 | L6: 48 | N6: 48 | Q6: 4941010913
A7: =IF(B7="◯",COUNTIF(#REF!,#REF!),"") | C7: 4/6 | D7: 212176508 | F7: 9000053399 | G7: 406092812 | I7: R0103 | J7: 3000 | K7: 450 | L7: 168 | N7: 168 | Q7: 4941010922
A8: =IF(B8="◯",COUNTIF(#REF!,#REF!),"") | C8: 4/6 | D8: 212176512 | F8: 667788 | G8: 406112380 | H8: 493 | I8: R0101 | J8: 10000 | K8: 1500 | L8: 12+168 | N8: 12 | O8: 0.41 | P8: 202.13 | Q8: 4941010927 | S8: B020 | T8: 0001 | U8: 0001-3 | V8: BA 利用可能在庫 12 PC : 667788 B020 0001 406112380 が不足です | W8: 4941010617対応済
A9: =IF(B9="◯",COUNTIF(#REF!,#REF!),"") | D9: 212176512 | F9: 667788 | G9: 406147211 | I9: R0101 | J9: 10000 | K9: 1500 | N9: 180
A10: =IF(B10="◯",COUNTIF(#REF!,#REF!),"") | C10: 4/6 | D10: 212176514 | F10: 667788 | G10: 406147211 | I10: R0101 | J10: 10000 | K10: 1500 | L10: 192 | N10: 192 | Q10: 4941010933
A11: =IF(B11="◯",COUNTIF(#REF!,#REF!),"") | C11: 4/6 | D11: 212176513 | F11: 667788 | G11: 406147211 | I11: R0101 | J11: 10000 | K11: 1500 | L11: 289 | N11: 389 | Q11: 4941010929
A12: =IF(B12="◯",COUNTIF(#REF!,#REF!),"") | C12: 4/6 | D12: 212176513 | F12: 667618A | G12: 406147091 | H12: 380 | I12: R0101 | J12: 5000 | K12: 750 | L12: 380 | N12: 4 | O12: 0.45 | P12: 171 | Q12: 4941010928 | S12: B020 | T12: 0001 | U12: 0001-3 | V12: BA 利用可能在庫 380 PC : 667618A B020 0001 406147091 が不足です | W12: 4941010617対応済
A13: =IF(B13="◯",COUNTIF(#REF!,#REF!),"") | D13: 212176513 | F13: 667618A | G13: 406147094 | I13: R0101 | J13: 5000 | K13: 750 | N13: 380
A14: =IF(B14="◯",COUNTIF(#REF!,#REF!),"") | C14: 4/6 | D14: 212176514 | F14: 9000041875 | G14: 406055096 | H14: 180 | I14: R0102 | J14: 2500 | K14: 375 | M14: 194 | N14: 14 | O14: 11.12 | P14: 2001.6 | S14: B020 | T14: 0001 | U14: 0001-3 | V14: BA 利用可能在庫 180 PC : 9000041875 B020 0001 406055096 が不足です | W14: 4941010617対応済
A15: =IF(B15="◯",COUNTIF(#REF!,#REF!),"") | C15: 4/6 | D15: 212176514 | F15: 9000041875 | G15: 406432411 | I15: R0102 | J15: 2500 | K15: 375 | N15: 180
A16: =IF(B16="◯",COUNTIF(#REF!,#REF!),"") | C16: 4/7 | D16: 110013242 | F16: 9000053399 | G16: 406117964 | H16: 448 | I16: R0103 | J16: 3000 | K16: 450 | O16: 81.16 | P16: 36359.68 | Q16: 4941027029 | S16: B020 | T16: 0001 | U16: 0001-3 | V16: BA 利用可能在庫 48 PC : 9000053399 B020 0001 406117964 が不足です | W16: 4941026801対応済
A17: =IF(B17="◯",COUNTIF(#REF!,#REF!),"") | C17: 4/7 | D17: 110013242 | F17: 9000053399 | G17: 406092812 | I17: R0103 | J17: 3000 | K17: 450 | L17: 48 | Q17: 4941027029
A18: =IF(B18="◯",COUNTIF(#REF!,#REF!),"") | C18: 4/7 | D18: 212177294 | F18: 9000053399 | G18: 406092812 | I18: R0103 | J18: 3000 | K18: 450 | L18: 48 | Q18: 4941027052
A19: =IF(B19="◯",COUNTIF(#REF!,#REF!),"") | C19: 4/7 | D19: 212177295 | F19: 9000053399 | G19: 406092812 | I19: R0103 | J19: 3000 | K19: 450 | L19: 48 | Q19: 4941027053
A20: =IF(B20="◯",COUNTIF(#REF!,#REF!),"") | C20: 4/7 | D20: 212177296 | F20: 9000053399 | G20: 406092812 | I20: R0103 | J20: 3000 | K20: 450 | L20: 114 | Q20: 4941029012
A21: =IF(B21="◯",COUNTIF(#REF!,#REF!),"") | C21: 4/7 | D21: 212177292 | F21: 9000053399 | G21: 406092812 | I21: R0103 | J21: 3000 | K21: 450 | L21: 192 | Q21: 4940127050
A22: =IF(B22="◯",COUNTIF(#REF!,#REF!),"") | C22: 4/7 | D22: 212177292 | F22: 9000066859 | G22: 406419678 | H22: 444 | I22: R1201 | J22: 4000 | K22: 600 | L22: 2 | M22: 576 | N22: 132 | O22: 1.91 | P22: 848.04 | Q22: 4941027051 | S22: B020 | T22: 0001 | U22: 0001-3 | V22: BA 利用可能在庫 444 PC : 9000066859 B020 0001 406419678 が不足です | W22: 4941026801対応済
A23: =IF(B23="◯",COUNTIF(#REF!,#REF!),"") | D23: 212177292 | F23: 9000066859 | G23: 406426349 | I23: R1201 | J23: 4000 | K23: 600 | N23: 444
A24: =IF(B24="◯",COUNTIF(#REF!,#REF!),"") | C24: 4/7 | D24: 212177307 | F24: 620606 | G24: 406367330 | H24: 776 | I24: R0101 | J24: 10000 | K24: 1500 | L24: 6 | N24: 0 | O24: 0.6 | P24: 465.6 | Q24: 4941027056 | S24: B020 | T24: 0001 | U24: 0001-3 | V24: BA 利用可能在庫 6 PC : 620606 B020 0001 406367330 が不足です | W24: 4941026801対応済
A25: =IF(B25="◯",COUNTIF(#REF!,#REF!),"") | D25: 212177307 | F25: 620606 | G25: 406409004 | I25: R0101 | J25: 10000 | K25: 1500 | M25: 60 | N25: 60
A26: =IF(B26="◯",COUNTIF(#REF!,#REF!),"") | C26: 4/7 | D26: 212177309 | F26: 620606 | G26: 406409004 | I26: R0101 | J26: 10000 | K26: 1500 | L26: 770 | M26: 716 | N26: 719 | Q26: 4941027058
A27: =IF(B27="◯",COUNTIF(#REF!,#REF!),"") | D27: 212177309 | F27: 620606 | G27: 406367330 | I27: R0101 | J27: 10000 | K27: 1500 | M27: 54 | N27: 54
A28: =IF(B28="◯",COUNTIF(#REF!,#REF!),"") | C28: 4/7 | D28: 212177309 | E28: 確認 | F28: 9000066582 | G28: 406345529 | H28: 848 | I28: R0101 | J28: 10000 | K28: 1500 | M28: 1056 | N28: 988 | O28: 0.49 | P28: 415.52 | Q28: 4941027063 | S28: B020 | T28: 0001 | U28: 0001-3 | V28: BA 利用可能在庫 848 PC : 9000066582 B020 0001 406345529 が不足です | W28: 4941026801対応済
A29: =IF(B29="◯",COUNTIF(#REF!,#REF!),"") | D29: 212177309 | E29: 確認 | F29: 9000066582 | G29: 406360730 | I29: R0101 | J29: 10000 | K29: 1500 | N29: 69 | Q29: 4941029015
A30: =IF(B30="◯",COUNTIF(#REF!,#REF!),"") | C30: 4/7 | D30: 212177309 | F30: 9000070378 | G30: 406216349 | H30: 48 | I30: R0101 | J30: 5000 | K30: 750 | M30: 96 | N30: 48 | O30: 6.5 | P30: 312 | S30: B020 | T30: 0001 | U30: 0001-3 | V30: BA 利用可能在庫 48 PC : 9000070378 B020 0001 406216349 が不足です | W30: 4941026801対応済
A31: =IF(B31="◯",COUNTIF(#REF!,#REF!),"") | D31: 212177309 | F31: 9000070378 | G31: 406412776 | I31: R0101 | J31: 5000 | K31: 750 | N31: 48
A32: =IF(B32="◯",COUNTIF(#REF!,#REF!),"") | C32: 4/7 | D32: 212177944 | F32: 667618A | G32: 406147091 | H32: 384 | I32: R0101 | J32: 5000 | K32: 750 | O32: 0.45 | P32: 172.8 | Q32: 4941027069 | S32: B020 | T32: 0001 | U32: 0001-3 | V32: BA 利用可能在庫 384 PC : 667618A B020 0001 406147091 が不足です | W32: 4941026801対応済
A33: =IF(B33="◯",COUNTIF(#REF!,#REF!),"") | C33: 4/7 | D33: 212177944 | F33: 667618A | G33: 406147094 | I33: R0101 | J33: 5000 | K33: 750 | N33: 384
A34: =IF(B34="◯",COUNTIF(#REF!,#REF!),"") | C34: 4/7 | D34: 212177944 | F34: 667788 | G34: 406112380 | H34: 288 | I34: R0101 | J34: 10000 | K34: 1500 | O34: 0.41 | P34: 118.08 | S34: B020 | T34: 0001 | U34: 0001-3 | V34: BA 利用可能在庫 288 PC : 667788 B020 0001 406112380 が不足です | W34: 4941026801対応済
A35: =IF(B35="◯",COUNTIF(#REF!,#REF!),"") | C35: 4/7 | D35: 212177944 | F35: 667788 | G35: 406147211 | I35: R0101 | J35: 10000 | K35: 1500 | N35: 288 | Q35: 4941027072
A36: =IF(B36="◯",COUNTIF(#REF!,#REF!),"") | D36: 212176505 | E36: 落とし漏れー２ | F36: 9000072187 | G36: 406069148 | I36: R0106 | J36: 400 | K36: 60 | N36: 28
A37: =IF(B37="◯",COUNTIF(#REF!,#REF!),"") | C37: 4/8 | D37: 212176002 | F37: 620606 | G37: 406367330 | H37: 480 | I37: R0101 | J37: 10000 | K37: 1500 | M37: 480 | O37: 0.6 | P37: 288 | Q37: 4941042690 | S37: B020 | T37: 0001 | U37: 0001-3 | V37: BA 利用可能在庫 480 PC : 620606 B020 0001 406367330 が不足です
A38: =IF(B38="◯",COUNTIF(#REF!,#REF!),"") | D38: 212176002 | F38: 620606 | G38: 406409004 | I38: R0101 | J38: 10000 | K38: 1500 | N38: 480
A39: =IF(B39="◯",COUNTIF(#REF!,#REF!),"") | C39: 4/8 | D39: 212176002 | F39: 9000070378 | G39: 406216349 | H39: 240 | I39: R0101 | J39: 5000 | K39: 750 | M39: 240 | O39: 6.5 | P39: 1560 | V39: BA 利用可能在庫 240 PC : 9000070378 B020 0001 406216349 が不足です
A40: =IF(B40="◯",COUNTIF(#REF!,#REF!),"") | D40: 212176002 | F40: 9000070378 | G40: 406412776 | I40: R0101 | J40: 5000 | K40: 750 | N40: 240
...

Sheet 固定グループ
A1: グループ名 | B1: 品目名 | C1: ライン | D1: 備考 | E1: 追加日
A2: AED | B2: UR-0396-01 | C2: Line-3
A3: AED | B3: UR-0451-01 | C3: Line-3
A4: AED | B4: UR-0610-01 | C4: Line-3
A5: AED | B5: UR-0511-01 | C5: Line-3
A6: AED | B6: UR-0388-01 | C6: Line-3
A7: AED | B7: UR-0559-06 | C7: Line-3
A8: AED | B8: UR-0624 | C8: Line-3
A9: AED | B9: URS-0432-01 | C9: Line-3
A10: AED | B10: UR-0558-02 | C10: Line-3
A11: AED | B11: UR-04511-01 | C11: Line-3 | E11: 45817
A12: AED | B12: UR-05581-02 | C12: Line-3 | E12: 45856
A13: AED | B13: UR-0558-01 | C13: Line-3
A14: AED | B14: UR-0509-01 | C14: Line-3
A15: AED | B15: UR-0388 | C15: Line-3
A16: AED | B16: UR-04511 | C16: Line-3
A17: AED | B17: URS-0432 | C17: Line-3
A18: AED | B18: UR-0451 | C18: Line-3
A19: AED | B19: UR-06101-01 | C19: Line-3
A20: AED | B20: UR-0509-02 | C20: Line-3
A21: AED | B21: UR-05091-03 | C21: Line-3
A22: AED | B22: UR-06101-02 | C22: Line-3 | E22: 45877
A23: AED | B23: MVD-0388-01 | C23: Line-3 | E23: 46010
A24: AED | B24: MVD-0509-02 | C24: Line-3 | E24: 46010
A25: AED | B25: UR-0624-01 | C25: Line-3 | E25: 46077
A26: AED | B26: UR-05091-04 | C26: Line-3 | E26: 46078
A27: AED | B27: URS-0509-02 | C27: Line-3 | E27: 46078
A28: AED | B28: UR-0509-03 | C28: Line-3 | E28: 46083
A29: AED | B29: URS-0509-03 | C29: Line-3 | E29: 46083
A30: AED | B30: UR-0559-07 | C30: Line-3 | E30: 46083
A31: AED | B31: URS-0559-07 | C31: Line-3 | E31: 46083
A32: AED | B32: UR-06101-03 | C32: Line-3 | E32: 46086
A33: AED | B33: UR-0610-03 | C33: Line-2 | E33: 46191
... A35: NKV | B35: URS-4558 | C35: Line-1 | E35: 46106
A36: TEC-1000 | B36: URS-05971 | C36: Line-2 | D36: 半成半製分離
A37: TEC-1000 | B37: URS-05972 | C37: Line-2 | D37: 半成半製分離
A38: TEC-1000 | B38: URS-0596 | C38: Line-2
A39: TEC-1000 | B39: URS-0598 | C39: Line-2
A40: TEC-1000 | B40: URS-0601 | C40: Line-2
A41: TEC-1000 | B41: URS-0625 | C41: Line-2 | E41: 45763
...

Sheet グループ分け

Sheet 依頼検索
B1: 部品名 | E1: 番号 | G1: 品目 | H1: ロット | I1: 差異入力数 | J1: 棚分類 | K1: EGPro巻き数 | L1: 0.15 | M1: 指図差異数 | N1: 使用数 | O1: 実際に使用した数 | Q1: 単価 | R1: 金額 | S1: シリアル番号 | T1: 移動元プラント | U1: 移動元保管場所 | V1: 移動元ロケーション | W1: メッセージテキスト
B2: 667485A | D2: {=_xlfn._xlws.FILTER(依頼!C:V,依頼!F:F=依頼検索!B2)} -> 6/8 | E2: 212201177 | F2: 1 | G2: 667485A | H2: 406349100 | I2: 288 | J2: R0101 | K2: 5000 | L2: 750 | M2: 0 | N2: 0 | O2: 0 | P2: 0 | Q2: 0.45 | R2: 129.6 | S2: 0 | T2: 0 | U2: 0 | V2: 0 | W2: BA 利用可能在庫 288 PC : 667485A B020 0001 406349100 が不足です
D3: 6/11 | E3: 212202993 | F3: 1 | G3: 667485A | H3: 406349100 | I3: 20 | J3: R0101 | K3: 5000 | L3: 750 | M3: 0 | N3: 0 | O3: 0 | P3: 0 | Q3: 0.45 | R3: 9 | S3: 0 | T3: 0 | U3: 0 | V3: 0 | W3: BA 利用可能在庫 20 PC : 667485A B020 0001 406349100 が不足です

Sheet 回答
A1: 対応日 | B1: 指図 | C1: 品番 | D1: シリアル番号 | E1: 発注番号 | F1: 吸着数 | G1: 備考 | H1: 処理
A2: 46119 | B2: 212177307 | C2: 9000066582 | D2: 9000066582 100538 | E2: 406360730 | F2: 420 | H2: 対応済
A3: 46119 | B3: 212177307 | C3: 9000066582 | D3: 9000066582 100538 | E3: 406360730 | F3: 360 | H3: 対応済
A4: 46119 | B4: 212177309 | C4: 9000066582 | D4: 9000066582 100538 | E4: 406360730 | F4: 69 | H4: 対応済
A5: 46119 | B5: 212177309 | C5: 9000066582 | D5: 9000066582 100535 | E5: 406345529 | F5: =577-69 -> 508 | H5: 対応済
A6: 46119 | B6: 212177309 | C6: 9000066582 | D6: 9000066582 100535 | E6: 406345529 | F6: 480 | H6: 対応済
A7: 46119 | B7: 212176524 | C7: 9000066582 | D7: 9000066582 100535 | E7: 406345529 | F7: 672 | H7: 対応済
A8: 46119 | B8: 212176524 | C8: 9000066582 | D8: 9000066582 100535 | E8: 406345529 | F8: 384 | H8: 対応済
A9: 46119 | B9: 212178518 | C9: 9000066859 | D9: 9000066859 100835 | E9: 406426349 | F9: 576 | H9: 対応済
A10: 46119 | B10: 212177938 | C10: 9000066859 | D10: 9000066859 100835 | E10: 406426349 | F10: 576 | H10: 対応済
A11: 46119 | B11: 212177292 | C11: 9000066859 | D11: 9000066859 100835 | E11: 406426349 | F11: 444 | H11: 対応済
A12: 46119 | B12: 212177292 | C12: 9000066859 | D12: 9000066859 100831 | E12: 406419678 | F12: 132 | H12: 対応済
A13: 46119 | B13: 212176505 | C13: 9000066859 | D13: 9000066859 100831 | E13: 406419678 | F13: 576 | H13: 対応済
A14: 46119 | B14: 212176002 | C14: 9000070378 | D14: 9000070378 100004 | E14: 406412776 | F14: 240 | H14: 対応済
A15: 46119 | B15: 212177309 | C15: 9000070378 | D15: 9000070378 100004 | E15: 406412776 | F15: 48 | H15: 対応済
A16: 46119 | B16: 212177309 | C16: 9000070378 | D16: 9000070378 100003 | E16: 406216349 | F16: 48 | H16: 対応済
A17: 46122 | B17: 212179619 | C17: 581639A | D17: 581639A100240 | E17: 406378753 | F17: 30 | G17: 棚卸しが間違っている可能性が高いのでそのまま入庫して引き落としで良いと思います。 | H17: 処理なし | P17: 指図 | Q17: 品番 | R17: 発注番号 | S17: 吸着数
A18: 46129 | B18: 212181340 | C18: 683921 | D18: 683921 100389 | E18: 405370678 | F18: 204 | H18: 4941202589 | P18: 212173280 | Q18: 9000070824 | R18: 406448768 | S18: 72
A19: 46129 | B19: 212181340 | C19: 683921 | D19: 683921 100365 | E19: 405265809 | F19: 85 | P19: 212173280 | Q19: 9000071090 | R19: 406448767 | S19: 72
A20: 46129 | B20: 212176003 | C20: 9000069523 | D20: 9000069523 100007 | E20: 406315914 | F20: 460 | G20: 4941202592 | H20: 4941202592
A21: 46129 | B21: 212176003 | C21: 9000069523 | D21: 9000069523 100009 | E21: 406412782 | F21: 22
A22: 46129 | B22: 212182590 | C22: 9000066590 | D22: 9000066590 101748 | E22: 406366297 | F22: 70 | G22: リールごとの誤差の積み重ねです。 | H22: 処理なし
A23: 46133 | B23: 212176508 | C23: 667859 | D23: 667859 101106 | E23: 405565837 | F23: 207 | G23: 棚卸し減が間違っています。実際物がありました。このままBOSSの修正は不要だと思います。 | H23: 処理なし
A24: 46134 | B24: 212173280 | C24: 9000070824 | D24: 9000070824 100003 | E24: 406448768 | F24: 72 | G24: 実績上げ処理済み、4/22夜間に連携
A25: 46134 | B25: 212173279 | C25: 9000070824 | D25: 9000070824 100003 | E25: 406448768 | F25: 72 | G25: 情シスメール分 実績修正お願いします。 | H25: 406244888を修正
A26: 46134 | B26: 212178060 | C26: 9000070824 | D26: 9000070824 100003 | E26: 406448768 | F26: 84 | H26: 406244888を修正
A27: 46134 | B27: 212178060 | C27: 9000070824 | D27: 9000070824 100002 | E27: 406244888 | F27: 62
A28: 46134 | B28: 212173280 | C28: 9000071090 | D28: 9000071090 100002 | E28: 406448767 | F28: 72 | G28: 実績上げ処理済み、4/22夜間に連携
A29: 46134 | B29: 212173279 | C29: 9000071090 | D29: 9000071090 100002 | E29: 406448767 | F29: 13 | G29: 情シスメール分 実績修正お願いします。
A30: 46134 | B30: 212173279 | C30: 9000071090 | D30: 9000071090 100001 | E30: 406036211 | F30: 60
A31: 46134 | B31: 212182083 | C31: 9000067789 | D31: 9000067789 100040 | E31: 406141906 | F31: 394 | G31: 406332089 394PC | H31: 4941282022修正/4941282025で87PB取り消し
A32: 46134 | B32: 212182083 | C32: 9000067789 | D32: 9000067789 100041 | E32: 406332089 | F32: 87 | G32: 406141906 87PC
A33: 46139 | B33: 212182083 | C33: 9000067789 | D33: 9000067789 100040 | E33: 406141906 | F33: 81 | G33: 406141906 81PC
A34: 46139 | B34: 212182083 | C34: 9000067789 | D34: 9000067789 100041 | E34: 406332089 | F34: 400 | G34: 406141906 400PC
A35: 46139 | B35: 212182084 | C35: 9000067789 | D35: 9000067789 100040 | E35: 406141906 | F35: 480 | H35: 4941282020修正/4941282021で406332089/480PC取り消し
A36: 46139 | B36: 212186061 | C36: 9000064027 | D36: 9000064027 100023 | E36: 406355517 | F36: 48 | G36: 設備で異常な取り付けを確認しました。 原因不明、新規不具合です。 対象の作業者が1名なので作業ミスな 気がしますが原因調査中です。
A37: 46139 | B37: 212186060 | C37: 9000064027 | D37: 9000064027 100023 | E37: 406355517 | F37: 48
A38: 46139 | B38: 212184954 | C38: 9000064027 | D38: 9000064027 100023 | E38: 406355517 | F38: 1
A39: 46139 | B39: 212184954 | C39: 9000064027 | D39: 9000064027 100022 | E39: 406244486 | F39: 48
A40: 46139 | B40: 212182082 | C40: 9000066862 | E40: 406431159 | F40: 13 | G40: 本部品は日常的に設備で+1～+7の差分を出しているようです。
...

Sheet 計算用
A1: =IF(O1="","",O1) -> 212201177 | B1: =IF(P1="","",P1) -> 606177A | C1: =IF(Q1="","",Q1) -> 606177A100271 | D1: =IF(R1="","",R1) -> 406192431 | E1: =IF(X1="","",X1) -> 47 | G1: ↓超えた分 | I1: 次のロット | J1: {=LOOKUP(2, 1/(E:E<>""), E:E)-J2} -> 19 | L1: ここに貼付→ | M1: 3034708 | N1: 000212201177-2010 | O1: 212201177 | P1: 606177A | Q1: 606177A100271 | R1: 406192431 | S1: 2 | T1: M24 | U1: 46177.81 | V1: 46178.423 | W1: 100130 | X1: 47 | Y1: 47 | Z1: 0 | AA1: 46178.419 | AB1: 46178.426
A2: =IF(O2="","",O2) | B2: =IF(P2="","",P2) | C2: =IF(Q2="","",Q2) | D2: =IF(R2="","",R2) | E2: =IF(X2="","",X2) | G2: 19 | I2: 正しいロット | J2: =SUM(E:E)-G2 -> 28
A3: =IF(O3="","",O3) | B3: =IF(P3="","",P3) | C3: =IF(Q3="","",Q3) | D3: =IF(R3="","",R3) | E3: =IF(X3="","",X3)
A4: =IF(O4="","",O4) | B4: =IF(P4="","",P4) | C4: =IF(Q4="","",Q4) | D4: =IF(R4="","",R4) | E4: =IF(X4="","",X4)
A5: =IF(O5="","",O5) | B5: =IF(P5="","",P5) | C5: =IF(Q5="","",Q5) | D5: =IF(R5="","",R5) | E5: =IF(X5="","",X5)
A6: =IF(O6="","",O6) | B6: =IF(P6="","",P6) | C6: =IF(Q6="","",Q6) | D6: =IF(R6="","",R6) | E6: =IF(X6="","",X6)
A7: =IF(O7="","",O7) | B7: =IF(P7="","",P7) | C7: =IF(Q7="","",Q7) | D7: =IF(R7="","",R7) | E7: =IF(X7="","",X7)
A8: =IF(O8="","",O8) | B8: =IF(P8="","",P8) | C8: =IF(Q8="","",Q8) | D8: =IF(R8="","",R8) | E8: =IF(X8="","",X8)
A9: =IF(O9="","",O9) | B9: =IF(P9="","",P9) | C9: =IF(Q9="","",Q9) | D9: =IF(R9="","",R9) | E9: =IF(X9="","",X9)
A10: =IF(O10="","",O10) | B10: =IF(P10="","",P10) | C10: =IF(Q10="","",Q10) | D10: =IF(R10="","",R10) | E10: =IF(X10="","",X10)
A11: =IF(O11="","",O11) | B11: =IF(P11="","",P11) | C11: =IF(Q11="","",Q11) | D11: =IF(R11="","",R11) | E11: =IF(X11="","",X11)
A12: =IF(O12="","",O12) | B12: =IF(P12="","",P12) | C12: =IF(Q12="","",Q12) | D12: =IF(R12="","",R12) | E12: =IF(X12="","",X12)
A13: =IF(O13="","",O13) | B13: =IF(P13="","",P13) | C13: =IF(Q13="","",Q13) | D13: =IF(R13="","",R13) | E13: =IF(X13="","",X13)
A14: =IF(O14="","",O14) | B14: =IF(P14="","",P14) | C14: =IF(Q14="","",Q14) | D14: =IF(R14="","",R14) | E14: =IF(X14="","",X14)
... A40: =IF(O40="","",O40) | B40: =IF(P40="","",P40) | C40: =IF(Q40="","",Q40) | D40: =IF(R40="","",R40) | E40: =IF(X40="","",X40)

Sheet EGP　MES BOSS差異
B1: 日付 | C1: 保管場所 | D1: 品目 | E1: 数量 | F1: LOT | G1: 処理伝票NO | H1: MESその他出庫 | I1: テキスト「 | J1: EGPro調整出庫 | K1: 」
A2: 関口 | B2: 20250522 | C2: 0001 | D2: 9000064828 | E2: 2 | F2: 406491827 | G2: 4941478866 | H2: 済
A3: 関口 | B3: 20250522 | C3: 0001 | D3: 9000064828 | E3: 2 | F3: 406496926 | G3: 4941478866 | H3: 済
A4: 菅原 | B4: 20260624 | C4: 0001 | D4: 9000069231 | E4: 2 | F4: 406314602 | G4: 4941905816 | H4: 済
A5: 菅原 | B5: 20260630 | C5: 0001 | D5: 534806 | E5: 1 | F5: 406236786 | G5: 4941908660 | H5: 済
A6: 菅原 | B6: 20260702 | C6: 0001 | D6: 363447B | E6: 4 | F6: 403757143 | G6: 4941998069 | H6: 済
A7: 菅原 | B7: 20260706 | C7: 0001 | D7: 9000063369 | E7: 1 | F7: 405706192 | G7: 4941998069 | H7: 済
A8: 菅原 | B8: 20260707 | C8: 0001 | D8: 9000063330 | E8: 1 | F8: 405585400 | G8: 4941998069 | H8: 済
A9: 菅原 | B9: 20260707 | C9: 0001 | D9: 9000053728 | E9: 1 | F9: 406194252 | G9: 4941998069 | H9: 済
A10: 菅原 | B10: 20260707 | C10: 0001 | D10: 9000047227 | E10: 1 | F10: 406160786 | G10: 4941998069 | H10: 済
A11: 菅原 | B11: 20260710 | C11: 0001 | D11: 935543 | E11: 3 | F11: 405920350 | G11: 4942106345 | H11: 済
A12: 菅原 | B12: 20260710 | C12: 0001 | D12: 9000045942 | E12: 2 | F12: 406115755 | G12: 4942106345 | H12: 済
A13: 菅原 | B13: 20260717 | C13: 0001 | D13: 9000067543 | E13: 1 | F13: 406393820 | G13: 4942106345 | H13: 済
A14: 菅原 | B14: 20260723 | C14: 0001 | D14: 9000063376 | E14: 1 | F14: 406432978

Sheet 4.13Egp差異
B1: 番号 | C1: 品目 | D1: ロット | E1: 差異入力数 | F1: ←差異→ | G1: →合計 | H1: 212179065 | I1: 212179068 | J1: 212179616 | K1: 212179642 | L1: 212179615 | M1: 212179619 | O1: 212179615 | P1: 212179619
A2: =C2&D2 -> 346047B406369094 | B2: 212179065 | C2: 346047B | D2: 406369094 | E2: 575 | F2: =E2-G2 -> -1 | G2: =SUM(H2:M2) -> 576 | H2: 384 | I2: 0 | J2: 96 | K2: 96 | L2: 0 | M2: 0 | O2: #N/A | P2: 192
A3: =C3&D3 -> 581639A406378753 | B3: 212179619 | C3: 581639A | D3: 406378753 | E3: 33 | F3: =E3-G3 -> 0 | G3: =SUM(H3:M3) -> 33 | H3: 0 | I3: 0 | J3: 0 | K3: 0 | L3: 0 | M3: 33 | O3: #N/A | P3: 384
A4: =C4&D4 -> 611135B406374905 | B4: 212179616 | C4: 611135B | D4: 406374905 | E4: 746 | F4: =E4-G4 -> -166 | G4: =SUM(H4:M4) -> 912 | H4: 384 | I4: 336 | J4: 96 | K4: 96 | L4: 0 | M4: 0 | O4: #N/A | P4: #N/A
A5: =C5&D5 -> 616504A406091904 | B5: 212180182 | C5: 616504A | D5: 406091904 | E5: 57 | F5: =E5-G5 -> -519 | G5: =SUM(H5:M5) -> 576 | H5: 576 | I5: 0 | J5: 0 | K5: 0 | L5: 0 | M5: 0 | O5: #N/A | P5: #N/A
A6: =C6&D6 -> 654641406146706 | B6: 212179068 | C6: 654641 | D6: 406146706 | E6: 1822 | F6: =E6-G6 -> -2 | G6: =SUM(H6:M6) -> 1824 | H6: 768 | I6: 672 | J6: 192 | K6: 192 | L6: 0 | M6: 0 | O6: #N/A | P6: 384
A7: =C7&D7 -> 655417406310286 | B7: 212179065 | C7: 655417 | D7: 406310286 | E7: 896 | F7: =E7-G7 -> 0 | G7: =SUM(H7:M7) -> 896 | H7: 384 | I7: 336 | J7: 80 | K7: 96 | L7: 0 | M7: 0 | O7: #N/A | P7: #N/A
A8: =C8&D8 -> 667164A406147000 | B8: 212179068 | C8: 667164A | D8: 406147000 | E8: 4560 | F8: =E8-G8 -> 0 | G8: =SUM(H8:M8) -> 4560 | H8: 1920 | I8: 1680 | J8: 480 | K8: 480 | L8: 0 | M8: 0 | O8: #N/A | P8: #N/A
A9: =C9&D9 -> 667271A406340150 | B9: 212179614 | C9: 667271A | D9: 406340150 | E9: 457 | F9: =E9-G9 -> 1 | G9: =SUM(H9:M9) -> 456 | H9: 192 | I9: 168 | J9: 48 | K9: 48 | L9: 0 | M9: 0 | O9: #N/A | P9: #N/A
A10: =C10&D10 -> 667351A406192570 | B10: 212179614 | C10: 667351A | D10: 406192570 | E10: 458 | F10: =E10-G10 -> 2 | G10: =SUM(H10:M10) -> 456 | H10: 192 | I10: 168 | J10: 48 | K10: 48 | L10: 0 | M10: 0 | O10: #N/A | P10: #N/A
A11: =C11&D11 -> 667672406314232 | B11: 212179065 | C11: 667672 | D11: 406314232 | E11: 1321 | F11: =E11-G11 -> 1 | G11: =SUM(H11:M11) -> 1320 | H11: 384 | I11: 840 | J11: 48 | K11: 48 | L11: 0 | M11: 0 | O11: #N/A | P11: 384
A12: =C12&D12 -> 667823406321815 | B12: 212179065 | C12: 667823 | D12: 406321815 | E12: 913 | F12: =E12-G12 -> 0 | G12: =SUM(H12:M12) -> 913 | H12: 192 | I12: 504 | J12: 73 | K12: 144 | L12: 0 | M12: 0 | O12: #N/A | P12: 192
A13: =C13&D13 -> 675609A406141038 | B13: 212179616 | C13: 675609A | D13: 406141038 | E13: 894 | F13: =E13-G13 -> -18 | G13: =SUM(H13:M13) -> 912 | H13: 384 | I13: 336 | J13: 96 | K13: 96 | L13: 0 | M13: 0 | O13: #N/A | P13: #N/A
A14: =C14&D14 -> 9000028364406256811 | B14: 212179617 | C14: 9000028364 | D14: 406256811 | E14: 417 | F14: =E14-G14 -> -111 | G14: =SUM(H14:M14) -> 528 | H14: 0 | I14: 336 | J14: 96 | K14: 96 | L14: 0 | M14: 0 | O14: #N/A | P14: #N/A
A15: =C15&D15 -> 9000035579406286924 | B15: 212179068 | C15: 9000035579 | D15: 406286924 | E15: 825 | F15: =E15-G15 -> 3 | G15: =SUM(H15:M15) -> 822 | H15: 0 | I15: 504 | J15: 144 | K15: 174 | L15: 0 | M15: 0 | O15: #N/A | P15: #N/A
A16: =C16&D16 -> 9000040403406325204 | B16: 212180182 | C16: 9000040403 | D16: 406325204 | E16: 162 | F16: =E16-G16 -> -294 | G16: =SUM(H16:M16) -> 456 | H16: 192 | I16: 168 | J16: 48 | K16: 48 | L16: 0 | M16: 0 | O16: #N/A | P16: 192
A17: =C17&D17 -> 9000041866406258230 | B17: 212179068 | C17: 9000041866 | D17: 406258230 | E17: 39 | F17: =E17-G17 -> 0 | G17: =SUM(H17:M17) -> 39 | H17: 0 | I17: 39 | J17: 0 | K17: 0 | L17: 0 | M17: 0 | O17: #N/A | P17: #N/A
A18: =C18&D18 -> 9000051053406260353 | B18: 212179068 | C18: 9000051053 | D18: 406260353 | E18: 27466 | F18: =E18-G18 -> -8198 | G18: =SUM(H18:M18) -> 35664 | H18: 0 | I18: 28896 | J18: 3408 | K18: 3360 | L18: 0 | M18: 0 | O18: #N/A | P18: #N/A
A19: =C19&D19 -> 9000051053406269948 | C19: 9000051053 | D19: 406269948 | E19: 10553 | F19: =E19-G19 -> -7 | G19: =SUM(H19:M19) -> 10560 | H19: 0 | I19: 0 | J19: 5328 | K19: 5232 | L19: 0 | M19: 0 | O19: #N/A | P19: #N/A
A20: =C20&D20 -> 9000053479406340161 | B20: 212179614 | C20: 9000053479 | D20: 406340161 | E20: 911 | F20: =E20-G20 -> -1 | G20: =SUM(H20:M20) -> 912 | H20: 384 | I20: 336 | J20: 96 | K20: 96 | L20: 0 | M20: 0 | O20: #N/A | P20: #N/A
A21: =C21&D21 -> 9000059114406007475 | B21: 212180221 | C21: 9000059114 | D21: 406007475 | E21: 48 | F21: =E21-G21 -> -48 | G21: =SUM(H21:M21) -> 96 | H21: 0 | I21: 0 | J21: 48 | K21: 48 | L21: 0 | M21: 0 | O21: #N/A | P21: #N/A
A22: =C22&D22 -> 9000059200406115645 | B22: 212179065 | C22: 9000059200 | D22: 406115645 | E22: 384 | F22: =E22-G22 -> 0 | G22: =SUM(H22:M22) -> 384 | H22: 192 | I22: 168 | J22: 0 | K22: 24 | L22: 0 | M22: 0 | O22: #N/A | P22: #N/A
A23: =C23&D23 -> 9000059207406370333 | B23: 212179617 | C23: 9000059207 | D23: 406370333 | E23: 352 | F23: =E23-G23 -> -104 | G23: =SUM(H23:M23) -> 456 | H23: 192 | I23: 168 | J23: 48 | K23: 48 | L23: 0 | M23: 0 | O23: #N/A | P23: #N/A
A24: =C24&D24 -> 9000059217406263653 | B24: 212179068 | C24: 9000059217 | D24: 406263653 | E24: 711 | F24: =E24-G24 -> 1 | G24: =SUM(H24:M24) -> 710 | H24: 0 | I24: 710 | J24: 0 | K24: 0 | L24: 0 | M24: 0 | O24: #N/A | P24: #N/A
A25: =C25&D25 -> 9000059823406421021 | B25: 212179068 | C25: 9000059823 | D25: 406421021 | E25: 363 | F25: =E25-G25 -> 3 | G25: =SUM(H25:M25) -> 360 | H25: 192 | I25: 168 | J25: 0 | K25: 0 | L25: 0 | M25: 0 | O25: #N/A | P25: #N/A
A26: =C26&D26 -> 9000060539406092856 | B26: 212179065 | C26: 9000060539 | D26: 406092856 | E26: 453 | F26: =E26-G26 -> -3 | G26: =SUM(H26:M26) -> 456 | H26: 192 | I26: 168 | J26: 48 | K26: 48 | L26: 0 | M26: 0 | O26: #N/A | P26: #N/A
A27: =C27&D27 -> 9000066299405875950 | B27: 212179614 | C27: 9000066299 | D27: 405875950 | E27: 453 | F27: =E27-G27 -> -3 | G27: =SUM(H27:M27) -> 456 | H27: 192 | I27: 168 | J27: 48 | K27: 48 | L27: 0 | M27: 0 | O27: #N/A | P27: #N/A
A28: =C28&D28 -> 9000066517406392103 | B28: 212179068 | C28: 9000066517 | D28: 406392103 | E28: 1293 | F28: =E28-G28 -> 1 | G28: =SUM(H28:M28) -> 1292 | H28: 0 | I28: 1292 | J28: 0 | K28: 0 | L28: 0 | M28: 0 | O28: #N/A | P28: #N/A
A29: =C29&D29 -> 9000066578406313246 | B29: 212179616 | C29: 9000066578 | D29: 406313246 | E29: 2574 | F29: =E29-G29 -> -66 | G29: =SUM(H29:M29) -> 2640 | H29: 0 | I29: 1680 | J29: 480 | K29: 480 | L29: 0 | M29: 0 | O29: #N/A | P29: #N/A
A30: =C30&D30 -> 9000066587406393799 | B30: 212179068 | C30: 9000066587 | D30: 406393799 | E30: 218 | F30: =E30-G30 -> 0 | G30: =SUM(H30:M30) -> 218 | H30: 0 | I30: 168 | J30: 2 | K30: 48 | L30: 0 | M30: 0 | O30: #N/A | P30: #N/A
A31: =C31&D31 -> 9000066588406313242 | B31: 212179068 | C31: 9000066588 | D31: 406313242 | E31: 1878 | F31: =E31-G31 -> 2 | G31: =SUM(H31:M31) -> 1876 | H31: 0 | I31: 1512 | J31: 144 | K31: 220 | L31: 0 | M31: 0 | O31: #N/A | P31: #N/A
... A33: =C33&D33 -> 9000066594406366312 | B33: 212179065 | C33: 9000066594 | D33: 406366312 | E33: 212 | F33: =E33-G33 -> 0 | G33: =SUM(H33:M33) -> 212 | H33: 192 | I33: 20 | J33: 0 | K33: 0 | L33: 0 | M33: 0 | O33: #N/A | P33: #N/A
A34: =C34&D34 -> 9000066595406377122 | B34: 212179616 | C34: 9000066595 | D34: 406377122 | E34: 2662 | F34: =E34-G34 -> -314 | G34: =SUM(H34:M34) -> 2976 | H34: 768 | I34: 1008 | J34: 336 | K34: 240 | L34: 624 | M34: 0 | O34: 1248 | P34: #N/A
A35: =C35&D35 -> 9000066598406362945 | B35: 212179065 | C35: 9000066598 | D35: 406362945 | E35: 9654 | F35: =E35-G35 -> -3882 | G35: =SUM(H35:M35) -> 13536 | H35: 13440 | I35: 0 | J35: 0 | K35: 0 | L35: 0 | M35: 96 | O35: #N/A | P35: 192
A36: =C36&D36 -> 9000066687406403337 | B36: 212179068 | C36: 9000066687 | D36: 406403337 | E36: 77 | F36: =E36-G36 -> 0 | G36: =SUM(H36:M36) -> 77 | H36: 0 | I36: 77 | J36: 0 | K36: 0 | L36: 0 | M36: 0 | O36: #N/A | P36: #N/A
A37: =C37&D37 -> 9000066815406306114 | B37: 212179068 | C37: 9000066815 | D37: 406306114 | E37: 168 | F37: =E37-G37 -> 0 | G37: =SUM(H37:M37) -> 168 | H37: 0 | I37: 168 | J37: 0 | K37: 0 | L37: 0 | M37: 0 | O37: #N/A | P37: #N/A
A38: =C38&D38 -> 9000066849406372330 | B38: 212179617 | C38: 9000066849 | D38: 406372330 | E38: 737 | F38: =E38-G38 -> -1999 | G38: =SUM(H38:M38) -> 2736 | H38: 1152 | I38: 1008 | J38: 288 | K38: 288 | L38: 0 | M38: 0 | O38: #N/A | P38: #N/A
A39: =C39&D39 -> 9000066896406366309 | B39: 212179065 | C39: 9000066896 | D39: 406366309 | E39: 192 | F39: =E39-G39 -> 0 | G39: =SUM(H39:M39) -> 192 | H39: 192 | I39: 0 | J39: 0 | K39: 0 | L39: 0 | M39: 0 | O39: #N/A | P39: #N/A
A40: =C40&D40 -> 9000066900406203171 | B40: 212179065 | C40: 9000066900 | D40: 406203171 | E40: 458 | F40: =E40-G40 -> 2 | G40: =SUM(H40:M40) -> 456 | H40: 192 | I40: 168 | J40: 48 | K40: 48 | L40: 0 | M40: 0 | O40: #N/A | P40: #N/A
A41: =C41&D41 -> 9000067013406399997 | B41: 212179065 | C41: 9000067013 | D41: 406399997 | E41: 192 | F41: =E41-G41 -> 0 | G41: =SUM(H41:M41) -> 192 | H41: 192 | I41: 0 | J41: 0 | K41: 0 | L41: 0 | M41: 0 | O41: #N/A | P41: #N/A
...

Sheet 4.10に2重に送信した生データ
A1: 品目 | B1: 合計 | D1: 212179065 | E1: 212179068 | F1: 212179615 | G1: 212179616 | H1: 212179619 | I1: 212179642
A2: 534806 | B2: =SUM(D2:I2) -> 456 | C2: 456 | D2: 192 | E2: 168 | G2: 48 | I2: 48 | J2: =B2-C2 -> 0
A3: 554179 | B3: =SUM(D3:I3) -> 552 | C3: 552 | D3: 192 | E3: 168 | G3: 48 | H3: 96 | I3: 48 | J3: =B3-C3 -> 0
A4: 587535 | B4: =SUM(D4:I4) -> 552 | C4: 552 | D4: 192 | E4: 168 | G4: 48 | H4: 96 | I4: 48 | J4: =B4-C4 -> 0
A5: 608932 | B5: =SUM(D5:I5) -> 216 | C5: 216 | E5: 168 | G5: 48 | J5: =B5-C5 -> 0
A6: 620508 | B6: =SUM(D6:I6) -> 6336 | C6: 6337 | D6: 6336 | J6: =B6-C6 -> -1
A7: 620598 | B7: =SUM(D7:I7) -> 192 | C7: 192 | H7: 192 | J7: =B7-C7 -> 0
A8: 620606 | B8: =SUM(D8:I8) -> 552 | C8: 552 | D8: 192 | E8: 168 | G8: 48 | H8: 96 | I8: 48 | J8: =B8-C8 -> 0
A9: 620624 | B9: =SUM(D9:I9) -> 1464 | C9: 1464 | D9: 576 | E9: 504 | G9: 144 | H9: 96 | I9: 144 | J9: =B9-C9 -> 0
A10: 632023 | B10: =SUM(D10:I10) -> 1656 | C10: 1659 | D10: 576 | E10: 504 | G10: 144 | H10: 288 | I10: 144 | J10: =B10-C10 -> -3
A11: 632032 | B11: =SUM(D11:I11) -> 192 | C11: 193 | G11: 96 | I11: 96 | J11: =B11-C11 -> -1
A12: 639132 | B12: =SUM(D12:I12) -> 456 | C12: 456 | D12: 192 | E12: 168 | G12: 48 | I12: 48 | J12: =B12-C12 -> 0
A13: 641263 | B13: =SUM(D13:I13) -> 528 | C13: 528 | D13: 384 | H13: 96 | I13: 48 | J13: =B13-C13 -> 0
A14: 644955 | B14: =SUM(D14:I14) -> 2280 | C14: 2280 | D14: 960 | E14: 840 | G14: 240 | I14: 240 | J14: =B14-C14 -> 0
A15: 654597 | B15: =SUM(D15:I15) -> 96 | C15: 96 | H15: 96 | J15: =B15-C15 -> 0
A16: 654605 | B16: =SUM(D16:I16) -> 1728 | C16: 1728 | D16: 1728 | J16: =B16-C16 -> 0
A17: 654614 | B17: =SUM(D17:I17) -> 384 | C17: 384 | D17: 384 | J17: =B17-C17 -> 0
A18: 654623 | B18: =SUM(D18:I18) -> 192 | C18: 192 | H18: 192 | J18: =B18-C18 -> 0
A19: 654641 | B19: =SUM(D19:I19) -> 2016 | C19: 2016 | D19: 768 | E19: 672 | G19: 192 | H19: 192 | I19: 192 | J19: =B19-C19 -> 0
A20: 655417 | B20: =SUM(D20:I20) -> 912 | C20: 912 | D20: 384 | E20: 336 | G20: 96 | I20: 96 | J20: =B20-C20 -> 0
A21: 658058 | B21: =SUM(D21:I21) -> 96 | C21: 96 | G21: 48 | I21: 48 | J21: =B21-C21 -> 0
A22: 659226 | B22: =SUM(D22:I22) -> 552 | C22: 552 | D22: 192 | E22: 168 | G22: 48 | H22: 96 | I22: 48 | J22: =B22-C22 -> 0
A23: 659298 | B23: =SUM(D23:I23) -> 25848 | C23: 25850 | D23: 10560 | E23: 8568 | G23: 2544 | H23: 1632 | I23: 2544 | J23: =B23-C23 -> -2
A24: 661393 | B24: =SUM(D24:I24) -> 2472 | C24: 2472 | D24: 960 | E24: 840 | G24: 336 | I24: 336 | J24: =B24-C24 -> 0
A25: 662516 | B25: =SUM(D25:I25) -> 96 | C25: 96 | H25: 96 | J25: =B25-C25 -> 0
A26: 662917 | B26: =SUM(D26:I26) -> 768 | C26: 768 | D26: 576 | H26: 192 | J26: =B26-C26 -> 0
A27: 663275 | B27: =SUM(D27:I27) -> 10776 | C27: 10777 | D27: 3648 | E27: 4536 | G27: 1296 | I27: 1296 | J27: =B27-C27 -> -1
A28: 663435 | B28: =SUM(D28:I28) -> 96 | C28: 96 | H28: 96 | J28: =B28-C28 -> 0
A29: 663738 | B29: =SUM(D29:I29) -> 456 | C29: 456 | D29: 192 | E29: 168 | G29: 48 | I29: 48 | J29: =B29-C29 -> 0
A30: 666192 | B30: =SUM(D30:I30) -> 3744 | C30: 3744 | H30: 3744 | J30: =B30-C30 -> 0
A31: 666744 | B31: =SUM(D31:I31) -> 648 | C31: 649 | D31: 384 | E31: 168 | G31: 48 | I31: 48 | J31: =B31-C31 -> -1
A32: 666771 | B32: =SUM(D32:I32) -> 192 | C32: 192 | H32: 192 | J32: =B32-C32 -> 0
A33: 666789 | B33: =SUM(D33:I33) -> 288 | C33: 288 | H33: 288 | J33: =B33-C33 -> 0
A34: 666824 | B34: =SUM(D34:I34) -> 264 | C34: 264 | E34: 168 | G34: 48 | I34: 48 | J34: =B34-C34 -> 0
A35: 667627 | B35: =SUM(D35:I35) -> 10776 | C35: 10777 | D35: 3456 | E35: 4536 | G35: 1344 | H35: 288 | I35: 1152 | J35: =B35-C35 -> -1
A36: 667636 | B36: =SUM(D36:I36) -> 13824 | C36: 13827 | D36: 5376 | E36: 4704 | G36: 1440 | H36: 864 | I36: 1440 | J36: =B36-C36 -> -3
A37: 667645 | B37: =SUM(D37:I37) -> 28824 | C37: 28827 | D37: 10560 | E37: 10248 | G37: 3120 | H37: 1824 | I37: 3072 | J37: =B37-C37 -> -3
A38: 667654 | B38: =SUM(D38:I38) -> 23328 | C38: 23330 | D38: 8064 | E38: 8736 | G38: 2736 | H38: 960 | I38: 2832 | J38: =B38-C38 -> -2
A39: 667672 | B39: =SUM(D39:I39) -> 1656 | C39: 1656 | D39: 384 | E39: 840 | G39: 144 | H39: 192 | I39: 96 | J39: =B39-C39 -> 0
A40: 667699 | B40: =SUM(D40:I40) -> 8088 | C40: 8089 | D40: 3456 | E40: 3192 | G40: 720 | I40: 720 | J40: =B40-C40 -> -1
...

Sheet 4.13差異
A1: 番号 | B1: 明細番号 | C1: 移動元プラント | D1: 移動タイプ | E1: 移動元棚番 | F1: 移動元保管場所 | G1: 移動元ロケーション | H1: 移動元在庫ステータス | I1: 移行先プラント | J1: 移動先棚番 | K1: 移動先保管場所 | L1: 移動先ロケーション | M1: 移動先在庫ステータス | N1: 品目コード | O1: 数量 | P1: ロットNO | Q1: 単位 | R1: ロット特採・代替品管理番号 | S1: ロット入庫日 | T1: ロット有効期限 | U1: ロット再検査有効期限 | V1: 移動理由 | W1: 取消日時_YYYYMMDDhhmmss | X1: 実績計上日時_YYYYMMDDhhmmss | Z1: 合計 / 数量
A2: 212173278 | B2: 1 | C2: B020 | D2: M40 | E2: A1A-A1-1-1 | F2: 0001 | G2: 0001-3 | H2: 1 | I2: B020 | J2: A1A-A1-1-1 | K2: 0001 | L2: 0001-3 | M2: 1 | N2: 675333A | O2: 3 | P2: 405640180 | Q2: PC | S2: 2024/11/06 | T2: < NULL > | U2: 2026/11/30 | W2: < NULL > | X2: 2026/04/10 18:30:28 | Z2: 品目コード | AA2: ロットNO | AB2: 集計
A3: 212173278 | B3: 1 | C3: B020 | D3: M40 | E3: A1A-A1-1-1 | F3: 0001 | G3: 0001-3 | H3: 1 | I3: B020 | J3: A1A-A1-1-1 | K3: 0001 | L3: 0001-3 | M3: 1 | N3: 9000071839 | O3: 1 | P3: 406310936 | Q3: PC | R3: R4120717-250188 | S3: 2025/10/09 | T3: < NULL > | U3: 2026/11/30 | W3: < NULL > | X3: 2026/04/10 18:30:28 | Z3: 346047B | AA3: 406369094 | AB3: 575
A4: 212179065 | B4: 1 | C4: B020 | D4: M40 | E4: A1A-A1-1-1 | F4: 0001 | G4: 0001-3 | H4: 1 | I4: B020 | J4: A1A-A1-1-1 | K4: 0001 | L4: 0001-3 | M4: 1 | N4: 346047B | O4: 371 | P4: 406369094 | Q4: PC | S4: 2025/12/17 | T4: < NULL > | U4: 2026/12/31 | W4: < NULL > | X4: 2026/04/10 18:30:28 | Z4: 346047B 集計 | AB4: 575
A5: 212179065 | B5: 1 | C5: B020 | D5: M40 | F5: 0001 | G5: 0001-3 | H5: 1 | I5: B020 | K5: 0001 | L5: 0001-3 | M5: 1 | N5: 655417 | O5: 384 | P5: 406310286 | Q5: PC | S5: 2025/12/08 | T5: < NULL > | U5: 2026/12/31 | W5: < NULL > | X5: 2026/04/10 18:30:28 | Z5: 581639A | AA5: 406378753 | AB5: 33
A6: 212179065 | B6: 1 | C6: B020 | D6: M40 | E6: A1A-A1-1-1 | F6: 0001 | G6: 0001-3 | H6: 1 | I6: B020 | J6: A1A-A1-1-1 | K6: 0001 | L6: 0001-3 | M6: 1 | N6: 667672 | O6: 325 | P6: 406314232 | Q6: PC | S6: 2025/12/09 | T6: < NULL > | U6: 2026/12/31 | W6: < NULL > | X6: 2026/04/10 18:30:28 | Z6: 581639A 集計 | AB6: 33
A7: 212179065 | B7: 1 | C7: B020 | D7: M40 | E7: A1A-A1-1-1 | F7: 0001 | G7: 0001-3 | H7: 1 | I7: B020 | J7: A1A-A1-1-1 | K7: 0001 | L7: 0001-3 | M7: 1 | N7: 667823 | O7: 47 | P7: 406321815 | Q7: PC | S7: 2025/12/23 | T7: < NULL > | U7: 2026/12/31 | W7: < NULL > | X7: 2026/04/10 18:30:28 | Z7: 611135B | AA7: 406374905 | AB7: 746
A8: 212179065 | B8: 1 | C8: B020 | D8: M40 | F8: 0001 | G8: 0001-3 | H8: 1 | I8: B020 | K8: 0001 | L8: 0001-3 | M8: 1 | N8: 9000059200 | O8: 192 | P8: 406115645 | Q8: PC | S8: 2025/11/07 | T8: < NULL > | U8: 2026/11/30 | W8: < NULL > | X8: 2026/04/10 18:30:28 | Z8: 611135B 集計 | AB8: 746
A9: 212179065 | B9: 1 | C9: B020 | D9: M40 | E9: A1A-A1-1-1 | F9: 0001 | G9: 0001-3 | H9: 1 | I9: B020 | J9: A1A-A1-1-1 | K9: 0001 | L9: 0001-3 | M9: 1 | N9: 9000060539 | O9: 171 | P9: 406092856 | Q9: PC | S9: 2025/11/05 | T9: < NULL > | U9: 2026/11/30 | W9: < NULL > | X9: 2026/04/10 18:30:28 | Z9: 616504A | AA9: 406091904 | AB9: 57
A10: 212179065 | B10: 1 | C10: B020 | D10: M40 | F10: 0001 | G10: 0001-3 | H10: 1 | I10: B020 | K10: 0001 | L10: 0001-3 | M10: 1 | N10: 9000066594 | O10: 192 | P10: 406366312 | Q10: PC | S10: 2025/12/10 | T10: < NULL > | U10: 2026/12/31 | W10: < NULL > | X10: 2026/04/10 18:30:28 | Z10: 616504A 集計 | AB10: 57
A11: 212179065 | B11: 1 | C11: B020 | D11: M40 | E11: A1A-A1-1-1 | F11: 0001 | G11: 0001-3 | H11: 1 | I11: B020 | J11: A1A-A1-1-1 | K11: 0001 | L11: 0001-3 | M11: 1 | N11: 9000066598 | O11: 3351 | P11: 406362945 | Q11: PC | S11: 2025/12/05 | T11: < NULL > | U11: 2026/12/31 | W11: < NULL > | X11: 2026/04/10 18:30:28 | Z11: 620624 | AA11: 406352701 | AB11: 4
A12: 212179065 | B12: 1 | C12: B020 | D12: M40 | E12: A1A-A1-1-1 | F12: 0001 | G12: 0001-3 | H12: 1 | I12: B020 | J12: A1A-A1-1-1 | K12: 0001 | L12: 0001-3 | M12: 1 | N12: 9000066896 | O12: 70 | P12: 406366309 | Q12: PC | S12: 2025/12/16 | T12: < NULL > | U12: 2026/12/31 | W12: < NULL > | X12: 2026/04/10 18:30:28 | Z12: 620624 集計 | AB12: 4
A13: 212179065 | B13: 1 | C13: B020 | D13: M40 | E13: A1A-A1-1-1 | F13: 0001 | G13: 0001-3 | H13: 1 | I13: B020 | J13: A1A-A1-1-1 | K13: 0001 | L13: 0001-3 | M13: 1 | N13: 9000066900 | O13: 159 | P13: 406203171 | Q13: PC | S13: 2025/10/16 | T13: < NULL > | U13: 2026/11/30 | W13: < NULL > | X13: 2026/04/10 18:30:28 | Z13: 632718 | AA13: 406361443 | AB13: 2
A14: 212179065 | B14: 1 | C14: B020 | D14: M40 | E14: A1A-A1-1-1 | F14: 0001 | G14: 0001-3 | H14: 1 | I14: B020 | J14: A1A-A1-1-1 | K14: 0001 | L14: 0001-3 | M14: 1 | N14: 9000067013 | O14: 69 | P14: 406399997 | Q14: PC | S14: 2026/01/29 | T14: < NULL > | U14: 2027/01/31 | W14: < NULL > | X14: 2026/04/10 18:30:28 | Z14: 632718 集計 | AB14: 2
A15: 212179065 | B15: 1 | C15: B020 | D15: M40 | F15: 0001 | G15: 0001-3 | H15: 1 | I15: B020 | K15: 0001 | L15: 0001-3 | M15: 1 | N15: 9000067014 | O15: 1872 | P15: 406350519 | Q15: PC | S15: 2025/11/25 | T15: < NULL > | U15: 2026/11/30 | W15: < NULL > | X15: 2026/04/10 18:30:28 | Z15: 651555B | AA15: 406091323 | AB15: 2
A16: 212179065 | B16: 1 | C16: B020 | D16: M40 | E16: A1A-A1-1-1 | F16: 0001 | G16: 0001-3 | H16: 1 | I16: B020 | J16: A1A-A1-1-1 | K16: 0001 | L16: 0001-3 | M16: 1 | N16: 9000067289 | O16: 312 | P16: 406416296 | Q16: PC | S16: 2026/01/20 | T16: < NULL > | U16: 2027/01/31 | W16: < NULL > | X16: 2026/04/10 18:30:28 | Z16: 651555B 集計 | AB16: 2
A17: 212179065 | B17: 1 | C17: B020 | D17: M40 | F17: 0001 | G17: 0001-3 | H17: 1 | I17: B020 | K17: 0001 | L17: 0001-3 | M17: 1 | N17: 9000068524 | O17: 960 | P17: 406407728 | Q17: PC | S17: 2026/02/06 | T17: < NULL > | U17: 2027/02/28 | W17: < NULL > | X17: 2026/04/10 18:30:28 | Z17: 654641 | AA17: 406146706 | AB17: 1822
A18: 212179065 | B18: 1 | C18: B020 | D18: M40 | F18: 0001 | G18: 0001-3 | H18: 1 | I18: B020 | K18: 0001 | L18: 0001-3 | M18: 1 | N18: 9000069417 | O18: 576 | P18: 406325233 | Q18: PC | S18: 2025/11/13 | T18: < NULL > | U18: 2026/11/30 | W18: < NULL > | X18: 2026/04/10 18:30:28 | Z18: 654641 集計 | AB18: 1822
A19: 212179065 | B19: 1 | C19: B020 | D19: M40 | F19: 0001 | G19: 0001-3 | H19: 1 | I19: B020 | K19: 0001 | L19: 0001-3 | M19: 1 | N19: 908092 | O19: 152 | P19: 406141066 | Q19: PC | S19: 2025/09/08 | T19: < NULL > | U19: 2026/11/30 | W19: < NULL > | X19: 2026/04/10 18:30:28 | Z19: 655417 | AA19: 406310286 | AB19: 896
A20: 212179065 | B20: 1 | C20: B020 | D20: M40 | E20: A1A-A1-1-1 | F20: 0001 | G20: 0001-3 | H20: 1 | I20: B020 | J20: A1A-A1-1-1 | K20: 0001 | L20: 0001-3 | M20: 1 | N20: 938442 | O20: 110 | P20: 406326723 | Q20: PC | S20: 2025/12/23 | T20: < NULL > | U20: 2026/12/31 | W20: < NULL > | X20: 2026/04/10 18:30:28 | Z20: 655417 集計 | AB20: 896
A21: 212179068 | B21: 1 | C21: B020 | D21: M40 | E21: A1A-A1-1-1 | F21: 0001 | G21: 0001-3 | H21: 1 | I21: B020 | J21: A1A-A1-1-1 | K21: 0001 | L21: 0001-3 | M21: 1 | N21: 654641 | O21: 342 | P21: 406146706 | Q21: PC | S21: 2025/08/26 | T21: < NULL > | U21: 2026/11/30 | W21: < NULL > | X21: 2026/04/10 18:30:28 | Z21: 667164A | AA21: 406147000 | AB21: 4560
A22: 212179068 | B22: 1 | C22: B020 | D22: M40 | F22: 0001 | G22: 0001-3 | H22: 1 | I22: B020 | K22: 0001 | L22: 0001-3 | M22: 1 | N22: 655417 | O22: 336 | P22: 406310286 | Q22: PC | S22: 2025/12/08 | T22: < NULL > | U22: 2026/12/31 | W22: < NULL > | X22: 2026/04/10 18:30:28 | Z22: 667164A 集計 | AB22: 4560
A23: 212179068 | B23: 1 | C23: B020 | D23: M40 | E23: A1A-A1-1-1 | F23: 0001 | G23: 0001-3 | H23: 1 | I23: B020 | J23: A1A-A1-1-1 | K23: 0001 | L23: 0001-3 | M23: 1 | N23: 667164A | O23: 905 | P23: 406147000 | Q23: PC | S23: 2025/09/01 | T23: < NULL > | U23: 2026/11/30 | W23: < NULL > | X23: 2026/04/10 18:30:28 | Z23: 667271A | AA23: 406340150 | AB23: 457
A24: 212179068 | B24: 1 | C24: B020 | D24: M40 | E24: A1A-A1-1-1 | F24: 0001 | G24: 0001-3 | H24: 1 | I24: B020 | J24: A1A-A1-1-1 | K24: 0001 | L24: 0001-3 | M24: 1 | N24: 667672 | O24: 840 | P24: 406314232 | Q24: PC | S24: 2025/12/09 | T24: < NULL > | U24: 2026/12/31 | W24: < NULL > | X24: 2026/04/10 18:30:28 | Z24: 667271A 集計 | AB24: 457
A25: 212179068 | B25: 1 | C25: B020 | D25: M40 | E25: A1A-A1-1-1 | F25: 0001 | G25: 0001-3 | H25: 1 | I25: B020 | J25: A1A-A1-1-1 | K25: 0001 | L25: 0001-3 | M25: 1 | N25: 667823 | O25: 504 | P25: 406321815 | Q25: PC | S25: 2025/12/23 | T25: < NULL > | U25: 2026/12/31 | W25: < NULL > | X25: 2026/04/10 18:30:28 | Z25: 667351A | AA25: 406192570 | AB25: 458
A26: 212179068 | B26: 1 | C26: B020 | D26: M40 | E26: A1A-A1-1-1 | F26: 0001 | G26: 0001-3 | H26: 1 | I26: B020 | J26: A1A-A1-1-1 | K26: 0001 | L26: 0001-3 | M26: 1 | N26: 9000035579 | O26: 2 | P26: 406286924 | Q26: PC | S26: 2025/11/04 | T26: < NULL > | U26: 2026/11/30 | W26: < NULL > | X26: 2026/04/10 18:30:28 | Z26: 667351A 集計 | AB26: 458
A27: 212179068 | B27: 1 | C27: B020 | D27: M40 | F27: 0001 | G27: 0001-3 | H27: 1 | I27: B020 | K27: 0001 | L27: 0001-3 | M27: 1 | N27: 9000041866 | O27: 39 | P27: 406258230 | Q27: PC | S27: 2025/10/07 | T27: < NULL > | U27: 2026/11/30 | W27: < NULL > | X27: 2026/04/10 18:30:28 | Z27: 667672 | AA27: 406314232 | AB27: 1321
A28: 212179068 | B28: 1 | C28: B020 | D28: M40 | E28: A1A-A1-1-1 | F28: 0001 | G28: 0001-3 | H28: 1 | I28: B020 | J28: A1A-A1-1-1 | K28: 0001 | L28: 0001-3 | M28: 1 | N28: 9000051053 | O28: 18894 | P28: 406260353 | Q28: PC | S28: 2025/10/03 | T28: < NULL > | U28: 2026/11/30 | W28: < NULL > | X28: 2026/04/10 18:30:28 | Z28: 667672 集計 | AB28: 1321
A29: 212179068 | B29: 1 | C29: B020 | D29: M40 | F29: 0001 | G29: 0001-3 | H29: 1 | I29: B020 | K29: 0001 | L29: 0001-3 | M29: 1 | N29: 9000059200 | O29: 168 | P29: 406115645 | Q29: PC | S29: 2025/11/07 | T29: < NULL > | U29: 2026/11/30 | W29: < NULL > | X29: 2026/04/10 18:30:28 | Z29: 667823 | AA29: 406321815 | AB29: 913
A30: 212179068 | B30: 1 | C30: B020 | D30: M40 | F30: 0001 | G30: 0001-3 | H30: 1 | I30: B020 | K30: 0001 | L30: 0001-3 | M30: 1 | N30: 9000059217 | O30: 711 | P30: 406263653 | Q30: PC | S30: 2025/10/06 | T30: < NULL > | U30: 2026/11/30 | W30: < NULL > | X30: 2026/04/10 18:30:28 | Z30: 667823 集計 | AB30: 913
A31: 212179068 | B31: 1 | C31: B020 | D31: M40 | E31: A1A-A1-1-1 | F31: 0001 | G31: 0001-3 | H31: 1 | I31: B020 | J31: A1A-A1-1-1 | K31: 0001 | L31: 0001-3 | M31: 1 | N31: 9000059823 | O31: 166 | P31: 406421021 | Q31: PC | S31: 2026/01/26 | T31: < NULL > | U31: 2027/01/31 | W31: < NULL > | X31: 2026/04/10 18:30:28 | Z31: 675333A | AA31: 405640180 | AB31: 3
A32: 212179068 | B32: 1 | C32: B020 | D32: M40 | E32: A1A-A1-1-1 | F32: 0001 | G32: 0001-3 | H32: 1 | I32: B020 | J32: A1A-A1-1-1 | K32: 0001 | L32: 0001-3 | M32: 1 | N32: 9000060539 | O32: 168 | P32: 406092856 | Q32: PC | S32: 2025/11/05 | T32: < NULL > | U32: 2026/11/30 | W32: < NULL > | X32: 2026/04/10 18:30:28 | Z32: 675333A 集計 | AB32: 3
A33: 212179068 | B33: 1 | C33: B020 | D33: M40 | F33: 0001 | G33: 0001-3 | H33: 1 | I33: B020 | K33: 0001 | L33: 0001-3 | M33: 1 | N33: 9000066517 | O33: 1293 | P33: 406392103 | Q33: PC | S33: 2026/01/16 | T33: < NULL > | U33: 2027/01/31 | W33: < NULL > | X33: 2026/04/10 18:30:28 | Z33: 675609A | AA33: 406141038 | AB33: 894
A34: 212179068 | B34: 1 | C34: B020 | D34: M40 | F34: 0001 | G34: 0001-3 | H34: 1 | I34: B020 | K34: 0001 | L34: 0001-3 | M34: 1 | N34: 9000066587 | O34: 168 | P34: 406393799 | Q34: PC | S34: 2026/01/19 | T34: < NULL > | U34: 2027/01/31 | W34: < NULL > | X34: 2026/04/10 18:30:28 | Z34: 675609A 集計 | AB34: 894
A35: 212179068 | B35: 1 | C35: B020 | D35: M40 | E35: A1A-A1-1-1 | F35: 0001 | G35: 0001-3 | H35: 1 | I35: B020 | J35: A1A-A1-1-1 | K35: 0001 | L35: 0001-3 | M35: 1 | N35: 9000066588 | O35: 1009 | P35: 406313242 | Q35: PC | S35: 2025/10/08 | T35: < NULL > | U35: 2026/11/30 | W35: < NULL > | X35: 2026/04/10 18:30:28 | Z35: 680666 | AA35: 406256775 | AB35: 1
A36: 212179068 | B36: 1 | C36: B020 | D36: M40 | E36: A1A-A1-1-1 | F36: 0001 | G36: 0001-3 | H36: 1 | I36: B020 | J36: A1A-A1-1-1 | K36: 0001 | L36: 0001-3 | M36: 1 | N36: 9000066591 | O36: 116 | P36: 406388651 | Q36: PC | S36: 2026/01/13 | T36: < NULL > | U36: 2027/01/31 | W36: < NULL > | X36: 2026/04/10 18:30:29 | Z36: 680666 集計 | AB36: 1
A37: 212179068 | B37: 1 | C37: B020 | D37: M40 | F37: 0001 | G37: 0001-3 | H37: 1 | I37: B020 | K37: 0001 | L37: 0001-3 | M37: 1 | N37: 9000066594 | O37: 20 | P37: 406366312 | Q37: PC | S37: 2025/12/10 | T37: < NULL > | U37: 2026/12/31 | W37: < NULL > | X37: 2026/04/10 18:30:29 | Z37: 9000028364 | AA37: 406256811 | AB37: 417
A38: 212179068 | B38: 1 | C38: B020 | D38: M40 | F38: 0001 | G38: 0001-3 | H38: 1 | I38: B020 | K38: 0001 | L38: 0001-3 | M38: 1 | N38: 9000066687 | O38: 77 | P38: 406403337 | Q38: PC | S38: 2026/01/30 | T38: < NULL > | U38: 2027/01/31 | W38: < NULL > | X38: 2026/04/10 18:30:29 | Z38: 9000028364 集計 | AB38: 417
A39: 212179068 | B39: 1 | C39: B020 | D39: M40 | E39: A1A-A1-1-1 | F39: 0001 | G39: 0001-3 | H39: 1 | I39: B020 | J39: A1A-A1-1-1 | K39: 0001 | L39: 0001-3 | M39: 1 | N39: 9000066815 | O39: 116 | P39: 406306114 | Q39: PC | S39: 2025/09/29 | T39: < NULL > | U39: 2026/11/30 | W39: < NULL > | X39: 2026/04/10 18:30:29 | Z39: 9000035579 | AA39: 406286924 | AB39: 825
A40: 212179068 | B40: 1 | C40: B020 | D40: M40 | E40: A1A-A1-1-1 | F40: 0001 | G40: 0001-3 | H40: 1 | I40: B020 | J40: A1A-A1-1-1 | K40: 0001 | L40: 0001-3 | M40: 1 | N40: 9000066900 | O40: 168 | P40: 406203171 | Q40: PC | S40: 2025/10/16 | T40: < NULL > | U40: 2026/11/30 | W40: < NULL > | X40: 2026/04/10 18:30:29 | Z40: 9000035579 集計 | AB40: 825
...

Sheet ①
A1: 品目コード | B1: 品目名称 | C1: プラント | D1: 保管場所 | E1: ロット番号 | F1: 数量単位 | G1: 利用可能在庫 | H1: 保留在庫 | I1: 有効期間期限日 | J1: 前回入庫日付 | K1: 再検査期限日
A2: 154468A | B2: RK73B2BTTD152J 1/4W 1.5K OHM | C2: B020 | D2: 0001 | E2: 405191015 | F2: PC | G2: 1262 | H2: 0 | J2: 44501 | K2: 46356
A3: 154468A | B3: RK73B2BTTD152J 1/4W 1.5K OHM | C3: B020 | D3: 0001 | E3: 405122329 | F3: PC | G3: 4396 | H3: 0 | J3: 44508 | K3: 46356
A4: 154468A | B4: RK73B2BTTD152J 1/4W 1.5K OHM | C4: B020 | D4: 0001 | E4: 405048375 | F4: PC | G4: 5000 | H4: 0 | J4: 44588 | K4: 46356
A5: 154468A | B5: RK73B2BTTD152J 1/4W 1.5K OHM | C5: B020 | D5: 0001 | E5: 405001228 | F5: PC | G5: 4502 | H5: 0 | J5: 44592 | K5: 46356
A6: 158704B | B6: RN412DTTE10R0F50 10 OHM | C6: B020 | D6: 0001 | E6: 405539208 | F6: PC | G6: 2000 | H6: 0 | J6: 45168 | K6: 46356
A7: 158704B | B7: RN412DTTE10R0F50 10 OHM | C7: B020 | D7: 0001 | E7: 405539569 | F7: PC | G7: 992 | H7: 0 | J7: 45168 | K7: 46356
A8: 158704B | B8: RN412DTTE10R0F50 10 OHM | C8: B020 | D8: 0001 | E8: 405567605 | F8: PC | G8: 4000 | H8: 0 | J8: 45168 | K8: 46356
A9: 158731B | B9: RN412DTTE49R9F50 49.9 OHM | C9: B020 | D9: 0001 | E9: 405011535 | F9: PC | G9: 1404 | H9: 0 | J9: 44375 | K9: 46356
A10: 158731B | B10: RN412DTTE49R9F50 49.9 OHM | C10: B020 | D10: 0001 | E10: 405009546 | F10: PC | G10: 1956 | H10: 0 | J10: 44438 | K10: 46356
A11: 158758B | B11: RN412DTTE1000F50 100 OHM | C11: B020 | D11: 0001 | E11: 405164440 | F11: PC | G11: 1632 | H11: 0 | J11: 44805 | K11: 46356
A12: 158758B | B12: RN412DTTE1000F50 100 OHM | C12: B020 | D12: 0001 | E12: 405539577 | F12: PC | G12: 6000 | H12: 0 | J12: 45168 | K12: 46356
A13: 158767B | B13: RN412DTTE1500F50 150 OHM | C13: B020 | D13: 0001 | E13: 405079921 | F13: PC | G13: 457 | H13: 0 | J13: 44657 | K13: 46356
... A194: 361146B | B194: MMA02040E2802BB300 28KOHM | C194: B020 | D194: 0001 | E194: 404918541 | F194: PC | G194: 3000 | H194: 0 | J194: 44253 | K194: 46356
A195: 361146B | B195: MMA02040E2802BB300 28KOHM | C195: B020 | D195: 0001 | E195: 404976129 | F195: PC | G195: 2186 | H195: 0 | I195: 44609 | J195: 45955 | K195: 46142
A196: 361565A | B196: TC4051BF(EL,N,F) | C196: B020 | D196: 0001 | E196: 405633856 | F196: PC | G196: 1645 | H196: 0 | J196: 45939 | K196: 46356
A197: 361636C | B197: NJM2904M-TE1-#**** | C197: B020 | D197: 0001 | E197: 405760889 | F197: PC | G197: 1550 | H197: 0 | J197: 45623 | K197: 46356
A198: 361636C | B198: NJM2904M-TE1-#**** | C198: B020 | D198: 0001 | E198: 406181980 | F198: PC | G198: 1333 | H198: 0 | J198: 45924 | K198: 46356
A199: 361636C | B199: NJM2904M-TE1-#**** | C199: B020 | D199: 0001 | E199: 406255804 | F199: PC | G199: 2 | H199: 0 | J199: 45972 | K199: 46356
A200: 361636C | B200: NJM2904M-TE1-#**** | C200: B020 | D200: 0001 | E200: 406255806 | F200: PC | G200: 12 | H200: 0 | J200: 46001 | K200: 46387
A201: 361636C | B201: NJM2904M-TE1-#**** | C201: B020 | D201: 0001 | E201: 406325208 | F201: PC | G201: 9 | H201: 0 | J201: 46029 | K201: 46418
A202: 361636C | B202: NJM2904M-TE1-#**** | C202: B020 | D202: 0001 | E202: 406332139 | F202: PC | G202: 3 | H202: 0 | J202: 46049 | K202: 46418
A203: 361636C | B203: NJM2904M-TE1-#**** | C203: B020 | D203: 0001 | E203: 406359932 | F203: PC | G203: 1 | H203: 0 | J203: 46052 | K203: 46418
A204: 361636C | B204: NJM2904M-TE1-#**** | C204: B020 | D204: 0001 | E204: 406349346 | F204: PC | G204: 7 | H204: 0 | J204: 46055 | K204: 46446
A205: 361636C | B205: NJM2904M-TE1-#**** | C205: B020 | D205: 0001 | E205: 406337480 | F205: PC | G205: 13004 | H205: 0 | J205: 46077 | K205: 46446
A206: 361636C | B206: NJM2904M-TE1-#**** | C206: B020 | D206: 0001 | E206: 406355575 | F206: PC | G206: 2000 | H206: 0 | J206: 46080 | K206: 46446
A207: 361636C | B207: NJM2904M-TE1-#**** | C207: B020 | D207: 0001 | E207: 406351442 | F207: PC | G207: 2000 | H207: 0 | J207: 46090 | K207: 46477
... A6432: 9000058958 | B6432: RG1005P-104-B-T10 100K OHM | C6432: B020 | D6432: 0001 | E6432: 406198397 | F6432: PC | G6432: 7298 | H6432: 0 | J6432: 46098 | K6432: 46356
A6433: 9000058966 | B6433: DLW5ATN272SQ2L | C6433: B020 | D6433: 0001 | E6433: 405939425 | F6433: PC | G6433: 216 | H6433: 0 | I6433: 45549 | J6433: 45955 | K6433: 46142
A6434: 9000058968 | B6434: DSO221SRBB 3.072MHZ | C6434: B020 | D6434: 0001 | E6434: 406066534 | F6434: PC | G6434: 106 | H6434: 0 | J6434: 45644 | K6434: 46356
A6435: 9000058968 | B6435: DSO221SRBB 3.072MHZ | C6435: B020 | D6435: 0001 | E6435: 406350526 | F6435: PC | G6435: 2000 | H6435: 0 | J6435: 45980 | K6435: 46356
A6436: 9000058976 | B6436: SN74LVC2G17DRYR | C6436: B020 | D6436: 0001 | E6436: 405843472 | F6436: PC | G6436: 626 | H6436: 0 | J6436: 45817 | K6436: 46356
A6437: 9000058976 | B6437: SN74LVC2G17DRYR | C6437: B020 | D6437: 0001 | E6437: 406115789 | F6437: PC | G6437: 4276 | H6437: 0 | J6437: 46043 | K6437: 46418
A6438: 9000058976 | B6438: SN74LVC2G17DRYR | C6438: B020 | D6438: 0001 | E6438: 406115790 | F6438: PC | G6438: 5000 | H6438: 0 | J6438: 46094 | K6438: 46477
A6439: 9000058984 | B6439: DLW21SN900HQ2L | C6439: B020 | D6439: 0001 | E6439: 405787153 | F6439: PC | G6439: 2 | H6439: 0 | J6439: 45447 | K6439: 46356
A6440: 9000058984 | B6440: DLW21SN900HQ2L | C6440: B020 | D6440: 0001 | E6440: 406228485 | F6440: PC | G6440: 4000 | H6440: 0 | J6440: 45889 | K6440: 46356
A6441: 9000058984 | B6441: DLW21SN900HQ2L | C6441: B020 | D6441: 0001 | E6441: 406242345 | F6441: PC | G6441: 1875 | H6441: 0 | J6441: 45889 | K6441: 46356
A6442: 9000058984 | B6442: DLW21SN900HQ2L | C6442: B020 | D6442: 0001 | E6442: 406286221 | F6442: PC | G6442: 2000 | H6442: 0 | J6442: 45940 | K6442: 46356
A6443: 9000058984 | B6443: DLW21SN900HQ2L | C6443: B020 | D6443: 0001 | E6443: 406295858 | F6443: PC | G6443: 2000 | H6443: 0 | J6443: 45978 | K6443: 46356
A6444: 9000058984 | B6444: DLW21SN900HQ2L | C6444: B020 | D6444: 0001 | E6444: 406319984 | F6444: PC | G6444: 2000 | H6444: 0 | J6444: 46006 | K6444: 46387
...
